Workbook

Sheet SHUI & PIT
A1: Taxable income | B1: PIT Rate | C1: PIT Deduct | E1: 0.1
A2: 0 | B2: 0.05 | C2: 0
A3: 5000000 | B3: 0.1 | C3: 250000
A4: 10000000 | B4: 0.15 | C4: 750000
A5: 18000000 | B5: 0.2 | C5: 1650000
A6: 32000000 | B6: 0.25 | C6: 3250000
A7: 52000000 | B7: 0.3 | C7: 5850000
A8: 80000000 | B8: 0.35 | C8: 9850000
B10: Statutory pay rate: | C10: 1800000 | D10: SI, HI | E10: Contribution rates | F10: SI | G10: HI | H10: UI | I10: TU
B11: Region-based minimum wages: | C11: 4160000 | D11: UI | E11: EE | F11: 0.08 | G11: 0.015 | H11: 0.01
B12: SHI salary contribution cap: | C12: =C10*20 -> 36000000 | E12: ER | F12: 0.175 | G12: 0.03 | H12: 0.01 | I12: 0.02
B13: UI salary contribution cap: | C13: =C11*20 -> 83200000
B16: SEIT | C16: Work location | D16: Total salary for Social Insurance, Health Insurance | E16: Total salary for Unemployment Insurance | F16: Social Insurance (Salary for SI x 25.5%) | G16: Health Insurance fee (Salary for HI x 4.5%) | H16: Unemployment Insurance (Salary for UI x 2%) | I16: Supplement payment (*) | K16: debt from last month | L16: Total of SI, HI, UI
I17: Supplement payment (*) | J17: HI
B18: 1 | C18: 2 | D18: 3 | E18: 4 | F18: 5 | G18: 6 | H18: 7 | I18: 8 | J18: 9 | K18: 10 | L18: 11
B19: 1 | C19: VNM - SEVN - HQ | D19: =SUMIF(#REF!,'SHUI & PIT'!$C19,#REF!)-D21 -> #REF! | E19: =SUMIF(#REF!,'SHUI & PIT'!$C19,#REF!)-E21 -> #REF! | F19: =SUMIF(#REF!,'SHUI & PIT'!$C19,#REF!)+SUMIF(#REF!,'SHUI & PIT'!$C19,#REF!)-F21 -> #REF! | G19: =SUMIF(#REF!,'SHUI & PIT'!$C19,#REF!)+SUMIF(#REF!,'SHUI & PIT'!$C19,#REF!)-G21 -> #REF! | H19: =SUMIF(#REF!,'SHUI & PIT'!$C19,#REF!)+SUMIF(#REF!,'SHUI & PIT'!$C19,#REF!)-H21 -> #REF! | L19: =ROUND(SUM(F19:H19),0) -> #REF!
B20: 2 | C20: VNM - Hanoi - Vinaconex Bldg. | D20: =SUMIF(#REF!,'SHUI & PIT'!$C20,#REF!) -> #REF! | E20: =SUMIF(#REF!,'SHUI & PIT'!$C20,#REF!) -> #REF! | F20: =SUMIF(#REF!,'SHUI & PIT'!$C20,#REF!)+SUMIF(#REF!,'SHUI & PIT'!$C20,#REF!) -> #REF! | G20: =SUMIF(#REF!,'SHUI & PIT'!$C20,#REF!)+SUMIF(#REF!,'SHUI & PIT'!$C20,#REF!) -> #REF! | H20: =SUMIF(#REF!,'SHUI & PIT'!$C20,#REF!)+SUMIF(#REF!,'SHUI & PIT'!$C20,#REF!) -> #REF! | L20: =ROUND(SUM(F20:H20),0) -> #REF!
B21: 3 | C21: 00247979 | D21: =SUMIF(#REF!,'SHUI & PIT'!$C$21,#REF!) -> #REF! | E21: =SUMIF(#REF!,'SHUI & PIT'!$C$21,#REF!) -> #REF! | F21: =SUMIF(#REF!,'SHUI & PIT'!$C21,#REF!)+SUMIF(#REF!,'SHUI & PIT'!$C21,#REF!) -> #REF! | G21: =SUMIF(#REF!,'SHUI & PIT'!$C21,#REF!)+SUMIF(#REF!,'SHUI & PIT'!$C21,#REF!) -> #REF! | H21: =SUMIF(#REF!,'SHUI & PIT'!$C21,#REF!)+SUMIF(#REF!,'SHUI & PIT'!$C21,#REF!) -> #REF! | L21: =ROUND(SUM(F21:H21),0) -> #REF!
B22: TOTAL PAID TO GOVERNEMNT | L22: =SUM(L19:L21) -> #REF!
B24: SEVL | C24: Work location | D24: Total salary for Social Insurance, Health Insurance | E24: Total salary for Unemployment Insurance | F24: Social Insurance (Salary for SI x 25.5%) | G24: Health Insurance fee (Salary for HI x 4.5%) | H24: Unemployment Insurance (Salary for UI x 2%) | I24: Supplement payment (*) | K24: debt from last month | L24: Total of SI, HI, UI
I25: Supplement payment (*) | J25: HI
B26: 1 | C26: 2 | D26: 3 | E26: 4 | F26: 5 | G26: 6 | H26: 7 | I26: 8 | J26: 9 | K26: 10 | L26: 11
B27: 1 | C27: VNM - SEVN - HQ | D27: =SUMIF(#REF!,'SHUI & PIT'!$C27,#REF!)-D29 -> #REF! | E27: =SUMIF(#REF!,'SHUI & PIT'!$C27,#REF!)-E29 -> #REF! | F27: =SUMIF(#REF!,'SHUI & PIT'!$C27,#REF!)+SUMIF(#REF!,'SHUI & PIT'!$C27,#REF!)-F29 -> #REF! | G27: =SUMIF(#REF!,'SHUI & PIT'!$C27,#REF!)+SUMIF(#REF!,'SHUI & PIT'!$C27,#REF!)-G29 -> #REF! | H27: =SUMIF(#REF!,'SHUI & PIT'!$C27,#REF!)+SUMIF(#REF!,'SHUI & PIT'!$C27,#REF!)-H29 -> #REF! | L27: =ROUND(SUM(F27:H27),0) -> #REF!
B28: 2 | C28: VNM - Hanoi - Vinaconex Bldg. | D28: =SUMIF(#REF!,'SHUI & PIT'!$C28,#REF!) -> #REF! | E28: =SUMIF(#REF!,'SHUI & PIT'!$C28,#REF!) -> #REF! | F28: =SUMIF(#REF!,'SHUI & PIT'!$C28,#REF!)+SUMIF(#REF!,'SHUI & PIT'!$C28,#REF!) -> #REF! | G28: =SUMIF(#REF!,'SHUI & PIT'!$C28,#REF!)+SUMIF(#REF!,'SHUI & PIT'!$C28,#REF!) -> #REF! | H28: =SUMIF(#REF!,'SHUI & PIT'!$C28,#REF!)+SUMIF(#REF!,'SHUI & PIT'!$C28,#REF!) -> #REF! | L28: =ROUND(SUM(F28:H28),0) -> #REF!
B29: 3 | C29: 00247979 | D29: =SUMIF(#REF!,'SHUI & PIT'!$C$21,#REF!) -> #REF! | E29: =SUMIF(#REF!,'SHUI & PIT'!$C$21,#REF!) -> #REF! | F29: =SUMIF(#REF!,'SHUI & PIT'!$C29,#REF!)+SUMIF(#REF!,'SHUI & PIT'!$C29,#REF!) -> #REF! | G29: =SUMIF(#REF!,'SHUI & PIT'!$C29,#REF!)+SUMIF(#REF!,'SHUI & PIT'!$C29,#REF!) -> #REF! | H29: =SUMIF(#REF!,'SHUI & PIT'!$C29,#REF!)+SUMIF(#REF!,'SHUI & PIT'!$C29,#REF!) -> #REF! | L29: =ROUND(SUM(F29:H29),0) -> #REF!
B30: TOTAL PAID TO GOVERNEMNT | L30: =SUM(L27:L29) -> #REF!
C38: Tính theo | D38: Căn cứ đóng BHXH | E38: Chịu thuế TNCN
B39: Responsibility | C39: Toàn bộ số tiền theo tháng | D39: Có | E39: Có
B40: Petrol | C40: Số ngày làm việc thực tế | D40: Không | E40: Có
B41: Parking | C41: Số ngày làm việc thực tế | D41: Không | E41: Có
B42: Support allowance | C42: Toàn bộ số tiền được gửi | D42: Không | E42: Có
B43: Retention allowance | C43: Toàn bộ số tiền được gửi | D43: Không | E43: Có
B44: Sales incentive | C44: Toàn bộ số tiền được gửi | D44: Không | E44: Có
B45: OT - PIT | C45: Số tiền được gửi theo Timesheet | D45: Không | E45: Có
B46: OT - Non PIT | C46: Số tiền được gửi theo Timesheet | D46: Không | E46: Không
B47: Meal allowance | C47: Số ngày làm việc thực tế | D47: Không | E47: Không
B48: Deduction of meal | C48: Số tiền được gửi theo Timesheet | D48: Không | E48: Không
B49: Phone | C49: Toàn bộ số tiền theo tháng | D49: Không | E49: Không
B50: Taxi | C50: Toàn bộ số tiền theo tháng | D50: Không | E50: Có
B51: Rewards | C51: Toàn bộ số tiền được gửi | D51: Không | E51: Có

Sheet SEVL
A1: 1 | B1: 2 | C1: 3 | D1: 4 | F1: 6 | G1: 7 | H1: 8 | I1: 9 | M1: 10 | N1: 11 | P1: 12 | W1: 17 | X1: 18 | Y1: 20 | Z1: 21 | AA1: 22 | AB1: 23 | AC1: 24 | AD1: 25 | AE1: 26 | AF1: 27 | AG1: 28 | AH1: 29 | AI1: 30 | AJ1: 31 | AK1: 32 | AL1: 33 | AM1: 34 | AN1: 35 | AV1: 36 | AW1: 37 | AX1: 38 | BC1: 39 | BD1: 40 | BE1: 41 | BF1: 42 | BG1: 43 | BH1: 44 | BI1: 45 | BJ1: 46 | BK1: 47 | BL1: 48 | BM1: 49 | BN1: 50 | BO1: 51 | BP1: 52 | BQ1: 53 | BR1: 54 | BS1: 55 | BT1: 56 | BU1: 57 | BV1: 58 | BW1: 59 | BX1: 60 | BY1: 61 | BZ1: 62 | CA1: 63 | CB1: 64 | CC1: 65 | CD1: 66 | CF1: 67 | CG1: 68 | CI1: 73 | CJ1: 69
Q2: Số ngày tt | R2: Total tháng | V2: Total tháng | BI2: =425700-29800000*1% -> 127700
C3: 45342 | G3: TN chịu thuế | H3: Miễn thuế TNCN | I3: 730k trở xuống thì miễn thuế | J3: TN chịu thuế | K3: TN chịu thuế | L3: TN chịu thuế | P3: Trả theo ngày thực tế làm việc | Q3: TN chịu thuế | R3: Miễn thuế TNCN | S3: 730k trở xuống thì miễn thuế | T3: TN chịu thuế | U3: TN chịu thuế | V3: TN chịu thuế | AF3: Công thức giống với cột TU ee -> bỏ thử | BN3: Thu nhập tính thuế | BO3: Thuế TNCN phải nộp | CJ3: Thu nhập chịu thuế
F4: =SUM(F7:F26) -> 371740000 | G4: =SUM(G7:G26) -> 12420000 | H4: =SUM(H7:H26) -> 9000000 | I4: =SUM(I7:I26) -> 8893000 | M4: =SUM(M7:M26) -> 3850 | N4: =SUM(N7:N26) -> 3726 | P4: =SUM(P7:P26) -> 364377500 | Q4: =SUM(Q7:Q26) -> 8981250 | R4: =SUM(R7:R26) -> 8677083.3 | S4: =SUM(S7:S26) -> 7001690.7 | W4: =SUM(W7:W26) -> 0 | X4: =SUM(X7:X26) -> 7125000 | Y4: =SUM(Y7:Y26) -> 0 | Z4: =SUM(Z7:Z26) -> 0 | AA4: =SUM(AA7:AA26) -> 0 | AB4: =SUM(AB7:AB26) -> 0 | AC4: =SUM(AC7:AC26) -> 0 | AD4: =SUM(AD7:AD26) -> 0 | ... AN4: =SUM(AN7:AN26) -> 0 | AO4: =SUM(AO7:AO139) -> 52.24 | AP4: =SUM(AP7:AP139) -> 15.17 | AQ4: =SUM(AQ7:AQ139) -> 10.08 | AR4: =SUM(AR7:AR139) -> 0 | AS4: =SUM(AS7:AS139) -> 0 | AT4: =SUM(AT7:AT139) -> 0 | AU4: =SUM(AU7:AU139) -> 0 | AV4: =SUM(AV7:AV26) -> 1723602.7 | AW4: =SUM(AW7:AW26) -> 1121649.5 | AX4: =SUM(AX7:AX26) -> 1989449.3 | BC4: =SUM(BC7:BC26) -> 5900702 | BD4: =SUM(BD7:BD26) -> 4.3475119e+08 | BE4: =SUM(BE7:BE26) -> 0 | BF4: =SUM(BF7:BF26) -> 0 | BG4: =SUM(BG7:BG26) -> 27135200 | BH4: =SUM(BH7:BH26) -> 5087850 | BI4: =SUM(BI7:BI26) -> 3781900 | BJ4: =SUM(BJ7:BJ26) -> 36004950 | ... CD4: =SUM(CD7:CD26) -> 2461658 | CF4: =SUM(CF7:CF105) -> 319000 | CG4: =SUM(CG7:CG26) -> 21.32 | CJ4: =SUM(CJ7:CJ26) -> 4.1661076e+08
A5: EMPLOYEE CODE | B5: EMPLOYEE NAME | C5: HIRE DATE | D5: NEW HIRE/ RESIGNEE/ LONG LEAVE | E5: Location | F5: Base Salary | G5: Gaz | H5: Phone Amount | I5: Meal | J5: Responsibility | K5: Parking | L5: Taxi allowance | M5: Standard whr | N5: Actual Working Hours incl. Paid leave | O5: Actual Working Hours. NOT incl. Paid leave | P5: Actual Basic salary | Q5: Gaz | R5: Phone Amount | S5: Meal | T5: Responsibility | U5: Parking | V5: Taxi allowance | W5: Recognition Bonus | X5: Other Income | Y5: Other Bonus | Z5: Bonus - STIP | AA5: Sign-on bonus | AB5: Retention Bonus | AC5: Marsh Insurance refund (Non-tax) | AD5: Adjustment | AE5: TU Participation | AF5: Trade Union Allowance | AG5: Goodwill | AH5: Sales Incentive | AI5: 13th month salary | AJ5: Referral Bonus | AK5: Severance allowance (Non-tax) | AL5: Notice Pay by ER | AM5: Reimbursement Payment | AN5: VN-Employer Tax | AO5: OT 1.5 Hours | AP5: OT 2 Hours | AQ5: OT 3 Hours | AR5: Night shif payment | AS5: OT Night shift wk day | AT5: OT Night shift off day | AU5: OT Ngiht shift Holiday | AV5: OT 1.5 Amount | AW5: OT 2 Amount | AX5: OT 3 Amount | AY5: Night shif amount | AZ5: OT Night shift wk day amount | BA5: OT Night shift off day amount | BB5: OT Ngiht shift Holiday amount | BC5: Total Overtime Amount | BD5: Actual Total Income | BE5: Unpaid Leave (Covid-19) | BF5: Ded. Outstanding A-Leave | BG5: Social Ins. - 8% | BH5: Medical Ins. - 1.5% | BI5: Unemployment Ins. - 1 % | BJ5: SI-HI-IU Total 10.5% | BK5: Employee Trade Union | BL5: Dependent No. | BM5: Dependent Amount | BN5: Tax Accessable Income | BO5: Monthly PIT | BP5: Other Deduction | BQ5: Reimbursement deduction | BR5: Marsh / Other Deduction | BS5: Total Deductions | BT5: Net Pay | BU5: Social Ins. - 17.5% | BV5: Medical Ins. - 3% | BW5: Unempt Ins. - 1% | BX5: MI 4.5% | BY5: SI-HI-UI Total 21.5% | BZ5: Trade Union ER 2% | CA5: Total Cost to Employer | CB5: Salary for SI | CC5: Salary for UI | CD5: OT Non-Taxable (Ref) | CE5: OT PIT for check | CF5: Meal allowance deduction for La Nga visit | CG5: OT Tài xế - giờ | CH5: OT tài xế tiền | CI5: La Nga không ăn cơm nhà máy | CJ5: Taxable Income
F6: =SUBTOTAL(9,F7:F55) -> 403960000 | G6: =SUBTOTAL(9,G7:G55) -> 12420000 | H6: =SUBTOTAL(9,H7:H55) -> 9700000 | I6: =SUBTOTAL(9,I7:I55) -> 8893000 | J6: =SUBTOTAL(9,J7:J55) -> 19170000 | K6: =SUBTOTAL(9,K7:K55) -> 4400000 | L6: =SUBTOTAL(9,L7:L55) -> 2500000 | M6: =SUBTOTAL(9,M7:M55) -> 4428 | ... CJ6: =SUBTOTAL(9,CJ7:CJ55) -> 4.5111397e+08
A7: 0639 | C7: 42461 | D7: =DATEDIF(C7,$C$3,"D") -> 2881 | E7: HCM | F7: 15710000 | G7: 0 | H7: 300000 | I7: 680000 | J7: 0 | K7: 0 | L7: 0 | M7: =_xlfn.XLOOKUP(A7,Main!$B$13:$B$1048576,Main!$D$13:$D$1048576,0,0)*8 -> 194 | N7: =_xlfn.XLOOKUP(A7,Main!$B$13:$B$1048576,Main!$BQ$13:$BQ$1048576,0,0) -> 194 | O7: =_xlfn.XLOOKUP(A7,Main!$B$13:$B$1048576,Main!$BR$13:$BR$1048576,0,0) -> 134 | P7: =ROUND(F7/M7*N7,0) -> 15710000 | Q7: =G7/M7*O7 -> 0 | R7: =IF(D7>=(M7/8),H7,H7/M7*N7) -> 300000 | S7: =IF(CI7="N",26500*(ROUND(O7/8,0)),(I7/M7*O7)-CF7) -> 150690.72 | T7: =J7 -> 0 | U7: =K7/M7*O7 -> 0 | V7: =IF(D7>=(M7/8),L7,L7/M7*N7) -> 0 | AE7: YES | AO7: =_xlfn.XLOOKUP($A7,Main!$B$13:$B$35,Main!BU$13:BU$35,0,0) -> 0 | AP7: =_xlfn.XLOOKUP($A7,Main!$B$13:$B$35,Main!BV$13:BV$35,0,0) -> 0 | AQ7: =_xlfn.XLOOKUP($A7,Main!$B$13:$B$35,Main!BW$13:BW$35,0,0) -> 0 | AR7: =_xlfn.XLOOKUP($A7,Main!$B$13:$B$35,Main!BX$13:BX$35,0,0) -> 0 | AS7: =_xlfn.XLOOKUP($A7,Main!$B$13:$B$35,Main!BY$13:BY$35,0,0) -> 0 | AT7: =_xlfn.XLOOKUP($A7,Main!$B$13:$B$35,Main!BZ$13:BZ$35,0,0) -> 0 | AU7: =_xlfn.XLOOKUP($A7,Main!$B$13:$B$35,Main!CA$13:CA$35,0,0) -> 0 | AV7: =$F7/$M7*AO7*150% -> 0 | AW7: =$F7/$M7*AP7*200% -> 0 | AX7: =$F7/$M7*AQ7*300% -> 0 | AY7: =$F7/$M7*AR7*30% -> 0 | AZ7: =$F7/$M7*AS7*210% -> 0 | BA7: =$F7/$M7*AT7*270% -> 0 | BB7: =$F7/$M7*AU7*390% -> 0 | BC7: =ROUND(SUM(AV7:BB7)+CH7,0) -> 558000 | BD7: =SUM(P7:AN7)+BC7 -> 16718691 | BG7: =ROUND($CB7*'SHUI & PIT'!$F$11,0) -> 1256800 | BH7: =ROUND($CB7*'SHUI & PIT'!$G$11,0) -> 235650 | BI7: =ROUND($CC7*'SHUI & PIT'!$H$11,0) -> 157100 | BJ7: =SUM(BG7:BI7) -> 1649550 | BK7: =IF(E7="La Nga",0,IF(E7="HCM",35000,IF(AE7="YES",IF($BG7>0,ROUND(MIN($CB7*1%,180000),0),0),0))) -> 35000 | BL7: =VLOOKUP(A7,'[1]Payroll master '!B$12:AD$160,29,0) -> 0 | BM7: =11000000+4400000*BL7 -> 11000000 | BN7: =ROUND(IF((CJ7-BJ7-BM7-BR7)<0,0,(CJ7-BJ7-BM7-BR7)),0) -> 3618450 | BO7: =ROUND((VLOOKUP(BN7,'SHUI & PIT'!$A$1:$C$8,2,1)*BN7-VLOOKUP(BN7,'SHUI & PIT'!$A$1:$C$8,3,1)),0) -> 180923 | BP7: =Y7 -> 0 | BS7: =BJ7+BO7+BP7+BR7+BE7+BF7+BQ7+BK7 -> 1865473 | BT7: =ROUND(IF((BD7-BS7)<0,0,(BD7-BS7)),0) -> 14853218 | BU7: =ROUND($CB7*'SHUI & PIT'!$F$12,0) -> 2749250 | BV7: =ROUND($CB7*'SHUI & PIT'!$G$12,0) -> 471300 | BW7: =ROUND($CC7*'SHUI & PIT'!$H$12,0) -> 157100 | BY7: =SUM(BU7:BX7) -> 3377650 | BZ7: =IF(BU7>0,ROUND($CB7*'SHUI & PIT'!$I$12,0),0) -> 314200 | CA7: =BD7+BY7-AC7+BZ7-BQ7 -> 20410541 | CB7: =IF(($F7+$T7)>='SHUI & PIT'!$C$12,'SHUI & PIT'!$C$12,($F7+$T7)) -> 15710000 | CC7: =IF(($F7+$T7)>='SHUI & PIT'!$C$13,'SHUI & PIT'!$C$13,($F7+$T7)) -> 15710000 | CD7: =ROUND(($F7/M7)*($AO7*0.5+$AP7+$AQ7*2+AR7*0.3+AS7*1.1+AT7*1.7+AU7*2.9),0) -> 0 | CE7: =BC7-CD7 -> 558000 | CF7: =_xlfn.XLOOKUP(A7,'[2]Termination and others'!B$12:B$33,'[2]Termination and others'!F$12:F$33,0,0) -> 319000 | CG7: =VLOOKUP(A7,Main!$B$13:$BN$405,65,0) -> 11.16 | CH7: =IF(50000<F7/M7,50000,F7/M7)*CG7 -> 558000 | CJ7: =BD7-R7-S7-AK7-CD7-AC7-BE7-BF7-BQ7 -> 16268000
A8: 11094 | C8: 43399 | D8: =DATEDIF(C8,$C$3,"D") -> 1943 | E8: HCM | F8: 19510000 | G8: 1200000 | H8: 500000 | I8: 680000 | J8: 0 | K8: 400000 | L8: 500000 | M8: =_xlfn.XLOOKUP(A8,Main!$B$13:$B$1048576,Main!$D$13:$D$1048576,0,0)*8 -> 192 | N8: =_xlfn.XLOOKUP(A8,Main!$B$13:$B$1048576,Main!$BQ$13:$BQ$1048576,0,0) -> 192 | O8: =_xlfn.XLOOKUP(A8,Main!$B$13:$B$1048576,Main!$BR$13:$BR$1048576,0,0) -> 152 | P8: =ROUND(F8/M8*N8,0) -> 19510000 | Q8: =G8/M8*O8 -> 950000 | R8: =IF(D8>=(M8/8),H8,H8/M8*N8) -> 500000 | S8: =IF(CI8="N",26500*(ROUND(O8/8,0)),(I8/M8*O8)-CF8) -> 538333.33 | T8: =J8 -> 0 | U8: =K8/M8*O8 -> 316666.67 | V8: =IF(D8>=(M8/8),L8,L8/M8*N8) -> 500000 | AE8: YES | AO8: =_xlfn.XLOOKUP($A8,Main!$B$13:$B$35,Main!BU$13:BU$35,0,0) -> 0 | AP8: =_xlfn.XLOOKUP($A8,Main!$B$13:$B$35,Main!BV$13:BV$35,0,0) -> 0 | AQ8: =_xlfn.XLOOKUP($A8,Main!$B$13:$B$35,Main!BW$13:BW$35,0,0) -> 0 | AR8: =_xlfn.XLOOKUP($A8,Main!$B$13:$B$35,Main!BX$13:BX$35,0,0) -> 0 | AS8: =_xlfn.XLOOKUP($A8,Main!$B$13:$B$35,Main!BY$13:BY$35,0,0) -> 0 | AT8: =_xlfn.XLOOKUP($A8,Main!$B$13:$B$35,Main!BZ$13:BZ$35,0,0) -> 0 | AU8: =_xlfn.XLOOKUP($A8,Main!$B$13:$B$35,Main!CA$13:CA$35,0,0) -> 0 | AV8: =$F8/$M8*AO8*150% -> 0 | AW8: =$F8/$M8*AP8*200% -> 0 | AX8: =$F8/$M8*AQ8*300% -> 0 | AY8: =$F8/$M8*AR8*30% -> 0 | AZ8: =$F8/$M8*AS8*210% -> 0 | BA8: =$F8/$M8*AT8*270% -> 0 | BB8: =$F8/$M8*AU8*390% -> 0 | BC8: =ROUND(SUM(AV8:BB8)+CH8,0) -> 0 | BD8: =SUM(P8:AN8)+BC8 -> 22315000 | BG8: =ROUND($CB8*'SHUI & PIT'!$F$11,0) -> 1560800 | BH8: =ROUND($CB8*'SHUI & PIT'!$G$11,0) -> 292650 | BI8: =ROUND($CC8*'SHUI & PIT'!$H$11,0) -> 195100 | BJ8: =SUM(BG8:BI8) -> 2048550 | BK8: =IF(E8="La Nga",0,IF(E8="HCM",35000,IF(AE8="YES",IF($BG8>0,ROUND(MIN($CB8*1%,180000),0),0),0))) -> 35000 | BL8: =VLOOKUP(A8,'[1]Payroll master '!B$12:AD$160,29,0) -> 4 | BM8: =11000000+4400000*BL8 -> 28600000 | BN8: =ROUND(IF((CJ8-BJ8-BM8-BR8)<0,0,(CJ8-BJ8-BM8-BR8)),0) -> 0 | BO8: =ROUND((VLOOKUP(BN8,'SHUI & PIT'!$A$1:$C$8,2,1)*BN8-VLOOKUP(BN8,'SHUI & PIT'!$A$1:$C$8,3,1)),0) -> 0 | BP8: =Y8 -> 0 | BS8: =BJ8+BO8+BP8+BR8+BE8+BF8+BQ8+BK8 -> 2083550 | BT8: =ROUND(IF((BD8-BS8)<0,0,(BD8-BS8)),0) -> 20231450 | BU8: =ROUND($CB8*'SHUI & PIT'!$F$12,0) -> 3414250 | BV8: =ROUND($CB8*'SHUI & PIT'!$G$12,0) -> 585300 | BW8: =ROUND($CC8*'SHUI & PIT'!$H$12,0) -> 195100 | BY8: =SUM(BU8:BX8) -> 4194650 | BZ8: =IF(BU8>0,ROUND($CB8*'SHUI & PIT'!$I$12,0),0) -> 390200 | CA8: =BD8+BY8-AC8+BZ8-BQ8 -> 26899850 | CB8: =IF(($F8+$T8)>='SHUI & PIT'!$C$12,'SHUI & PIT'!$C$12,($F8+$T8)) -> 19510000 | CC8: =IF(($F8+$T8)>='SHUI & PIT'!$C$13,'SHUI & PIT'!$C$13,($F8+$T8)) -> 19510000 | CD8: =ROUND(($F8/M8)*($AO8*0.5+$AP8+$AQ8*2+AR8*0.3+AS8*1.1+AT8*1.7+AU8*2.9),0) -> 0 | CE8: =BC8-CD8 -> 0 | CF8: =_xlfn.XLOOKUP(A8,'[2]Termination and others'!B$12:B$33,'[2]Termination and others'!F$12:F$33,0,0) -> 0 | CG8: =VLOOKUP(A8,Main!$B$13:$BN$405,65,0) -> 0 | CH8: =IF(50000<F8/M8,50000,F8/M8)*CG8 -> 0 | CJ8: =BD8-R8-S8-AK8-CD8-AC8-BE8-BF8-BQ8 -> 21276667
A9: 11126 | C9: 43479 | D9: =DATEDIF(C9,$C$3,"D") -> 1863 | E9: HCM | F9: 16690000 | G9: 1200000 | H9: 500000 | I9: 680000 | J9: 0 | K9: 400000 | L9: 500000 | M9: =_xlfn.XLOOKUP(A9,Main!$B$13:$B$1048576,Main!$D$13:$D$1048576,0,0)*8 -> 192 | N9: =_xlfn.XLOOKUP(A9,Main!$B$13:$B$1048576,Main!$BQ$13:$BQ$1048576,0,0) -> 192 | O9: =_xlfn.XLOOKUP(A9,Main!$B$13:$B$1048576,Main!$BR$13:$BR$1048576,0,0) -> 152 | P9: =ROUND(F9/M9*N9,0) -> 16690000 | Q9: =G9/M9*O9 -> 950000 | R9: =IF(D9>=(M9/8),H9,H9/M9*N9) -> 500000 | S9: =IF(CI9="N",26500*(ROUND(O9/8,0)),(I9/M9*O9)-CF9) -> 538333.33 | T9: =J9 -> 0 | U9: =K9/M9*O9 -> 316666.67 | V9: =IF(D9>=(M9/8),L9,L9/M9*N9) -> 500000 | AE9: YES | AO9: =_xlfn.XLOOKUP($A9,Main!$B$13:$B$35,Main!BU$13:BU$35,0,0) -> 0 | AP9: =_xlfn.XLOOKUP($A9,Main!$B$13:$B$35,Main!BV$13:BV$35,0,0) -> 0 | AQ9: =_xlfn.XLOOKUP($A9,Main!$B$13:$B$35,Main!BW$13:BW$35,0,0) -> 0 | AR9: =_xlfn.XLOOKUP($A9,Main!$B$13:$B$35,Main!BX$13:BX$35,0,0) -> 0 | AS9: =_xlfn.XLOOKUP($A9,Main!$B$13:$B$35,Main!BY$13:BY$35,0,0) -> 0 | AT9: =_xlfn.XLOOKUP($A9,Main!$B$13:$B$35,Main!BZ$13:BZ$35,0,0) -> 0 | AU9: =_xlfn.XLOOKUP($A9,Main!$B$13:$B$35,Main!CA$13:CA$35,0,0) -> 0 | AV9: =$F9/$M9*AO9*150% -> 0 | AW9: =$F9/$M9*AP9*200% -> 0 | AX9: =$F9/$M9*AQ9*300% -> 0 | AY9: =$F9/$M9*AR9*30% -> 0 | AZ9: =$F9/$M9*AS9*210% -> 0 | BA9: =$F9/$M9*AT9*270% -> 0 | BB9: =$F9/$M9*AU9*390% -> 0 | BC9: =ROUND(SUM(AV9:BB9)+CH9,0) -> 0 | BD9: =SUM(P9:AN9)+BC9 -> 19495000 | BG9: =ROUND($CB9*'SHUI & PIT'!$F$11,0) -> 1335200 | BH9: =ROUND($CB9*'SHUI & PIT'!$G$11,0) -> 250350 | BI9: =ROUND($CC9*'SHUI & PIT'!$H$11,0) -> 166900 | BJ9: =SUM(BG9:BI9) -> 1752450 | BK9: =IF(E9="La Nga",0,IF(E9="HCM",35000,IF(AE9="YES",IF($BG9>0,ROUND(MIN($CB9*1%,180000),0),0),0))) -> 35000 | BL9: =VLOOKUP(A9,'[1]Payroll master '!B$12:AD$160,29,0) -> 2 | BM9: =11000000+4400000*BL9 -> 19800000 | BN9: =ROUND(IF((CJ9-BJ9-BM9-BR9)<0,0,(CJ9-BJ9-BM9-BR9)),0) -> 0 | BO9: =ROUND((VLOOKUP(BN9,'SHUI & PIT'!$A$1:$C$8,2,1)*BN9-VLOOKUP(BN9,'SHUI & PIT'!$A$1:$C$8,3,1)),0) -> 0 | BP9: =Y9 -> 0 | BS9: =BJ9+BO9+BP9+BR9+BE9+BF9+BQ9+BK9 -> 1787450 | BT9: =ROUND(IF((BD9-BS9)<0,0,(BD9-BS9)),0) -> 17707550 | BU9: =ROUND($CB9*'SHUI & PIT'!$F$12,0) -> 2920750 | BV9: =ROUND($CB9*'SHUI & PIT'!$G$12,0) -> 500700 | BW9: =ROUND($CC9*'SHUI & PIT'!$H$12,0) -> 166900 | BY9: =SUM(BU9:BX9) -> 3588350 | BZ9: =IF(BU9>0,ROUND($CB9*'SHUI & PIT'!$I$12,0),0) -> 333800 | CA9: =BD9+BY9-AC9+BZ9-BQ9 -> 23417150 | CB9: =IF(($F9+$T9)>='SHUI & PIT'!$C$12,'SHUI & PIT'!$C$12,($F9+$T9)) -> 16690000 | CC9: =IF(($F9+$T9)>='SHUI & PIT'!$C$13,'SHUI & PIT'!$C$13,($F9+$T9)) -> 16690000 | CD9: =ROUND(($F9/M9)*($AO9*0.5+$AP9+$AQ9*2+AR9*0.3+AS9*1.1+AT9*1.7+AU9*2.9),0) -> 0 | CE9: =BC9-CD9 -> 0 | CF9: =_xlfn.XLOOKUP(A9,'[2]Termination and others'!B$12:B$33,'[2]Termination and others'!F$12:F$33,0,0) -> 0 | CG9: =VLOOKUP(A9,Main!$B$13:$BN$405,65,0) -> 0 | CH9: =IF(50000<F9/M9,50000,F9/M9)*CG9 -> 0 | CJ9: =BD9-R9-S9-AK9-CD9-AC9-BE9-BF9-BQ9 -> 18456667
A10: 11141 | C10: 43529 | D10: =DATEDIF(C10,$C$3,"D") -> 1813 | E10: HCM | F10: 12680000 | G10: 1200000 | H10: 500000 | I10: 680000 | J10: 1320000 | K10: 400000 | L10: 0 | M10: =_xlfn.XLOOKUP(A10,Main!$B$13:$B$1048576,Main!$D$13:$D$1048576,0,0)*8 -> 192 | N10: =_xlfn.XLOOKUP(A10,Main!$B$13:$B$1048576,Main!$BQ$13:$BQ$1048576,0,0) -> 192 | O10: =_xlfn.XLOOKUP(A10,Main!$B$13:$B$1048576,Main!$BR$13:$BR$1048576,0,0) -> 152 | P10: =ROUND(F10/M10*N10,0) -> 12680000 | Q10: =G10/M10*O10 -> 950000 | R10: =IF(D10>=(M10/8),H10,H10/M10*N10) -> 500000 | S10: =IF(CI10="N",26500*(ROUND(O10/8,0)),(I10/M10*O10)-CF10) -> 538333.33 | T10: =J10 -> 1320000 | U10: =K10/M10*O10 -> 316666.67 | V10: =IF(D10>=(M10/8),L10,L10/M10*N10) -> 0 | AE10: YES | AH10: 200000 | AO10: =_xlfn.XLOOKUP($A10,Main!$B$13:$B$35,Main!BU$13:BU$35,0,0) -> 0 | AP10: =_xlfn.XLOOKUP($A10,Main!$B$13:$B$35,Main!BV$13:BV$35,0,0) -> 0 | AQ10: =_xlfn.XLOOKUP($A10,Main!$B$13:$B$35,Main!BW$13:BW$35,0,0) -> 0 | AR10: =_xlfn.XLOOKUP($A10,Main!$B$13:$B$35,Main!BX$13:BX$35,0,0) -> 0 | AS10: =_xlfn.XLOOKUP($A10,Main!$B$13:$B$35,Main!BY$13:BY$35,0,0) -> 0 | AT10: =_xlfn.XLOOKUP($A10,Main!$B$13:$B$35,Main!BZ$13:BZ$35,0,0) -> 0 | AU10: =_xlfn.XLOOKUP($A10,Main!$B$13:$B$35,Main!CA$13:CA$35,0,0) -> 0 | AV10: =$F10/$M10*AO10*150% -> 0 | AW10: =$F10/$M10*AP10*200% -> 0 | AX10: =$F10/$M10*AQ10*300% -> 0 | AY10: =$F10/$M10*AR10*30% -> 0 | AZ10: =$F10/$M10*AS10*210% -> 0 | BA10: =$F10/$M10*AT10*270% -> 0 | BB10: =$F10/$M10*AU10*390% -> 0 | BC10: =ROUND(SUM(AV10:BB10)+CH10,0) -> 0 | BD10: =SUM(P10:AN10)+BC10 -> 16505000 | BG10: =ROUND($CB10*'SHUI & PIT'!$F$11,0) -> 1120000 | BH10: =ROUND($CB10*'SHUI & PIT'!$G$11,0) -> 210000 | BI10: =ROUND($CC10*'SHUI & PIT'!$H$11,0) -> 140000 | BJ10: =SUM(BG10:BI10) -> 1470000 | BK10: =IF(E10="La Nga",0,IF(E10="HCM",35000,IF(AE10="YES",IF($BG10>0,ROUND(MIN($CB10*1%,180000),0),0),0))) -> 35000 | BL10: =VLOOKUP(A10,'[1]Payroll master '!B$12:AD$160,29,0) -> 0 | BM10: =11000000+4400000*BL10 -> 11000000 | BN10: =ROUND(IF((CJ10-BJ10-BM10-BR10)<0,0,(CJ10-BJ10-BM10-BR10)),0) -> 2996667 | BO10: =ROUND((VLOOKUP(BN10,'SHUI & PIT'!$A$1:$C$8,2,1)*BN10-VLOOKUP(BN10,'SHUI & PIT'!$A$1:$C$8,3,1)),0) -> 149833 | BP10: =Y10 -> 0 | BS10: =BJ10+BO10+BP10+BR10+BE10+BF10+BQ10+BK10 -> 1654833 | BT10: =ROUND(IF((BD10-BS10)<0,0,(BD10-BS10)),0) -> 14850167 | BU10: =ROUND($CB10*'SHUI & PIT'!$F$12,0) -> 2450000 | BV10: =ROUND($CB10*'SHUI & PIT'!$G$12,0) -> 420000 | BW10: =ROUND($CC10*'SHUI & PIT'!$H$12,0) -> 140000 | BY10: =SUM(BU10:BX10) -> 3010000 | BZ10: =IF(BU10>0,ROUND($CB10*'SHUI & PIT'!$I$12,0),0) -> 280000 | CA10: =BD10+BY10-AC10+BZ10-BQ10 -> 19795000 | CB10: =IF(($F10+$T10)>='SHUI & PIT'!$C$12,'SHUI & PIT'!$C$12,($F10+$T10)) -> 14000000 | CC10: =IF(($F10+$T10)>='SHUI & PIT'!$C$13,'SHUI & PIT'!$C$13,($F10+$T10)) -> 14000000 | CD10: =ROUND(($F10/M10)*($AO10*0.5+$AP10+$AQ10*2+AR10*0.3+AS10*1.1+AT10*1.7+AU10*2.9),0) -> 0 | CE10: =BC10-CD10 -> 0 | CF10: =_xlfn.XLOOKUP(A10,'[2]Termination and others'!B$12:B$33,'[2]Termination and others'!F$12:F$33,0,0) -> 0 | CG10: =VLOOKUP(A10,Main!$B$13:$BN$405,65,0) -> 0 | CH10: =IF(50000<F10/M10,50000,F10/M10)*CG10 -> 0 | CJ10: =BD10-R10-S10-AK10-CD10-AC10-BE10-BF10-BQ10 -> 15466667
A11: 11168 | C11: 43558 | D11: =DATEDIF(C11,$C$3,"D") -> 1784 | E11: HCM | F11: 12780000 | G11: 1200000 | H11: 500000 | I11: 680000 | J11: 1320000 | K11: 400000 | L11: 0 | M11: =_xlfn.XLOOKUP(A11,Main!$B$13:$B$1048576,Main!$D$13:$D$1048576,0,0)*8 -> 192 | N11: =_xlfn.XLOOKUP(A11,Main!$B$13:$B$1048576,Main!$BQ$13:$BQ$1048576,0,0) -> 192 | O11: =_xlfn.XLOOKUP(A11,Main!$B$13:$B$1048576,Main!$BR$13:$BR$1048576,0,0) -> 152 | P11: =ROUND(F11/M11*N11,0) -> 12780000 | Q11: =G11/M11*O11 -> 950000 | R11: =IF(D11>=(M11/8),H11,H11/M11*N11) -> 500000 | S11: =IF(CI11="N",26500*(ROUND(O11/8,0)),(I11/M11*O11)-CF11) -> 538333.33 | T11: =J11 -> 1320000 | U11: =K11/M11*O11 -> 316666.67 | V11: =IF(D11>=(M11/8),L11,L11/M11*N11) -> 0 | AE11: YES | AH11: 1380000 | AO11: =_xlfn.XLOOKUP($A11,Main!$B$13:$B$35,Main!BU$13:BU$35,0,0) -> 0 | AP11: =_xlfn.XLOOKUP($A11,Main!$B$13:$B$35,Main!BV$13:BV$35,0,0) -> 0 | AQ11: =_xlfn.XLOOKUP($A11,Main!$B$13:$B$35,Main!BW$13:BW$35,0,0) -> 0 | AR11: =_xlfn.XLOOKUP($A11,Main!$B$13:$B$35,Main!BX$13:BX$35,0,0) -> 0 | AS11: =_xlfn.XLOOKUP($A11,Main!$B$13:$B$35,Main!BY$13:BY$35,0,0) -> 0 | AT11: =_xlfn.XLOOKUP($A11,Main!$B$13:$B$35,Main!BZ$13:BZ$35,0,0) -> 0 | AU11: =_xlfn.XLOOKUP($A11,Main!$B$13:$B$35,Main!CA$13:CA$35,0,0) -> 0 | AV11: =$F11/$M11*AO11*150% -> 0 | AW11: =$F11/$M11*AP11*200% -> 0 | AX11: =$F11/$M11*AQ11*300% -> 0 | AY11: =$F11/$M11*AR11*30% -> 0 | AZ11: =$F11/$M11*AS11*210% -> 0 | BA11: =$F11/$M11*AT11*270% -> 0 | BB11: =$F11/$M11*AU11*390% -> 0 | BC11: =ROUND(SUM(AV11:BB11)+CH11,0) -> 0 | BD11: =SUM(P11:AN11)+BC11 -> 17785000 | BG11: =ROUND($CB11*'SHUI & PIT'!$F$11,0) -> 1128000 | BH11: =ROUND($CB11*'SHUI & PIT'!$G$11,0) -> 211500 | BI11: =ROUND($CC11*'SHUI & PIT'!$H$11,0) -> 141000 | BJ11: =SUM(BG11:BI11) -> 1480500 | BK11: =IF(E11="La Nga",0,IF(E11="HCM",35000,IF(AE11="YES",IF($BG11>0,ROUND(MIN($CB11*1%,180000),0),0),0))) -> 35000 | BL11: =VLOOKUP(A11,'[1]Payroll master '!B$12:AD$160,29,0) -> 0 | BM11: =11000000+4400000*BL11 -> 11000000 | BN11: =ROUND(IF((CJ11-BJ11-BM11-BR11)<0,0,(CJ11-BJ11-BM11-BR11)),0) -> 4266167 | BO11: =ROUND((VLOOKUP(BN11,'SHUI & PIT'!$A$1:$C$8,2,1)*BN11-VLOOKUP(BN11,'SHUI & PIT'!$A$1:$C$8,3,1)),0) -> 213308 | BP11: =Y11 -> 0 | BS11: =BJ11+BO11+BP11+BR11+BE11+BF11+BQ11+BK11 -> 1728808 | BT11: =ROUND(IF((BD11-BS11)<0,0,(BD11-BS11)),0) -> 16056192 | BU11: =ROUND($CB11*'SHUI & PIT'!$F$12,0) -> 2467500 | BV11: =ROUND($CB11*'SHUI & PIT'!$G$12,0) -> 423000 | BW11: =ROUND($CC11*'SHUI & PIT'!$H$12,0) -> 141000 | BY11: =SUM(BU11:BX11) -> 3031500 | BZ11: =IF(BU11>0,ROUND($CB11*'SHUI & PIT'!$I$12,0),0) -> 282000 | CA11: =BD11+BY11-AC11+BZ11-BQ11 -> 21098500 | CB11: =IF(($F11+$T11)>='SHUI & PIT'!$C$12,'SHUI & PIT'!$C$12,($F11+$T11)) -> 14100000 | CC11: =IF(($F11+$T11)>='SHUI & PIT'!$C$13,'SHUI & PIT'!$C$13,($F11+$T11)) -> 14100000 | CD11: =ROUND(($F11/M11)*($AO11*0.5+$AP11+$AQ11*2+AR11*0.3+AS11*1.1+AT11*1.7+AU11*2.9),0) -> 0 | CE11: =BC11-CD11 -> 0 | CF11: =_xlfn.XLOOKUP(A11,'[2]Termination and others'!B$12:B$33,'[2]Termination and others'!F$12:F$33,0,0) -> 0 | CG11: =VLOOKUP(A11,Main!$B$13:$BN$405,65,0) -> 0 | CH11: =IF(50000<F11/M11,50000,F11/M11)*CG11 -> 0 | CJ11: =BD11-R11-S11-AK11-CD11-AC11-BE11-BF11-BQ11 -> 16746667
A12: 11188 | C12: 43620 | D12: =DATEDIF(C12,$C$3,"D") -> 1722 | E12: HCM | F12: 28780000 | G12: 810000 | H12: 1000000 | I12: 680000 | J12: 2750000 | K12: 400000 | L12: 500000 | M12: =_xlfn.XLOOKUP(A12,Main!$B$13:$B$1048576,Main!$D$13:$D$1048576,0,0)*8 -> 192 | N12: =_xlfn.XLOOKUP(A12,Main!$B$13:$B$1048576,Main!$BQ$13:$BQ$1048576,0,0) -> 192 | O12: =_xlfn.XLOOKUP(A12,Main!$B$13:$B$1048576,Main!$BR$13:$BR$1048576,0,0) -> 152 | P12: =ROUND(F12/M12*N12,0) -> 28780000 | Q12: =G12/M12*O12 -> 641250 | R12: =IF(D12>=(M12/8),H12,H12/M12*N12) -> 1000000 | S12: =IF(CI12="N",26500*(ROUND(O12/8,0)),(I12/M12*O12)-CF12) -> 538333.33 | T12: =J12 -> 2750000 | U12: =K12/M12*O12 -> 316666.67 | V12: =IF(D12>=(M12/8),L12,L12/M12*N12) -> 500000 | AE12: YES | AH12: 5024628 | AO12: =_xlfn.XLOOKUP($A12,Main!$B$13:$B$35,Main!BU$13:BU$35,0,0) -> 0 | AP12: =_xlfn.XLOOKUP($A12,Main!$B$13:$B$35,Main!BV$13:BV$35,0,0) -> 0 | AQ12: =_xlfn.XLOOKUP($A12,Main!$B$13:$B$35,Main!BW$13:BW$35,0,0) -> 0 | AR12: =_xlfn.XLOOKUP($A12,Main!$B$13:$B$35,Main!BX$13:BX$35,0,0) -> 0 | AS12: =_xlfn.XLOOKUP($A12,Main!$B$13:$B$35,Main!BY$13:BY$35,0,0) -> 0 | AT12: =_xlfn.XLOOKUP($A12,Main!$B$13:$B$35,Main!BZ$13:BZ$35,0,0) -> 0 | AU12: =_xlfn.XLOOKUP($A12,Main!$B$13:$B$35,Main!CA$13:CA$35,0,0) -> 0 | AV12: =$F12/$M12*AO12*150% -> 0 | AW12: =$F12/$M12*AP12*200% -> 0 | AX12: =$F12/$M12*AQ12*300% -> 0 | AY12: =$F12/$M12*AR12*30% -> 0 | AZ12: =$F12/$M12*AS12*210% -> 0 | BA12: =$F12/$M12*AT12*270% -> 0 | BB12: =$F12/$M12*AU12*390% -> 0 | BC12: =ROUND(SUM(AV12:BB12)+CH12,0) -> 0 | BD12: =SUM(P12:AN12)+BC12 -> 39550878 | BG12: =ROUND($CB12*'SHUI & PIT'!$F$11,0) -> 2522400 | BH12: =ROUND($CB12*'SHUI & PIT'!$G$11,0) -> 472950 | BI12: =ROUND($CC12*'SHUI & PIT'!$H$11,0) -> 315300 | BJ12: =SUM(BG12:BI12) -> 3310650 | BK12: =IF(E12="La Nga",0,IF(E12="HCM",35000,IF(AE12="YES",IF($BG12>0,ROUND(MIN($CB12*1%,180000),0),0),0))) -> 35000 | BL12: =VLOOKUP(A12,'[1]Payroll master '!B$12:AD$160,29,0) -> 3 | BM12: =11000000+4400000*BL12 -> 24200000 | BN12: =ROUND(IF((CJ12-BJ12-BM12-BR12)<0,0,(CJ12-BJ12-BM12-BR12)),0) -> 10501895 | BO12: =ROUND((VLOOKUP(BN12,'SHUI & PIT'!$A$1:$C$8,2,1)*BN12-VLOOKUP(BN12,'SHUI & PIT'!$A$1:$C$8,3,1)),0) -> 825284 | BP12: =Y12 -> 0 | BS12: =BJ12+BO12+BP12+BR12+BE12+BF12+BQ12+BK12 -> 4170934 | BT12: =ROUND(IF((BD12-BS12)<0,0,(BD12-BS12)),0) -> 35379944 | BU12: =ROUND($CB12*'SHUI & PIT'!$F$12,0) -> 5517750 | BV12: =ROUND($CB12*'SHUI & PIT'!$G$12,0) -> 945900 | BW12: =ROUND($CC12*'SHUI & PIT'!$H$12,0) -> 315300 | BY12: =SUM(BU12:BX12) -> 6778950 | BZ12: =IF(BU12>0,ROUND($CB12*'SHUI & PIT'!$I$12,0),0) -> 630600 | CA12: =BD12+BY12-AC12+BZ12-BQ12 -> 46960428 | CB12: =IF(($F12+$T12)>='SHUI & PIT'!$C$12,'SHUI & PIT'!$C$12,($F12+$T12)) -> 31530000 | CC12: =IF(($F12+$T12)>='SHUI & PIT'!$C$13,'SHUI & PIT'!$C$13,($F12+$T12)) -> 31530000 | CD12: =ROUND(($F12/M12)*($AO12*0.5+$AP12+$AQ12*2+AR12*0.3+AS12*1.1+AT12*1.7+AU12*2.9),0) -> 0 | CE12: =BC12-CD12 -> 0 | CF12: =_xlfn.XLOOKUP(A12,'[2]Termination and others'!B$12:B$33,'[2]Termination and others'!F$12:F$33,0,0) -> 0 | CG12: =VLOOKUP(A12,Main!$B$13:$BN$405,65,0) -> 0 | CH12: =IF(50000<F12/M12,50000,F12/M12)*CG12 -> 0 | CJ12: =BD12-R12-S12-AK12-CD12-AC12-BE12-BF12-BQ12 -> 38012545
A13: 11502 | C13: 44984 | D13: =DATEDIF(C13,$C$3,"D") -> 358 | E13: HCM | F13: 15610000 | G13: 1200000 | H13: 500000 | I13: 680000 | J13: 1320000 | K13: 400000 | L13: 0 | M13: =_xlfn.XLOOKUP(A13,Main!$B$13:$B$1048576,Main!$D$13:$D$1048576,0,0)*8 -> 192 | N13: =_xlfn.XLOOKUP(A13,Main!$B$13:$B$1048576,Main!$BQ$13:$BQ$1048576,0,0) -> 192 | O13: =_xlfn.XLOOKUP(A13,Main!$B$13:$B$1048576,Main!$BR$13:$BR$1048576,0,0) -> 152 | P13: =ROUND(F13/M13*N13,0) -> 15610000 | Q13: =G13/M13*O13 -> 950000 | R13: =IF(D13>=(M13/8),H13,H13/M13*N13) -> 500000 | S13: =IF(CI13="N",26500*(ROUND(O13/8,0)),(I13/M13*O13)-CF13) -> 538333.33 | T13: =J13 -> 1320000 | U13: =K13/M13*O13 -> 316666.67 | V13: =IF(D13>=(M13/8),L13,L13/M13*N13) -> 0 | AE13: YES | AO13: =_xlfn.XLOOKUP($A13,Main!$B$13:$B$35,Main!BU$13:BU$35,0,0) -> 0 | AP13: =_xlfn.XLOOKUP($A13,Main!$B$13:$B$35,Main!BV$13:BV$35,0,0) -> 0 | AQ13: =_xlfn.XLOOKUP($A13,Main!$B$13:$B$35,Main!BW$13:BW$35,0,0) -> 0 | AR13: =_xlfn.XLOOKUP($A13,Main!$B$13:$B$35,Main!BX$13:BX$35,0,0) -> 0 | AS13: =_xlfn.XLOOKUP($A13,Main!$B$13:$B$35,Main!BY$13:BY$35,0,0) -> 0 | AT13: =_xlfn.XLOOKUP($A13,Main!$B$13:$B$35,Main!BZ$13:BZ$35,0,0) -> 0 | AU13: =_xlfn.XLOOKUP($A13,Main!$B$13:$B$35,Main!CA$13:CA$35,0,0) -> 0 | AV13: =$F13/$M13*AO13*150% -> 0 | AW13: =$F13/$M13*AP13*200% -> 0 | AX13: =$F13/$M13*AQ13*300% -> 0 | AY13: =$F13/$M13*AR13*30% -> 0 | AZ13: =$F13/$M13*AS13*210% -> 0 | BA13: =$F13/$M13*AT13*270% -> 0 | BB13: =$F13/$M13*AU13*390% -> 0 | BC13: =ROUND(SUM(AV13:BB13)+CH13,0) -> 0 | BD13: =SUM(P13:AN13)+BC13 -> 19235000 | BG13: =ROUND($CB13*'SHUI & PIT'!$F$11,0) -> 1354400 | BH13: =ROUND($CB13*'SHUI & PIT'!$G$11,0) -> 253950 | BI13: =ROUND($CC13*'SHUI & PIT'!$H$11,0) -> 169300 | BJ13: =SUM(BG13:BI13) -> 1777650 | BK13: =IF(E13="La Nga",0,IF(E13="HCM",35000,IF(AE13="YES",IF($BG13>0,ROUND(MIN($CB13*1%,180000),0),0),0))) -> 35000 | BL13: =VLOOKUP(A13,'[1]Payroll master '!B$12:AD$160,29,0) -> 0 | BM13: =11000000+4400000*BL13 -> 11000000 | BN13: =ROUND(IF((CJ13-BJ13-BM13-BR13)<0,0,(CJ13-BJ13-BM13-BR13)),0) -> 5419017 | BO13: =ROUND((VLOOKUP(BN13,'SHUI & PIT'!$A$1:$C$8,2,1)*BN13-VLOOKUP(BN13,'SHUI & PIT'!$A$1:$C$8,3,1)),0) -> 291902 | BP13: =Y13 -> 0 | BS13: =BJ13+BO13+BP13+BR13+BE13+BF13+BQ13+BK13 -> 2104552 | BT13: =ROUND(IF((BD13-BS13)<0,0,(BD13-BS13)),0) -> 17130448 | BU13: =ROUND($CB13*'SHUI & PIT'!$F$12,0) -> 2962750 | BV13: =ROUND($CB13*'SHUI & PIT'!$G$12,0) -> 507900 | BW13: =ROUND($CC13*'SHUI & PIT'!$H$12,0) -> 169300 | BY13: =SUM(BU13:BX13) -> 3639950 | BZ13: =IF(BU13>0,ROUND($CB13*'SHUI & PIT'!$I$12,0),0) -> 338600 | CA13: =BD13+BY13-AC13+BZ13-BQ13 -> 23213550 | CB13: =IF(($F13+$T13)>='SHUI & PIT'!$C$12,'SHUI & PIT'!$C$12,($F13+$T13)) -> 16930000 | CC13: =IF(($F13+$T13)>='SHUI & PIT'!$C$13,'SHUI & PIT'!$C$13,($F13+$T13)) -> 16930000 | CD13: =ROUND(($F13/M13)*($AO13*0.5+$AP13+$AQ13*2+AR13*0.3+AS13*1.1+AT13*1.7+AU13*2.9),0) -> 0 | CE13: =BC13-CD13 -> 0 | CF13: =_xlfn.XLOOKUP(A13,'[2]Termination and others'!B$12:B$33,'[2]Termination and others'!F$12:F$33,0,0) -> 0 | CG13: =VLOOKUP(A13,Main!$B$13:$BN$405,65,0) -> 0 | CH13: =IF(50000<F13/M13,50000,F13/M13)*CG13 -> 0 | CJ13: =BD13-R13-S13-AK13-CD13-AC13-BE13-BF13-BQ13 -> 18196667
A14: 11587 | C14: 45166 | D14: =DATEDIF(C14,$C$3,"D") -> 176 | E14: HCM | F14: 75000000 | G14: 0 | H14: 1000000 | I14: 680000 | J14: 0 | K14: 0 | L14: 500000 | M14: =_xlfn.XLOOKUP(A14,Main!$B$13:$B$1048576,Main!$D$13:$D$1048576,0,0)*8 -> 192 | N14: =_xlfn.XLOOKUP(A14,Main!$B$13:$B$1048576,Main!$BQ$13:$BQ$1048576,0,0) -> 192 | O14: =_xlfn.XLOOKUP(A14,Main!$B$13:$B$1048576,Main!$BR$13:$BR$1048576,0,0) -> 152 | P14: =ROUND(F14/M14*N14,0) -> 75000000 | Q14: =G14/M14*O14 -> 0 | R14: =IF(D14>=(M14/8),H14,H14/M14*N14) -> 1000000 | S14: =IF(CI14="N",26500*(ROUND(O14/8,0)),(I14/M14*O14)-CF14) -> 538333.33 | T14: =J14 -> 0 | U14: =K14/M14*O14 -> 0 | V14: =IF(D14>=(M14/8),L14,L14/M14*N14) -> 500000 | AE14: YES | AH14: 750000 | AO14: =_xlfn.XLOOKUP($A14,Main!$B$13:$B$35,Main!BU$13:BU$35,0,0) -> 0 | AP14: =_xlfn.XLOOKUP($A14,Main!$B$13:$B$35,Main!BV$13:BV$35,0,0) -> 0 | AQ14: =_xlfn.XLOOKUP($A14,Main!$B$13:$B$35,Main!BW$13:BW$35,0,0) -> 0 | AR14: =_xlfn.XLOOKUP($A14,Main!$B$13:$B$35,Main!BX$13:BX$35,0,0) -> 0 | AS14: =_xlfn.XLOOKUP($A14,Main!$B$13:$B$35,Main!BY$13:BY$35,0,0) -> 0 | AT14: =_xlfn.XLOOKUP($A14,Main!$B$13:$B$35,Main!BZ$13:BZ$35,0,0) -> 0 | AU14: =_xlfn.XLOOKUP($A14,Main!$B$13:$B$35,Main!CA$13:CA$35,0,0) -> 0 | AV14: =$F14/$M14*AO14*150% -> 0 | AW14: =$F14/$M14*AP14*200% -> 0 | AX14: =$F14/$M14*AQ14*300% -> 0 | AY14: =$F14/$M14*AR14*30% -> 0 | AZ14: =$F14/$M14*AS14*210% -> 0 | BA14: =$F14/$M14*AT14*270% -> 0 | BB14: =$F14/$M14*AU14*390% -> 0 | BC14: =ROUND(SUM(AV14:BB14)+CH14,0) -> 0 | BD14: =SUM(P14:AN14)+BC14 -> 77788333 | BG14: =ROUND($CB14*'SHUI & PIT'!$F$11,0) -> 2880000 | BH14: =ROUND($CB14*'SHUI & PIT'!$G$11,0) -> 540000 | BI14: =ROUND($CC14*'SHUI & PIT'!$H$11,0) -> 750000 | BJ14: =SUM(BG14:BI14) -> 4170000 | BK14: =IF(E14="La Nga",0,IF(E14="HCM",35000,IF(AE14="YES",IF($BG14>0,ROUND(MIN($CB14*1%,180000),0),0),0))) -> 35000 | BL14: =VLOOKUP(A14,'[1]Payroll master '!B$12:AD$160,29,0) -> 4 | BM14: =11000000+4400000*BL14 -> 28600000 | BN14: =ROUND(IF((CJ14-BJ14-BM14-BR14)<0,0,(CJ14-BJ14-BM14-BR14)),0) -> 43480000 | BO14: =ROUND((VLOOKUP(BN14,'SHUI & PIT'!$A$1:$C$8,2,1)*BN14-VLOOKUP(BN14,'SHUI & PIT'!$A$1:$C$8,3,1)),0) -> 7620000 | BP14: =Y14 -> 0 | BS14: =BJ14+BO14+BP14+BR14+BE14+BF14+BQ14+BK14 -> 11825000 | BT14: =ROUND(IF((BD14-BS14)<0,0,(BD14-BS14)),0) -> 65963333 | BU14: =ROUND($CB14*'SHUI & PIT'!$F$12,0) -> 6300000 | BV14: =ROUND($CB14*'SHUI & PIT'!$G$12,0) -> 1080000 | BW14: =ROUND($CC14*'SHUI & PIT'!$H$12,0) -> 750000 | BY14: =SUM(BU14:BX14) -> 8130000 | BZ14: =IF(BU14>0,ROUND($CB14*'SHUI & PIT'!$I$12,0),0) -> 720000 | CA14: =BD14+BY14-AC14+BZ14-BQ14 -> 86638333 | CB14: =IF(($F14+$T14)>='SHUI & PIT'!$C$12,'SHUI & PIT'!$C$12,($F14+$T14)) -> 36000000 | CC14: =IF(($F14+$T14)>='SHUI & PIT'!$C$13,'SHUI & PIT'!$C$13,($F14+$T14)) -> 75000000 | CD14: =ROUND(($F14/M14)*($AO14*0.5+$AP14+$AQ14*2+AR14*0.3+AS14*1.1+AT14*1.7+AU14*2.9),0) -> 0 | CE14: =BC14-CD14 -> 0 | CF14: =_xlfn.XLOOKUP(A14,'[2]Termination and others'!B$12:B$33,'[2]Termination and others'!F$12:F$33,0,0) -> 0 | CG14: =VLOOKUP(A14,Main!$B$13:$BN$405,65,0) -> 0 | CH14: =IF(50000<F14/M14,50000,F14/M14)*CG14 -> 0 | CJ14: =BD14-R14-S14-AK14-CD14-AC14-BE14-BF14-BQ14 -> 76250000
A15: 11626 | C15: 45174 | D15: =DATEDIF(C15,$C$3,"D") -> 168 | E15: HCM | F15: 20000000 | G15: 1200000 | H15: 500000 | I15: 680000 | J15: 0 | K15: 400000 | L15: 0 | M15: =_xlfn.XLOOKUP(A15,Main!$B$13:$B$1048576,Main!$D$13:$D$1048576,0,0)*8 -> 192 | N15: =_xlfn.XLOOKUP(A15,Main!$B$13:$B$1048576,Main!$BQ$13:$BQ$1048576,0,0) -> 192 | O15: =_xlfn.XLOOKUP(A15,Main!$B$13:$B$1048576,Main!$BR$13:$BR$1048576,0,0) -> 116 | P15: =ROUND(F15/M15*N15,0) -> 20000000 | Q15: =G15/M15*O15 -> 725000 | R15: =IF(D15>=(M15/8),H15,H15/M15*N15) -> 500000 | S15: =IF(CI15="N",26500*(ROUND(O15/8,0)),(I15/M15*O15)-CF15) -> 410833.33 | T15: =J15 -> 0 | U15: =K15/M15*O15 -> 241666.67 | V15: =IF(D15>=(M15/8),L15,L15/M15*N15) -> 0 | AE15: YES | AH15: 200000 | AO15: =_xlfn.XLOOKUP($A15,Main!$B$13:$B$35,Main!BU$13:BU$35,0,0) -> 0 | AP15: =_xlfn.XLOOKUP($A15,Main!$B$13:$B$35,Main!BV$13:BV$35,0,0) -> 0 | AQ15: =_xlfn.XLOOKUP($A15,Main!$B$13:$B$35,Main!BW$13:BW$35,0,0) -> 0 | AR15: =_xlfn.XLOOKUP($A15,Main!$B$13:$B$35,Main!BX$13:BX$35,0,0) -> 0 | AS15: =_xlfn.XLOOKUP($A15,Main!$B$13:$B$35,Main!BY$13:BY$35,0,0) -> 0 | AT15: =_xlfn.XLOOKUP($A15,Main!$B$13:$B$35,Main!BZ$13:BZ$35,0,0) -> 0 | AU15: =_xlfn.XLOOKUP($A15,Main!$B$13:$B$35,Main!CA$13:CA$35,0,0) -> 0 | AV15: =$F15/$M15*AO15*150% -> 0 | AW15: =$F15/$M15*AP15*200% -> 0 | AX15: =$F15/$M15*AQ15*300% -> 0 | AY15: =$F15/$M15*AR15*30% -> 0 | AZ15: =$F15/$M15*AS15*210% -> 0 | BA15: =$F15/$M15*AT15*270% -> 0 | BB15: =$F15/$M15*AU15*390% -> 0 | BC15: =ROUND(SUM(AV15:BB15)+CH15,0) -> 0 | BD15: =SUM(P15:AN15)+BC15 -> 22077500 | BG15: =ROUND($CB15*'SHUI & PIT'!$F$11,0) -> 1600000 | BH15: =ROUND($CB15*'SHUI & PIT'!$G$11,0) -> 300000 | BI15: =ROUND($CC15*'SHUI & PIT'!$H$11,0) -> 200000 | BJ15: =SUM(BG15:BI15) -> 2100000 | BK15: =IF(E15="La Nga",0,IF(E15="HCM",35000,IF(AE15="YES",IF($BG15>0,ROUND(MIN($CB15*1%,180000),0),0),0))) -> 35000 | BL15: =VLOOKUP(A15,'[1]Payroll master '!B$12:AD$160,29,0) -> 0 | BM15: =11000000+4400000*BL15 -> 11000000 | BN15: =ROUND(IF((CJ15-BJ15-BM15-BR15)<0,0,(CJ15-BJ15-BM15-BR15)),0) -> 8066667 | BO15: =ROUND((VLOOKUP(BN15,'SHUI & PIT'!$A$1:$C$8,2,1)*BN15-VLOOKUP(BN15,'SHUI & PIT'!$A$1:$C$8,3,1)),0) -> 556667 | BP15: =Y15 -> 0 | BS15: =BJ15+BO15+BP15+BR15+BE15+BF15+BQ15+BK15 -> 2691667 | BT15: =ROUND(IF((BD15-BS15)<0,0,(BD15-BS15)),0) -> 19385833 | BU15: =ROUND($CB15*'SHUI & PIT'!$F$12,0) -> 3500000 | BV15: =ROUND($CB15*'SHUI & PIT'!$G$12,0) -> 600000 | BW15: =ROUND($CC15*'SHUI & PIT'!$H$12,0) -> 200000 | BY15: =SUM(BU15:BX15) -> 4300000 | BZ15: =IF(BU15>0,ROUND($CB15*'SHUI & PIT'!$I$12,0),0) -> 400000 | CA15: =BD15+BY15-AC15+BZ15-BQ15 -> 26777500 | CB15: =IF(($F15+$T15)>='SHUI & PIT'!$C$12,'SHUI & PIT'!$C$12,($F15+$T15)) -> 20000000 | CC15: =IF(($F15+$T15)>='SHUI & PIT'!$C$13,'SHUI & PIT'!$C$13,($F15+$T15)) -> 20000000 | CD15: =ROUND(($F15/M15)*($AO15*0.5+$AP15+$AQ15*2+AR15*0.3+AS15*1.1+AT15*1.7+AU15*2.9),0) -> 0 | CE15: =BC15-CD15 -> 0 | CF15: =_xlfn.XLOOKUP(A15,'[2]Termination and others'!B$12:B$33,'[2]Termination and others'!F$12:F$33,0,0) -> 0 | CG15: =VLOOKUP(A15,Main!$B$13:$BN$405,65,0) -> 0 | CH15: =IF(50000<F15/M15,50000,F15/M15)*CG15 -> 0 | CJ15: =BD15-R15-S15-AK15-CD15-AC15-BE15-BF15-BQ15 -> 21166667
A16: 4044 | C16: 37438 | D16: =DATEDIF(C16,$C$3,"D") -> 7904 | E16: HCM | F16: 16530000 | G16: 1200000 | H16: 500000 | I16: 680000 | J16: 1320000 | K16: 400000 | L16: 0 | M16: =_xlfn.XLOOKUP(A16,Main!$B$13:$B$1048576,Main!$D$13:$D$1048576,0,0)*8 -> 192 | N16: =_xlfn.XLOOKUP(A16,Main!$B$13:$B$1048576,Main!$BQ$13:$BQ$1048576,0,0) -> 192 | O16: =_xlfn.XLOOKUP(A16,Main!$B$13:$B$1048576,Main!$BR$13:$BR$1048576,0,0) -> 152 | P16: =ROUND(F16/M16*N16,0) -> 16530000 | Q16: =G16/M16*O16 -> 950000 | R16: =IF(D16>=(M16/8),H16,H16/M16*N16) -> 500000 | S16: =IF(CI16="N",26500*(ROUND(O16/8,0)),(I16/M16*O16)-CF16) -> 538333.33 | T16: =J16 -> 1320000 | U16: =K16/M16*O16 -> 316666.67 | V16: =IF(D16>=(M16/8),L16,L16/M16*N16) -> 0 | AE16: YES | AH16: 400000 | AO16: =_xlfn.XLOOKUP($A16,Main!$B$13:$B$35,Main!BU$13:BU$35,0,0) -> 0 | AP16: =_xlfn.XLOOKUP($A16,Main!$B$13:$B$35,Main!BV$13:BV$35,0,0) -> 0 | AQ16: =_xlfn.XLOOKUP($A16,Main!$B$13:$B$35,Main!BW$13:BW$35,0,0) -> 0 | AR16: =_xlfn.XLOOKUP($A16,Main!$B$13:$B$35,Main!BX$13:BX$35,0,0) -> 0 | AS16: =_xlfn.XLOOKUP($A16,Main!$B$13:$B$35,Main!BY$13:BY$35,0,0) -> 0 | AT16: =_xlfn.XLOOKUP($A16,Main!$B$13:$B$35,Main!BZ$13:BZ$35,0,0) -> 0 | AU16: =_xlfn.XLOOKUP($A16,Main!$B$13:$B$35,Main!CA$13:CA$35,0,0) -> 0 | AV16: =$F16/$M16*AO16*150% -> 0 | AW16: =$F16/$M16*AP16*200% -> 0 | AX16: =$F16/$M16*AQ16*300% -> 0 | AY16: =$F16/$M16*AR16*30% -> 0 | AZ16: =$F16/$M16*AS16*210% -> 0 | BA16: =$F16/$M16*AT16*270% -> 0 | BB16: =$F16/$M16*AU16*390% -> 0 | BC16: =ROUND(SUM(AV16:BB16)+CH16,0) -> 0 | BD16: =SUM(P16:AN16)+BC16 -> 20555000 | BG16: =ROUND($CB16*'SHUI & PIT'!$F$11,0) -> 1428000 | BH16: =ROUND($CB16*'SHUI & PIT'!$G$11,0) -> 267750 | BI16: =ROUND($CC16*'SHUI & PIT'!$H$11,0) -> 178500 | BJ16: =SUM(BG16:BI16) -> 1874250 | BK16: =IF(E16="La Nga",0,IF(E16="HCM",35000,IF(AE16="YES",IF($BG16>0,ROUND(MIN($CB16*1%,180000),0),0),0))) -> 35000 | BL16: =VLOOKUP(A16,'[1]Payroll master '!B$12:AD$160,29,0) -> 0 | BM16: =11000000+4400000*BL16 -> 11000000 | BN16: =ROUND(IF((CJ16-BJ16-BM16-BR16)<0,0,(CJ16-BJ16-BM16-BR16)),0) -> 6642417 | BO16: =ROUND((VLOOKUP(BN16,'SHUI & PIT'!$A$1:$C$8,2,1)*BN16-VLOOKUP(BN16,'SHUI & PIT'!$A$1:$C$8,3,1)),0) -> 414242 | BP16: =Y16 -> 0 | BS16: =BJ16+BO16+BP16+BR16+BE16+BF16+BQ16+BK16 -> 2323492 | BT16: =ROUND(IF((BD16-BS16)<0,0,(BD16-BS16)),0) -> 18231508 | BU16: =ROUND($CB16*'SHUI & PIT'!$F$12,0) -> 3123750 | BV16: =ROUND($CB16*'SHUI & PIT'!$G$12,0) -> 535500 | BW16: =ROUND($CC16*'SHUI & PIT'!$H$12,0) -> 178500 | BY16: =SUM(BU16:BX16) -> 3837750 | BZ16: =IF(BU16>0,ROUND($CB16*'SHUI & PIT'!$I$12,0),0) -> 357000 | CA16: =BD16+BY16-AC16+BZ16-BQ16 -> 24749750 | CB16: =IF(($F16+$T16)>='SHUI & PIT'!$C$12,'SHUI & PIT'!$C$12,($F16+$T16)) -> 17850000 | CC16: =IF(($F16+$T16)>='SHUI & PIT'!$C$13,'SHUI & PIT'!$C$13,($F16+$T16)) -> 17850000 | CD16: =ROUND(($F16/M16)*($AO16*0.5+$AP16+$AQ16*2+AR16*0.3+AS16*1.1+AT16*1.7+AU16*2.9),0) -> 0 | CE16: =BC16-CD16 -> 0 | CF16: =_xlfn.XLOOKUP(A16,'[2]Termination and others'!B$12:B$33,'[2]Termination and others'!F$12:F$33,0,0) -> 0 | CG16: =VLOOKUP(A16,Main!$B$13:$BN$405,65,0) -> 0 | CH16: =IF(50000<F16/M16,50000,F16/M16)*CG16 -> 0 | CJ16: =BD16-R16-S16-AK16-CD16-AC16-BE16-BF16-BQ16 -> 19516667
A17: 4045 | C17: 37867 | D17: =DATEDIF(C17,$C$3,"D") -> 7475 | E17: HCM | F17: 28550000 | G17: 810000 | H17: 1000000 | I17: 680000 | J17: 2750000 | K17: 400000 | L17: 500000 | M17: =_xlfn.XLOOKUP(A17,Main!$B$13:$B$1048576,Main!$D$13:$D$1048576,0,0)*8 -> 192 | N17: =_xlfn.XLOOKUP(A17,Main!$B$13:$B$1048576,Main!$BQ$13:$BQ$1048576,0,0) -> 192 | O17: =_xlfn.XLOOKUP(A17,Main!$B$13:$B$1048576,Main!$BR$13:$BR$1048576,0,0) -> 128 | P17: =ROUND(F17/M17*N17,0) -> 28550000 | Q17: =G17/M17*O17 -> 540000 | R17: =IF(D17>=(M17/8),H17,H17/M17*N17) -> 1000000 | S17: =IF(CI17="N",26500*(ROUND(O17/8,0)),(I17/M17*O17)-CF17) -> 453333.33 | T17: =J17 -> 2750000 | U17: =K17/M17*O17 -> 266666.67 | V17: =IF(D17>=(M17/8),L17,L17/M17*N17) -> 500000 | AE17: YES | AO17: =_xlfn.XLOOKUP($A17,Main!$B$13:$B$35,Main!BU$13:BU$35,0,0) -> 0 | AP17: =_xlfn.XLOOKUP($A17,Main!$B$13:$B$35,Main!BV$13:BV$35,0,0) -> 0 | AQ17: =_xlfn.XLOOKUP($A17,Main!$B$13:$B$35,Main!BW$13:BW$35,0,0) -> 0 | AR17: =_xlfn.XLOOKUP($A17,Main!$B$13:$B$35,Main!BX$13:BX$35,0,0) -> 0 | AS17: =_xlfn.XLOOKUP($A17,Main!$B$13:$B$35,Main!BY$13:BY$35,0,0) -> 0 | AT17: =_xlfn.XLOOKUP($A17,Main!$B$13:$B$35,Main!BZ$13:BZ$35,0,0) -> 0 | AU17: =_xlfn.XLOOKUP($A17,Main!$B$13:$B$35,Main!CA$13:CA$35,0,0) -> 0 | AV17: =$F17/$M17*AO17*150% -> 0 | AW17: =$F17/$M17*AP17*200% -> 0 | AX17: =$F17/$M17*AQ17*300% -> 0 | AY17: =$F17/$M17*AR17*30% -> 0 | AZ17: =$F17/$M17*AS17*210% -> 0 | BA17: =$F17/$M17*AT17*270% -> 0 | BB17: =$F17/$M17*AU17*390% -> 0 | BC17: =ROUND(SUM(AV17:BB17)+CH17,0) -> 0 | BD17: =SUM(P17:AN17)+BC17 -> 34060000 | BG17: =ROUND($CB17*'SHUI & PIT'!$F$11,0) -> 2504000 | BH17: =ROUND($CB17*'SHUI & PIT'!$G$11,0) -> 469500 | BI17: =ROUND($CC17*'SHUI & PIT'!$H$11,0) -> 313000 | BJ17: =SUM(BG17:BI17) -> 3286500 | BK17: =IF(E17="La Nga",0,IF(E17="HCM",35000,IF(AE17="YES",IF($BG17>0,ROUND(MIN($CB17*1%,180000),0),0),0))) -> 35000 | BL17: =VLOOKUP(A17,'[1]Payroll master '!B$12:AD$160,29,0) -> 0 | BM17: =11000000+4400000*BL17 -> 11000000 | BN17: =ROUND(IF((CJ17-BJ17-BM17-BR17)<0,0,(CJ17-BJ17-BM17-BR17)),0) -> 18320167 | BO17: =ROUND((VLOOKUP(BN17,'SHUI & PIT'!$A$1:$C$8,2,1)*BN17-VLOOKUP(BN17,'SHUI & PIT'!$A$1:$C$8,3,1)),0) -> 2014033 | BP17: =Y17 -> 0 | BS17: =BJ17+BO17+BP17+BR17+BE17+BF17+BQ17+BK17 -> 5335533 | BT17: =ROUND(IF((BD17-BS17)<0,0,(BD17-BS17)),0) -> 28724467 | BU17: =ROUND($CB17*'SHUI & PIT'!$F$12,0) -> 5477500 | BV17: =ROUND($CB17*'SHUI & PIT'!$G$12,0) -> 939000 | BW17: =ROUND($CC17*'SHUI & PIT'!$H$12,0) -> 313000 | BY17: =SUM(BU17:BX17) -> 6729500 | BZ17: =IF(BU17>0,ROUND($CB17*'SHUI & PIT'!$I$12,0),0) -> 626000 | CA17: =BD17+BY17-AC17+BZ17-BQ17 -> 41415500 | CB17: =IF(($F17+$T17)>='SHUI & PIT'!$C$12,'SHUI & PIT'!$C$12,($F17+$T17)) -> 31300000 | CC17: =IF(($F17+$T17)>='SHUI & PIT'!$C$13,'SHUI & PIT'!$C$13,($F17+$T17)) -> 31300000 | CD17: =ROUND(($F17/M17)*($AO17*0.5+$AP17+$AQ17*2+AR17*0.3+AS17*1.1+AT17*1.7+AU17*2.9),0) -> 0 | CE17: =BC17-CD17 -> 0 | CF17: =_xlfn.XLOOKUP(A17,'[2]Termination and others'!B$12:B$33,'[2]Termination and others'!F$12:F$33,0,0) -> 0 | CG17: =VLOOKUP(A17,Main!$B$13:$BN$405,65,0) -> 0 | CH17: =IF(50000<F17/M17,50000,F17/M17)*CG17 -> 0 | CJ17: =BD17-R17-S17-AK17-CD17-AC17-BE17-BF17-BQ17 -> 32606667
A18: 4047 | C18: 39204 | D18: =DATEDIF(C18,$C$3,"D") -> 6138 | E18: HCM | F18: 17630000 | G18: 1200000 | H18: 500000 | I18: 680000 | J18: 1320000 | K18: 400000 | L18: 0 | M18: =_xlfn.XLOOKUP(A18,Main!$B$13:$B$1048576,Main!$D$13:$D$1048576,0,0)*8 -> 192 | N18: =_xlfn.XLOOKUP(A18,Main!$B$13:$B$1048576,Main!$BQ$13:$BQ$1048576,0,0) -> 192 | O18: =_xlfn.XLOOKUP(A18,Main!$B$13:$B$1048576,Main!$BR$13:$BR$1048576,0,0) -> 152 | P18: =ROUND(F18/M18*N18,0) -> 17630000 | Q18: =G18/M18*O18 -> 950000 | R18: =IF(D18>=(M18/8),H18,H18/M18*N18) -> 500000 | S18: =IF(CI18="N",26500*(ROUND(O18/8,0)),(I18/M18*O18)-CF18) -> 538333.33 | T18: =J18 -> 1320000 | U18: =K18/M18*O18 -> 316666.67 | V18: =IF(D18>=(M18/8),L18,L18/M18*N18) -> 0 | AE18: YES | AH18: 600000 | AO18: =_xlfn.XLOOKUP($A18,Main!$B$13:$B$35,Main!BU$13:BU$35,0,0) -> 0 | AP18: =_xlfn.XLOOKUP($A18,Main!$B$13:$B$35,Main!BV$13:BV$35,0,0) -> 0 | AQ18: =_xlfn.XLOOKUP($A18,Main!$B$13:$B$35,Main!BW$13:BW$35,0,0) -> 0 | AR18: =_xlfn.XLOOKUP($A18,Main!$B$13:$B$35,Main!BX$13:BX$35,0,0) -> 0 | AS18: =_xlfn.XLOOKUP($A18,Main!$B$13:$B$35,Main!BY$13:BY$35,0,0) -> 0 | AT18: =_xlfn.XLOOKUP($A18,Main!$B$13:$B$35,Main!BZ$13:BZ$35,0,0) -> 0 | AU18: =_xlfn.XLOOKUP($A18,Main!$B$13:$B$35,Main!CA$13:CA$35,0,0) -> 0 | AV18: =$F18/$M18*AO18*150% -> 0 | AW18: =$F18/$M18*AP18*200% -> 0 | AX18: =$F18/$M18*AQ18*300% -> 0 | AY18: =$F18/$M18*AR18*30% -> 0 | AZ18: =$F18/$M18*AS18*210% -> 0 | BA18: =$F18/$M18*AT18*270% -> 0 | BB18: =$F18/$M18*AU18*390% -> 0 | BC18: =ROUND(SUM(AV18:BB18)+CH18,0) -> 0 | BD18: =SUM(P18:AN18)+BC18 -> 21855000 | BG18: =ROUND($CB18*'SHUI & PIT'!$F$11,0) -> 1516000 | BH18: =ROUND($CB18*'SHUI & PIT'!$G$11,0) -> 284250 | BI18: =ROUND($CC18*'SHUI & PIT'!$H$11,0) -> 189500 | BJ18: =SUM(BG18:BI18) -> 1989750 | BK18: =IF(E18="La Nga",0,IF(E18="HCM",35000,IF(AE18="YES",IF($BG18>0,ROUND(MIN($CB18*1%,180000),0),0),0))) -> 35000 | BL18: =VLOOKUP(A18,'[1]Payroll master '!B$12:AD$160,29,0) -> 2 | BM18: =11000000+4400000*BL18 -> 19800000 | BN18: =ROUND(IF((CJ18-BJ18-BM18-BR18)<0,0,(CJ18-BJ18-BM18-BR18)),0) -> 0 | BO18: =ROUND((VLOOKUP(BN18,'SHUI & PIT'!$A$1:$C$8,2,1)*BN18-VLOOKUP(BN18,'SHUI & PIT'!$A$1:$C$8,3,1)),0) -> 0 | BP18: =Y18 -> 0 | BS18: =BJ18+BO18+BP18+BR18+BE18+BF18+BQ18+BK18 -> 2024750 | BT18: =ROUND(IF((BD18-BS18)<0,0,(BD18-BS18)),0) -> 19830250 | BU18: =ROUND($CB18*'SHUI & PIT'!$F$12,0) -> 3316250 | BV18: =ROUND($CB18*'SHUI & PIT'!$G$12,0) -> 568500 | BW18: =ROUND($CC18*'SHUI & PIT'!$H$12,0) -> 189500 | BY18: =SUM(BU18:BX18) -> 4074250 | BZ18: =IF(BU18>0,ROUND($CB18*'SHUI & PIT'!$I$12,0),0) -> 379000 | CA18: =BD18+BY18-AC18+BZ18-BQ18 -> 26308250 | CB18: =IF(($F18+$T18)>='SHUI & PIT'!$C$12,'SHUI & PIT'!$C$12,($F18+$T18)) -> 18950000 | CC18: =IF(($F18+$T18)>='SHUI & PIT'!$C$13,'SHUI & PIT'!$C$13,($F18+$T18)) -> 18950000 | CD18: =ROUND(($F18/M18)*($AO18*0.5+$AP18+$AQ18*2+AR18*0.3+AS18*1.1+AT18*1.7+AU18*2.9),0) -> 0 | CE18: =BC18-CD18 -> 0 | CF18: =_xlfn.XLOOKUP(A18,'[2]Termination and others'!B$12:B$33,'[2]Termination and others'!F$12:F$33,0,0) -> 0 | CG18: =VLOOKUP(A18,Main!$B$13:$BN$405,65,0) -> 0 | CH18: =IF(50000<F18/M18,50000,F18/M18)*CG18 -> 0 | CJ18: =BD18-R18-S18-AK18-CD18-AC18-BE18-BF18-BQ18 -> 20816667
A19: 4145 | C19: 41855 | D19: 0 | E19: HCM | F19: 11400000 | G19: 1200000 | H19: 500000 | I19: 680000 | J19: 1320000 | K19: 400000 | L19: 0 | M19: =_xlfn.XLOOKUP(A19,Main!$B$13:$B$1048576,Main!$D$13:$D$1048576,0,0)*8 -> 192 | N19: =_xlfn.XLOOKUP(A19,Main!$B$13:$B$1048576,Main!$BQ$13:$BQ$1048576,0,0) -> 68 | O19: =_xlfn.XLOOKUP(A19,Main!$B$13:$B$1048576,Main!$BR$13:$BR$1048576,0,0) -> 68 | P19: =ROUND(F19/M19*N19,0) -> 4037500 | Q19: =G19/M19*O19 -> 425000 | R19: =IF(D19>=(M19/8),H19,H19/M19*N19) -> 177083.33 | S19: =IF(CI19="N",26500*(ROUND(O19/8,0)),(I19/M19*O19)-CF19) -> 240833.33 | T19: 0 | U19: =K19/M19*O19 -> 141666.67 | V19: =IF(D19>=(M19/8),L19,L19/M19*N19) -> 0 | X19: =F19/(M19/8)*15 -> 7125000 | AE19: YES | AH19: 600000 | AO19: =_xlfn.XLOOKUP($A19,Main!$B$13:$B$35,Main!BU$13:BU$35,0,0) -> 0 | AP19: =_xlfn.XLOOKUP($A19,Main!$B$13:$B$35,Main!BV$13:BV$35,0,0) -> 0 | AQ19: =_xlfn.XLOOKUP($A19,Main!$B$13:$B$35,Main!BW$13:BW$35,0,0) -> 0 | AR19: =_xlfn.XLOOKUP($A19,Main!$B$13:$B$35,Main!BX$13:BX$35,0,0) -> 0 | AS19: =_xlfn.XLOOKUP($A19,Main!$B$13:$B$35,Main!BY$13:BY$35,0,0) -> 0 | AT19: =_xlfn.XLOOKUP($A19,Main!$B$13:$B$35,Main!BZ$13:BZ$35,0,0) -> 0 | AU19: =_xlfn.XLOOKUP($A19,Main!$B$13:$B$35,Main!CA$13:CA$35,0,0) -> 0 | AV19: =$F19/$M19*AO19*150% -> 0 | AW19: =$F19/$M19*AP19*200% -> 0 | AX19: =$F19/$M19*AQ19*300% -> 0 | AY19: =$F19/$M19*AR19*30% -> 0 | AZ19: =$F19/$M19*AS19*210% -> 0 | BA19: =$F19/$M19*AT19*270% -> 0 | BB19: =$F19/$M19*AU19*390% -> 0 | BC19: =ROUND(SUM(AV19:BB19)+CH19,0) -> 0 | BD19: =SUM(P19:AN19)+BC19 -> 12747083 | BJ19: =SUM(BG19:BI19) -> 0 | BL19: =VLOOKUP(A19,'[1]Payroll master '!B$12:AD$160,29,0) -> 2 | BM19: =11000000+4400000*BL19 -> 19800000 | BN19: =ROUND(IF((CJ19-BJ19-BM19-BR19)<0,0,(CJ19-BJ19-BM19-BR19)),0) -> 0 | BO19: =ROUND((VLOOKUP(BN19,'SHUI & PIT'!$A$1:$C$8,2,1)*BN19-VLOOKUP(BN19,'SHUI & PIT'!$A$1:$C$8,3,1)),0) -> 0 | BP19: =Y19 -> 0 | BS19: =BJ19+BO19+BP19+BR19+BE19+BF19+BQ19+BK19 -> 0 | BT19: =ROUND(IF((BD19-BS19)<0,0,(BD19-BS19)),0) -> 12747083 | BY19: =SUM(BU19:BX19) -> 0 | BZ19: =IF(BU19>0,ROUND($CB19*'SHUI & PIT'!$I$12,0),0) -> 0 | CA19: =BD19+BY19-AC19+BZ19-BQ19 -> 12747083 | CB19: =IF(($F19+$T19)>='SHUI & PIT'!$C$12,'SHUI & PIT'!$C$12,($F19+$T19)) -> 11400000 | CC19: =IF(($F19+$T19)>='SHUI & PIT'!$C$13,'SHUI & PIT'!$C$13,($F19+$T19)) -> 11400000 | CD19: =ROUND(($F19/M19)*($AO19*0.5+$AP19+$AQ19*2+AR19*0.3+AS19*1.1+AT19*1.7+AU19*2.9),0) -> 0 | CE19: =BC19-CD19 -> 0 | CF19: =_xlfn.XLOOKUP(A19,'[2]Termination and others'!B$12:B$33,'[2]Termination and others'!F$12:F$33,0,0) -> 0 | CG19: =VLOOKUP(A19,Main!$B$13:$BN$405,65,0) -> 0 | CH19: =IF(50000<F19/M19,50000,F19/M19)*CG19 -> 0 | CJ19: =BD19-R19-S19-AK19-CD19-AC19-BE19-BF19-BQ19 -> 12329167
A20: 0014 | C20: 35690 | D20: =DATEDIF(C20,$C$3,"D") -> 9652 | E20: La Nga | F20: 15460000 | G20: 0 | H20: 300000 | I20: 0 | J20: 0 | K20: 0 | L20: 0 | M20: =_xlfn.XLOOKUP(A20,Main!$B$13:$B$1048576,Main!$D$13:$D$1048576,0,0)*8 -> 194 | N20: =_xlfn.XLOOKUP(A20,Main!$B$13:$B$1048576,Main!$BQ$13:$BQ$1048576,0,0) -> 194 | O20: =_xlfn.XLOOKUP(A20,Main!$B$13:$B$1048576,Main!$BR$13:$BR$1048576,0,0) -> 126 | P20: =ROUND(F20/M20*N20,0) -> 15460000 | Q20: =G20/M20*O20 -> 0 | R20: =IF(D20>=(M20/8),H20,H20/M20*N20) -> 300000 | S20: =IF(CI20="N",26500*(ROUND(O20/8,0)),(I20/M20*O20)-CF20) -> 0 | T20: =J20 -> 0 | U20: =K20/M20*O20 -> 0 | V20: =IF(D20>=(M20/8),L20,L20/M20*N20) -> 0 | AE20: YES | AF20: 0 | AG20: 0 | AJ20: 0 | AK20: 0 | AL20: 0 | AM20: 0 | AN20: 0 | AO20: =_xlfn.XLOOKUP($A20,Main!$B$13:$B$35,Main!BU$13:BU$35,0,0) -> 0 | AP20: =_xlfn.XLOOKUP($A20,Main!$B$13:$B$35,Main!BV$13:BV$35,0,0) -> 0 | AQ20: =_xlfn.XLOOKUP($A20,Main!$B$13:$B$35,Main!BW$13:BW$35,0,0) -> 0 | AR20: =_xlfn.XLOOKUP($A20,Main!$B$13:$B$35,Main!BX$13:BX$35,0,0) -> 0 | AS20: =_xlfn.XLOOKUP($A20,Main!$B$13:$B$35,Main!BY$13:BY$35,0,0) -> 0 | AT20: =_xlfn.XLOOKUP($A20,Main!$B$13:$B$35,Main!BZ$13:BZ$35,0,0) -> 0 | AU20: =_xlfn.XLOOKUP($A20,Main!$B$13:$B$35,Main!CA$13:CA$35,0,0) -> 0 | AV20: =$F20/$M20*AO20*150% -> 0 | AW20: =$F20/$M20*AP20*200% -> 0 | AX20: =$F20/$M20*AQ20*300% -> 0 | AY20: =$F20/$M20*AR20*30% -> 0 | AZ20: =$F20/$M20*AS20*210% -> 0 | BA20: =$F20/$M20*AT20*270% -> 0 | BB20: =$F20/$M20*AU20*390% -> 0 | BC20: =ROUND(SUM(AV20:BB20)+CH20,0) -> 508000 | BD20: =SUM(P20:AN20)+BC20 -> 16268000 | BG20: =ROUND($CB20*'SHUI & PIT'!$F$11,0) -> 1236800 | BH20: =ROUND($CB20*'SHUI & PIT'!$G$11,0) -> 231900 | BI20: =ROUND($CC20*'SHUI & PIT'!$H$11,0) -> 154600 | BJ20: =SUM(BG20:BI20) -> 1623300 | BK20: =IF(E20="La Nga",0,IF(E20="HCM",35000,IF(AE20="YES",IF($BG20>0,ROUND(MIN($CB20*1%,180000),0),0),0))) -> 0 | BL20: =VLOOKUP(A20,'[1]Payroll master '!B$12:AD$160,29,0) -> 2 | BM20: =11000000+4400000*BL20 -> 19800000 | BN20: =ROUND(IF((CJ20-BJ20-BM20-BR20)<0,0,(CJ20-BJ20-BM20-BR20)),0) -> 0 | BO20: =ROUND((VLOOKUP(BN20,'SHUI & PIT'!$A$1:$C$8,2,1)*BN20-VLOOKUP(BN20,'SHUI & PIT'!$A$1:$C$8,3,1)),0) -> 0 | BP20: =Y20 -> 0 | BS20: =BJ20+BO20+BP20+BR20+BE20+BF20+BQ20+BK20 -> 1623300 | BT20: =ROUND(IF((BD20-BS20)<0,0,(BD20-BS20)),0) -> 14644700 | BU20: =ROUND($CB20*'SHUI & PIT'!$F$12,0) -> 2705500 | BV20: =ROUND($CB20*'SHUI & PIT'!$G$12,0) -> 463800 | BW20: =ROUND($CC20*'SHUI & PIT'!$H$12,0) -> 154600 | BX20: 0 | BY20: =SUM(BU20:BX20) -> 3323900 | BZ20: =IF(BU20>0,ROUND($CB20*'SHUI & PIT'!$I$12,0),0) -> 309200 | CA20: =BD20+BY20-AC20+BZ20-BQ20 -> 19901100 | CB20: =IF(($F20+$T20)>='SHUI & PIT'!$C$12,'SHUI & PIT'!$C$12,($F20+$T20)) -> 15460000 | CC20: =IF(($F20+$T20)>='SHUI & PIT'!$C$13,'SHUI & PIT'!$C$13,($F20+$T20)) -> 15460000 | CD20: =ROUND(($F20/M20)*($AO20*0.5+$AP20+$AQ20*2+AR20*0.3+AS20*1.1+AT20*1.7+AU20*2.9),0) -> 0 | CE20: =BC20-CD20 -> 508000 | CF20: =_xlfn.XLOOKUP(A20,'[2]Termination and others'!B$12:B$33,'[2]Termination and others'!F$12:F$33,0,0) -> 0 | CG20: =VLOOKUP(A20,Main!$B$13:$BN$405,65,0) -> 10.16 | CH20: =IF(50000<F20/M20,50000,F20/M20)*CG20 -> 508000 | CJ20: =BD20-R20-S20-AK20-CD20-AC20-BE20-BF20-BQ20 -> 15968000
A21: 0016 | C21: 36342 | D21: =DATEDIF(C21,$C$3,"D") -> 9000 | E21: La Nga | F21: 6810000 | G21: 0 | H21: 0 | I21: 26500 | J21: 0 | K21: 0 | L21: 0 | M21: =_xlfn.XLOOKUP(A21,Main!$B$13:$B$1048576,Main!$D$13:$D$1048576,0,0)*8 -> 192 | N21: =_xlfn.XLOOKUP(A21,Main!$B$13:$B$1048576,Main!$BQ$13:$BQ$1048576,0,0) -> 192 | O21: =_xlfn.XLOOKUP(A21,Main!$B$13:$B$1048576,Main!$BR$13:$BR$1048576,0,0) -> 144 | P21: =ROUND(F21/M21*N21,0) -> 6810000 | Q21: =G21/M21*O21 -> 0 | R21: =IF(D21>=(M21/8),H21,H21/M21*N21) -> 0 | S21: =IF(CI21="N",26500*(ROUND(O21/8,0)),(I21/M21*O21)-CF21) -> 477000 | T21: =J21 -> 0 | U21: =K21/M21*O21 -> 0 | V21: =IF(D21>=(M21/8),L21,L21/M21*N21) -> 0 | AE21: YES | AF21: 0 | AG21: 0 | AJ21: 0 | AK21: 0 | AL21: 0 | AM21: 0 | AN21: 0 | AO21: =_xlfn.XLOOKUP($A21,Main!$B$13:$B$35,Main!BU$13:BU$35,0,0) -> 0 | AP21: =_xlfn.XLOOKUP($A21,Main!$B$13:$B$35,Main!BV$13:BV$35,0,0) -> 0 | AQ21: =_xlfn.XLOOKUP($A21,Main!$B$13:$B$35,Main!BW$13:BW$35,0,0) -> 0 | AR21: =_xlfn.XLOOKUP($A21,Main!$B$13:$B$35,Main!BX$13:BX$35,0,0) -> 0 | AS21: =_xlfn.XLOOKUP($A21,Main!$B$13:$B$35,Main!BY$13:BY$35,0,0) -> 0 | AT21: =_xlfn.XLOOKUP($A21,Main!$B$13:$B$35,Main!BZ$13:BZ$35,0,0) -> 0 | AU21: =_xlfn.XLOOKUP($A21,Main!$B$13:$B$35,Main!CA$13:CA$35,0,0) -> 0 | AV21: =$F21/$M21*AO21*150% -> 0 | AW21: =$F21/$M21*AP21*200% -> 0 | AX21: =$F21/$M21*AQ21*300% -> 0 | AY21: =$F21/$M21*AR21*30% -> 0 | AZ21: =$F21/$M21*AS21*210% -> 0 | BA21: =$F21/$M21*AT21*270% -> 0 | BB21: =$F21/$M21*AU21*390% -> 0 | BC21: =ROUND(SUM(AV21:BB21)+CH21,0) -> 0 | BD21: =SUM(P21:AN21)+BC21 -> 7287000 | BG21: =ROUND($CB21*'SHUI & PIT'!$F$11,0) -> 544800 | BH21: =ROUND($CB21*'SHUI & PIT'!$G$11,0) -> 102150 | BI21: =ROUND($CC21*'SHUI & PIT'!$H$11,0) -> 68100 | BJ21: =SUM(BG21:BI21) -> 715050 | BK21: =IF(E21="La Nga",0,IF(E21="HCM",35000,IF(AE21="YES",IF($BG21>0,ROUND(MIN($CB21*1%,180000),0),0),0))) -> 0 | BL21: =VLOOKUP(A21,'[1]Payroll master '!B$12:AD$160,29,0) -> 0 | BM21: =11000000+4400000*BL21 -> 11000000 | BN21: =ROUND(IF((CJ21-BJ21-BM21-BR21)<0,0,(CJ21-BJ21-BM21-BR21)),0) -> 0 | BO21: =ROUND((VLOOKUP(BN21,'SHUI & PIT'!$A$1:$C$8,2,1)*BN21-VLOOKUP(BN21,'SHUI & PIT'!$A$1:$C$8,3,1)),0) -> 0 | BP21: =Y21 -> 0 | BS21: =BJ21+BO21+BP21+BR21+BE21+BF21+BQ21+BK21 -> 715050 | BT21: =ROUND(IF((BD21-BS21)<0,0,(BD21-BS21)),0) -> 6571950 | BU21: =ROUND($CB21*'SHUI & PIT'!$F$12,0) -> 1191750 | BV21: =ROUND($CB21*'SHUI & PIT'!$G$12,0) -> 204300 | BW21: =ROUND($CC21*'SHUI & PIT'!$H$12,0) -> 68100 | BX21: 0 | BY21: =SUM(BU21:BX21) -> 1464150 | BZ21: =IF(BU21>0,ROUND($CB21*'SHUI & PIT'!$I$12,0),0) -> 136200 | CA21: =BD21+BY21-AC21+BZ21-BQ21 -> 8887350 | CB21: =IF(($F21+$T21)>='SHUI & PIT'!$C$12,'SHUI & PIT'!$C$12,($F21+$T21)) -> 6810000 | CC21: =IF(($F21+$T21)>='SHUI & PIT'!$C$13,'SHUI & PIT'!$C$13,($F21+$T21)) -> 6810000 | CD21: =ROUND(($F21/M21)*($AO21*0.5+$AP21+$AQ21*2+AR21*0.3+AS21*1.1+AT21*1.7+AU21*2.9),0) -> 0 | CE21: =BC21-CD21 -> 0 | CF21: =_xlfn.XLOOKUP(A21,'[2]Termination and others'!B$12:B$33,'[2]Termination and others'!F$12:F$33,0,0) -> 0 | CG21: =VLOOKUP(A21,Main!$B$13:$BN$405,65,0) -> 0 | CH21: =IF(50000<F21/M21,50000,F21/M21)*CG21 -> 0 | CI21: N | CJ21: =BD21-R21-S21-AK21-CD21-AC21-BE21-BF21-BQ21 -> 6810000
