Workbook
Name \0: #REF!
Name \a: #REF!
Name \a: #REF!
Name \a: #REF!
Name \b: #N/A
Name \c: #N/A
Name \d: #N/A
Name \e: #REF!
Name \f: #REF!
Name \g: #REF!
Name \h: #REF!
Name \i: #REF!
Name \j: #REF!
Name \k: #REF!
Name \l: #REF!
Name \m: #REF!
Name \n: #REF!
Name \o: #REF!
Name \p: #N/A
Name \T: #REF!
Name \T: #REF!
Name \T: #REF!
Name \T: #REF!
Name \T: #REF!
Name \T: #REF!
Name \z: #REF!
Name _: "SQRT"
Name _.._mik: #REF!
Name _?: #REF!
Name _?: #REF!
Name _??: #N/A
Name _??????: #REF!
Name _??????: #REF!
Name _?1: #N/A
Name _?271: #N/A
Name _?춑_TOTAL: #N/A
Name _?춮t2: #N/A
Name __?: #N/A
Name __??: #N/A
Name __??????: #REF!
Name __??????: #REF!
Name __?1: #N/A
Name __?271: #N/A
Name ___?: #REF!
Name ___?: #REF!
Name ___?: #REF!
Name ___?: #REF!
Name ___?: #REF!
Name ___?: #REF!
Name ___??????: #REF!
Name ___??????: #REF!
Name ___??????: #REF!
Name ___??????: #REF!
Name ___??????: #REF!
Name ___??????: #REF!
Name ___________________________________C45_EXC_M: #REF!
Name __________________________________C45_EXC_M: #REF!
Name _________________________________C45_EXC_M: #REF!
Name ________________________________C45_EXC_M: #REF!
Name _______________________________C45_EXC_M: #REF!

Sheet BANG LUONG VTĐB 
A1: CÔNG TY ................. | AU1: 5143077 | AY1: 4946923 | AZ1: =AU1-AY1 -> 196154
A2: Địa chỉ: ............
A3: BẢNG THANH TOÁN TIỀN LƯƠNG THÁNG 11 NĂM 2025 | CT3: THỐNG KÊ LƯƠNG KỲ 2
AZ5: Nam Bộ | BF5: Nam Bộ | BG5: 11 | CJ5: Công chuẩn
AZ6: Bắc Bộ | BF6: Bắc Bộ | BG6: 11 | BV6: THÔNG TIN VỀ TÍNH THUẾ TNCN | CJ6: 25
A7: TT | B7: MSNV | C7: Họ và tên | D7: TĐ | E7: Ngạch lương | F7: Ngày vào | G7: Mức lương HĐLĐ | H7: Mức lương HĐTV | I7: Định mức thưởng HQCV | J7: Phụ cấp | K7: Tổng định mức thưởng HQCV | L7: Tổng thu nhập (Mức lương + Định mức thưởng HQCV) | M7: Tỷ lệ % tạm ứng thưởng HQCV | N7: Mức lương tính chế độ ngừng việc | P7: Ngày công trong tháng | AG7: Các khoản được hưởng trong tháng | AV7: Tiền công giao xe 20% chi cùng lương kỳ 2/11 | AW7: Thu nhập hoàn thuế năm.. | AX7: Chi quà 1/6 | AY7: Thu nhập đã tạm ứng kỳ 1/11 | AZ7: Tổng thu nhập còn lại trong tháng 11 | BA7: Các khoản giám trừ kỳ trong tháng | BL7: Tổng giảm trừ | BM7: Thực nhận | BN7: Thu vào kỳ sau | BV7: THUẾ THU NHẬP CÁ NHÂN | CF7: Khoản đc giảm trừ trong thuế | CI7: BHXH | CL7: KỲ I | CT7: KỲ II | DA7: Chức vụ | DB7: Bộ phận | DC7: Mail | DD7: Khu vực đóng góp tang chế | DE7: TÀI KHOẢN NGÂN HÀNG | DJ7: GHI CHÚ
P8: Công chính | Q8: Công giao xe | R8: Công Tăng ca ngày thường | S8: Công Chủ nhật | T8: Công ngày lễ, tết | W8: Hiếu, hỉ | X8: Ngày PN thanh toán T11/2025 | Y8: Ngày ngừng việc | AA8: Ngày ngừng việc BKK | AB8: Công ngày thứ 7 | AD8: Công phụ cấp | AF8: Ngày PN chưa nghỉ năm 2025 | AG8: Lương Ngày thường | AH8: Lương Tăng ca thường | AI8: Lương chủ nhật | AJ8: Lương ngày lễ, tết | AL8: Lương Hiếu, Hỉ | AM8: Lương phép PN thanh toán T11 | AN8: Lương tạm ngừng việc | AO8: Lương chế độ T7 | AP8: Thu nhập phụ cấp | AR8: Phép năm chưa nghỉ năm 2025 | AS8: Tạm ứng thưởng HQCV | AT8: Thu nhập khác (Phép năm thôi việc, Hỗ trợ thôi việc,...) | AU8: Tổng thu nhập tháng 11 | BA8: BHXH | BB8: BHYT | BC8: BHTN | BD8: BHXH,BHYT, BHTN | BE8: Phí công đoàn | BF8: Phí đoàn thanh niên (dưới 30 tuổi) | BG8: Tiền phúng điếu | BH8: Cước điện thoại T10/2025 | BI8: Thuế TNCN T11 | BJ8: Thu thuế TNCN T1/2024 lần 1 | BK8: Giảm trừ khác (thu hộ tiền ủng hộ Nguyễn Tấn Dũng, thu nợ kỳ trước, thu hộ tiền bồi thường,...) | BO8: KIỂM TRA | BV8: Thu nhập ngoài bảng lương đưa vào tính thuế | BZ8: THU NHẬP CHỊU THUẾ TNCN | CA8: SỐ NGƯỜI PHỤ THUỘC | CB8: GIẢM TRỪ GIA CẢNH | CC8: GIẢM TRỪ BẢN THÂN | CD8: TỔNG GIẢM TRỪ | CE8: TỔNG THU NHẬP TÍNH THUẾ TNCN
N9: Tạm ngừng việc 14 ngày đầu | O9: Tạm ngừng việc từ 15 ngày trở đi | T9: Đi làm lễ, tết | U9: Tăng ca | V9: Nghỉ lễ, tết | Y9: 14 ngày đầu | Z9: Từ ngày 15 trở đi | AB9: Đi làm T7 | AC9: Nghỉ T7 | AD9: Phụ cấp ban đêm | AE9: Phụ cấp bồi dưỡng làm việc | AJ9: Làm việc ngày lễ, tết | AK9: Nghỉ lễ, tết | AP9: Phụ cấp ban đêm | AQ9: Phụ cấp bồi dưỡng làm việc | BA9: 8% | BB9: 1.5% | BC9: 1% | BD9: (LHĐLĐ *10.5%) | BE9: (LHĐLĐ*1%) | BF9: 5.000đ/ người | BG9: 23 | BO9: MA BH | BP9: Ma KPCD | BQ9: Kiểm tra đối tượng hưởng lương | BR9: Kiểm tra đối tượng hưởng tăng ca | BS9: BD PHSK | BT9: MỨC TIỀN | BU9: Trừ tiền tang chế | BV9: Tiền ăn vượt mức | BW9: Thu nhập còn phải chi tháng 1 | BX9: Tiền thưởng | BY9: Thu nhập 100% giao xe | CF9: Hỗ trợ thôi việc, trợ cấp thôi việc | CG9: Truy lĩnh PC ĐH cho LX trung chuyển làm việc MT ĐH T3-T6/2025 | CH9: Trả lại tiền thu ĐTDD Tháng 8 - Chi nhánh | CI9: Truy thu BH | CJ9: Truy lĩnh BHXH | CK9: BHXH đã thu (số trong bảng đóng BHXH) | CL9: Mức lương | CM9: PC ThN | CN9: PC chức danh | CO9: PC kiêm nhiệm | CP9: PC biệt phái | CQ9: Tổng PC | CR9: Tổng thu nhập | CT9: Mức lương | CU9: PC ThN | CV9: PC chức danh | CW9: PC kiêm nhiệm | CX9: PC biệt phái | CY9: Tổng PC | CZ9: Tổng thu nhập | DE9: ICB | DF9: VCB | DG9: BIDV | DH9: NH khác | DI9: CCCD
A10: A. | B10: ="KHU VỰC CHU LAI: "&"["&COUNT(A11:A23)&"]" -> KHU VỰC CHU LAI: [10] | G10: =G11+G22+G14+#REF!+#REF!+#REF!+#REF!+#REF!+#REF! -> #REF! | H10: =H11+H22+H14+#REF!+#REF!+#REF!+#REF!+#REF!+#REF! -> #REF! | I10: =I11+I22+I14+#REF!+#REF!+#REF!+#REF!+#REF!+#REF! -> #REF! | J10: =J11+J22+J14+#REF!+#REF!+#REF!+#REF!+#REF!+#REF! -> #REF! | K10: =K11+K22+K14+#REF!+#REF!+#REF!+#REF!+#REF!+#REF! -> #REF! | L10: =L11+L22+L14+#REF!+#REF!+#REF!+#REF!+#REF!+#REF! -> #REF! | N10: =N11+N22+N14+#REF!+#REF!+#REF!+#REF!+#REF!+#REF! -> #REF! | O10: =O11+O22+O14+#REF!+#REF!+#REF!+#REF!+#REF!+#REF! -> #REF! | P10: =P11+P22+P14+#REF!+#REF!+#REF!+#REF!+#REF!+#REF! -> #REF! | Q10: =Q11+Q22+Q14+#REF!+#REF!+#REF!+#REF!+#REF!+#REF! -> #REF! | R10: =R11+R22+R14+#REF!+#REF!+#REF!+#REF!+#REF!+#REF! -> #REF! | S10: =S11+S22+S14+#REF!+#REF!+#REF!+#REF!+#REF!+#REF! -> #REF! | T10: =T11+T22+T14+#REF!+#REF!+#REF!+#REF!+#REF!+#REF! -> #REF! | U10: =U11+U22+U14+#REF!+#REF!+#REF!+#REF!+#REF!+#REF! -> #REF! | ... CZ10: =CZ11+CZ22+CZ14+#REF!+#REF!+#REF!+#REF!+#REF!+#REF! -> #REF!
A11: I | B11: ="............: "&"["&COUNT(A13:A13)&"]" -> ............: [1] | G11: =SUM(G12:G13) -> 0 | H11: =SUM(H12:H13) -> 0 | I11: =SUM(I12:I13) -> 0 | J11: =SUM(J12:J13) -> 0 | K11: =SUM(K12:K13) -> 0 | L11: =SUM(L12:L13) -> 0 | N11: =SUM(N12:N13) -> 7280000 | O11: =SUM(O12:O13) -> 0 | P11: =SUM(P12:P13) -> 0 | Q11: =SUM(Q12:Q13) -> 0 | R11: =SUM(R12:R13) -> 0 | S11: =SUM(S12:S13) -> 0 | T11: =SUM(T12:T13) -> 0 | U11: =SUM(U12:U13) -> 0 | ... DC11: =SUM(DC12:DC13) -> 0 | DE11: =SUM(DE13:DE13) -> 0 | DF11: =SUM(DF13:DF13) -> 0 | DG11: =SUM(DG13:DG13) -> 0 | DH11: =SUM(DH13:DH13) -> 0 | DI11: =SUM(DI13:DI13) -> 0
A12: =SUBTOTAL(3,$C$11:C12) -> 0 | I12: =IF(G12>0,CT12-G12,CT12-H12) -> 0 | J12: =CY12 -> 0 | K12: =SUM(I12:J12) -> 0 | L12: =IF(G12>0,G12+K12,H12+K12) -> 0 | M12: 1 | N12: =ROUND(MAX(G12*70%,H12*70%,3640000),0) -> 3640000 | O12: 0 | AE12: =IF(OR(BS12="M1",BS12="M2",BS12="M3",BS12="M4"),P12+R12+S12+T12+U12,0) -> 0 | AG12: =MAX(ROUND(IF(P12=0,0,IF(AND(BQ12="Lương tháng",(AB12+AC12)=0),MAX(G12/26*P12*M12,H12/26*P12*M12),IF(BQ12="Lương tháng",MAX((G12-G12/26*($CJ$6-P12))*M12,(H12-H12/26*($CJ$6-P12))*M12),MAX(G12/26*P12*M12,H12/26*P12*M12)))),0),0) -> 0 | AH12: =ROUND(MAX((G12+I12)*M12/26*R12,(H12+I12)*M12/26*R12,G12/26*R12*150%,H12/26*R12*150%)*BR12,0) -> 0 | AI12: =ROUND(MAX((G12+I12)*M12/26*S12,(H12+I12)*M12/26*S12,G12/26*S12*200%,H12/26*S12*200%)*BR12,0) -> 0 | AJ12: =ROUND(IF(BQ12="Lương tháng",L12/26*T12,MAX((G12+I12)/26*(T12+U12)*200%+G12/26*T12,(H12+I12)/26*(T12+U12)*200%+H12/26*T12,G12/26*(T12+U12)*300%+G12/26*T12,H12/26*(T12+U12)*300%+H12/26*T12)),0) -> 0 | AK12: =ROUND(IF((P12+Q12)=0,0,IF(BQ12="Lương tháng",MAX((G12+I12)/26*V12,(H12+I12)/26*V12),MAX(G12/26*V12,H12/26*V12))),0) -> 0 | AL12: =ROUND(IF(G12>0,G12/26*W12,H12/26*W12),0) -> 0 | AM12: =ROUND((G12+50%*I12)/26*X12,0) -> 0 | AN12: =ROUND(N12/26*Y12+O12/26*Z12+MAX(G12/26*AA12,H12/26*AA12),0) -> 0 | AO12: =ROUND(IF(BQ12="Lương tháng",L12/26*AC12,L12/26*AC12+L12/26*AB12),0) -> 0 | AP12: =ROUND(IF(BQ12="lương tháng",0,MAX((G12+I12)/26*AD12*30%,(H12+I12)/26*AD12*30%)*BR12),0) -> 0 | AQ12: =ROUND(BT12*AE12,0) -> 0 | AR12: =ROUND((G12+I12)/26*AF12,0) -> 0 | AS12: =MAX(ROUND(IF(P12=0,0,IF(AND(BQ12="Lương tháng",(AB12+AC12)=0),K12/26*P12*M12,IF(BQ12="Lương tháng",(K12-K12/26*($CJ$6-P12))*M12,(K12/26*P12*M12)))),0),0)+ROUND(J12/26*Q12,0) -> 0 | AU12: =ROUND(SUM(AG12:AT12),0) -> 0 | AZ12: =ROUND(SUM(AU12:AX12)-AY12,0) -> 0 | BD12: =SUM(BA12:BC12) -> 0 | BE12: 0 | BG12: =IF(BU12="Xem lại",0,IF(CL12<11000000,5000,IF(AND(CL12>=11000000,CL12<25000000),10000,IF(AND(CL12>=25000000,CL12<40000000),15000,IF(AND(CL12>=40000000,CL12<120000000),20000,IF(AND(CL12>=120000000,CL12<240000000),25000,30000)))))*$BG$9) -> 0 | BI12: =IF(CE12>0,ROUND(IF(CE12>=80000000,CE12*35%-9850000,IF(CE12>=52000000,CE12*30%-5850000,IF(CE12>=32000000,CE12*25%-3250000,IF(CE12>=18000000,CE12*20%-1650000,IF(CE12>=10000000,CE12*15%-750000,IF(CE12>5000000,CE12*10%-250000,CE12*5%)))))),0),0) -> 0 | BL12: =ROUND(SUM(BD12:BK12),0) -> 0 | BM12: =ROUND(IF(AZ12>BL12,AZ12-BL12,0),0) -> 0 | BN12: =ROUND(IF(BL12>AZ12,BL12-AZ12,0),0) -> 0 | BO12: 1 | BP12: 1x | BQ12: =IF(AND(D12="QTNV CL",CT12>=11000000),"Lương tháng",IF(CT12>=18000000,"Lương tháng",0)) -> 0 | BR12: =IF(BQ12="Lương tháng",0,1) -> 1 | BS12: 0 | BT12: =IF(BS12="M1",13000,IF(BS12="M2",20000,IF(BS12="M3",26000,IF(BS12="M4",32000,0)))) -> 0 | BU12: =IF(AND(G12>0,(P12+Q12)>5),"Trừ tiền","Xem lại") -> Xem lại | BZ12: =AU12+SUM(BV12:BY12)-AL12-AP12-AQ12-SUM(CF12:CH12) -> 0 | CB12: =CA12*4400000 -> 0 | CC12: 11000000 | CD12: =CB12+CC12 -> 11000000 | CE12: =BZ12-SUM(CJ12:CK12)-CI12-BD12-CD12 -> -12798650 | CK12: 1798650 | CM12: 0 | CN12: 0 | CQ12: =SUM(CM12:CP12) -> 0 | CR12: =CL12+CQ12 -> 0 | CT12: =CL12 -> 0 | CU12: =CM12 -> 0 | CV12: =CN12 -> 0 | CW12: =CO12 -> 0 | CX12: =CP12 -> 0 | CY12: =SUM(CU12:CX12) -> 0 | CZ12: =CT12+CY12 -> 0
A13: =SUBTOTAL(3,$C$11:C13) -> 0 | I13: =IF(G13>0,CT13-G13,CT13-H13) -> 0 | J13: =CY13 -> 0 | K13: =SUM(I13:J13) -> 0 | L13: =IF(G13>0,G13+K13,H13+K13) -> 0 | M13: 1 | N13: =ROUND(MAX(G13*70%,H13*70%,3640000),0) -> 3640000 | O13: 0 | AE13: =IF(OR(BS13="M1",BS13="M2",BS13="M3",BS13="M4"),P13+R13+S13+T13+U13,0) -> 0 | AG13: =MAX(ROUND(IF(P13=0,0,IF(AND(BQ13="Lương tháng",(AB13+AC13)=0),MAX(G13/26*P13*M13,H13/26*P13*M13),IF(BQ13="Lương tháng",MAX((G13-G13/26*($CJ$6-P13))*M13,(H13-H13/26*($CJ$6-P13))*M13),MAX(G13/26*P13*M13,H13/26*P13*M13)))),0),0) -> 0 | AH13: =ROUND(MAX((G13+I13)*M13/26*R13,(H13+I13)*M13/26*R13,G13/26*R13*150%,H13/26*R13*150%)*BR13,0) -> 0 | AI13: =ROUND(MAX((G13+I13)*M13/26*S13,(H13+I13)*M13/26*S13,G13/26*S13*200%,H13/26*S13*200%)*BR13,0) -> 0 | AJ13: =ROUND(IF(BQ13="Lương tháng",L13/26*T13,MAX((G13+I13)/26*(T13+U13)*200%+G13/26*T13,(H13+I13)/26*(T13+U13)*200%+H13/26*T13,G13/26*(T13+U13)*300%+G13/26*T13,H13/26*(T13+U13)*300%+H13/26*T13)),0) -> 0 | AK13: =ROUND(IF((P13+Q13)=0,0,IF(BQ13="Lương tháng",MAX((G13+I13)/26*V13,(H13+I13)/26*V13),MAX(G13/26*V13,H13/26*V13))),0) -> 0 | AL13: =ROUND(IF(G13>0,G13/26*W13,H13/26*W13),0) -> 0 | AM13: =ROUND((G13+50%*I13)/26*X13,0) -> 0 | AN13: =ROUND(N13/26*Y13+O13/26*Z13+MAX(G13/26*AA13,H13/26*AA13),0) -> 0 | AO13: =ROUND(IF(BQ13="Lương tháng",L13/26*AC13,L13/26*AC13+L13/26*AB13),0) -> 0 | AP13: =ROUND(IF(BQ13="lương tháng",0,MAX((G13+I13)/26*AD13*30%,(H13+I13)/26*AD13*30%)*BR13),0) -> 0 | AQ13: =ROUND(BT13*AE13,0) -> 0 | AR13: =ROUND((G13+I13)/26*AF13,0) -> 0 | AS13: =MAX(ROUND(IF(P13=0,0,IF(AND(BQ13="Lương tháng",(AB13+AC13)=0),K13/26*P13*M13,IF(BQ13="Lương tháng",(K13-K13/26*($CJ$6-P13))*M13,(K13/26*P13*M13)))),0),0)+ROUND(J13/26*Q13,0) -> 0 | AU13: =ROUND(SUM(AG13:AT13),0) -> 0 | AZ13: =ROUND(SUM(AU13:AX13)-AY13,0) -> 0 | BD13: =SUM(BA13:BC13) -> 0 | BE13: 0 | BG13: =IF(BU13="Xem lại",0,IF(CL13<11000000,5000,IF(AND(CL13>=11000000,CL13<25000000),10000,IF(AND(CL13>=25000000,CL13<40000000),15000,IF(AND(CL13>=40000000,CL13<120000000),20000,IF(AND(CL13>=120000000,CL13<240000000),25000,30000)))))*$BG$9) -> 0 | BI13: =IF(CE13>0,ROUND(IF(CE13>=80000000,CE13*35%-9850000,IF(CE13>=52000000,CE13*30%-5850000,IF(CE13>=32000000,CE13*25%-3250000,IF(CE13>=18000000,CE13*20%-1650000,IF(CE13>=10000000,CE13*15%-750000,IF(CE13>5000000,CE13*10%-250000,CE13*5%)))))),0),0) -> 0 | BL13: =ROUND(SUM(BD13:BK13),0) -> 0 | BM13: =ROUND(IF(AZ13>BL13,AZ13-BL13,0),0) -> 0 | BN13: =ROUND(IF(BL13>AZ13,BL13-AZ13,0),0) -> 0 | BO13: 1 | BP13: 1x | BQ13: =IF(AND(D13="QTNV CL",CT13>=11000000),"Lương tháng",IF(CT13>=18000000,"Lương tháng",0)) -> 0 | BR13: =IF(BQ13="Lương tháng",0,1) -> 1 | BS13: 0 | BT13: =IF(BS13="M1",13000,IF(BS13="M2",20000,IF(BS13="M3",26000,IF(BS13="M4",32000,0)))) -> 0 | BU13: =IF(AND(G13>0,(P13+Q13)>5),"Trừ tiền","Xem lại") -> Xem lại | BV13: 0 | BZ13: =AU13+SUM(BV13:BY13)-AL13-AP13-AQ13-SUM(CF13:CH13) -> 0 | CB13: =CA13*4400000 -> 0 | CC13: 11000000 | CD13: =CB13+CC13 -> 11000000 | CE13: =BZ13-SUM(CJ13:CK13)-CI13-BD13-CD13 -> -12209600 | CK13: 1209600 | CM13: 0 | CN13: 0 | CQ13: =SUM(CM13:CP13) -> 0 | CR13: =CL13+CQ13 -> 0 | CT13: =CL13 -> 0 | CU13: =CM13 -> 0 | CV13: =CN13 -> 0 | CW13: =CO13 -> 0 | CX13: =CP13 -> 0 | CY13: =SUM(CU13:CX13) -> 0 | CZ13: =CT13+CY13 -> 0
A14: II | B14: ="...............: " &"["&COUNT(A15:A20)& "]" -> ...............: [6] | G14: =SUM(G15:G20) -> 29140000 | H14: =SUM(H15:H20) -> 0 | I14: =SUM(I15:I20) -> 35860000 | J14: =SUM(J15:J20) -> 3925000 | K14: =SUM(K15:K20) -> 39785000 | L14: =SUM(L15:L20) -> 68925000 | N14: =SUM(N15:N20) -> 22610000 | O14: =SUM(O15:O20) -> 0 | P14: =SUM(P15:P20) -> 123.5 | Q14: =SUM(Q15:Q20) -> 25 | R14: =SUM(R15:R20) -> 13.94 | S14: =SUM(S15:S20) -> 0 | T14: =SUM(T15:T20) -> 0 | U14: =SUM(U15:U20) -> 0 | ... DC14: =SUM(DC15:DC20) -> 0
A15: =SUBTOTAL(3,$C$11:C15) -> 1 | C15: Nguyễn Văn A | D15: THILOGI | E15: =IF(CL15>=400000000,"A1",IF(CL15>=300000000,"A2",IF(CL15>=240000000,"A3",IF(CL15>=180000000,"A4",IF(CL15>=120000000,"A5",IF(CL15>=80000000,"A6",IF(CL15>=40000000,"A7",IF(CL15>=25000000,"B1",IF(CL15>=12000000,"B2","B3"))))))))) -> B2 | F15: 45371 | G15: 6300000 | I15: =IF(G15>0,CT15-G15,CT15-H15) -> 5700000 | J15: =CY15 -> 0 | K15: =SUM(I15:J15) -> 5700000 | L15: =IF(G15>0,G15+K15,H15+K15) -> 12000000 | M15: 1 | N15: =ROUND(MAX(G15*70%,H15*70%,3640000),0) -> 4410000 | O15: 0 | P15: 22.5 | Q15: 0 | R15: 2 | S15: 0 | X15: 0.5 | AA15: 0 | AB15: 0 | AC15: 2 | AD15: 0 | AE15: 0 | AG15: =MAX(ROUND(IF(P15=0,0,IF(AND(BQ15="Lương tháng",(AB15+AC15)=0),MAX(G15/26*P15*M15,H15/26*P15*M15),IF(BQ15="Lương tháng",MAX((G15-G15/26*($CJ$6-P15))*M15,(H15-H15/26*($CJ$6-P15))*M15),MAX(G15/26*P15*M15,H15/26*P15*M15)))),0),0) -> 5451923 | AH15: =ROUND(MAX((G15+I15)*M15/26*R15,(H15+I15)*M15/26*R15,G15/26*R15*150%,H15/26*R15*150%)*BR15,0) -> 923077 | AI15: =ROUND(MAX((G15+I15)*M15/26*S15,(H15+I15)*M15/26*S15,G15/26*S15*200%,H15/26*S15*200%)*BR15,0) -> 0 | AJ15: =ROUND(IF(BQ15="Lương tháng",L15/26*T15,MAX((G15+I15)/26*(T15+U15)*200%+G15/26*T15,(H15+I15)/26*(T15+U15)*200%+H15/26*T15,G15/26*(T15+U15)*300%+G15/26*T15,H15/26*(T15+U15)*300%+H15/26*T15)),0) -> 0 | AK15: =ROUND(IF((P15+Q15)=0,0,IF(BQ15="Lương tháng",MAX((G15+I15)/26*V15,(H15+I15)/26*V15),MAX(G15/26*V15,H15/26*V15))),0) -> 0 | AL15: =ROUND(IF(G15>0,G15/26*W15,H15/26*W15),0) -> 0 | AM15: =ROUND((G15+50%*I15)/26*X15,0) -> 175962 | AN15: =ROUND(N15/26*Y15+O15/26*Z15+MAX(G15/26*AA15,H15/26*AA15),0) -> 0 | AO15: =ROUND(IF(BQ15="Lương tháng",L15/26*AC15,L15/26*AC15+L15/26*AB15),0) -> 923077 | AP15: =ROUND(IF(BQ15="lương tháng",0,MAX((G15+I15)/26*AD15*30%,(H15+I15)/26*AD15*30%)*BR15),0) -> 0 | AQ15: =ROUND(BT15*AE15,0) -> 0 | AR15: =ROUND((G15+I15)/26*AF15,0) -> 0 | AS15: =MAX(ROUND(IF(P15=0,0,IF(AND(BQ15="Lương tháng",(AB15+AC15)=0),K15/26*P15*M15,IF(BQ15="Lương tháng",(K15-K15/26*($CJ$6-P15))*M15,(K15/26*P15*M15)))),0),0)+ROUND(J15/26*Q15,0) -> 4932692 | AY15: =VLOOKUP(B15,'TAM UNG'!$B$12:$AQ$623,42,0) -> #N/A | AZ15: =ROUND(SUM(AU15:AX15)-AY15,0) -> #N/A | BD15: =SUM(BA15:BC15) -> 0 | BE15: 0 | BG15: =IF(BU15="Xem lại",0,IF(CL15<11000000,5000,IF(AND(CL15>=11000000,CL15<25000000),10000,IF(AND(CL15>=25000000,CL15<40000000),15000,IF(AND(CL15>=40000000,CL15<120000000),20000,IF(AND(CL15>=120000000,CL15<240000000),25000,30000)))))*$BG$9) -> 230000 | BI15: =IF(CE15>0,ROUND(IF(CE15>=80000000,CE15*35%-9850000,IF(CE15>=52000000,CE15*30%-5850000,IF(CE15>=32000000,CE15*25%-3250000,IF(CE15>=18000000,CE15*20%-1650000,IF(CE15>=10000000,CE15*15%-750000,IF(CE15>5000000,CE15*10%-250000,CE15*5%)))))),0),0) -> 0 | BL15: =ROUND(SUM(BD15:BK15),0) -> 230000 | BM15: =ROUND(IF(AZ15>BL15,AZ15-BL15,0),0) -> #N/A | BN15: =ROUND(IF(BL15>AZ15,BL15-AZ15,0),0) -> #N/A | BO15: 1 | BP15: 1x | BQ15: =IF(AND(D15="QTNV CL",CT15>=11000000),"Lương tháng",IF(CT15>=18000000,"Lương tháng",0)) -> 0 | BR15: =IF(BQ15="Lương tháng",0,1) -> 1 | BS15: 0 | BT15: =IF(BS15="M1",13000,IF(BS15="M2",20000,IF(BS15="M3",26000,IF(BS15="M4",32000,0)))) -> 0 | BU15: =IF(AND(G15>0,(P15+Q15)>5),"Trừ tiền","Xem lại") -> Trừ tiền | BZ15: =AU15+SUM(BV15:BY15)-AL15-AP15-AQ15-SUM(CF15:CH15) -> 0 | CB15: =CA15*4400000 -> 0 | CC15: 11000000 | CD15: =CB15+CC15 -> 11000000 | CE15: =BZ15-SUM(CJ15:CK15)-CI15-BD15-CD15 -> -11661500 | CK15: 661500 | CL15: 12000000 | CQ15: =SUM(CM15:CP15) -> 0 | CR15: =CL15+CQ15 -> 12000000 | CT15: =CL15 -> 12000000 | CU15: =CM15 -> 0 | CV15: =CN15 -> 0 | CW15: =CO15 -> 0 | CX15: =CP15 -> 0 | CY15: =SUM(CU15:CX15) -> 0 | CZ15: =CT15+CY15 -> 12000000 | DJ15: Nhân sự văn phòng
A16: =SUBTOTAL(3,$C$11:C16) -> 2 | C16: Nguyễn Văn B | D16: THILOGI | E16: =IF(CL16>=400000000,"A1",IF(CL16>=300000000,"A2",IF(CL16>=240000000,"A3",IF(CL16>=180000000,"A4",IF(CL16>=120000000,"A5",IF(CL16>=80000000,"A6",IF(CL16>=40000000,"A7",IF(CL16>=25000000,"B1",IF(CL16>=12000000,"B2","B3"))))))))) -> B3 | F16: 43570 | G16: 4520000 | I16: =IF(G16>0,CT16-G16,CT16-H16) -> 3980000 | J16: =CY16 -> 425000 | K16: =SUM(I16:J16) -> 4405000 | L16: =IF(G16>0,G16+K16,H16+K16) -> 8925000 | M16: 1 | N16: =ROUND(MAX(G16*70%,H16*70%,3640000),0) -> 3640000 | O16: 0 | P16: 25 | Q16: 0 | R16: 7.78 | S16: 0 | X16: 0 | AA16: 0 | AB16: 2 | AC16: 0 | AD16: 0.81 | AE16: 32.78 | AG16: =MAX(ROUND(IF(P16=0,0,IF(AND(BQ16="Lương tháng",(AB16+AC16)=0),MAX(G16/26*P16*M16,H16/26*P16*M16),IF(BQ16="Lương tháng",MAX((G16-G16/26*($CJ$6-P16))*M16,(H16-H16/26*($CJ$6-P16))*M16),MAX(G16/26*P16*M16,H16/26*P16*M16)))),0),0) -> 4346154 | AH16: =ROUND(MAX((G16+I16)*M16/26*R16,(H16+I16)*M16/26*R16,G16/26*R16*150%,H16/26*R16*150%)*BR16,0) -> 2543462 | AI16: =ROUND(MAX((G16+I16)*M16/26*S16,(H16+I16)*M16/26*S16,G16/26*S16*200%,H16/26*S16*200%)*BR16,0) -> 0 | AJ16: =ROUND(IF(BQ16="Lương tháng",L16/26*T16,MAX((G16+I16)/26*(T16+U16)*200%+G16/26*T16,(H16+I16)/26*(T16+U16)*200%+H16/26*T16,G16/26*(T16+U16)*300%+G16/26*T16,H16/26*(T16+U16)*300%+H16/26*T16)),0) -> 0 | AK16: =ROUND(IF((P16+Q16)=0,0,IF(BQ16="Lương tháng",MAX((G16+I16)/26*V16,(H16+I16)/26*V16),MAX(G16/26*V16,H16/26*V16))),0) -> 0 | AL16: =ROUND(IF(G16>0,G16/26*W16,H16/26*W16),0) -> 0 | AM16: =ROUND((G16+50%*I16)/26*X16,0) -> 0 | AN16: =ROUND(N16/26*Y16+O16/26*Z16+MAX(G16/26*AA16,H16/26*AA16),0) -> 0 | AO16: =ROUND(IF(BQ16="Lương tháng",L16/26*AC16,L16/26*AC16+L16/26*AB16),0) -> 686538 | AP16: =ROUND(IF(BQ16="lương tháng",0,MAX((G16+I16)/26*AD16*30%,(H16+I16)/26*AD16*30%)*BR16),0) -> 79442 | AQ16: =ROUND(BT16*AE16,0) -> 426140 | AR16: =ROUND((G16+I16)/26*AF16,0) -> 0 | AS16: =MAX(ROUND(IF(P16=0,0,IF(AND(BQ16="Lương tháng",(AB16+AC16)=0),K16/26*P16*M16,IF(BQ16="Lương tháng",(K16-K16/26*($CJ$6-P16))*M16,(K16/26*P16*M16)))),0),0)+ROUND(J16/26*Q16,0) -> 4235577 | AU16: =ROUND(SUM(AG16:AT16),0) -> 12317313 | AY16: 3000000 | AZ16: =ROUND(SUM(AU16:AX16)-AY16,0) -> 9317313 | BD16: =SUM(BA16:BC16) -> 0 | BE16: 0 | BG16: =IF(BU16="Xem lại",0,IF(CL16<11000000,5000,IF(AND(CL16>=11000000,CL16<25000000),10000,IF(AND(CL16>=25000000,CL16<40000000),15000,IF(AND(CL16>=40000000,CL16<120000000),20000,IF(AND(CL16>=120000000,CL16<240000000),25000,30000)))))*$BG$9) -> 115000 | BI16: =IF(CE16>0,ROUND(IF(CE16>=80000000,CE16*35%-9850000,IF(CE16>=52000000,CE16*30%-5850000,IF(CE16>=32000000,CE16*25%-3250000,IF(CE16>=18000000,CE16*20%-1650000,IF(CE16>=10000000,CE16*15%-750000,IF(CE16>5000000,CE16*10%-250000,CE16*5%)))))),0),0) -> 16857 | BL16: =ROUND(SUM(BD16:BK16),0) -> 131857 | BM16: =ROUND(IF(AZ16>BL16,AZ16-BL16,0),0) -> 9185456 | BN16: =ROUND(IF(BL16>AZ16,BL16-AZ16,0),0) -> 0 | BO16: 1 | BP16: Không | BQ16: =IF(AND(D16="QTNV CL",CT16>=11000000),"Lương tháng",IF(CT16>=18000000,"Lương tháng",0)) -> 0 | BR16: =IF(BQ16="Lương tháng",0,1) -> 1 | BS16: M1 | BT16: =IF(BS16="M1",13000,IF(BS16="M2",20000,IF(BS16="M3",26000,IF(BS16="M4",32000,0)))) -> 13000 | BU16: =IF(AND(G16>0,(P16+Q16)>5),"Trừ tiền","Xem lại") -> Trừ tiền | BV16: 0 | BZ16: =AU16+SUM(BV16:BY16)-AL16-AP16-AQ16-SUM(CF16:CH16) -> 11811731 | CA16: 0 | CB16: =CA16*4400000 -> 0 | CC16: 11000000 | CD16: =CB16+CC16 -> 11000000 | CE16: =BZ16-SUM(CJ16:CK16)-CI16-BD16-CD16 -> 337131 | CK16: 474600 | CL16: 8500000 | CM16: =CL16*5% -> 425000 | CN16: 0 | CO16: 0 | CQ16: =SUM(CM16:CP16) -> 425000 | CR16: =CL16+CQ16 -> 8925000 | CT16: =CL16 -> 8500000 | CU16: =CM16 -> 425000 | CV16: =CN16 -> 0 | CW16: =CO16 -> 0 | CX16: =CP16 -> 0 | CY16: =SUM(CU16:CX16) -> 425000 | CZ16: =CT16+CY16 -> 8925000 | DJ16: Công nhân kho bãi xe
A17: =SUBTOTAL(3,$C$11:C17) -> 3 | C17: Nguyễn Văn C | D17: THILOGI | E17: =IF(CL17>=400000000,"A1",IF(CL17>=300000000,"A2",IF(CL17>=240000000,"A3",IF(CL17>=180000000,"A4",IF(CL17>=120000000,"A5",IF(CL17>=80000000,"A6",IF(CL17>=40000000,"A7",IF(CL17>=25000000,"B1",IF(CL17>=12000000,"B2","B3"))))))))) -> B3 | F17: 42110 | G17: 4300000 | I17: =IF(G17>0,CT17-G17,CT17-H17) -> 3700000 | J17: =CY17 -> 800000 | K17: =SUM(I17:J17) -> 4500000 | L17: =IF(G17>0,G17+K17,H17+K17) -> 8800000 | M17: 1 | N17: =ROUND(MAX(G17*70%,H17*70%,3640000),0) -> 3640000 | O17: 0 | P17: 25 | Q17: 0 | R17: 0 | S17: 0 | X17: 0 | AA17: 0 | AB17: 0 | AC17: 0 | AD17: 0 | AE17: 0 | AG17: =MAX(ROUND(IF(P17=0,0,IF(AND(BQ17="Lương tháng",(AB17+AC17)=0),MAX(G17/26*P17*M17,H17/26*P17*M17),IF(BQ17="Lương tháng",MAX((G17-G17/26*($CJ$6-P17))*M17,(H17-H17/26*($CJ$6-P17))*M17),MAX(G17/26*P17*M17,H17/26*P17*M17)))),0),0) -> 4134615 | AH17: =ROUND(MAX((G17+I17)*M17/26*R17,(H17+I17)*M17/26*R17,G17/26*R17*150%,H17/26*R17*150%)*BR17,0) -> 0 | AI17: =ROUND(MAX((G17+I17)*M17/26*S17,(H17+I17)*M17/26*S17,G17/26*S17*200%,H17/26*S17*200%)*BR17,0) -> 0 | AJ17: =ROUND(IF(BQ17="Lương tháng",L17/26*T17,MAX((G17+I17)/26*(T17+U17)*200%+G17/26*T17,(H17+I17)/26*(T17+U17)*200%+H17/26*T17,G17/26*(T17+U17)*300%+G17/26*T17,H17/26*(T17+U17)*300%+H17/26*T17)),0) -> 0 | AK17: =ROUND(IF((P17+Q17)=0,0,IF(BQ17="Lương tháng",MAX((G17+I17)/26*V17,(H17+I17)/26*V17),MAX(G17/26*V17,H17/26*V17))),0) -> 0 | AL17: =ROUND(IF(G17>0,G17/26*W17,H17/26*W17),0) -> 0 | AM17: =ROUND((G17+50%*I17)/26*X17,0) -> 0 | AN17: =ROUND(N17/26*Y17+O17/26*Z17+MAX(G17/26*AA17,H17/26*AA17),0) -> 0 | AO17: =ROUND(IF(BQ17="Lương tháng",L17/26*AC17,L17/26*AC17+L17/26*AB17),0) -> 0 | AP17: =ROUND(IF(BQ17="lương tháng",0,MAX((G17+I17)/26*AD17*30%,(H17+I17)/26*AD17*30%)*BR17),0) -> 0 | AQ17: =ROUND(BT17*AE17,0) -> 0 | AR17: =ROUND((G17+I17)/26*AF17,0) -> 0 | AS17: =MAX(ROUND(IF(P17=0,0,IF(AND(BQ17="Lương tháng",(AB17+AC17)=0),K17/26*P17*M17,IF(BQ17="Lương tháng",(K17-K17/26*($CJ$6-P17))*M17,(K17/26*P17*M17)))),0),0)+ROUND(J17/26*Q17,0) -> 4326923 | AU17: =ROUND(SUM(AG17:AT17),0) -> 8461538 | AV17: 0 | AY17: 3000000 | AZ17: =ROUND(SUM(AU17:AX17)-AY17,0) -> 5461538 | BD17: =SUM(BA17:BC17) -> 0 | BE17: 0 | BG17: =IF(BU17="Xem lại",0,IF(CL17<11000000,5000,IF(AND(CL17>=11000000,CL17<25000000),10000,IF(AND(CL17>=25000000,CL17<40000000),15000,IF(AND(CL17>=40000000,CL17<120000000),20000,IF(AND(CL17>=120000000,CL17<240000000),25000,30000)))))*$BG$9) -> 115000 | BI17: =IF(CE17>0,ROUND(IF(CE17>=80000000,CE17*35%-9850000,IF(CE17>=52000000,CE17*30%-5850000,IF(CE17>=32000000,CE17*25%-3250000,IF(CE17>=18000000,CE17*20%-1650000,IF(CE17>=10000000,CE17*15%-750000,IF(CE17>5000000,CE17*10%-250000,CE17*5%)))))),0),0) -> 0 | BL17: =ROUND(SUM(BD17:BK17),0) -> 115000 | BM17: =ROUND(IF(AZ17>BL17,AZ17-BL17,0),0) -> 5346538 | BN17: =ROUND(IF(BL17>AZ17,BL17-AZ17,0),0) -> 0 | BO17: 1 | BP17: 1x | BQ17: =IF(AND(D17="QTNV CL",CT17>=11000000),"Lương tháng",IF(CT17>=18000000,"Lương tháng",0)) -> 0 | BR17: =IF(BQ17="Lương tháng",0,1) -> 1 | BS17: 0 | BT17: =IF(BS17="M1",13000,IF(BS17="M2",20000,IF(BS17="M3",26000,IF(BS17="M4",32000,0)))) -> 0 | BU17: =IF(AND(G17>0,(P17+Q17)>5),"Trừ tiền","Xem lại") -> Trừ tiền | BV17: 0 | BZ17: =AU17+SUM(BV17:BY17)-AL17-AP17-AQ17-SUM(CF17:CH17) -> 8461538 | CA17: 1 | CB17: =CA17*4400000 -> 4400000 | CC17: 11000000 | CD17: =CB17+CC17 -> 15400000 | CE17: =BZ17-SUM(CJ17:CK17)-CI17-BD17-CD17 -> -7389962 | CK17: 451500 | CL17: 8000000 | CM17: =CL17*10% -> 800000 | CN17: 0 | CO17: 0 | CQ17: =SUM(CM17:CP17) -> 800000 | CR17: =CL17+CQ17 -> 8800000 | CT17: =CL17 -> 8000000 | CU17: =CM17 -> 800000 | CV17: =CN17 -> 0 | CW17: =CO17 -> 0 | CX17: =CP17 -> 0 | CY17: =SUM(CU17:CX17) -> 800000 | CZ17: =CT17+CY17 -> 8800000 | DJ17: Công nhân lái xe chuyên dụng (lương khoán, ko tính lương chủ nhật, tăng ca, đi làm thứ 7, chỉ được bù)
A18: =SUBTOTAL(3,$C$11:C18) -> 4 | C18: Nguyễn Văn D | D18: THILOGI | E18: =IF(CL18>=400000000,"A1",IF(CL18>=300000000,"A2",IF(CL18>=240000000,"A3",IF(CL18>=180000000,"A4",IF(CL18>=120000000,"A5",IF(CL18>=80000000,"A6",IF(CL18>=40000000,"A7",IF(CL18>=25000000,"B1",IF(CL18>=12000000,"B2","B3"))))))))) -> B3 | F18: 42110 | G18: 4520000 | I18: =IF(G18>0,CT18-G18,CT18-H18) -> 3980000 | J18: =CY18 -> 1700000 | K18: =SUM(I18:J18) -> 5680000 | L18: =IF(G18>0,G18+K18,H18+K18) -> 10200000 | M18: 1 | N18: =ROUND(MAX(G18*70%,H18*70%,3640000),0) -> 3640000 | O18: 0 | P18: 1 | Q18: 25 | R18: 0 | S18: 0 | X18: 0 | AA18: 0 | AB18: 0 | AC18: 1 | AD18: 0 | AE18: 0 | AG18: =MAX(ROUND(IF(P18=0,0,IF(AND(BQ18="Lương tháng",(AB18+AC18)=0),MAX(G18/26*P18*M18,H18/26*P18*M18),IF(BQ18="Lương tháng",MAX((G18-G18/26*($CJ$6-P18))*M18,(H18-H18/26*($CJ$6-P18))*M18),MAX(G18/26*P18*M18,H18/26*P18*M18)))),0),0) -> 173846 | AH18: =ROUND(MAX((G18+I18)*M18/26*R18,(H18+I18)*M18/26*R18,G18/26*R18*150%,H18/26*R18*150%)*BR18,0) -> 0 | AI18: =ROUND(MAX((G18+I18)*M18/26*S18,(H18+I18)*M18/26*S18,G18/26*S18*200%,H18/26*S18*200%)*BR18,0) -> 0 | AJ18: =ROUND(IF(BQ18="Lương tháng",L18/26*T18,MAX((G18+I18)/26*(T18+U18)*200%+G18/26*T18,(H18+I18)/26*(T18+U18)*200%+H18/26*T18,G18/26*(T18+U18)*300%+G18/26*T18,H18/26*(T18+U18)*300%+H18/26*T18)),0) -> 0 | AK18: =ROUND(IF((P18+Q18)=0,0,IF(BQ18="Lương tháng",MAX((G18+I18)/26*V18,(H18+I18)/26*V18),MAX(G18/26*V18,H18/26*V18))),0) -> 0 | AL18: =ROUND(IF(G18>0,G18/26*W18,H18/26*W18),0) -> 0 | AM18: =ROUND((G18+50%*I18)/26*X18,0) -> 0 | AN18: =ROUND(N18/26*Y18+O18/26*Z18+MAX(G18/26*AA18,H18/26*AA18),0) -> 0 | AO18: =ROUND(IF(BQ18="Lương tháng",L18/26*AC18,L18/26*AC18+L18/26*AB18),0) -> 392308 | AP18: =ROUND(IF(BQ18="lương tháng",0,MAX((G18+I18)/26*AD18*30%,(H18+I18)/26*AD18*30%)*BR18),0) -> 0 | AQ18: =ROUND(BT18*AE18,0) -> 0 | AR18: =ROUND((G18+I18)/26*AF18,0) -> 0 | AS18: =MAX(ROUND(IF(P18=0,0,IF(AND(BQ18="Lương tháng",(AB18+AC18)=0),K18/26*P18*M18,IF(BQ18="Lương tháng",(K18-K18/26*($CJ$6-P18))*M18,(K18/26*P18*M18)))),0),0)+ROUND(J18/26*Q18,0) -> 1853077 | AU18: =ROUND(SUM(AG18:AT18),0) -> 2419231 | AV18: 1206000 | AY18: 1000000 | AZ18: =ROUND(SUM(AU18:AX18)-AY18,0) -> 2625231 | BD18: =SUM(BA18:BC18) -> 0 | BE18: 0 | BG18: =IF(BU18="Xem lại",0,IF(CL18<11000000,5000,IF(AND(CL18>=11000000,CL18<25000000),10000,IF(AND(CL18>=25000000,CL18<40000000),15000,IF(AND(CL18>=40000000,CL18<120000000),20000,IF(AND(CL18>=120000000,CL18<240000000),25000,30000)))))*$BG$9) -> 115000 | BI18: =IF(CE18>0,ROUND(IF(CE18>=80000000,CE18*35%-9850000,IF(CE18>=52000000,CE18*30%-5850000,IF(CE18>=32000000,CE18*25%-3250000,IF(CE18>=18000000,CE18*20%-1650000,IF(CE18>=10000000,CE18*15%-750000,IF(CE18>5000000,CE18*10%-250000,CE18*5%)))))),0),0) -> 0 | BL18: =ROUND(SUM(BD18:BK18),0) -> 115000 | BM18: =ROUND(IF(AZ18>BL18,AZ18-BL18,0),0) -> 2510231 | BN18: =ROUND(IF(BL18>AZ18,BL18-AZ18,0),0) -> 0 | BO18: 1 | BP18: 1x | BQ18: =IF(AND(D18="QTNV CL",CT18>=11000000),"Lương tháng",IF(CT18>=18000000,"Lương tháng",0)) -> 0 | BR18: =IF(BQ18="Lương tháng",0,1) -> 1 | BS18: 0 | BT18: =IF(BS18="M1",13000,IF(BS18="M2",20000,IF(BS18="M3",26000,IF(BS18="M4",32000,0)))) -> 0 | BU18: =IF(AND(G18>0,(P18+Q18)>5),"Trừ tiền","Xem lại") -> Trừ tiền | BV18: 0 | BZ18: =AU18+SUM(BV18:BY18)-AL18-AP18-AQ18-SUM(CF18:CH18) -> 2419231 | CA18: 2 | CB18: =CA18*4400000 -> 8800000 | CC18: 11000000 | CD18: =CB18+CC18 -> 19800000 | CE18: =BZ18-SUM(CJ18:CK18)-CI18-BD18-CD18 -> -17855369 | CK18: 474600 | CL18: 8500000 | CM18: =CL18*10% -> 850000 | CN18: =CL18*10% -> 850000 | CO18: 0 | CQ18: =SUM(CM18:CP18) -> 1700000 | CR18: =CL18+CQ18 -> 10200000 | CT18: =CL18 -> 8500000 | CU18: =CM18 -> 850000 | CV18: 850000 | CW18: =CO18 -> 0 | CX18: =CP18 -> 0 | CY18: =SUM(CU18:CX18) -> 1700000 | CZ18: =CT18+CY18 -> 10200000 | DJ18: Công nhân lái xe chuyên dụng (lương khoán, ko tính lương chủ nhật, tăng ca, đi làm thứ 7, chỉ được bù, ngày nào giao xe thì để công giao xe, còn làm tại cty thì chấm X bên công chính
A19: =SUBTOTAL(3,$C$11:C19) -> 5 | C19: Nguyễn Văn E | D19: THILOGI | E19: =IF(CL19>=400000000,"A1",IF(CL19>=300000000,"A2",IF(CL19>=240000000,"A3",IF(CL19>=180000000,"A4",IF(CL19>=120000000,"A5",IF(CL19>=80000000,"A6",IF(CL19>=40000000,"A7",IF(CL19>=25000000,"B1",IF(CL19>=12000000,"B2","B3"))))))))) -> B3 | F19: 42110 | G19: 4750000 | I19: =IF(G19>0,CT19-G19,CT19-H19) -> 5250000 | J19: =CY19 -> 1000000 | K19: =SUM(I19:J19) -> 6250000 | L19: =IF(G19>0,G19+K19,H19+K19) -> 11000000 | M19: 1 | N19: =ROUND(MAX(G19*70%,H19*70%,3640000),0) -> 3640000 | O19: 0 | P19: 25 | Q19: 0 | R19: 0 | S19: 0 | X19: 0 | AA19: 0 | AB19: 0 | AC19: 0 | AD19: 0 | AE19: 0 | AG19: =MAX(ROUND(IF(P19=0,0,IF(AND(BQ19="Lương tháng",(AB19+AC19)=0),MAX(G19/26*P19*M19,H19/26*P19*M19),IF(BQ19="Lương tháng",MAX((G19-G19/26*($CJ$6-P19))*M19,(H19-H19/26*($CJ$6-P19))*M19),MAX(G19/26*P19*M19,H19/26*P19*M19)))),0),0) -> 4567308 | AH19: =ROUND(MAX((G19+I19)*M19/26*R19,(H19+I19)*M19/26*R19,G19/26*R19*150%,H19/26*R19*150%)*BR19,0) -> 0 | AI19: =ROUND(MAX((G19+I19)*M19/26*S19,(H19+I19)*M19/26*S19,G19/26*S19*200%,H19/26*S19*200%)*BR19,0) -> 0 | AJ19: =ROUND(IF(BQ19="Lương tháng",L19/26*T19,MAX((G19+I19)/26*(T19+U19)*200%+G19/26*T19,(H19+I19)/26*(T19+U19)*200%+H19/26*T19,G19/26*(T19+U19)*300%+G19/26*T19,H19/26*(T19+U19)*300%+H19/26*T19)),0) -> 0 | AK19: =ROUND(IF((P19+Q19)=0,0,IF(BQ19="Lương tháng",MAX((G19+I19)/26*V19,(H19+I19)/26*V19),MAX(G19/26*V19,H19/26*V19))),0) -> 0 | AL19: =ROUND(IF(G19>0,G19/26*W19,H19/26*W19),0) -> 0 | AM19: =ROUND((G19+50%*I19)/26*X19,0) -> 0 | AN19: =ROUND(N19/26*Y19+O19/26*Z19+MAX(G19/26*AA19,H19/26*AA19),0) -> 0 | AO19: =ROUND(IF(BQ19="Lương tháng",L19/26*AC19,L19/26*AC19+L19/26*AB19),0) -> 0 | AP19: =ROUND(IF(BQ19="lương tháng",0,MAX((G19+I19)/26*AD19*30%,(H19+I19)/26*AD19*30%)*BR19),0) -> 0 | AQ19: =ROUND(BT19*AE19,0) -> 0 | AR19: =ROUND((G19+I19)/26*AF19,0) -> 0 | AS19: =MAX(ROUND(IF(P19=0,0,IF(AND(BQ19="Lương tháng",(AB19+AC19)=0),K19/26*P19*M19,IF(BQ19="Lương tháng",(K19-K19/26*($CJ$6-P19))*M19,(K19/26*P19*M19)))),0),0)+ROUND(J19/26*Q19,0) -> 6009615 | AU19: =ROUND(SUM(AG19:AT19),0) -> 10576923 | AV19: 0 | AY19: 3000000 | AZ19: =ROUND(SUM(AU19:AX19)-AY19,0) -> 7576923 | BD19: =SUM(BA19:BC19) -> 0 | BE19: 0 | BG19: =IF(BU19="Xem lại",0,IF(CL19<11000000,5000,IF(AND(CL19>=11000000,CL19<25000000),10000,IF(AND(CL19>=25000000,CL19<40000000),15000,IF(AND(CL19>=40000000,CL19<120000000),20000,IF(AND(CL19>=120000000,CL19<240000000),25000,30000)))))*$BG$9) -> 115000 | BI19: =IF(CE19>0,ROUND(IF(CE19>=80000000,CE19*35%-9850000,IF(CE19>=52000000,CE19*30%-5850000,IF(CE19>=32000000,CE19*25%-3250000,IF(CE19>=18000000,CE19*20%-1650000,IF(CE19>=10000000,CE19*15%-750000,IF(CE19>5000000,CE19*10%-250000,CE19*5%)))))),0),0) -> 0 | BL19: =ROUND(SUM(BD19:BK19),0) -> 115000 | BM19: =ROUND(IF(AZ19>BL19,AZ19-BL19,0),0) -> 7461923 | BN19: =ROUND(IF(BL19>AZ19,BL19-AZ19,0),0) -> 0 | BO19: 1 | BP19: 1x | BQ19: =IF(AND(D19="QTNV CL",CT19>=11000000),"Lương tháng",IF(CT19>=18000000,"Lương tháng",0)) -> 0 | BR19: =IF(BQ19="Lương tháng",0,1) -> 1 | BS19: 0 | BT19: =IF(BS19="M1",13000,IF(BS19="M2",20000,IF(BS19="M3",26000,IF(BS19="M4",32000,0)))) -> 0 | BU19: =IF(AND(G19>0,(P19+Q19)>5),"Trừ tiền","Xem lại") -> Trừ tiền | BV19: 0 | BZ19: =AU19+SUM(BV19:BY19)-AL19-AP19-AQ19-SUM(CF19:CH19) -> 10576923 | CA19: 2 | CB19: =CA19*4400000 -> 8800000 | CC19: 11000000 | CD19: =CB19+CC19 -> 19800000 | CE19: =BZ19-SUM(CJ19:CK19)-CI19-BD19-CD19 -> -9721827 | CK19: 498750 | CL19: 10000000 | CM19: =CL19*10% -> 1000000 | CN19: 0 | CO19: 0 | CQ19: =SUM(CM19:CP19) -> 1000000 | CR19: =CL19+CQ19 -> 11000000 | CT19: =CL19 -> 10000000 | CU19: =CM19 -> 1000000 | CV19: =CN19 -> 0 | CW19: =CO19 -> 0 | CX19: =CP19 -> 0 | CY19: =SUM(CU19:CX19) -> 1000000 | CZ19: =CT19+CY19 -> 11000000 | DJ19: Công nhân lái xe chuyên dụng (lương khoán, ko tính lương chủ nhật, tăng ca, đi làm thứ 7, chỉ được bù)
A20: =SUBTOTAL(3,$C$11:C20) -> 6 | C20: Nguyễn Văn F | D20: THILOGI | E20: =IF(CL20>=400000000,"A1",IF(CL20>=300000000,"A2",IF(CL20>=240000000,"A3",IF(CL20>=180000000,"A4",IF(CL20>=120000000,"A5",IF(CL20>=80000000,"A6",IF(CL20>=40000000,"A7",IF(CL20>=25000000,"B1",IF(CL20>=12000000,"B2","B3"))))))))) -> B2 | F20: 45721 | G20: 4750000 | I20: =IF(G20>0,CT20-G20,CT20-H20) -> 13250000 | J20: =CY20 -> 0 | K20: =SUM(I20:J20) -> 13250000 | L20: =IF(G20>0,G20+K20,H20+K20) -> 18000000 | M20: 1 | N20: =ROUND(MAX(G20*70%,H20*70%,3640000),0) -> 3640000 | O20: 0 | P20: 25 | R20: 4.16 | AG20: =MAX(ROUND(IF(P20=0,0,IF(AND(BQ20="Lương tháng",(AB20+AC20)=0),MAX(G20/26*P20*M20,H20/26*P20*M20),IF(BQ20="Lương tháng",MAX((G20-G20/26*($CJ$6-P20))*M20,(H20-H20/26*($CJ$6-P20))*M20),MAX(G20/26*P20*M20,H20/26*P20*M20)))),0),0) -> 4567308 | AH20: =ROUND(MAX((G20+I20)*M20/26*R20,(H20+I20)*M20/26*R20,G20/26*R20*150%,H20/26*R20*150%)*BR20,0) -> 2880000 | AI20: =ROUND(MAX((G20+I20)*M20/26*S20,(H20+I20)*M20/26*S20,G20/26*S20*200%,H20/26*S20*200%)*BR20,0) -> 0 | AJ20: =ROUND(IF(BQ20="Lương tháng",L20/26*T20,MAX((G20+I20)/26*(T20+U20)*200%+G20/26*T20,(H20+I20)/26*(T20+U20)*200%+H20/26*T20,G20/26*(T20+U20)*300%+G20/26*T20,H20/26*(T20+U20)*300%+H20/26*T20)),0) -> 0 | AK20: =ROUND(IF((P20+Q20)=0,0,IF(BQ20="Lương tháng",MAX((G20+I20)/26*V20,(H20+I20)/26*V20),MAX(G20/26*V20,H20/26*V20))),0) -> 0 | AL20: =ROUND(IF(G20>0,G20/26*W20,H20/26*W20),0) -> 0 | AM20: =ROUND((G20+50%*I20)/26*X20,0) -> 0 | AN20: =ROUND(N20/26*Y20+O20/26*Z20+MAX(G20/26*AA20,H20/26*AA20),0) -> 0 | AO20: =ROUND(IF(BQ20="Lương tháng",L20/26*AC20,L20/26*AC20+L20/26*AB20),0) -> 0 | AP20: =ROUND(IF(BQ20="lương tháng",0,MAX((G20+I20)/26*AD20*30%,(H20+I20)/26*AD20*30%)*BR20),0) -> 0 | AQ20: =ROUND(BT20*AE20,0) -> 0 | AR20: =ROUND((G20+I20)/26*AF20,0) -> 0 | AS20: =MAX(ROUND(IF(P20=0,0,IF(AND(BQ20="Lương tháng",(AB20+AC20)=0),K20/26*P20*M20,IF(BQ20="Lương tháng",(K20-K20/26*($CJ$6-P20))*M20,(K20/26*P20*M20)))),0),0)+ROUND(J20/26*Q20,0) -> 12740385 | AU20: =ROUND(SUM(AG20:AT20),0) -> 20187693 | AY20: 9819677 | AZ20: =ROUND(SUM(AU20:AX20)-AY20,0) -> 10368016 | BD20: =SUM(BA20:BC20) -> 0 | BE20: 0 | BG20: =IF(BU20="Xem lại",0,IF(CL20<11000000,5000,IF(AND(CL20>=11000000,CL20<25000000),10000,IF(AND(CL20>=25000000,CL20<40000000),15000,IF(AND(CL20>=40000000,CL20<120000000),20000,IF(AND(CL20>=120000000,CL20<240000000),25000,30000)))))*$BG$9) -> 230000 | BI20: =IF(CE20>0,ROUND(IF(CE20>=80000000,CE20*35%-9850000,IF(CE20>=52000000,CE20*30%-5850000,IF(CE20>=32000000,CE20*25%-3250000,IF(CE20>=18000000,CE20*20%-1650000,IF(CE20>=10000000,CE20*15%-750000,IF(CE20>5000000,CE20*10%-250000,CE20*5%)))))),0),0) -> 0 | BL20: =ROUND(SUM(BD20:BK20),0) -> 230000 | BM20: =ROUND(IF(AZ20>BL20,AZ20-BL20,0),0) -> 10138016 | BN20: =ROUND(IF(BL20>AZ20,BL20-AZ20,0),0) -> 0 | BO20: 1 | BQ20: =IF(AND(D20="QTNV CL",CT20>=11000000),"Lương tháng",IF(CT20>=18000000,"Lương tháng",0)) -> Lương tháng | BR20: 1 | BS20: 0 | BT20: =IF(BS20="M1",13000,IF(BS20="M2",20000,IF(BS20="M3",26000,IF(BS20="M4",32000,0)))) -> 0 | BU20: =IF(AND(G20>0,(P20+Q20)>5),"Trừ tiền","Xem lại") -> Trừ tiền | BZ20: =AU20+SUM(BV20:BY20)-AL20-AP20-AQ20-SUM(CF20:CH20) -> 20187693 | CA20: 2 | CB20: =CA20*4400000 -> 8800000 | CC20: 11000000 | CD20: =CB20+CC20 -> 19800000 | CE20: =BZ20-SUM(CJ20:CK20)-CI20-BD20-CD20 -> -111057 | CK20: 498750 | CL20: 18000000 | CN20: 0 | CO20: 0 | CQ20: =SUM(CM20:CP20) -> 0 | CR20: =CL20+CQ20 -> 18000000 | CT20: =CL20 -> 18000000 | CU20: =CM20 -> 0 | CV20: =CN20 -> 0 | CW20: =CO20 -> 0 | CX20: =CP20 -> 0 | CY20: =SUM(CU20:CX20) -> 0 | CZ20: =CT20+CY20 -> 18000000 | DJ20: Công nhân vận hành thiết bị năng (lương tháng nhưng được tính lương làm thêm giờ)
A21: =SUBTOTAL(3,$C$11:C21) -> 7 | C21: Nguyễn Văn K | D21: THILOGI | E21: =IF(CL21>=400000000,"A1",IF(CL21>=300000000,"A2",IF(CL21>=240000000,"A3",IF(CL21>=180000000,"A4",IF(CL21>=120000000,"A5",IF(CL21>=80000000,"A6",IF(CL21>=40000000,"A7",IF(CL21>=25000000,"B1",IF(CL21>=12000000,"B2","B3"))))))))) -> B2 | F21: 45721 | G21: 4750000 | I21: =IF(G21>0,CT21-G21,CT21-H21) -> 9250000 | J21: =CY21 -> 0 | K21: =SUM(I21:J21) -> 9250000 | L21: =IF(G21>0,G21+K21,H21+K21) -> 14000000 | M21: 1 | N21: =ROUND(MAX(G21*70%,H21*70%,3640000),0) -> 3640000 | O21: 0 | P21: 25 | S21: 0 | AD21: 0 | AE21: 0 | AG21: =MAX(ROUND(IF(P21=0,0,IF(AND(BQ21="Lương tháng",(AB21+AC21)=0),MAX(G21/26*P21*M21,H21/26*P21*M21),IF(BQ21="Lương tháng",MAX((G21-G21/26*($CJ$6-P21))*M21,(H21-H21/26*($CJ$6-P21))*M21),MAX(G21/26*P21*M21,H21/26*P21*M21)))),0),0) -> 4567308 | AH21: =ROUND(MAX((G21+I21)*M21/26*R21,(H21+I21)*M21/26*R21,G21/26*R21*150%,H21/26*R21*150%)*BR21,0) -> 0 | AI21: =ROUND(MAX((G21+I21)*M21/26*S21,(H21+I21)*M21/26*S21,G21/26*S21*200%,H21/26*S21*200%)*BR21,0) -> 0 | AJ21: =ROUND(IF(BQ21="Lương tháng",L21/26*T21,MAX((G21+I21)/26*(T21+U21)*200%+G21/26*T21,(H21+I21)/26*(T21+U21)*200%+H21/26*T21,G21/26*(T21+U21)*300%+G21/26*T21,H21/26*(T21+U21)*300%+H21/26*T21)),0) -> 0 | AK21: =ROUND(IF((P21+Q21)=0,0,IF(BQ21="Lương tháng",MAX((G21+I21)/26*V21,(H21+I21)/26*V21),MAX(G21/26*V21,H21/26*V21))),0) -> 0 | AL21: =ROUND(IF(G21>0,G21/26*W21,H21/26*W21),0) -> 0 | AM21: =ROUND((G21+50%*I21)/26*X21,0) -> 0 | AN21: =ROUND(N21/26*Y21+O21/26*Z21+MAX(G21/26*AA21,H21/26*AA21),0) -> 0 | AO21: =ROUND(IF(BQ21="Lương tháng",L21/26*AC21,L21/26*AC21+L21/26*AB21),0) -> 0 | AP21: =ROUND(IF(BQ21="lương tháng",0,MAX((G21+I21)/26*AD21*30%,(H21+I21)/26*AD21*30%)*BR21),0) -> 0 | AQ21: =ROUND(BT21*AE21,0) -> 0 | AR21: =ROUND((G21+I21)/26*AF21,0) -> 0 | AS21: =MAX(ROUND(IF(P21=0,0,IF(AND(BQ21="Lương tháng",(AB21+AC21)=0),K21/26*P21*M21,IF(BQ21="Lương tháng",(K21-K21/26*($CJ$6-P21))*M21,(K21/26*P21*M21)))),0),0)+ROUND(J21/26*Q21,0) -> 8894231 | AU21: =ROUND(SUM(AG21:AT21),0) -> 13461539 | AY21: 5720000 | AZ21: =ROUND(SUM(AU21:AX21)-AY21,0) -> 7741539 | BD21: =SUM(BA21:BC21) -> 0 | BE21: 0 | BG21: =IF(BU21="Xem lại",0,IF(CL21<11000000,5000,IF(AND(CL21>=11000000,CL21<25000000),10000,IF(AND(CL21>=25000000,CL21<40000000),15000,IF(AND(CL21>=40000000,CL21<120000000),20000,IF(AND(CL21>=120000000,CL21<240000000),25000,30000)))))*$BG$9) -> 230000 | BI21: =IF(CE21>0,ROUND(IF(CE21>=80000000,CE21*35%-9850000,IF(CE21>=52000000,CE21*30%-5850000,IF(CE21>=32000000,CE21*25%-3250000,IF(CE21>=18000000,CE21*20%-1650000,IF(CE21>=10000000,CE21*15%-750000,IF(CE21>5000000,CE21*10%-250000,CE21*5%)))))),0),0) -> 98139 | BL21: =ROUND(SUM(BD21:BK21),0) -> 328139 | BM21: =ROUND(IF(AZ21>BL21,AZ21-BL21,0),0) -> 7413400 | BN21: =ROUND(IF(BL21>AZ21,BL21-AZ21,0),0) -> 0 | BO21: 1 | BQ21: =IF(AND(D21="QTNV CL",CT21>=11000000),"Lương tháng",IF(CT21>=18000000,"Lương tháng",0)) -> 0 | BR21: =IF(BQ21="Lương tháng",0,1) -> 1 | BS21: 0 | BT21: =IF(BS21="M1",13000,IF(BS21="M2",20000,IF(BS21="M3",26000,IF(BS21="M4",32000,0)))) -> 0 | BU21: =IF(AND(G21>0,(P21+Q21)>5),"Trừ tiền","Xem lại") -> Trừ tiền | BZ21: =AU21+SUM(BV21:BY21)-AL21-AP21-AQ21-SUM(CF21:CH21) -> 13461539 | CB21: =CA21*4400000 -> 0 | CC21: 11000000 | CD21: =CB21+CC21 -> 11000000 | CE21: =BZ21-SUM(CJ21:CK21)-CI21-BD21-CD21 -> 1962789 | CK21: 498750 | CL21: 14000000 | CN21: 0 | CO21: 0 | CQ21: =SUM(CM21:CP21) -> 0 | CR21: =CL21+CQ21 -> 14000000 | CT21: =CL21 -> 14000000 | CU21: =CM21 -> 0 | CV21: =CN21 -> 0 | CW21: =CO21 -> 0 | CX21: =CP21 -> 0 | CY21: =SUM(CU21:CX21) -> 0 | CZ21: =CT21+CY21 -> 14000000 | DJ21: Thuyèn viên tàu lai (tính khoán theo công chuẩn hằng tháng)
A22: III | B22: ="Suất ăn công nghiệp: " &"["&COUNT(A23:A23)& "]" -> Suất ăn công nghiệp: [1] | G22: =SUM(G23:G23) -> 4090000 | H22: =SUM(H23:H23) -> 0 | I22: =SUM(I23:I23) -> 2410000 | J22: =SUM(J23:J23) -> 0 | K22: =SUM(K23:K23) -> 2410000 | L22: =SUM(L23:L23) -> 6500000 | N22: =SUM(N23:N23) -> 3640000 | O22: =SUM(O23:O23) -> 0 | P22: =SUM(P23:P23) -> 25 | Q22: =SUM(Q23:Q23) -> 0 | R22: =SUM(R23:R23) -> 0 | S22: =SUM(S23:S23) -> 0 | T22: =SUM(T23:T23) -> 0 | U22: =SUM(U23:U23) -> 0 | ... DC22: =SUM(DC23:DC23) -> 0
A23: =SUBTOTAL(3,$C$11:C23) -> 7 | D23: THILOGI | E23: =IF(CL23>=400000000,"A1",IF(CL23>=300000000,"A2",IF(CL23>=240000000,"A3",IF(CL23>=180000000,"A4",IF(CL23>=120000000,"A5",IF(CL23>=80000000,"A6",IF(CL23>=40000000,"A7",IF(CL23>=25000000,"B1",IF(CL23>=12000000,"B2","B3"))))))))) -> B3 | F23: 44256 | G23: 4090000 | I23: =IF(G23>0,CT23-G23,CT23-H23) -> 2410000 | J23: =CY23 -> 0 | K23: =SUM(I23:J23) -> 2410000 | L23: =IF(G23>0,G23+K23,H23+K23) -> 6500000 | M23: 1 | N23: =ROUND(MAX(G23*70%,H23*70%,3640000),0) -> 3640000 | O23: 0 | P23: 25 | AG23: =MAX(ROUND(IF(P23=0,0,IF(AND(BQ23="Lương tháng",(AB23+AC23)=0),MAX(G23/26*P23*M23,H23/26*P23*M23),IF(BQ23="Lương tháng",MAX((G23-G23/26*($CJ$6-P23))*M23,(H23-H23/26*($CJ$6-P23))*M23),MAX(G23/26*P23*M23,H23/26*P23*M23)))),0),0) -> 3932692 | AH23: =ROUND(MAX((G23+I23)*M23/26*R23,(H23+I23)*M23/26*R23,G23/26*R23*150%,H23/26*R23*150%)*BR23,0) -> 0 | AI23: =ROUND(MAX((G23+I23)*M23/26*S23,(H23+I23)*M23/26*S23,G23/26*S23*200%,H23/26*S23*200%)*BR23,0) -> 0 | AJ23: =ROUND(IF(BQ23="Lương tháng",L23/26*T23,MAX((G23+I23)/26*(T23+U23)*200%+G23/26*T23,(H23+I23)/26*(T23+U23)*200%+H23/26*T23,G23/26*(T23+U23)*300%+G23/26*T23,H23/26*(T23+U23)*300%+H23/26*T23)),0) -> 0 | AK23: =ROUND(IF((P23+Q23)=0,0,IF(BQ23="Lương tháng",MAX((G23+I23)/26*V23,(H23+I23)/26*V23),MAX(G23/26*V23,H23/26*V23))),0) -> 0 | AL23: =ROUND(IF(G23>0,G23/26*W23,H23/26*W23),0) -> 0 | AM23: =ROUND((G23+50%*I23)/26*X23,0) -> 0 | AN23: =ROUND(N23/26*Y23+O23/26*Z23+MAX(G23/26*AA23,H23/26*AA23),0) -> 0 | AO23: =ROUND(IF(BQ23="Lương tháng",L23/26*AC23,L23/26*AC23+L23/26*AB23),0) -> 0 | AP23: =ROUND(IF(BQ23="lương tháng",0,MAX((G23+I23)/26*AD23*30%,(H23+I23)/26*AD23*30%)*BR23),0) -> 0 | AQ23: =ROUND(BT23*AE23,0) -> 0 | AR23: =ROUND((G23+I23)/26*AF23,0) -> 0 | AS23: =MAX(ROUND(IF(P23=0,0,IF(AND(BQ23="Lương tháng",(AB23+AC23)=0),K23/26*P23*M23,IF(BQ23="Lương tháng",(K23-K23/26*($CJ$6-P23))*M23,(K23/26*P23*M23)))),0),0)+ROUND(J23/26*Q23,0) -> 2317308 | AU23: =ROUND(SUM(AG23:AT23),0) -> 6250000 | AY23: 2000000 | AZ23: =ROUND(SUM(AU23:AX23)-AY23,0) -> 4250000 | BD23: =SUM(BA23:BC23) -> 0 | BE23: 0 | BG23: =IF(BU23="Xem lại",0,IF(CL23<11000000,5000,IF(AND(CL23>=11000000,CL23<25000000),10000,IF(AND(CL23>=25000000,CL23<40000000),15000,IF(AND(CL23>=40000000,CL23<120000000),20000,IF(AND(CL23>=120000000,CL23<240000000),25000,30000)))))*$BG$9) -> 0 | BI23: =IF(CE23>0,ROUND(IF(CE23>=80000000,CE23*35%-9850000,IF(CE23>=52000000,CE23*30%-5850000,IF(CE23>=32000000,CE23*25%-3250000,IF(CE23>=18000000,CE23*20%-1650000,IF(CE23>=10000000,CE23*15%-750000,IF(CE23>5000000,CE23*10%-250000,CE23*5%)))))),0),0) -> 0 | BL23: =ROUND(SUM(BD23:BK23),0) -> 0 | BM23: =ROUND(IF(AZ23>BL23,AZ23-BL23,0),0) -> 4250000 | BN23: =ROUND(IF(BL23>AZ23,BL23-AZ23,0),0) -> 0 | BO23: 1 | BP23: Không | BQ23: =IF(AND(D23="QTNV CL",CT23>=11000000),"Lương tháng",IF(CT23>=18000000,"Lương tháng",0)) -> 0 | BR23: =IF(BQ23="Lương tháng",0,1) -> 1 | BS23: 0 | BT23: =IF(BS23="M1",13000,IF(BS23="M2",20000,IF(BS23="M3",26000,IF(BS23="M4",32000,0)))) -> 0 | BU23: Xem lại | BV23: 0 | BZ23: =AU23+SUM(BV23:BY23)-AL23-AP23-AQ23-SUM(CF23:CH23) -> 6250000 | CA23: 0 | CB23: =CA23*4400000 -> 0 | CC23: 11000000 | CD23: =CB23+CC23 -> 11000000 | CE23: =BZ23-SUM(CJ23:CK23)-CI23-BD23-CD23 -> -5179450 | CK23: 429450 | CL23: 6500000 | CM23: 0 | CN23: 0 | CO23: 0 | CQ23: =SUM(CM23:CP23) -> 0 | CR23: =CL23+CQ23 -> 6500000 | CT23: =CL23 -> 6500000 | CU23: =CM23 -> 0 | CV23: =CN23 -> 0 | CW23: =CO23 -> 0 | CX23: =CP23 -> 0 | CY23: =SUM(CU23:CX23) -> 0 | CZ23: =CT23+CY23 -> 6500000 | DA23: Nhân viên SACN | DB23: Dự án Suất ăn công nghiệp | DC23: 0 | DD23: Chu Lai | DH23: TM | DJ23: Suất ăn công nghiệp bên THIDICO (mặc định không thu tang chế)
O24: 0 | P24: =#REF!-#REF! -> #REF! | Q24: =#REF!-#REF! -> #REF! | R24: =#REF!-#REF! -> #REF! | S24: =#REF!-#REF! -> #REF! | T24: =#REF!-#REF! -> #REF! | U24: =#REF!-#REF! -> #REF! | V24: =#REF!-#REF! -> #REF! | W24: =#REF!-#REF! -> #REF! | X24: =#REF!-#REF! -> #REF! | AA24: =#REF!-#REF! -> #REF! | AB24: =#REF!-#REF! -> #REF! | AC24: =#REF!-#REF! -> #REF! | AD24: =#REF!-#REF! -> #REF! | AY24: 2137505812 | AZ24: =#REF!-AY24 -> #REF! | BY24: 3631871000
BI25: Núi Thành, ngày 01 tháng 12 năm 2025
C26: Giám đốc | R26: Phòng Kế toán | AO26: Phòng Nhân sự | BI26: Người lập
AW28: =#REF!-AW24 -> #REF! | AX28: =#REF!-AX24 -> #REF! | AY28: =#REF!-AY24 -> #REF! | AZ28: =#REF!-AZ24 -> #REF! | BA28: =#REF!-BA24 -> #REF! | BB28: =#REF!-BB24 -> #REF! | BC28: =#REF!-BC24 -> #REF! | BD28: =#REF!-BD24 -> #REF! | BE28: =#REF!-BE24 -> #REF! | BG28: =#REF!-BG24 -> #REF! | BH28: =#REF!-BH24 -> #REF! | BI28: =#REF!-BI24 -> #REF! | BJ28: =#REF!-BJ24 -> #REF! | BL28: =#REF!-BL24 -> #REF! | BM28: =#REF!-BM24 -> #REF!

Sheet TAM UNG
A1: CÔNG TY TNHH LIÊN VẬN ĐÔNG DƯƠNG THILOGI
A2: Địa chỉ: Khu công nghiệp Cảng và Hậu cần Cảng Chu Lai Trường Hải, xã Núi Thành, Thành phố Đà Nẵng
A3: BẢNG THANH TOÁN TIỀN LƯƠNG TẠM ỨNG THÁNG 11 NĂM 2025 | CM3: THỐNG KÊ LƯƠNG KỲ 2
BA5: Nam Bộ | BB5: 24 | CC5: Công chuẩn
BA6: Bắc Bộ | BB6: 24 | BO6: THÔNG TIN VỀ TÍNH THUẾ TNCN | CC6: 13
A7: TT | B7: MSNV | C7: Họ và tên | D7: TĐ | E7: Ngạch lương | F7: Ngày vào | G7: Mức lương HĐLĐ | H7: Mức lương HĐTV | I7: Định mức thưởng HQCV | J7: Phụ cấp | K7: Tổng định mức thưởng HQCV | L7: Tổng thu nhập (Mức lương + Định mức thưởng HQCV) | M7: Tỷ lệ % tạm ứng lương | N7: Mức lương tính chế độ ngừng việc | P7: Ngày công trong tháng | AF7: Các khoản được hưởng trong tháng | AR7: Thu nhập giao xe 20% kỳ 1/11 | AS7: Hoàn thuế TNCN | AT7: Chi quà 1/6 | AU7: Truy lĩnh | AV7: Tổng thu nhập tạm ứng kỳ 1/11 | AW7: Các khoản giám trừ kỳ trong tháng | BE7: Tổng giảm trừ | BF7: Thực nhận | BG7: Thu vào kỳ sau | BO7: THUẾ THU NHẬP CÁ NHÂN | BY7: Khoản đc giảm trừ trong thuế | CB7: BHXH | CE7: KỲ I | CM7: KỲ II | CT7: Chức vụ | CU7: Bộ phận | CV7: Mail | CW7: Khu vực
P8: Công chính | Q8: Công giao xe | R8: Công tăng ca ngày thường | S8: Công Chủ nhật | T8: Công nghỉ lễ, tết | W8: Hiếu, hỉ | X8: Ngày PN thanh toán T1/2024 | Y8: Ngày ngừng việc/ cách ly trong tháng | AA8: Ngừng việc BKK | AB8: Công ngày thứ 7 | AD8: Công phụ cấp | AF8: Tạm ứng Lương Ngày thường | AG8: Lương Tăng ca thường | AH8: Lương chủ nhật | AI8: Lương ngày lễ, tết | AK8: Lương Hiếu, Hỉ | AL8: Lương tạm ngừng việc (BKK) | AM8: Lương chế độ T7 | AN8: Thu nhập phụ cấp | AP8: Thu nhập khác (phép năm thôi việc) | AQ8: Tổng tiền lương tạm ứng kỳ 1/11 | AW8: BHXH | AX8: BHYT | AY8: BHTN | AZ8: BHXH,BHYT, BHTN | BA8: Phí công đoàn | BB8: Tiền phúng điếu | BC8: Tạm thu thuế | BD8: Giảm trừ khác (Thu hộ tiền mua xe, thu nợ kỳ trước) | BH8: KIỂM TRA | BO8: Thu nhập ngoài bảng lương đưa vào tính thuế | BS8: THU NHẬP CHỊU THUẾ TNCN | BT8: SỐ NGƯỜI PHỤ THUỘC | BU8: GIẢM TRỪ GIA CẢNH | BV8: GIẢM TRỪ BẢN THÂN | BW8: TỔNG GIẢM TRỪ | BX8: TỔNG THU NHẬP TÍNH THUẾ TNCN
N9: Tạm ngừng việc 14 ngày đầu | O9: Tạm ngừng việc từ 15 ngày trở đi | T9: Chính | U9: Tăng ca | V9: Nghỉ lễ, tết | Y9: 14 ngày đầu | Z9: Từ ngày 15 trở đi | AB9: Đi làm T7 | AC9: Nghỉ T7 | AD9: Phụ cấp ban đêm | AE9: Phụ cấp bồi dưỡng làm việc | AI9: Làm việc ngày lễ, tết | AJ9: Nghỉ lễ, tết | AN9: Phụ cấp ban đêm | AO9: Phụ cấp bồi dưỡng làm việc | AW9: 8% | AX9: 1.5% | AY9: 1% | AZ9: (LHĐLĐ*10.5%) | BA9: (LHĐLĐ*0.5%) | BB9: 22 | BH9: MA BH | BI9: Ma KPCD | BJ9: Kiểm tra đối tượng hưởng lương | BK9: Kiểm tra đối tượng hưởng tăng ca | BL9: BD PHSK | BM9: MỨC TIỀN | BN9: Trừ tiền tang chế | BO9: Nội dung thu nhập 1 | BP9: Nội dung thu nhập 2 | BQ9: Tiền thưởng | BR9: Thu nhập 100% giao xe | BY9: Nội dung giảm trừ 1 | BZ9: Nội dung 1 | CA9: Nội dung 1 | CB9: Truy thu BH | CC9: Truy lĩnh BHXH | CD9: BHXH đã thu đưa vào tính thuế (số bảng đóng BHXH) | CE9: Mức lương | CF9: PC ThN | CG9: PC chức danh | CH9: PC kiêm nhiệm | CI9: PC biệt phái | CJ9: Tổng PC | CK9: Tổng thu nhập | CM9: Mức lương | CN9: PC ThN | CO9: PC chức danh | CP9: PC kiêm nhiệm | CQ9: PC biệt phát | CR9: Tổng PC | CS9: Tổng thu nhập
A10: A. | B10: ="KHU VỰC CHU LAI: "&"["&COUNT(A11:A421)&"]" -> KHU VỰC CHU LAI: [377] | G10: =G11+G22+G14+G24+G27+G29+G268+G274+G398 -> 1757160000 | H10: =H11+H22+H14+H24+H27+H29+H268+H274+H398 -> 52250000 | I10: =I11+I22+I14+I24+I27+I29+I268+I274+I398 -> 2115390000 | J10: =J11+J22+J14+J24+J27+J29+J268+J274+J398 -> 225370000 | K10: =K11+K22+K14+K24+K27+K29+K268+K274+K398 -> 2340760000 | L10: =L11+L22+L14+L24+L27+L29+L268+L274+L398 -> 4150170000 | N10: =N11+N22+N14+N24+N27+N29+N268+N274+N398 -> 1436785000 | O10: =O11+O22+O14+O24+O27+O29+O268+O274+O398 -> 0 | P10: =P11+P22+P14+P24+P27+P29+P268+P274+P398 -> 3268 | Q10: =Q11+Q22+Q14+Q24+Q27+Q29+Q268+Q274+Q398 -> 1501 | R10: =R11+R22+R14+R24+R27+R29+R268+R274+R398 -> 84.25 | S10: =S11+S22+S14+S24+S27+S29+S268+S274+S398 -> 23.14 | T10: =T11+T22+T14+T24+T27+T29+T268+T274+T398 -> 0 | U10: =U11+U22+U14+U24+U27+U29+U268+U274+U398 -> 0 | ... BG10: =BG11+BG22+BG14+BG24+BG27+BG29+BG268+BG274+BG398 -> 2094700 | BI10: =BI11+BI22+BI14+BI24+BI27+BI29+BI268+BI274+BI398 -> 0 | BJ10: =BJ11+BJ22+BJ14+BJ24+BJ27+BJ29+BJ268+BJ274+BJ398 -> 0 | BK10: =BK11+BK22+BK14+BK24+BK27+BK29+BK268+BK274+BK398 -> 0 | BL10: =BL11+BL22+BL14+BL24+BL27+BL29+BL268+BL274+BL398 -> 0 | BM10: =BM11+BM22+BM14+BM24+BM27+BM29+BM268+BM274+BM398 -> 515000 | BN10: =BN11+BN22+BN14+BN24+BN27+BN29+BN268+BN274+BN398 -> 0 | BO10: =BO11+BO22+BO14+BO24+BO27+BO29+BO268+BO274+BO398 -> 0 | BP10: =BP11+BP22+BP14+BP24+BP27+BP29+BP268+BP274+BP398 -> 0 | ... CS10: =CS11+CS22+CS14+CS24+CS27+CS29+CS268+CS274+CS398 -> 4150170000 | CT10: =SUM(CT11:CT11) -> 0 | CU10: =SUM(CU11:CU11) -> 0 | CV10: =SUM(CV11:CV11) -> 0
A11: I | B11: ="Ban Lãnh đạo: "&"["&COUNT(A12:A13)&"]" -> Ban Lãnh đạo: [2] | G11: =SUM(G12:G13) -> 28650000 | H11: =SUM(H12:H13) -> 0 | I11: =SUM(I12:I13) -> 181350000 | J11: =SUM(J12:J13) -> 35000000 | K11: =SUM(K12:K13) -> 216350000 | L11: =SUM(L12:L13) -> 245000000 | N11: =SUM(N12:N13) -> 20055000 | O11: =SUM(O12:O13) -> 0 | P11: =SUM(P12:P13) -> 25.5 | Q11: =SUM(Q12:Q13) -> 0 | R11: =SUM(R12:R13) -> 0 | S11: =SUM(S12:S13) -> 0 | T11: =SUM(T12:T13) -> 0 | U11: =SUM(U12:U13) -> 0 | ... CV11: =SUM(CV12:CV13) -> 0
A12: =SUBTOTAL(3,$C$11:C12) -> 1 | B12: 0803006 | C12: Bùi Trần Nhân Trí | D12: THILOGI | E12: =IF(CM12>=400000000,"A1",IF(CM12>=300000000,"A2",IF(CM12>=240000000,"A3",IF(CM12>=180000000,"A4",IF(CM12>=120000000,"A5",IF(CM12>=80000000,"A6",IF(CM12>=40000000,"A7",IF(CM12>=25000000,"B1",IF(CM12>=12000000,"B2","B3"))))))))) -> A5 | F12: 39449 | G12: 17130000 | I12: =IF(G12>0,CM12-G12,CM12-H12) -> 132870000 | J12: =CR12 -> 30000000 | K12: =SUM(I12:J12) -> 162870000 | L12: =IF(G12>0,G12+K12,H12+K12) -> 180000000 | M12: =IF(CE12>=11000000,80%,100%) -> 0.8 | N12: =ROUND(MAX(G12*70%,H12*70%,3640000),0) -> 11991000 | O12: 0 | P12: 13 | Q12: 0 | R12: 0 | S12: 0 | AD12: 0 | AE12: =IF(OR(BL12="M1",BL12="M2",BL12="M3",BL12="M4"),P12+R12+S12+T12+U12,0) -> 0 | AF12: =ROUND(IF($P12=0,0,IF(OR($BJ12="lương tháng",$CE12>=11000000),($L12/2-$L12/26*($CC$6-$P12))*$M12,$L12/26*$P12*$M12)),0) -> 72000000 | AG12: =ROUND(MAX((G12+I12)*M12/26*R12,(H12+I12)*M12/26*R12,G12/26*R12*150%,H12/26*R12*150%)*BK12,0) -> 0 | AH12: =ROUND(MAX((G12+I12)*M12/26*S12,(H12+I12)*M12/26*S12,G12/26*S12*200%,H12/26*S12*200%)*BK12,0) -> 0 | AI12: =ROUND(IF(BJ12="Lương tháng",L12/26*T12,MAX((G12+I12)/26*(T12+U12)*200%+G12/26*T12,(H12+I12)/26*(T12+U12)*200%+H12/26*T12,G12/26*(T12+U12)*300%+G12/26*T12,H12/26*(T12+U12)*300%+H12/26*T12)),0) -> 0 | AJ12: =ROUND(IF((P12+Q12)=0,0,IF(BJ12="Lương tháng",MAX((G12+I12)/26*V12,(H12+I12)/26*V12),MAX(G12/26*V12,H12/26*V12))),0) -> 0 | AK12: =ROUND(IF(G12>0,G12/26*W12,H12/26*W12),0) -> 0 | AL12: =ROUND(N12/26*Y12+O12/26*Z12+MAX(G12/26*AA12,H12/26*AA12),0) -> 0 | AM12: =ROUND(IF(BJ12="Lương tháng",L12/26*AC12,L12/26*AC12+MAX((G12+I12)/26*AB12,(H12+I12)/26*AB12)),0) -> 0 | AN12: =ROUND(IF(BJ12="lương tháng",0,MAX((G12+I12)/26*AD12*30%,(H12+I12)/26*AD12*30%)*BK12),0) -> 0 | AO12: =ROUND(BM12*AE12,0) -> 0 | AP12: 0 | AQ12: =ROUND(SUM(AF12:AP12),0) -> 72000000 | AV12: =ROUND(SUM(AQ12:AT12)-AU12,0) -> 72000000 | AW12: =ROUND(IF($BH12=1,$G12*$AW$9,0),0) -> 1370400 | AX12: =ROUND(IF($BH12=1,$G12*$AX$9,0),0) -> 256950 | AY12: =ROUND(IF($BH12=1,$G12*$AY$9,0),0) -> 171300 | AZ12: =SUM(AW12:AY12) -> 1798650 | BA12: =ROUND(IF($BI12="1x",$G12*0.5%,0),0) -> 85650 | BB12: =IF(BN12="Xem lại",0,IF(CM12<11000000,5000,IF(AND(CM12>=11000000,CM12<25000000),10000,IF(AND(CM12>=25000000,CM12<40000000),15000,IF(AND(CM12>=40000000,CM12<120000000),20000,IF(AND(CM12>=120000000,CM12<240000000),25000,30000)))))*$BB$9) -> 550000 | BD12: 0 | BE12: =ROUND(SUM(AZ12:BD12),0) -> 2434300 | BF12: =ROUND(IF(AV12>BE12,AV12-BE12,0),0) -> 69565700 | BG12: =ROUND(IF(BE12>AV12,BE12-AV12,0),0) -> 0 | BH12: 1 | BI12: 1x | BJ12: =IF(AND(D12="QTNV CL",CM12>=11000000),"Lương tháng",IF(CM12>=18000000,"Lương tháng",0)) -> Lương tháng | BK12: =IF(BJ12="Lương tháng",0,1) -> 0 | BL12: 0 | BM12: =IF(BL12="M1",13000,IF(BL12="M2",20000,IF(BL12="M3",26000,IF(BL12="M4",32000,0)))) -> 0 | BN12: =IF(AND(G12>0,(P12+Q12)>=5),"Trừ tiền","Xem lại") -> Trừ tiền | BS12: =AQ12+SUM(BO12:BR12)-AN12-AO12-SUM(BY12:CA12) -> 72000000 | BT12: 2 | BU12: =BT12*4400000 -> 8800000 | BV12: 11000000 | BW12: =BU12+BV12 -> 19800000 | BX12: =BS12-SUM(CC12:CD12)-CB12-AZ12-BW12 -> 50401350 | CE12: 150000000 | CF12: 0 | CG12: 0 | CH12: 30000000 | CJ12: =SUM(CF12:CI12) -> 30000000 | CK12: =CE12+CJ12 -> 180000000 | CM12: =CE12 -> 150000000 | CN12: =CF12 -> 0 | CO12: =CG12 -> 0 | CP12: =CH12 -> 30000000 | CQ12: =CI12 -> 0 | CR12: =SUM(CN12:CQ12) -> 30000000 | CS12: =CM12+CR12 -> 180000000 | CT12: Giám đốc | CU12: Ban Lãnh đạo THILOGI | CV12: buitrannhantri@thilogi.com.vn | CW12: Chu Lai
A13: =SUBTOTAL(3,$C$11:C13) -> 2 | B13: 0708065 | C13: Bùi Vĩnh Vũ | D13: THILOGI | E13: =IF(CM13>=400000000,"A1",IF(CM13>=300000000,"A2",IF(CM13>=240000000,"A3",IF(CM13>=180000000,"A4",IF(CM13>=120000000,"A5",IF(CM13>=80000000,"A6",IF(CM13>=40000000,"A7",IF(CM13>=25000000,"B1",IF(CM13>=12000000,"B2","B3"))))))))) -> A7 | F13: 39314 | G13: 11520000 | I13: =IF(G13>0,CM13-G13,CM13-H13) -> 48480000 | J13: =CR13 -> 5000000 | K13: =SUM(I13:J13) -> 53480000 | L13: =IF(G13>0,G13+K13,H13+K13) -> 65000000 | M13: =IF(CE13>=11000000,80%,100%) -> 0.8 | N13: =ROUND(MAX(G13*70%,H13*70%,3640000),0) -> 8064000 | O13: 0 | P13: 12.5 | Q13: 0 | R13: 0 | S13: 0 | AD13: 0 | AE13: =IF(OR(BL13="M1",BL13="M2",BL13="M3",BL13="M4"),P13+R13+S13+T13+U13,0) -> 0 | AF13: =ROUND(IF($P13=0,0,IF(OR($BJ13="lương tháng",$CE13>=11000000),($L13/2-$L13/26*($CC$6-$P13))*$M13,$L13/26*$P13*$M13)),0) -> 25000000 | AG13: =ROUND(MAX((G13+I13)*M13/26*R13,(H13+I13)*M13/26*R13,G13/26*R13*150%,H13/26*R13*150%)*BK13,0) -> 0 | AH13: =ROUND(MAX((G13+I13)*M13/26*S13,(H13+I13)*M13/26*S13,G13/26*S13*200%,H13/26*S13*200%)*BK13,0) -> 0 | AI13: =ROUND(IF(BJ13="Lương tháng",L13/26*T13,MAX((G13+I13)/26*(T13+U13)*200%+G13/26*T13,(H13+I13)/26*(T13+U13)*200%+H13/26*T13,G13/26*(T13+U13)*300%+G13/26*T13,H13/26*(T13+U13)*300%+H13/26*T13)),0) -> 0 | AJ13: =ROUND(IF((P13+Q13)=0,0,IF(BJ13="Lương tháng",MAX((G13+I13)/26*V13,(H13+I13)/26*V13),MAX(G13/26*V13,H13/26*V13))),0) -> 0 | AK13: =ROUND(IF(G13>0,G13/26*W13,H13/26*W13),0) -> 0 | AL13: =ROUND(N13/26*Y13+O13/26*Z13+MAX(G13/26*AA13,H13/26*AA13),0) -> 0 | AM13: =ROUND(IF(BJ13="Lương tháng",L13/26*AC13,L13/26*AC13+MAX((G13+I13)/26*AB13,(H13+I13)/26*AB13)),0) -> 0 | AN13: =ROUND(IF(BJ13="lương tháng",0,MAX((G13+I13)/26*AD13*30%,(H13+I13)/26*AD13*30%)*BK13),0) -> 0 | AO13: =ROUND(BM13*AE13,0) -> 0 | AP13: 0 | AQ13: =ROUND(SUM(AF13:AP13),0) -> 25000000 | AV13: =ROUND(SUM(AQ13:AT13)-AU13,0) -> 25000000 | AW13: =ROUND(IF($BH13=1,$G13*$AW$9,0),0) -> 921600 | AX13: =ROUND(IF($BH13=1,$G13*$AX$9,0),0) -> 172800 | AY13: =ROUND(IF($BH13=1,$G13*$AY$9,0),0) -> 115200 | AZ13: =SUM(AW13:AY13) -> 1209600 | BA13: =ROUND(IF($BI13="1x",$G13*0.5%,0),0) -> 57600 | BB13: =IF(BN13="Xem lại",0,IF(CM13<11000000,5000,IF(AND(CM13>=11000000,CM13<25000000),10000,IF(AND(CM13>=25000000,CM13<40000000),15000,IF(AND(CM13>=40000000,CM13<120000000),20000,IF(AND(CM13>=120000000,CM13<240000000),25000,30000)))))*$BB$9) -> 440000 | BD13: 0 | BE13: =ROUND(SUM(AZ13:BD13),0) -> 1707200 | BF13: =ROUND(IF(AV13>BE13,AV13-BE13,0),0) -> 23292800 | BG13: =ROUND(IF(BE13>AV13,BE13-AV13,0),0) -> 0 | BH13: 1 | BI13: 1x | BJ13: =IF(AND(D13="QTNV CL",CM13>=11000000),"Lương tháng",IF(CM13>=18000000,"Lương tháng",0)) -> Lương tháng | BK13: =IF(BJ13="Lương tháng",0,1) -> 0 | BL13: 0 | BM13: =IF(BL13="M1",13000,IF(BL13="M2",20000,IF(BL13="M3",26000,IF(BL13="M4",32000,0)))) -> 0 | BN13: =IF(AND(G13>0,(P13+Q13)>=5),"Trừ tiền","Xem lại") -> Trừ tiền | BS13: =AQ13+SUM(BO13:BR13)-AN13-AO13-SUM(BY13:CA13) -> 25000000 | BT13: 3 | BU13: =BT13*4400000 -> 13200000 | BV13: 11000000 | BW13: =BU13+BV13 -> 24200000 | BX13: =BS13-SUM(CC13:CD13)-CB13-AZ13-BW13 -> -409600 | CE13: 60000000 | CF13: 0 | CG13: 0 | CH13: 5000000 | CJ13: =SUM(CF13:CI13) -> 5000000 | CK13: =CE13+CJ13 -> 65000000 | CM13: =CE13 -> 60000000 | CN13: =CF13 -> 0 | CO13: =CG13 -> 0 | CP13: =CH13 -> 5000000 | CQ13: =CI13 -> 0 | CR13: =SUM(CN13:CQ13) -> 5000000 | CS13: =CM13+CR13 -> 65000000 | CT13: Phó Giám đốc - Phụ trách ô tô, cơ khí & LKPT | CU13: Ban Lãnh đạo THILOGI | CV13: buivinhvu@thilogi.com.vn | CW13: Chu Lai
A14: II | B14: ="Phòng Kế toán: " &"["&COUNT(A15:A21)& "]" -> Phòng Kế toán: [7] | G14: =SUM(G15:G21) -> 42450000 | H14: =SUM(H15:H21) -> 0 | I14: =SUM(I15:I21) -> 73050000 | J14: =SUM(J15:J21) -> 1400000 | K14: =SUM(K15:K21) -> 74450000 | L14: =SUM(L15:L21) -> 116900000 | N14: =SUM(N15:N21) -> 30975000 | O14: =SUM(O15:O21) -> 0 | P14: =SUM(P15:P21) -> 88.5 | Q14: =SUM(Q15:Q21) -> 0 | R14: =SUM(R15:R21) -> 5.93 | S14: =SUM(S15:S21) -> 0 | T14: =SUM(T15:T21) -> 0 | U14: =SUM(U15:U21) -> 0 | ... BG14: =SUM(BG15:BG21) -> 0 | BI14: =SUM(BI15:BI21) -> 0 | BJ14: =SUM(BJ15:BJ21) -> 0 | BL14: =SUM(BL15:BL21) -> 0 | BM14: =SUM(BM15:BM21) -> 0 | BN14: =SUM(BN15:BN21) -> 0 | BO14: =SUM(BO15:BO21) -> 0 | BP14: =SUM(BP15:BP21) -> 0 | BQ14: =SUM(BQ15:BQ21) -> 0 | BR14: =SUM(BR15:BR21) -> 0 | BS14: =SUM(BS15:BS21) -> 52134692 | ... CV14: =SUM(CV15:CV21) -> 0
