Workbook
Name \a: #REF!
Name \b: #N/A
Name \c: #N/A
Name \d: #N/A
Name \p: #N/A
Name \T: #REF!
Name _: "SQRT"
Name _.._mik: #REF!
Name _?: #REF!
Name _??: #N/A
Name _??????: #REF!
Name _??????1: BlankMacro1
Name _??????1: BlankMacro1
Name _??????1: BlankMacro1
Name _??????1: BlankMacro1
Name _??????2: BlankMacro1
Name _??????2: BlankMacro1
Name _??????2: BlankMacro1
Name _??????2: BlankMacro1
Name _??????3: BlankMacro1
Name _??????3: BlankMacro1
Name _??????3: BlankMacro1
Name _??????3: BlankMacro1
Name _??????4: BlankMacro1
Name _??????4: BlankMacro1
Name _??????4: BlankMacro1
Name _??????4: BlankMacro1
Name _??????5: BlankMacro1
Name _??????5: BlankMacro1
Name _??????5: BlankMacro1
Name _??????5: BlankMacro1
Name _??????6: BlankMacro1
Name _??????6: BlankMacro1
Name _??????6: BlankMacro1
Name _??????6: BlankMacro1
Name _?1: #N/A
Name _?271: #N/A
Name _?춑_TOTAL: #N/A
Name _?춮t2: #N/A
Name __?: #N/A
Name __??: #N/A
Name __??????: #REF!
Name __?1: #N/A
Name __?271: #N/A
Name ___?: #REF!
Name ___??????: #REF!
Name _____KDX3: #REF!
Name ____KDX3: #N/A
Name ___a10: #N/A
Name ___atn1: #REF!
Name ___atn10: #REF!
Name ___atn2: #REF!
Name ___atn3: #REF!
Name ___atn4: #REF!
Name ___atn5: #REF!
Name ___atn6: #REF!
Name ___atn7: #REF!
Name ___atn8: #REF!
Name ___atn9: #REF!
Name ___Bia1: #N/A

Sheet Bảng lương CB-NV
A1: CÔNG TY …..............
A2: ĐC:…...........
A3: ="BẢNG THANH TOÁN TIỀN LƯƠNG THÁNG …."&" NĂM "&YEAR(NOW()) -> BẢNG THANH TOÁN TIỀN LƯƠNG THÁNG …. NĂM 2026 | BW3: THỐNG KÊ LƯƠNG | CE3: Ngày công thực tế tháng | CF3: 26
A8: TT | B8: MSNV | C8: Họ và tên | D8: Đơn vị | E8: Loại HĐLĐ | F8: Đối tượng được tính làm thêm giờ | G8: Mức lương HĐLĐ | H8: Phụ cấp (PCCC, ATVSV) | I8: Định mức Thưởng HQCV | J8: Tỷ lệ % tạm ứng thưởng HQCV | K8: Ngày công trong tháng | Y8: Các khoản được hưởng trong tháng | AP8: Truy lãnh lương | AQ8: Truy thu lương | AR8: Hỗ trợ cơm | AS8: Hỗ trợ Nhà ở | AT8: Thưởng năm | AU8: Chi trả phép năm chưa sử dụng | AV8: Tổng thu nhập | AW8: Thu nhập chịu thuế khác | AX8: Tham gia BHXH | AY8: Các khoản trừ | BR8: Quyết toán thuế | BT8: Thực nhận kỳ 1 | BU8: Thực nhận kỳ 2 | BW8: Ngạch lương | BX8: Các khoản được hưởng | CB8: Tổng lương và các khoản PC khác | CC8: Là ĐT, ĐP PCCC, AT-VSV | CD8: Mức Bồi dưỡng sức khỏe
K9: Công đi làm ngày thường | L9: Công tác | M9: Phép năm | N9: Nghỉ chế độ | O9: Nghỉ Lễ/Tết | P9: Tăng ca ngày thường | Q9: Tăng ca ngày chủ nhật | R9: Tăng ca Lễ tết | S9: Công phụ cấp ban đêm | T9: Giờ công nữ nghỉ HK | U9: Làm việc ngày T7 được nghỉ | V9: Ngày ngừng việc trong tháng | X9: Ngày công PHSK | Y9: Lương Ngày thường | Z9: Lương ngày nghỉ phép | AA9: Lương ngày nghỉ chế độ | AB9: Lương ngày nghỉ Lễ Tết | AC9: Lương Tăng ca ngày thường | AD9: Lương tăng ca ngày nghỉ | AE9: Lương tăng ca ngày Lễ/Tết | AF9: Lương phụ cấp ban đêm | AG9: Lương nữ nghỉ HK | AH9: Lương làm việc ngày T7 được nghỉ | AI9: Lương ngày tạm ngừng việc | AJ9: Lương trực hỗ trợ bảo vệ | AK9: Phụ cấp công tác | AL9: Phép năm nghỉ việc | AM9: Bồi dưỡng PHSK | AN9: Phụ cấp PCCC (ĐT, ĐP), Phụ cấp AT-VSV | AO9: Tạm ứng thưởng HQCV | AY9: Các khoản trích nộp | BM9: Các khoản thu hộ/thu khác | BR9: Truy thu theo QTT | BS9: Hoàn trả theo QTT
AY10: BHXH | AZ10: BHYT | BA10: BHTN | BB10: TỔng BHXH | BC10: Truy thu BHXH | BD10: Hoàn trả BHXH | BE10: Phí công đoàn | BF10: TN miễn thuế | BG10: Thu nhập chịu thuế | BH10: NPT | BI10: Giảm trừ NPT | BJ10: Giảm trừ cá nhân | BK10: TNTT | BL10: Thuế TNCN | BM10: Thu tiền tạm ứng | BN10: Thu hộ cho Cty Đầu tư tiền KBT…, | BO10: Thu tiền điện thoại vượt mức | BP10: Tiền phúng điếu | BQ10: …..............
V11: 14 ngày đầu | W11: Từ ngày 15 trở đi | AY11: 8% | AZ11: 1.5% | BA11: 1% | BX11: PC chức danh | BY11: PC kiêm nhiệm | BZ11: PC Biệt phái | CA11: PC thâm niên
A12: 1 | B12: =A12+1 -> 2 | C12: =B12+1 -> 3 | D12: =C12+1 -> 4 | F12: =D12+1 -> 5 | G12: =F12+1 -> 6 | H12: =G12+1 -> 7 | I12: =H12+1 -> 8 | J12: =I12+1 -> 9 | K12: =J12+1 -> 10 | L12: =K12+1 -> 11 | M12: =L12+1 -> 12 | N12: =M12+1 -> 13 | ... AV12: =AU12+1 -> 47 | AY12: =AV12+1 -> 48 | AZ12: =AY12+1 -> 49 | BA12: =AZ12+1 -> 50 | BB12: =BA12+1 -> 51 | BC12: =BB12+1 -> 52 | BD12: =BC12+1 -> 53 | BE12: =BD12+1 -> 54 | BL12: =BE12+1 -> 55 | BM12: =BL12+1 -> 56 | BN12: =BM12+1 -> 57 | BO12: =BN12+1 -> 58 | BP12: =BO12+1 -> 59 | BQ12: =BP12+1 -> 60 | BR12: =BQ12+1 -> 61 | BS12: =BR12+1 -> 62 | BT12: =BS12+1 -> 63 | BU12: =BT12+1 -> 64 | BW12: 65 | BX12: =BW12+1 -> 66 | BY12: =BX12+1 -> 67 | BZ12: =BY12+1 -> 68 | CA12: =BZ12+1 -> 69 | CB12: =CA12+1 -> 70 | CC12: =CB12+1 -> 71 | CD12: =CC12+1 -> 72
A13: IN | B13: IN | C13: IN | G13: IN | H13: IN | I13: IN
G14: =SUM(G15:G21) -> 50340000 | H14: =SUM(H15:H21) -> 1080000 | I14: =SUM(I15:I21) -> 182280000 | K14: =SUM(K15:K21) -> 166 | L14: =SUM(L15:L21) -> 8 | M14: =SUM(M15:M21) -> 2 | N14: =SUM(N15:N21) -> 2 | O14: =SUM(O15:O21) -> 0 | P14: =SUM(P15:P21) -> 5 | Q14: =SUM(Q15:Q21) -> 2 | R14: =SUM(R15:R21) -> 0 | S14: =SUM(S15:S21) -> 2 | U14: =SUM(U15:U21) -> 2 | V14: =SUM(V15:V21) -> 0 | W14: =SUM(W15:W21) -> 0 | X14: =SUM(X15:X21) -> 0 | Y14: =SUM(Y15:Y21) -> 48340000 | AC14: =SUM(AC15:AC21) -> 1828846.2 | AD14: =SUM(AD15:AD21) -> 975384.62 | AF14: =SUM(AF15:AF21) -> 111923.08 | AG14: =SUM(AG15:AG21) -> 0 | AH14: =SUM(AH15:AH21) -> 3246153.8 | AI14: =SUM(AI15:AI21) -> 0 | AJ14: =SUM(AJ15:AJ21) -> 0 | AK14: =SUM(AK15:AK21) -> 61538.462 | AL14: =SUM(AL15:AL21) -> 0 | AM14: =SUM(AM15:AM21) -> 0 | ... AO14: =SUM(AO15:AO21) -> 1.8128308e+08 | AV14: =SUM(AV15:AV21) -> 2.3926692e+08 | AY14: =SUM(AY15:AY21) -> 3544000 | AZ14: =SUM(AZ15:AZ21) -> 664500 | BA14: =SUM(BA15:BA21) -> 443000 | BB14: =SUM(BB15:BB21) -> 4651500 | BC14: =SUM(BC15:BC21) -> 0 | BE14: =SUM(BE15:BE21) -> 503400 | BL14: =SUM(BL15:BL21) -> 20461490 | BM14: =SUM(BM15:BM21) -> 0 | BN14: =SUM(BN15:BN21) -> 0 | BO14: =SUM(BO15:BO21) -> 0 | BP14: =SUM(BP15:BP21) -> 0 | BQ14: =SUM(BQ15:BQ21) -> 0 | BT14: =SUM(BT15:BT21) -> 92038615 | BU14: =SUM(BU15:BU21) -> 1.2161192e+08
A15: =IF(B15=0,"",COUNTA($B$15:(B15))) -> 1 | B15: 2405236 | C15: Tô Thanh Liêm | D15: Ban kế toán | E15: CT | F15: LT | G15: 9520000 | H15: =+IF(OR(CC15="ĐT PCCC",CC15="ĐP PCCC"),780000,IF(CC15="AT-VSV",300000,0)) -> 0 | I15: =CB15-BZ15-G15-H15 -> 50480000 | J15: 1 | K15: 26 | L15: 0 | M15: 0 | N15: 0 | O15: 0 | P15: 0 | Q15: 0 | R15: 0 | S15: 0 | U15: 0 | V15: 0 | W15: 0 | X15: 0 | Y15: =G15*(K15+L15)/26 -> 9520000 | Z15: =M15*G15/26 -> 0 | AA15: =G15*N15/26 -> 0 | AB15: =G15*O15/26 -> 0 | AC15: =G15*P15*150%/26 -> 0 | AD15: =G15*Q15/26*200% -> 0 | AE15: =G15*R15/26*300% -> 0 | AF15: =ROUND((G15+H15)/26*S15*30%,0) -> 0 | AG15: =T15*G15/26/8 -> 0 | AH15: =CB15/26*U15 -> 0 | AI15: =G15*V15/26 -> 0 | AK15: =BZ15*L15/26 -> 0 | AM15: =X15*CD15 -> 0 | AN15: =H15/26*(K15+L15) -> 0 | AO15: =IF(F15="LN",I15*(K15+L15)/26+(H15+I15)*50%*M15/26+MAX($G15*P15/26*150%,P15*$BW15/26)-AC15+MAX($G15*Q15/26*200%,Q15*$BW15/26)-AD15+MAX($G15*R15/26*300%,R15*$BW15/26)-AE15+BW15*S15/26-AF15+AH15-AG15,I15-I15*($CF$3-K15-L15)/26+(H15+I15)*50%*M15/26+BW15*O15/26-AB15+MAX($G15*P15/26*150%,P15*$BW15/26)-AC15+MAX($G15*Q15/26*200%,Q15*$BW15/26)-AD15+MAX($G15*R15/26*300%,R15*$BW15/26)-AE15+BW15*S15/26-AF15+AH15-AG15+(G15-G15*($CF$3-K15-L15)/26-Y15)+(H15-H15*($CF$3-K15-L15)/26-AN15)) -> 50480000 | AR15: 1000000 | AV15: =Y15+Z15+AA15+AB15+AC15+AD15+AE15+AF15+AG15+AI15+AJ15+AK15+AL15+AM15+AN15+AO15+AP15-AQ15+AR15+AS15+AT15+AU15 -> 61000000 | AX15: x | AY15: =ROUND(IF($AX15="x",($G15+$H15)*AY$11,0),0) -> 761600 | AZ15: =ROUND(IF($AX15="x",($G15+$H15)*AZ$11,0),0) -> 142800 | BA15: =ROUND(IF($AX15="x",($G15+$H15)*BA$11,0),0) -> 95200 | BB15: =SUM(AY15:BA15) -> 999600 | BE15: =IF(G15*1%>=234000,234000,G15*1%) -> 95200 | BF15: =AM15+IF(E15="CT",IF(AR15>=730000,730000,AR15),0)+IF(((AV15-AM15-IF(AR15>=730000,730000,AR15)-AS15)*15%-AS15)>"0",((AV15-AM15-IF(AR15>=730000,730000,AR15)-AS15)*15%-AS15),0) -> 730000 | BG15: =AV15-BF15+AW15 -> 60270000 | BH15: 3 | BI15: 4400000 | BJ15: =IF(E15="CT",11000000,0) -> 11000000 | BK15: =BG15-BB15-BC15+BD15-BH15*BI15-BJ15 -> 35070400 | BL15: =IF(E15="TV",BK15*10%,IF(BK15>0,ROUND(IF(BK15>=80000000,BK15*35%-9850000,IF(BK15>=52000000,BK15*30%-5850000,IF(BK15>=32000000,BK15*25%-3250000,IF(BK15>=18000000,BK15*20%-1650000,IF(BK15>=10000000,BK15*15%-750000,IF(BK15>5000000,BK15*10%-250000,BK15*5%)))))),0),0)) -> 5517600 | BO15: 0 | BT15: =SUMIFS('Bảng lương tạm ứng kỳ 1'!BT:BT,'Bảng lương CB-NV'!B:B,'Bảng lương tạm ứng kỳ 1'!B15) -> 25846154 | BU15: =AV15-BB15-BC15+BD15-BE15-BL15-BM15-BN15-BO15-BP15-BQ15-BR15+BS15-BT15 -> 28541446 | BW15: 60000000 | BX15: 0 | BZ15: 200000 | CA15: 0 | CB15: =SUM(BW15:CA15) -> 60200000
A16: =IF(B16=0,"",COUNTA($B$15:(B16))) -> 2 | B16: 2106723 | C16: Nguyễn Thành An | D16: Ban nhân sự | E16: CT | F16: LT | G16: 8480000 | H16: =+IF(OR(CC16="ĐT PCCC",CC16="ĐP PCCC"),780000,IF(CC16="AT-VSV",300000,0)) -> 0 | I16: =CB16-BZ16-G16-H16 -> 43520000 | J16: 1 | K16: 19 | L16: 5 | M16: 0 | N16: 0 | O16: 0 | P16: 0 | Q16: 0 | R16: 0 | S16: 0 | U16: 0 | V16: 0 | W16: 0 | X16: 0 | Y16: =G16*(K16+L16)/26 -> 7827692.3 | Z16: =M16*G16/26 -> 0 | AA16: =G16*N16/26 -> 0 | AB16: =G16*O16/26 -> 0 | AC16: =G16*P16*150%/26 -> 0 | AD16: =G16*Q16/26*200% -> 0 | AE16: =G16*R16/26*300% -> 0 | AF16: =ROUND((G16+H16)/26*S16*30%,0) -> 0 | AG16: =T16*G16/26/8 -> 0 | AH16: =CB16/26*U16 -> 0 | AI16: =G16*V16/26 -> 0 | AK16: =BZ16*L16/26 -> 38461.538 | AM16: =X16*CD16 -> 0 | AN16: =H16/26*K16 -> 0 | AO16: =IF(F16="LN",I16*(K16+L16)/26+(H16+I16)*50%*M16/26+MAX($G16*P16/26*150%,P16*$BW16/26)-AC16+MAX($G16*Q16/26*200%,Q16*$BW16/26)-AD16+MAX($G16*R16/26*300%,R16*$BW16/26)-AE16+BW16*S16/26-AF16+AH16-AG16,I16-I16*($CF$3-K16-L16)/26+(H16+I16)*50%*M16/26+BW16*O16/26-AB16+MAX($G16*P16/26*150%,P16*$BW16/26)-AC16+MAX($G16*Q16/26*200%,Q16*$BW16/26)-AD16+MAX($G16*R16/26*300%,R16*$BW16/26)-AE16+BW16*S16/26-AF16+AH16-AG16+(G16-G16*($CF$3-K16-L16)/26-Y16)+(H16-H16*($CF$3-K16-L16)/26-AN16)) -> 40172308 | AR16: 720000 | AV16: =Y16+Z16+AA16+AB16+AC16+AD16+AE16+AF16+AG16+AI16+AJ16+AK16+AL16+AM16+AN16+AO16+AP16-AQ16+AR16+AS16+AT16+AU16 -> 48758462 | AX16: =IF(E16="CT","x",0) -> x | AY16: =ROUND(IF($AX16="x",($G16+$H16)*AY$11,0),0) -> 678400 | AZ16: =ROUND(IF($AX16="x",($G16+$H16)*AZ$11,0),0) -> 127200 | BA16: =ROUND(IF($AX16="x",($G16+$H16)*BA$11,0),0) -> 84800 | BB16: =SUM(AY16:BA16) -> 890400 | BE16: =IF(G16*1%>=234000,234000,G16*1%) -> 84800 | BF16: =AM16+IF(E16="CT",IF(AR16>=730000,730000,AR16),0)+IF(((AV16-AM16-IF(AR16>=730000,730000,AR16)-AS16)*15%-AS16)>"0",((AV16-AM16-IF(AR16>=730000,730000,AR16)-AS16)*15%-AS16),0) -> 720000 | BG16: =AV16-BF16+AW16 -> 48038462 | BI16: 4400000 | BJ16: =IF(E16="CT",11000000,0) -> 11000000 | BK16: =BG16-BB16-BC16+BD16-BH16*BI16-BJ16 -> 36148062 | BL16: =IF(E16="TV",BK16*10%,IF(BK16>0,ROUND(IF(BK16>=80000000,BK16*35%-9850000,IF(BK16>=52000000,BK16*30%-5850000,IF(BK16>=32000000,BK16*25%-3250000,IF(BK16>=18000000,BK16*20%-1650000,IF(BK16>=10000000,BK16*15%-750000,IF(BK16>5000000,BK16*10%-250000,BK16*5%)))))),0),0)) -> 5787015 | BO16: 0 | BT16: =SUMIFS('Bảng lương tạm ứng kỳ 1'!BT:BT,'Bảng lương CB-NV'!B:B,'Bảng lương tạm ứng kỳ 1'!B14) -> 0 | BU16: =AV16-BB16-BC16+BD16-BE16-BL16-BM16-BN16-BO16-BP16-BQ16-BR16+BS16-BT16 -> 41996247 | BW16: 40000000 | BX16: 5000000 | BY16: 5000000 | BZ16: 200000 | CA16: =+BW16*5% -> 2000000 | CB16: =SUM(BW16:CA16) -> 52200000
A17: =IF(B17=0,"",COUNTA($B$15:(B17))) -> 3 | B17: 2504023 | C17: Nguyễn Hữu Thọ | D17: Ban tài chính | E17: CT | F17: LT | G17: 7820000 | H17: =+IF(OR(CC17="ĐT PCCC",CC17="ĐP PCCC"),780000,IF(CC17="AT-VSV",300000,0)) -> 0 | I17: =CB17-BZ17-G17-H17 -> 34180000 | J17: 1 | K17: 24 | L17: 0 | M17: 0 | N17: 0 | O17: 0 | P17: 0 | Q17: 0 | R17: 0 | S17: 0 | U17: 2 | V17: 0 | W17: 0 | X17: 0 | Y17: =G17*(K17+L17)/26 -> 7218461.5 | Z17: =M17*G17/26 -> 0 | AA17: =G17*N17/26 -> 0 | AB17: =G17*O17/26 -> 0 | AC17: =G17*P17*150%/26 -> 0 | AD17: =G17*Q17/26*200% -> 0 | AE17: =G17*R17/26*300% -> 0 | AF17: =IF(F17="LN",(G17+H17)/26*S17*30%,0) -> 0 | AG17: =T17*G17/26/8 -> 0 | AH17: =CB17/26*U17 -> 3246153.8 | AI17: =G17*V17/26 -> 0 | AK17: =BZ17*L17/26 -> 0 | AM17: =X17*CD17 -> 0 | AN17: =H17/26*K17 -> 0 | AO17: =IF(F17="LN",I17*(K17+L17)/26+(H17+I17)*50%*M17/26+MAX($G17*P17/26*150%,P17*$BW17/26)-AC17+MAX($G17*Q17/26*200%,Q17*$BW17/26)-AD17+MAX($G17*R17/26*300%,R17*$BW17/26)-AE17+BW17*S17/26-AF17+AH17-AG17,I17-I17*($CF$3-K17-L17)/26+(H17+I17)*50%*M17/26+BW17*O17/26-AB17+MAX($G17*P17/26*150%,P17*$BW17/26)-AC17+MAX($G17*Q17/26*200%,Q17*$BW17/26)-AD17+MAX($G17*R17/26*300%,R17*$BW17/26)-AE17+BW17*S17/26-AF17+AH17-AG17+(G17-G17*($CF$3-K17-L17)/26-Y17)+(H17-H17*($CF$3-K17-L17)/26-AN17)) -> 34796923 | AR17: 560000 | AV17: =Y17+Z17+AA17+AB17+AC17+AD17+AE17+AF17+AG17+AI17+AJ17+AK17+AL17+AM17+AN17+AO17+AP17-AQ17+AR17+AS17+AT17+AU17 -> 42575385 | AX17: =IF(E17="CT","x",0) -> x | AY17: =ROUND(IF($AX17="x",($G17+$H17)*AY$11,0),0) -> 625600 | AZ17: =ROUND(IF($AX17="x",($G17+$H17)*AZ$11,0),0) -> 117300 | BA17: =ROUND(IF($AX17="x",($G17+$H17)*BA$11,0),0) -> 78200 | BB17: =SUM(AY17:BA17) -> 821100 | BE17: =IF(G17*1%>=234000,234000,G17*1%) -> 78200 | BF17: =AM17+IF(E17="CT",IF(AR17>=730000,730000,AR17),0)+IF(((AV17-AM17-IF(AR17>=730000,730000,AR17)-AS17)*15%-AS17)>"0",((AV17-AM17-IF(AR17>=730000,730000,AR17)-AS17)*15%-AS17),0) -> 560000 | BG17: =AV17-BF17+AW17 -> 42015385 | BI17: 4400000 | BJ17: =IF(E17="CT",11000000,0) -> 11000000 | BK17: =BG17-BB17-BC17+BD17-BH17*BI17-BJ17 -> 30194285 | BL17: =IF(E17="TV",BK17*10%,IF(BK17>0,ROUND(IF(BK17>=80000000,BK17*35%-9850000,IF(BK17>=52000000,BK17*30%-5850000,IF(BK17>=32000000,BK17*25%-3250000,IF(BK17>=18000000,BK17*20%-1650000,IF(BK17>=10000000,BK17*15%-750000,IF(BK17>5000000,BK17*10%-250000,BK17*5%)))))),0),0)) -> 4388857 | BO17: 0 | BT17: =SUMIFS('Bảng lương tạm ứng kỳ 1'!BT:BT,'Bảng lương CB-NV'!B:B,'Bảng lương tạm ứng kỳ 1'!B15) -> 25846154 | BU17: =AV17-BB17-BC17+BD17-BE17-BL17-BM17-BN17-BO17-BP17-BQ17-BR17+BS17-BT17 -> 11441074 | BW17: 40000000 | BX17: 0 | BY17: 0 | BZ17: 200000 | CA17: =+BW17*5% -> 2000000 | CB17: =SUM(BW17:CA17) -> 42200000
A18: =IF(B18=0,"",COUNTA($B$15:(B18))) -> 4 | B18: 2406198 | C18: Trương Thị Thu Hiền | D18: Ban kế toán | E18: CT | F18: LT | G18: 6990000 | H18: =+IF(OR(CC18="ĐT PCCC",CC18="ĐP PCCC"),780000,IF(CC18="AT-VSV",300000,0)) -> 0 | I18: =CB18-BZ18-G18-H18 -> 19160000 | J18: 1 | K18: 23 | L18: 3 | M18: 0 | N18: 0 | O18: 0 | P18: 0 | Q18: 0 | R18: 0 | S18: 0 | U18: 0 | V18: 0 | W18: 0 | X18: 0 | Y18: =G18*(K18+L18)/26 -> 6990000 | Z18: =M18*G18/26 -> 0 | AA18: =G18*N18/26 -> 0 | AB18: =G18*O18/26 -> 0 | AC18: =G18*P18*150%/26 -> 0 | AD18: =G18*Q18/26*200% -> 0 | AE18: =G18*R18/26*300% -> 0 | AF18: =ROUND((G18+H18)/26*S18*30%,0) -> 0 | AG18: =T18*G18/26/8 -> 0 | AH18: =CB18/26*U18 -> 0 | AI18: =G18*V18/26 -> 0 | AK18: =BZ18*L18/26 -> 23076.923 | AM18: =X18*CD18 -> 0 | AN18: =H18/26*K18 -> 0 | AO18: =IF(F18="LN",I18*(K18+L18)/26+(H18+I18)*50%*M18/26+MAX($G18*P18/26*150%,P18*$BW18/26)-AC18+MAX($G18*Q18/26*200%,Q18*$BW18/26)-AD18+MAX($G18*R18/26*300%,R18*$BW18/26)-AE18+BW18*S18/26-AF18+AH18-AG18,I18-I18*($CF$3-K18-L18)/26+(H18+I18)*50%*M18/26+BW18*O18/26-AB18+MAX($G18*P18/26*150%,P18*$BW18/26)-AC18+MAX($G18*Q18/26*200%,Q18*$BW18/26)-AD18+MAX($G18*R18/26*300%,R18*$BW18/26)-AE18+BW18*S18/26-AF18+AH18-AG18+(G18-G18*($CF$3-K18-L18)/26-Y18)+(H18-H18*($CF$3-K18-L18)/26-AN18)) -> 19160000 | AR18: 720000 | AV18: =Y18+Z18+AA18+AB18+AC18+AD18+AE18+AF18+AG18+AI18+AJ18+AK18+AL18+AM18+AN18+AO18+AP18-AQ18+AR18+AS18+AT18+AU18 -> 26893077 | AX18: =IF(E18="CT","x",0) -> x | AY18: =ROUND(IF($AX18="x",($G18+$H18)*AY$11,0),0) -> 559200 | AZ18: =ROUND(IF($AX18="x",($G18+$H18)*AZ$11,0),0) -> 104850 | BA18: =ROUND(IF($AX18="x",($G18+$H18)*BA$11,0),0) -> 69900 | BB18: =SUM(AY18:BA18) -> 733950 | BE18: =IF(G18*1%>=234000,234000,G18*1%) -> 69900 | BF18: =AM18+IF(E18="CT",IF(AR18>=730000,730000,AR18),0)+IF(((AV18-AM18-IF(AR18>=730000,730000,AR18)-AS18)*15%-AS18)>"0",((AV18-AM18-IF(AR18>=730000,730000,AR18)-AS18)*15%-AS18),0) -> 720000 | BG18: =AV18-BF18+AW18 -> 26173077 | BI18: 4400000 | BJ18: =IF(E18="CT",11000000,0) -> 11000000 | BK18: =BG18-BB18-BC18+BD18-BH18*BI18-BJ18 -> 14439127 | BL18: =IF(E18="TV",BK18*10%,IF(BK18>0,ROUND(IF(BK18>=80000000,BK18*35%-9850000,IF(BK18>=52000000,BK18*30%-5850000,IF(BK18>=32000000,BK18*25%-3250000,IF(BK18>=18000000,BK18*20%-1650000,IF(BK18>=10000000,BK18*15%-750000,IF(BK18>5000000,BK18*10%-250000,BK18*5%)))))),0),0)) -> 1415869 | BO18: 0 | BT18: =SUMIFS('Bảng lương tạm ứng kỳ 1'!BT:BT,'Bảng lương CB-NV'!B:B,'Bảng lương tạm ứng kỳ 1'!B20) -> 10195308 | BU18: =AV18-BB18-BC18+BD18-BE18-BL18-BM18-BN18-BO18-BP18-BQ18-BR18+BS18-BT18 -> 14478050 | BW18: 23000000 | BX18: 0 | BY18: 2000000 | BZ18: 200000 | CA18: =+BW18*5% -> 1150000 | CB18: =SUM(BW18:CA18) -> 26350000
A19: =IF(B19=0,"",COUNTA($B$15:(B19))) -> 5 | B19: 2305991 | C19: Võ Thị Tú Trinh | D19: Ban hành chính | E19: CT | F19: LN | G19: 4850000 | H19: =+IF(OR(CC19="ĐT PCCC",CC19="ĐP PCCC"),780000,IF(CC19="AT-VSV",300000,0)) -> 0 | I19: =CB19-BZ19-G19-H19 -> 6700000 | J19: 1 | K19: 22 | L19: 0 | M19: 2 | N19: 2 | O19: 0 | P19: 0 | Q19: 0 | R19: 0 | S19: 2 | U19: 0 | V19: 0 | W19: 0 | X19: 0 | Y19: =G19*(K19+L19)/26 -> 4103846.2 | Z19: =M19*G19/26 -> 373076.92 | AA19: =G19*N19/26 -> 373076.92 | AB19: =G19*O19/26 -> 0 | AC19: =G19*P19*150%/26 -> 0 | AD19: =G19*Q19/26*200% -> 0 | AE19: =G19*R19/26*300% -> 0 | AF19: =IF(F19="LN",(G19+H19)/26*S19*30%,0) -> 111923.08 | AG19: =T19*G19/26/8 -> 0 | AH19: =CB19/26*U19 -> 0 | AI19: =G19*V19/26 -> 0 | AK19: =BZ19*L19/26 -> 0 | AM19: =X19*CD19 -> 0 | AN19: =H19/26*K19 -> 0 | AO19: =IF(F19="LN",I19*(K19+L19)/26+(H19+I19)*50%*M19/26+MAX($G19*P19/26*150%,P19*$BW19/26)-AC19+MAX($G19*Q19/26*200%,Q19*$BW19/26)-AD19+MAX($G19*R19/26*300%,R19*$BW19/26)-AE19+BW19*S19/26-AF19+AH19-AG19,I19-I19*($CF$3-K19-L19)/26+(H19+I19)*50%*M19/26+BW19*O19/26-AB19+MAX($G19*P19/26*150%,P19*$BW19/26)-AC19+MAX($G19*Q19/26*200%,Q19*$BW19/26)-AD19+MAX($G19*R19/26*300%,R19*$BW19/26)-AE19+BW19*S19/26-AF19+AH19-AG19+(G19-G19*($CF$3-K19-L19)/26-Y19)+(H19-H19*($CF$3-K19-L19)/26-AN19)) -> 6661153.8 | AR19: 560000 | AV19: =Y19+Z19+AA19+AB19+AC19+AD19+AE19+AF19+AG19+AI19+AJ19+AK19+AL19+AM19+AN19+AO19+AP19-AQ19+AR19+AS19+AT19+AU19 -> 12183077 | AX19: =IF(E19="CT","x",0) -> x | AY19: =ROUND(IF($AX19="x",($G19+$H19)*AY$11,0),0) -> 388000 | AZ19: =ROUND(IF($AX19="x",($G19+$H19)*AZ$11,0),0) -> 72750 | BA19: =ROUND(IF($AX19="x",($G19+$H19)*BA$11,0),0) -> 48500 | BB19: =SUM(AY19:BA19) -> 509250 | BE19: =IF(G19*1%>=234000,234000,G19*1%) -> 48500 | BF19: =AM19+IF(E19="CT",IF(AR19>=730000,730000,AR19),0)+IF(((AV19-AM19-IF(AR19>=730000,730000,AR19)-AS19)*15%-AS19)>"0",((AV19-AM19-IF(AR19>=730000,730000,AR19)-AS19)*15%-AS19),0) -> 560000 | BG19: =AV19-BF19+AW19 -> 11623077 | BI19: 4400000 | BJ19: =IF(E19="CT",11000000,0) -> 11000000 | BK19: =BG19-BB19-BC19+BD19-BH19*BI19-BJ19 -> 113826.92 | BL19: =IF(E19="TV",BK19*10%,IF(BK19>0,ROUND(IF(BK19>=80000000,BK19*35%-9850000,IF(BK19>=52000000,BK19*30%-5850000,IF(BK19>=32000000,BK19*25%-3250000,IF(BK19>=18000000,BK19*20%-1650000,IF(BK19>=10000000,BK19*15%-750000,IF(BK19>5000000,BK19*10%-250000,BK19*5%)))))),0),0)) -> 5691 | BO19: 0 | BT19: =SUMIFS('Bảng lương tạm ứng kỳ 1'!BT:BT,'Bảng lương CB-NV'!B:B,'Bảng lương tạm ứng kỳ 1'!B21) -> 9977846.2 | BU19: =AV19-BB19-BC19+BD19-BE19-BL19-BM19-BN19-BO19-BP19-BQ19-BR19+BS19-BT19 -> 1641789.8 | BW19: 11000000 | BX19: 0 | BY19: 0 | BZ19: 200000 | CA19: =+BW19*5% -> 550000 | CB19: =SUM(BW19:CA19) -> 11750000
A20: =IF(B20=0,"",COUNTA($B$15:(B20))) -> 6 | B20: 2406145 | C20: Nguyễn Ngọc Thủy Tiên | D20: Ban nhân sự | E20: TV | F20: LT | G20: 6340000 | H20: =+IF(OR(CC20="ĐT PCCC",CC20="ĐP PCCC"),780000,IF(CC20="AT-VSV",300000,0)) -> 780000 | I20: =CB20-BZ20-G20-H20 -> 17030000 | J20: 1 | K20: 26 | L20: 0 | M20: 0 | N20: 0 | O20: 0 | P20: 0 | Q20: 0 | R20: 0 | S20: 0 | U20: 0 | V20: 0 | W20: 0 | X20: 0 | Y20: =G20*(K20+L20)/26 -> 6340000 | Z20: =M20*G20/26 -> 0 | AA20: =G20*N20/26 -> 0 | AB20: =G20*O20/26 -> 0 | AC20: =G20*P20*150%/26 -> 0 | AD20: =G20*Q20/26*200% -> 0 | AE20: =G20*R20/26*300% -> 0 | AF20: =ROUND((G20+H20)/26*S20*30%,0) -> 0 | AG20: =T20*G20/26/8 -> 0 | AH20: =CB20/26*U20 -> 0 | AI20: =G20*V20/26 -> 0 | AK20: =BZ20*L20/26 -> 0 | AM20: =X20*CD20 -> 0 | AN20: =H20/26*K20 -> 780000 | AO20: =IF(F20="LN",I20*(K20+L20)/26+(H20+I20)*50%*M20/26+MAX($G20*P20/26*150%,P20*$BW20/26)-AC20+MAX($G20*Q20/26*200%,Q20*$BW20/26)-AD20+MAX($G20*R20/26*300%,R20*$BW20/26)-AE20+BW20*S20/26-AF20+AH20-AG20,I20-I20*($CF$3-K20-L20)/26+(H20+I20)*50%*M20/26+BW20*O20/26-AB20+MAX($G20*P20/26*150%,P20*$BW20/26)-AC20+MAX($G20*Q20/26*200%,Q20*$BW20/26)-AD20+MAX($G20*R20/26*300%,R20*$BW20/26)-AE20+BW20*S20/26-AF20+AH20-AG20+(G20-G20*($CF$3-K20-L20)/26-Y20)+(H20-H20*($CF$3-K20-L20)/26-AN20)) -> 17030000 | AR20: 720000 | AV20: =Y20+Z20+AA20+AB20+AC20+AD20+AE20+AF20+AG20+AI20+AJ20+AK20+AL20+AM20+AN20+AO20+AP20-AQ20+AR20+AS20+AT20+AU20 -> 24870000 | AX20: =IF(E20="CT","x",0) -> 0 | AY20: =ROUND(IF($AX20="x",($G20+$H20)*AY$11,0),0) -> 0 | AZ20: =ROUND(IF($AX20="x",($G20+$H20)*AZ$11,0),0) -> 0 | BA20: =ROUND(IF($AX20="x",($G20+$H20)*BA$11,0),0) -> 0 | BB20: =SUM(AY20:BA20) -> 0 | BE20: =IF(G20*1%>=234000,234000,G20*1%) -> 63400 | BF20: =AM20+IF(E20="CT",IF(AR20>=730000,730000,AR20),0)+IF(((AV20-AM20-IF(AR20>=730000,730000,AR20)-AS20)*15%-AS20)>"0",((AV20-AM20-IF(AR20>=730000,730000,AR20)-AS20)*15%-AS20),0) -> 0 | BG20: =AV20-BF20+AW20 -> 24870000 | BI20: 4400000 | BJ20: =IF(E20="CT",11000000,0) -> 0 | BK20: =BG20-BB20-BC20+BD20-BH20*BI20-BJ20 -> 24870000 | BL20: =IF(E20="TV",BK20*10%,IF(BK20>0,ROUND(IF(BK20>=80000000,BK20*35%-9850000,IF(BK20>=52000000,BK20*30%-5850000,IF(BK20>=32000000,BK20*25%-3250000,IF(BK20>=18000000,BK20*20%-1650000,IF(BK20>=10000000,BK20*15%-750000,IF(BK20>5000000,BK20*10%-250000,BK20*5%)))))),0),0)) -> 2487000 | BO20: 0 | BT20: =SUMIFS('Bảng lương tạm ứng kỳ 1'!BT:BT,'Bảng lương CB-NV'!B:B,'Bảng lương tạm ứng kỳ 1'!B20) -> 10195308 | BU20: =AV20-BB20-BC20+BD20-BE20-BL20-BM20-BN20-BO20-BP20-BQ20-BR20+BS20-BT20 -> 12124292 | BW20: 23000000 | BX20: 0 | BY20: 0 | BZ20: 200000 | CA20: =+BW20*5% -> 1150000 | CB20: =SUM(BW20:CA20) -> 24350000 | CC20: ĐP PCCC
A21: =IF(B21=0,"",COUNTA($B$15:(B21))) -> 7 | B21: 2006324 | C21: Nguyễn Hồng Nhung | D21: Ban Chuyển đổi số | E21: CT | F21: LT | G21: 6340000 | H21: =+IF(OR(CC21="ĐT PCCC",CC21="ĐP PCCC"),780000,IF(CC21="AT-VSV",300000,0)) -> 300000 | I21: =CB21-BZ21-G21-H21 -> 11210000 | J21: 1 | K21: 26 | L21: 0 | M21: 0 | N21: 0 | O21: 0 | P21: 5 | Q21: 2 | R21: 0 | S21: 0 | U21: 0 | V21: 0 | W21: 0 | X21: 0 | Y21: =G21*(K21+L21)/26 -> 6340000 | Z21: =M21*G21/26 -> 0 | AA21: =G21*N21/26 -> 0 | AB21: =G21*O21/26 -> 0 | AC21: =G21*P21*150%/26 -> 1828846.2 | AD21: =G21*Q21/26*200% -> 975384.62 | AE21: =G21*R21/26*300% -> 0 | AF21: =IF(F21="LN",(G21+H21)/26*S21*30%,0) -> 0 | AG21: =T21*G21/26/8 -> 0 | AH21: =CB21/26*U21 -> 0 | AI21: =G21*V21/26 -> 0 | AK21: =BZ21*L21/26 -> 0 | AM21: =X21*CD21 -> 0 | AN21: =H21/26*K21 -> 300000 | AO21: =IF(F21="LN",I21*(K21+L21)/26+(H21+I21)*50%*M21/26+MAX($G21*P21/26*150%,P21*$BW21/26)-AC21+MAX($G21*Q21/26*200%,Q21*$BW21/26)-AD21+MAX($G21*R21/26*300%,R21*$BW21/26)-AE21+BW21*S21/26-AF21+AH21-AG21,I21-I21*($CF$3-K21-L21)/26+(H21+I21)*50%*M21/26+BW21*O21/26-AB21+MAX($G21*P21/26*150%,P21*$BW21/26)-AC21+MAX($G21*Q21/26*200%,Q21*$BW21/26)-AD21+MAX($G21*R21/26*300%,R21*$BW21/26)-AE21+BW21*S21/26-AF21+AH21-AG21+(G21-G21*($CF$3-K21-L21)/26-Y21)+(H21-H21*($CF$3-K21-L21)/26-AN21)) -> 12982692 | AR21: 560000 | AV21: =Y21+Z21+AA21+AB21+AC21+AD21+AE21+AF21+AG21+AI21+AJ21+AK21+AL21+AM21+AN21+AO21+AP21-AQ21+AR21+AS21+AT21+AU21 -> 22986923 | AX21: =IF(E21="CT","x",0) -> x | AY21: =ROUND(IF($AX21="x",($G21+$H21)*AY$11,0),0) -> 531200 | AZ21: =ROUND(IF($AX21="x",($G21+$H21)*AZ$11,0),0) -> 99600 | BA21: =ROUND(IF($AX21="x",($G21+$H21)*BA$11,0),0) -> 66400 | BB21: =SUM(AY21:BA21) -> 697200 | BE21: =IF(G21*1%>=234000,234000,G21*1%) -> 63400 | BF21: =AM21+IF(E21="CT",IF(AR21>=730000,730000,AR21),0)+IF(((AV21-AM21-IF(AR21>=730000,730000,AR21)-AS21)*15%-AS21)>"0",((AV21-AM21-IF(AR21>=730000,730000,AR21)-AS21)*15%-AS21),0) -> 560000 | BG21: =AV21-BF21+AW21 -> 22426923 | BI21: 4400000 | BJ21: =IF(E21="CT",11000000,0) -> 11000000 | BK21: =BG21-BB21-BC21+BD21-BH21*BI21-BJ21 -> 10729723 | BL21: =IF(E21="TV",BK21*10%,IF(BK21>0,ROUND(IF(BK21>=80000000,BK21*35%-9850000,IF(BK21>=52000000,BK21*30%-5850000,IF(BK21>=32000000,BK21*25%-3250000,IF(BK21>=18000000,BK21*20%-1650000,IF(BK21>=10000000,BK21*15%-750000,IF(BK21>5000000,BK21*10%-250000,BK21*5%)))))),0),0)) -> 859458 | BO21: 0 | BT21: =SUMIFS('Bảng lương tạm ứng kỳ 1'!BT:BT,'Bảng lương CB-NV'!B:B,'Bảng lương tạm ứng kỳ 1'!B21) -> 9977846.2 | BU21: =AV21-BB21-BC21+BD21-BE21-BL21-BM21-BN21-BO21-BP21-BQ21-BR21+BS21-BT21 -> 11389019 | BW21: 17000000 | BX21: 0 | BY21: 0 | BZ21: 200000 | CA21: =+BW21*5% -> 850000 | CB21: =SUM(BW21:CA21) -> 18050000 | CC21: AT-VSV

Sheet Mô tả Bảng lương CB-NV
A1: CÔNG TY …..............
A2: ĐC:…...........
A3: ="BẢNG THANH TOÁN TIỀN LƯƠNG THÁNG …."&" NĂM "&YEAR(NOW()) -> BẢNG THANH TOÁN TIỀN LƯƠNG THÁNG …. NĂM 2026 | BW3: THỐNG KÊ LƯƠNG | CE3: Ngày công thực tế tháng | CF3: 26
A5: TT | B5: MSNV | C5: Họ và tên | D5: Đơn vị | E5: Loại HĐLĐ | F5: Đối tượng được tính làm thêm giờ | G5: Mức lương HĐLĐ | H5: Phụ cấp (PCCC, ATVSV) | I5: Định mức Thưởng HQCV | J5: Tỷ lệ % tạm ứng thưởng HQCV | K5: Ngày công trong tháng | Y5: Các khoản được hưởng trong tháng | AP5: Truy lãnh lương | AQ5: Truy thu lương | AR5: Hỗ trợ cơm | AS5: Hỗ trợ Nhà ở | AT5: Thưởng năm | AU5: Chi trả phép năm chưa sử dụng | AV5: Tổng thu nhập | AW5: Thu nhập chịu thuế khác | AX5: Tham gia BHXH | AY5: Các khoản trừ | BR5: Quyết toán thuế | BT5: Thực nhận kỳ 1 | BU5: Thực nhận kỳ 2 | BW5: Ngạch lương | BX5: Các khoản được hưởng | CB5: Tổng lương và các khoản PC khác | CC5: Là ĐT, ĐP PCCC, AT-VSV | CD5: Mức Bồi dưỡng sức khỏe
K6: Công đi làm ngày thường | L6: Công tác | M6: Phép năm | N6: Nghỉ chế độ | O6: Nghỉ Lễ/Tết | P6: Tăng ca ngày thường | Q6: Tăng ca ngày chủ nhật | R6: Tăng ca Lễ tết | S6: Công phụ cấp ban đêm | T6: Giờ công nữ nghỉ HK | U6: Làm việc ngày T7 được nghỉ | V6: Ngày ngừng việc trong tháng | X6: Ngày công PHSK | Y6: Lương Ngày thường | Z6: Lương ngày nghỉ phép | AA6: Lương ngày nghỉ chế độ | AB6: Lương ngày nghỉ Lễ Tết | AC6: Lương Tăng ca ngày thường | AD6: Lương tăng ca ngày nghỉ | AE6: Lương tăng ca ngày Lễ/Tết | AF6: Lương phụ cấp ban đêm | AG6: Lương nữ nghỉ HK | AH6: Lương làm việc ngày T7 được nghỉ | AI6: Lương ngày tạm ngừng việc | AJ6: Lương trực hỗ trợ bảo vệ | AK6: Phụ cấp công tác | AL6: Phép năm nghỉ việc | AM6: Bồi dưỡng PHSK | AN6: Phụ cấp PCCC (ĐT, ĐP), Phụ cấp AT-VSV | AO6: Tạm ứng thưởng HQCV | AY6: Các khoản trích nộp | BM6: Các khoản thu hộ/thu khác | BR6: Truy thu theo QTT | BS6: Hoàn trả theo QTT
AY7: BHXH | AZ7: BHYT | BA7: BHTN | BB7: TỔng BHXH | BC7: Truy thu BHXH | BD7: Hoàn trả BHXH | BE7: Phí công đoàn | BF7: TN miễn thuế | BG7: Thu nhập chịu thuế | BH7: NPT | BI7: Giảm trừ NPT | BJ7: Giảm trừ cá nhân | BK7: TNTT | BL7: Thuế TNCN | BM7: Thu tiền tạm ứng | BN7: Thu hộ cho Cty Đầu tư tiền KBT…, | BO7: Thu tiền điện thoại vượt mức | BP7: Tiền phúng điếu | BQ7: …..............
V8: 14 ngày đầu | W8: Từ ngày 15 trở đi | AY8: 8% | AZ8: 1.5% | BA8: 1% | BX8: PC chức danh | BY8: PC kiêm nhiệm | BZ8: PC Biệt phái | CA8: PC thâm niên
A9: 1 | B9: =A9+1 -> 2 | C9: =B9+1 -> 3 | D9: =C9+1 -> 4 | F9: =D9+1 -> 5 | G9: =F9+1 -> 6 | H9: =G9+1 -> 7 | I9: =H9+1 -> 8 | J9: =I9+1 -> 9 | K9: =J9+1 -> 10 | L9: =K9+1 -> 11 | M9: =L9+1 -> 12 | N9: =M9+1 -> 13 | ... AV9: =AU9+1 -> 47 | AY9: =AV9+1 -> 48 | AZ9: =AY9+1 -> 49 | BA9: =AZ9+1 -> 50 | BB9: =BA9+1 -> 51 | BC9: =BB9+1 -> 52 | BD9: =BC9+1 -> 53 | BE9: =BD9+1 -> 54 | BL9: =BE9+1 -> 55 | BM9: =BL9+1 -> 56 | BN9: =BM9+1 -> 57 | BO9: =BN9+1 -> 58 | BP9: =BO9+1 -> 59 | BQ9: =BP9+1 -> 60 | BR9: =BQ9+1 -> 61 | BS9: =BR9+1 -> 62 | BT9: =BS9+1 -> 63 | BU9: =BT9+1 -> 64 | BW9: 65 | BX9: =BW9+1 -> 66 | BY9: =BX9+1 -> 67 | BZ9: =BY9+1 -> 68 | CA9: =BZ9+1 -> 69 | CB9: =CA9+1 -> 70 | CC9: =CB9+1 -> 71 | CD9: =CC9+1 -> 72
A10: IN | B10: IN | C10: IN | G10: IN | H10: IN | I10: IN
G11: =SUM(G12:G14) -> 23500000 | H11: =SUM(H12:H14) -> 1860000 | I11: =SUM(I12:I14) -> 76640000 | K11: =SUM(K12:K14) -> 81 | R11: =SUM(R12:R14) -> 0 | S11: =SUM(S12:S14) -> 0 | U11: =SUM(U12:U14) -> 0 | V11: =SUM(V12:V14) -> 0 | W11: =SUM(W12:W14) -> 0 | X11: =SUM(X12:X14) -> 0 | Y11: =SUM(Y12:Y14) -> 24403846 | AC11: =SUM(AC12:AC14) -> 0 | AD11: =SUM(AD12:AD14) -> 0 | AF11: =SUM(AF12:AF14) -> 0 | AG11: =SUM(AG12:AG14) -> 0 | AH11: =SUM(AH12:AH14) -> 0 | AI11: =SUM(AI12:AI14) -> 0 | AJ11: =SUM(AJ12:AJ14) -> 0 | AK11: =SUM(AK12:AK14) -> 0 | AL11: =SUM(AL12:AL14) -> 0 | AM11: =SUM(AM12:AM14) -> 0 | ... AO11: =SUM(AO12:AO14) -> 79899231 | AV11: =SUM(AV12:AV14) -> 1.0748308e+08 | AY11: =SUM(AY12:AY14) -> 1204800 | AZ11: =SUM(AZ12:AZ14) -> 225900 | BA11: =SUM(BA12:BA14) -> 150600 | BB11: =SUM(BB12:BB14) -> 1581300 | BC11: =SUM(BC12:BC14) -> 0 | BE11: =SUM(BE12:BE14) -> 235000 | BL11: =SUM(BL12:BL14) -> 6662827.2 | BM11: =SUM(BM12:BM14) -> 0 | BN11: =SUM(BN12:BN14) -> 0 | BO11: =SUM(BO12:BO14) -> 0 | BP11: =SUM(BP12:BP14) -> 0 | BQ11: =SUM(BQ12:BQ14) -> 0 | BT11: =SUM(BT12:BT14) -> 0 | BU11: =SUM(BU12:BU14) -> 99003950
A12: =IF(B12=0,"",COUNTA($B$12:(B12))) -> 1 | B12: 123456 | C12: Nguyễn Văn A | D12: Ban… | E12: TV | F12: LT | G12: 9520000 | H12: =+IF(OR(CC12="ĐT PCCC",CC12="ĐP PCCC"),780000,IF(CC12="AT-VSV",300000,0)) -> 780000 | I12: =CB12-BZ12-G12-H12 -> 49700000 | J12: 1 | K12: 27 | R12: 0 | S12: 0 | U12: 0 | V12: 0 | W12: 0 | X12: 0 | Y12: =G12*(K12+L12)/26 -> 9886153.8 | Z12: =M12*G12/26 -> 0 | AA12: =G12*N12/26 -> 0 | AB12: =G12*O12/26 -> 0 | AC12: =G12*P12*150%/26 -> 0 | AD12: =G12*Q12/26*200% -> 0 | AE12: =G12*R12/26*300% -> 0 | AF12: =ROUND((G12+H12)/26*S12*30%,0) -> 0 | AG12: =T12*G12/26/8 -> 0 | AH12: =CB12/26*U12 -> 0 | AI12: =G12*V12/26 -> 0 | AK12: =BZ12*L12/26 -> 0 | AM12: =X12*CD12 -> 0 | AN12: =H12/26*(K12+L12) -> 810000 | AO12: =IF(F12="LN",I12*(K12+L12)/26+(H12+I12)*50%*M12/26+MAX($G12*P12/26*150%,P12*$BW12/26)-AC12+MAX($G12*Q12/26*200%,Q12*$BW12/26)-AD12+MAX($G12*R12/26*300%,R12*$BW12/26)-AE12+BW12*S12/26-AF12+AH12-AG12,I12-I12*($CF$3-K12-L12)/26+(H12+I12)*50%*M12/26+BW12*O12/26-AB12+MAX($G12*P12/26*150%,P12*$BW12/26)-AC12+MAX($G12*Q12/26*200%,Q12*$BW12/26)-AD12+MAX($G12*R12/26*300%,R12*$BW12/26)-AE12+BW12*S12/26-AF12+AH12-AG12+(G12-G12*($CF$3-K12-L12)/26-Y12)+(H12-H12*($CF$3-K12-L12)/26-AN12)) -> 51611538 | AR12: 780000 | AV12: =Y12+Z12+AA12+AB12+AC12+AD12+AE12+AF12+AG12+AI12+AJ12+AK12+AL12+AM12+AN12+AO12+AP12-AQ12+AR12+AS12+AT12+AU12 -> 63087692 | AX12: =IF(E12="CT","x",0) -> 0 | AY12: =ROUND(IF($AX12="x",($G12+$H12)*AY$8,0),0) -> 0 | AZ12: =ROUND(IF($AX12="x",($G12+$H12)*AZ$8,0),0) -> 0 | BA12: =ROUND(IF($AX12="x",($G12+$H12)*BA$8,0),0) -> 0 | BB12: =SUM(AY12:BA12) -> 0 | BE12: =IF(G12*1%>=234000,234000,G12*1%) -> 95200 | BF12: =AM12+IF(E12="CT",IF(AR12>=730000,730000,AR12),0)+IF(((AV12-AM12-IF(AR12>=730000,730000,AR12)-AS12)*15%-AS12)>"0",((AV12-AM12-IF(AR12>=730000,730000,AR12)-AS12)*15%-AS12),0) -> 0 | BG12: =AV12-BF12+AW12 -> 63087692 | BH12: 3 | BI12: 4400000 | BJ12: =IF(E12="CT",11000000,0) -> 0 | BK12: =BG12-BB12-BC12+BD12-BH12*BI12-BJ12 -> 49887692 | BL12: =IF(E12="TV",BK12*10%,IF(BK12>0,ROUND(IF(BK12>=80000000,BK12*35%-9850000,IF(BK12>=52000000,BK12*30%-5850000,IF(BK12>=32000000,BK12*25%-3250000,IF(BK12>=18000000,BK12*20%-1650000,IF(BK12>=10000000,BK12*15%-750000,IF(BK12>5000000,BK12*10%-250000,BK12*5%)))))),0),0)) -> 4988769.2 | BO12: 0 | BT12: =SUMIFS('Bảng lương tạm ứng kỳ 1'!BT:BT,'Mô tả Bảng lương CB-NV'!B:B,'Bảng lương tạm ứng kỳ 1'!B15) -> 0 | BU12: =AV12-BB12-BC12+BD12-BE12-BL12-BM12-BN12-BO12-BP12-BQ12-BR12+BS12-BT12 -> 58003723 | BW12: 60000000 | BX12: 0 | CA12: 0 | CB12: =SUM(BW12:CA12) -> 60000000 | CC12: ĐT PCCC
A13: =IF(B13=0,"",COUNTA($B$12:(B13))) -> 2 | B13: 3562789 | C13: Nguyễn Văn C | D13: Ban… | E13: CT | F13: LT | G13: 6990000 | H13: =+IF(OR(CC13="ĐT PCCC",CC13="ĐP PCCC"),780000,IF(CC13="AT-VSV",300000,0)) -> 780000 | I13: =CB13-BZ13-G13-H13 -> 16380000 | J13: 1 | K13: 27 | M13: 0 | R13: 0 | S13: 0 | U13: 0 | V13: 0 | W13: 0 | X13: 0 | Y13: =G13*(K13+L13)/26 -> 7258846.2 | Z13: =M13*G13/26 -> 0 | AA13: =G13*N13/26 -> 0 | AB13: =G13*O13/26 -> 0 | AC13: =G13*P13*150%/26 -> 0 | AD13: =G13*Q13/26*200% -> 0 | AE13: =G13*R13/26*300% -> 0 | AF13: =ROUND((G13+H13)/26*S13*30%,0) -> 0 | AG13: =T13*G13/26/8 -> 0 | AH13: =CB13/26*U13 -> 0 | AI13: =G13*V13/26 -> 0 | AK13: =BZ13*L13/26 -> 0 | AM13: =X13*CD13 -> 0 | AN13: =H13/26*K13 -> 810000 | AO13: =IF(F13="LN",I13*(K13+L13)/26+(H13+I13)*50%*M13/26+MAX($G13*P13/26*150%,P13*$BW13/26)-AC13+MAX($G13*Q13/26*200%,Q13*$BW13/26)-AD13+MAX($G13*R13/26*300%,R13*$BW13/26)-AE13+BW13*S13/26-AF13+AH13-AG13,I13-I13*($CF$3-K13-L13)/26+(H13+I13)*50%*M13/26+BW13*O13/26-AB13+MAX($G13*P13/26*150%,P13*$BW13/26)-AC13+MAX($G13*Q13/26*200%,Q13*$BW13/26)-AD13+MAX($G13*R13/26*300%,R13*$BW13/26)-AE13+BW13*S13/26-AF13+AH13-AG13+(G13-G13*($CF$3-K13-L13)/26-Y13)+(H13-H13*($CF$3-K13-L13)/26-AN13)) -> 17010000 | AR13: 780000 | AV13: =Y13+Z13+AA13+AB13+AC13+AD13+AE13+AF13+AG13+AI13+AJ13+AK13+AL13+AM13+AN13+AO13+AP13-AQ13+AR13+AS13+AT13+AU13 -> 25858846 | AX13: =IF(E13="CT","x",0) -> x | AY13: =ROUND(IF($AX13="x",($G13+$H13)*AY$8,0),0) -> 621600 | AZ13: =ROUND(IF($AX13="x",($G13+$H13)*AZ$8,0),0) -> 116550 | BA13: =ROUND(IF($AX13="x",($G13+$H13)*BA$8,0),0) -> 77700 | BB13: =SUM(AY13:BA13) -> 815850 | BE13: =IF(G13*1%>=234000,234000,G13*1%) -> 69900 | BF13: =AM13+IF(E13="CT",IF(AR13>=730000,730000,AR13),0)+IF(((AV13-AM13-IF(AR13>=730000,730000,AR13)-AS13)*15%-AS13)>"0",((AV13-AM13-IF(AR13>=730000,730000,AR13)-AS13)*15%-AS13),0) -> 730000 | BG13: =AV13-BF13+AW13 -> 25128846 | BI13: 4400000 | BJ13: =IF(E13="CT",11000000,0) -> 11000000 | BK13: =BG13-BB13-BC13+BD13-BH13*BI13-BJ13 -> 13312996 | BL13: =IF(E13="TV",BK13*10%,IF(BK13>0,ROUND(IF(BK13>=80000000,BK13*35%-9850000,IF(BK13>=52000000,BK13*30%-5850000,IF(BK13>=32000000,BK13*25%-3250000,IF(BK13>=18000000,BK13*20%-1650000,IF(BK13>=10000000,BK13*15%-750000,IF(BK13>5000000,BK13*10%-250000,BK13*5%)))))),0),0)) -> 1246949 | BO13: 0 | BT13: =SUMIFS('Bảng lương tạm ứng kỳ 1'!BT:BT,'Mô tả Bảng lương CB-NV'!B:B,'Bảng lương tạm ứng kỳ 1'!B20) -> 0 | BU13: =AV13-BB13-BC13+BD13-BE13-BL13-BM13-BN13-BO13-BP13-BQ13-BR13+BS13-BT13 -> 23726147 | BW13: 23000000 | BX13: 0 | BY13: 0 | CA13: =+BW13*5% -> 1150000 | CB13: =SUM(BW13:CA13) -> 24150000 | CC13: ĐP PCCC
A14: =IF(B14=0,"",COUNTA($B$12:(B14))) -> 3 | B14: 789123 | C14: Nguyễn Thị B | D14: Ban… | E14: CT | F14: LT | G14: 6990000 | H14: =+IF(OR(CC14="ĐT PCCC",CC14="ĐP PCCC"),780000,IF(CC14="AT-VSV",300000,0)) -> 300000 | I14: =CB14-BZ14-G14-H14 -> 10560000 | J14: 1 | K14: 27 | R14: 0 | S14: 0 | U14: 0 | V14: 0 | W14: 0 | X14: 0 | Y14: =G14*(K14+L14)/26 -> 7258846.2 | Z14: =M14*G14/26 -> 0 | AA14: =G14*N14/26 -> 0 | AB14: =G14*O14/26 -> 0 | AC14: =G14*P14*150%/26 -> 0 | AD14: =G14*Q14/26*200% -> 0 | AE14: =G14*R14/26*300% -> 0 | AF14: =IF(F14="LN",(G14+H14)/26*S14*30%,0) -> 0 | AG14: =T14*G14/26/8 -> 0 | AH14: =CB14/26*U14 -> 0 | AI14: =G14*V14/26 -> 0 | AK14: =BZ14*L14/26 -> 0 | AM14: =X14*CD14 -> 0 | AO14: =IF(F14="LN",I14*(K14+L14)/26+(H14+I14)*50%*M14/26+MAX($G14*P14/26*150%,P14*$BW14/26)-AC14+MAX($G14*Q14/26*200%,Q14*$BW14/26)-AD14+MAX($G14*R14/26*300%,R14*$BW14/26)-AE14+BW14*S14/26-AF14+AH14-AG14,I14-I14*($CF$3-K14-L14)/26+(H14+I14)*50%*M14/26+BW14*O14/26-AB14+MAX($G14*P14/26*150%,P14*$BW14/26)-AC14+MAX($G14*Q14/26*200%,Q14*$BW14/26)-AD14+MAX($G14*R14/26*300%,R14*$BW14/26)-AE14+BW14*S14/26-AF14+AH14-AG14+(G14-G14*($CF$3-K14-L14)/26-Y14)+(H14-H14*($CF$3-K14-L14)/26-AN14)) -> 11277692 | AV14: =Y14+Z14+AA14+AB14+AC14+AD14+AE14+AF14+AG14+AI14+AJ14+AK14+AL14+AM14+AN14+AO14+AP14-AQ14+AR14+AS14+AT14+AU14 -> 18536538 | AX14: =IF(E14="CT","x",0) -> x | AY14: =ROUND(IF($AX14="x",($G14+$H14)*AY$8,0),0) -> 583200 | AZ14: =ROUND(IF($AX14="x",($G14+$H14)*AZ$8,0),0) -> 109350 | BA14: =ROUND(IF($AX14="x",($G14+$H14)*BA$8,0),0) -> 72900 | BB14: =SUM(AY14:BA14) -> 765450 | BE14: =IF(G14*1%>=234000,234000,G14*1%) -> 69900 | BF14: =AM14+IF(E14="CT",IF(AR14>=730000,730000,AR14),0)+IF(((AV14-AM14-IF(AR14>=730000,730000,AR14)-AS14)*15%-AS14)>"0",((AV14-AM14-IF(AR14>=730000,730000,AR14)-AS14)*15%-AS14),0) -> 0 | BG14: =AV14-BF14+AW14 -> 18536538 | BI14: 4400000 | BJ14: =IF(E14="CT",11000000,0) -> 11000000 | BK14: =BG14-BB14-BC14+BD14-BH14*BI14-BJ14 -> 6771088.5 | BL14: =IF(E14="TV",BK14*10%,IF(BK14>0,ROUND(IF(BK14>=80000000,BK14*35%-9850000,IF(BK14>=52000000,BK14*30%-5850000,IF(BK14>=32000000,BK14*25%-3250000,IF(BK14>=18000000,BK14*20%-1650000,IF(BK14>=10000000,BK14*15%-750000,IF(BK14>5000000,BK14*10%-250000,BK14*5%)))))),0),0)) -> 427109 | BO14: 0 | BT14: =SUMIFS('Bảng lương tạm ứng kỳ 1'!BT:BT,'Mô tả Bảng lương CB-NV'!B:B,'Bảng lương tạm ứng kỳ 1'!B21) -> 0 | BU14: =AV14-BB14-BC14+BD14-BE14-BL14-BM14-BN14-BO14-BP14-BQ14-BR14+BS14-BT14 -> 17274079 | BW14: 17000000 | BX14: 0 | BY14: 0 | CA14: =+BW14*5% -> 850000 | CB14: =SUM(BW14:CA14) -> 17850000 | CC14: AT-VSV
A17: =A5&A6&A7&A8 -> TT | B17: =B5&B6&B7&B8 -> MSNV | C17: =C5&C6&C7&C8 -> Họ và tên | D17: =D5&D6&D7&D8 -> Đơn vị | E17: =E5&E6&E7&E8 -> Loại HĐLĐ | F17: =F5&F6&F7&F8 -> Đối tượng được tính làm thêm giờ | G17: =G5&G6&G7&G8 -> Mức lương HĐLĐ | H17: =H5&H6&H7&H8 -> Phụ cấp (PCCC, ATVSV) | ... X17: =X5&X6&X7&X8 -> Ngày công PHSK | Y17: =Y6 -> Lương Ngày thường | Z17: =Z6 -> Lương ngày nghỉ phép | AA17: =AA6 -> Lương ngày nghỉ chế độ | AB17: =AB6 -> Lương ngày nghỉ Lễ Tết | AC17: =AC6 -> Lương Tăng ca ngày thường | AD17: =AD6 -> Lương tăng ca ngày nghỉ | AE17: =AE6 -> Lương tăng ca ngày Lễ/Tết | AF17: =AF6 -> Lương phụ cấp ban đêm | ... AO17: =AO6 -> Tạm ứng thưởng HQCV | AP17: =AP5 -> Truy lãnh lương | AQ17: =AQ5 -> Truy thu lương | AR17: =AR5 -> Hỗ trợ cơm | AS17: =AS5 -> Hỗ trợ Nhà ở | AT17: =AT5 -> Thưởng năm | AU17: =AU5 -> Chi trả phép năm chưa sử dụng | AV17: =AV5 -> Tổng thu nhập | AW17: =AW5 -> Thu nhập chịu thuế khác | AX17: =AX5 -> Tham gia BHXH | AY17: =AY7 -> BHXH | AZ17: =AZ7 -> BHYT | BA17: =BA7 -> BHTN | BB17: =BB7 -> TỔng BHXH | BC17: =BC7 -> Truy thu BHXH | BD17: =BD7 -> Hoàn trả BHXH | BE17: =BE7 -> Phí công đoàn | BF17: =BF7 -> TN miễn thuế | ... BQ17: =BQ7 -> ….............. | BR17: =BR6 -> Truy thu theo QTT | BS17: =BS6 -> Hoàn trả theo QTT | BT17: =BT5 -> Thực nhận kỳ 1 | BU17: =BU5 -> Thực nhận kỳ 2 | BW17: =BW5 -> Ngạch lương | BX17: =BX8 -> PC chức danh | BY17: =BY8 -> PC kiêm nhiệm | BZ17: =BZ8 -> PC Biệt phái | CA17: =CA8 -> PC thâm niên | CB17: =CB5 -> Tổng lương và các khoản PC khác | CC17: =CC5 -> Là ĐT, ĐP PCCC, AT-VSV | CD17: =CD5 -> Mức Bồi dưỡng sức khỏe
A18: =SUBSTITUTE(ADDRESS(1,COLUMN(),4),1,"") -> A | B18: =SUBSTITUTE(ADDRESS(1,COLUMN(),4),1,"") -> B | C18: =SUBSTITUTE(ADDRESS(1,COLUMN(),4),1,"") -> C | D18: =SUBSTITUTE(ADDRESS(1,COLUMN(),4),1,"") -> D | E18: =SUBSTITUTE(ADDRESS(1,COLUMN(),4),1,"") -> E | F18: =SUBSTITUTE(ADDRESS(1,COLUMN(),4),1,"") -> F | G18: =SUBSTITUTE(ADDRESS(1,COLUMN(),4),1,"") -> G | H18: =SUBSTITUTE(ADDRESS(1,COLUMN(),4),1,"") -> H | ... BU18: =SUBSTITUTE(ADDRESS(1,COLUMN(),4),1,"") -> BU | BW18: =SUBSTITUTE(ADDRESS(1,COLUMN(),4),1,"") -> BW | BX18: =SUBSTITUTE(ADDRESS(1,COLUMN(),4),1,"") -> BX | BY18: =SUBSTITUTE(ADDRESS(1,COLUMN(),4),1,"") -> BY | BZ18: =SUBSTITUTE(ADDRESS(1,COLUMN(),4),1,"") -> BZ | CA18: =SUBSTITUTE(ADDRESS(1,COLUMN(),4),1,"") -> CA | CB18: =SUBSTITUTE(ADDRESS(1,COLUMN(),4),1,"") -> CB | CC18: =SUBSTITUTE(ADDRESS(1,COLUMN(),4),1,"") -> CC | CD18: =SUBSTITUTE(ADDRESS(1,COLUMN(),4),1,"") -> CD
A19: Số thứ tự | B19: Mã số nhân viên Lấy từ phần mềm HRM | C19: Tên nhân viên Lấy từ phần mềm HRM | D19: Phòng ban trực thuộc của nhân viên Lấy từ phần mềm HRM | E19: Loại hợp đồng hiệu lực mới nhất của nhân viên Lấy từ phần mềm HRM | F19: LT: Đối tượng hưởng lương tháng LN: Đối tượng hưởng lương ngày | G19: Mức lương hợp đồng hiệu lực mới nhất của nhân viên Lấy từ phần mềm HRM | H19: ="+IF(OR(["&CC17&"]=""ĐT PCCC"",["&CC17&"]=""ĐP PCCC""),780000,IF(["&CC17&"]=""AT-VSV"",300000,0))" -> +IF(OR([Là ĐT, ĐP PCCC, AT-VSV]="ĐT PCCC",[Là ĐT, ĐP PCCC, AT-VSV]="ĐP PCCC"),780000,IF([Là ĐT, ĐP PCCC, AT-VSV]="AT-VSV",300000,0)) | I19: ="["&CB17&"]-["&BZ17&"]-["&G17&"]-["&H17&"]" -> [Tổng lương và các khoản PC khác]-[PC Biệt phái]-[Mức lương HĐLĐ]-[ Phụ cấp (PCCC, ATVSV) ] | J19: Import, mặc định là 100% | K19: Số ngày công đi làm thực tế trong tháng Lấy từ phần mềm chấm công | L19: Số ngày đi công tác trong tháng Lấy từ phần mềm chấm công | M19: Số ngày nghỉ phép năm trong tháng Lấy từ phần mềm Chấm công | N19: Số ngày nghỉ phép năm trong tháng Lấy từ phần mềm Chấm công | O19: Số ngày nghỉ Lễ trong tháng Lấy từ phần mềm Chấm công | P19: Số giờ tăng ca (loại tăng ca ngày thường) trong tháng Lấy từ phần mềm Chấm công | Q19: Số giờ tăng ca (loại tăng ca ngày CN) trong tháng Lấy từ phần mềm Chấm công | R19: Số giờ tăng ca (loại tăng ca ngày Lễ) trong tháng Lấy từ phần mềm Chấm công | S19: Số ngày nghỉ phép năm trong tháng Lấy từ phần mềm Chấm công | U19: 0 | V19: 0 | W19: 0 | X19: 0 | Y19: ="["&G17&"]*(["&K17&"]+["&L17&"])/26" -> [Mức lương HĐLĐ]*([Ngày công trong thángCông đi làm ngày thường]+[Công tác])/26 | Z19: ="["&M17&"]*["&G17&"]/26" -> [Phép năm]*[Mức lương HĐLĐ]/26 | AA19: ="["&G17&"]*["&N17&"]/26" -> [Mức lương HĐLĐ]*[Nghỉ chế độ]/26 | AB19: ="["&G17&"]*["&O17&"]/26" -> [Mức lương HĐLĐ]*[Nghỉ Lễ/Tết]/26 | AC19: ="["&G17&"]*["&P17&"]*150%/26" -> [Mức lương HĐLĐ]*[Tăng ca ngày thường]*150%/26 | AD19: ="["&G17&"]*["&Q17&"]/26*200%" -> [Mức lương HĐLĐ]*[Tăng ca ngày chủ nhật]/26*200% | AE19: ="["&G17&"]*["&R17&"]/26*300%" -> [Mức lương HĐLĐ]*[Tăng ca Lễ tết]/26*300% | AF19: ="ROUND((["&G17&"]+["&H17&"])/26*["&S17&"]*30%,0)" -> ROUND(([Mức lương HĐLĐ]+[ Phụ cấp (PCCC, ATVSV) ])/26*[Công phụ cấp ban đêm]*30%,0) | AG19: ="["&T17&"]*["&G17&"]/26/8" -> [Giờ công nữ nghỉ HK]*[Mức lương HĐLĐ]/26/8 | AH19: ="["&CB17&"]/26*["&U17&"]" -> [Tổng lương và các khoản PC khác]/26*[Làm việc ngày T7 được nghỉ] | AI19: ="["&G17&"]*["&V17&"]/26" -> [Mức lương HĐLĐ]*[Ngày ngừng việc trong tháng14 ngày đầu]/26 | AK19: ="["&BZ17&"]*["&L17&"]/26" -> [PC Biệt phái]*[Công tác]/26 | AM19: ="["&X17&"]*["&CD17&"]" -> [Ngày công PHSK]*[Mức Bồi dưỡng sức khỏe] | AN19: ="["&H17&"]/26*(["&K17&"]+["&L17&"])" -> [ Phụ cấp (PCCC, ATVSV) ]/26*([Ngày công trong thángCông đi làm ngày thường]+[Công tác]) | AO19: ="IF(["&F17&"]=""LN"",["&I17&"]*(["&K17&"]+["&L17&"])/26+(["&H17&"]+["&I17&"])*50%*["&M17&"]/26+MAX(["&$G17&"]*["&P17&"]/26*150%,["&P17&"]*["&$BW17&"]/26)-["&AC17&"]+MAX(["&$G17&"]*["&Q17&"]/26*200%,["&Q17&"]*["&$BW17&"]/26)-["&AD17&"]+MAX(["&$G17&"]*["&R17&"]/26*300%,["&R17&"]*["&$BW17&"]/26)-["&AE17&"]+["&BW17&"]*["&S17&"]/26-["&AF17&"]+["&AH17&"]-["&AG17&"],["&I17&"]-["&I17&"]*(["&$CE$3&"]-["&K17&"]-["&L17&"])/26+(["&H17&"]+["&I17&"])*50%*["&M17&"]/26+["&BW17&"]*["&O17&"]/26-["&AB17&"]+MAX(["&$G17&"]*["&P17&"]/26*150%,["&P17&"]*["&$BW17&"]/26)-["&AC17&"]+MAX(["&$G17&"]*["&Q17&"]/26*200%,["&Q17&"]*["&$BW17&"]/26)-["&AD17&"]+MAX(["&$G17&"]*["&R17&"]/26*300%,["&R17&"]*["&$BW17&"]/26)-["&AE17&"]+["&BW17&"]*["&S17&"]/26-["&AF17&"]+["&AH17&"]-["&AG17&"]+(["&G17&"]-["&G17&"]*(["&$CE$3&"]-["&K17&"]-["&L17&"])/26-["&Y17&"])+(["&H17&"]-["&H17&"]*(["&$CE$3&"]-["&K17&"]-["&L17&"])/26-["&AN17&"]))" -> IF([Đối tượng được tính làm thêm giờ]="LN",[Định mức Thưởng HQCV]*([Ngày công trong thángCông đi làm ngày thường]+[Công tác])/26+([ Phụ cấp (PCCC, ATVSV) ]+[Định mức Thưởng HQCV])*50%*[Phép năm]/26+MAX([Mức lương HĐLĐ]*[Tăng ca ngày thường]/26*150%,[Tăng ca ngày thường]*[Ngạch lương]/26)-[Lương Tăng ca ngày thường]+MAX([Mức lương HĐLĐ]*[Tăng ca ngày chủ nhật]/26*200%,[Tăng ca ngày chủ nhật]*[Ngạch lương]/26)-[Lương tăng ca ngày nghỉ]+MAX([Mức lương HĐLĐ]*[Tăng ca Lễ tết]/26*300%,[Tăng ca Lễ tết]*[Ngạch lương]/26)-[Lương tăng ca ngày Lễ/Tết]+[Ngạch lương]*[Công phụ cấp ban đêm]/26-[Lương phụ cấp ban đêm]+[Lương làm việc ngày T7 được nghỉ]-[Lương nữ nghỉ HK],[Định mức Thưởng HQCV]-[Định mức Thưởng HQCV]*([Ngày công thực tế tháng ]-[Ngày công trong thángCông đi làm ngày thường]-[Công tác])/26+([ Phụ cấp (PCCC, ATVSV) ]+[Định mức Thưởng HQCV])*50%*[Phép năm]/26+[Ngạch lương]*[Nghỉ Lễ/Tết]/26-[Lương ngày nghỉ Lễ Tết]+MAX([Mức lương HĐLĐ]*[Tăng ca ngày thường]/26*150%,[Tăng ca ngày thường]*[Ngạch lương]/26)-[Lương Tăng ca ngày thường]+MAX([Mức lương HĐLĐ]*[Tăng ca ngày chủ nhật]/26*200%,[Tăng ca ngày chủ nhật]*[Ngạch lương]/26)-[Lương tăng ca ngày nghỉ]+MAX([Mức lương HĐLĐ]*[Tăng ca Lễ tết]/26*300%,[Tăng ca Lễ tết]*[Ngạch lương]/26)-[Lương tăng ca ngày Lễ/Tết]+[Ngạch lương]*[Công phụ cấp ban đêm]/26-[Lương phụ cấp ban đêm]+[Lương làm việc ngày T7 được nghỉ]-[Lương nữ nghỉ HK]+([Mức lương HĐLĐ]-[Mức lương HĐLĐ]*([Ngày công thực tế tháng ]-[Ngày công trong thángCông đi làm ngày thường]-[Công tác])/26-[Lương Ngày thường])+([ Phụ cấp (PCCC, ATVSV) ]-[ Phụ cấp (PCCC, ATVSV) ]*([Ngày công thực tế tháng ]-[Ngày công trong thángCông đi làm ngày thường]-[Công tác])/26-[Phụ cấp PCCC (ĐT, ĐP), Phụ cấp AT-VSV ])) | AR19: 780000 | AV19: ="["&Y17&"]+["&Z17&"]+["&AA17&"]+["&AB17&"]+["&AC17&"]+["&AD17&"]+["&AE17&"]+["&AF17&"]+["&AG17&"]+["&AI17&"]+["&AJ17&"]+["&AK17&"]+["&AL17&"]+["&AM17&"]+["&AN17&"]+["&AO17&"]+["&AP17&"]-["&AQ17&"]+["&AR17&"]+["&AS17&"]+["&AT17&"]+["&AU17&"]" -> [Lương Ngày thường]+[Lương ngày nghỉ phép]+[Lương ngày nghỉ chế độ]+[Lương ngày nghỉ Lễ Tết]+[Lương Tăng ca ngày thường]+[Lương tăng ca ngày nghỉ]+[Lương tăng ca ngày Lễ/Tết]+[Lương phụ cấp ban đêm]+[Lương nữ nghỉ HK]+[Lương ngày tạm ngừng việc]+[Lương trực hỗ trợ bảo vệ]+[Phụ cấp công tác]+[Phép năm nghỉ việc]+[Bồi dưỡng PHSK]+[Phụ cấp PCCC (ĐT, ĐP), Phụ cấp AT-VSV ]+[Tạm ứng thưởng HQCV]+[Truy lãnh lương]-[Truy thu lương]+[Hỗ trợ cơm]+[Hỗ trợ Nhà ở]+[Thưởng năm]+[Chi trả phép năm chưa sử dụng] | AX19: ="IF(["&E17&"]=""CT"",""x"",0)" -> IF([Loại HĐLĐ]="CT","x",0) | AY19: ="ROUND(IF(["&$AX17&"]=""x"",(["&$G17&"]+["&$H17&"])*["&AY$8&"],0),0)" -> ROUND(IF([Tham gia BHXH]="x",([Mức lương HĐLĐ]+[ Phụ cấp (PCCC, ATVSV) ])*[8%],0),0) | AZ19: ="ROUND(IF(["&$AX17&"]=""x"",(["&$G17&"]+["&$H17&"])*["&AZ$8&"],0),0)" -> ROUND(IF([Tham gia BHXH]="x",([Mức lương HĐLĐ]+[ Phụ cấp (PCCC, ATVSV) ])*[1.5%],0),0) | BA19: ="ROUND(IF(["&$AX17&"]=""x"",(["&$G17&"]+["&$H17&"])*["&BA$8&"],0),0)" -> ROUND(IF([Tham gia BHXH]="x",([Mức lương HĐLĐ]+[ Phụ cấp (PCCC, ATVSV) ])*[1%],0),0) | BB19: ="["&AY17&"]+["&AZ17&"]+["&BA17&"]" -> [BHXH]+[BHYT]+[BHTN] | BE19: ="IF(["&G17&"]*1%>=234000,234000,["&G17&"]*1%)" -> IF([Mức lương HĐLĐ]*1%>=234000,234000,[Mức lương HĐLĐ]*1%) | BF19: ="["&AM17&"]+IF(["&E17&"]=""CT"",IF(["&AR17&"]>=730000,730000,["&AR17&"]),0)+IF(((["&AV17&"]-["&AM17&"]-IF(["&AR17&"]>=730000,730000,["&AR17&"])-["&AS17&"])*15%-["&AS17&"])>""0"",((["&AV17&"]-["&AM17&"]-IF(["&AR17&"]>=730000,730000,["&AR17&"])-["&AS17&"])*15%-["&AS17&"]),0)" -> [Bồi dưỡng PHSK]+IF([Loại HĐLĐ]="CT",IF([Hỗ trợ cơm]>=730000,730000,[Hỗ trợ cơm]),0)+IF((([Tổng thu nhập]-[Bồi dưỡng PHSK]-IF([Hỗ trợ cơm]>=730000,730000,[Hỗ trợ cơm])-[Hỗ trợ Nhà ở])*15%-[Hỗ trợ Nhà ở])>"0",(([Tổng thu nhập]-[Bồi dưỡng PHSK]-IF([Hỗ trợ cơm]>=730000,730000,[Hỗ trợ cơm])-[Hỗ trợ Nhà ở])*15%-[Hỗ trợ Nhà ở]),0) | BG19: ="["&AV17&"]-["&BF17&"]+["&AW17&"]" -> [Tổng thu nhập]-[TN miễn thuế]+[Thu nhập chịu thuế khác] | BH19: 3 | BI19: 4400000 | BJ19: ="IF(["&E17&"]=""CT"",11000000,0)" -> IF([Loại HĐLĐ]="CT",11000000,0) | BK19: ="["&BG17&"]-["&BB17&"]-["&BC17&"]+["&BD17&"]-["&BH17&"]*["&BI17&"]-["&BJ17&"]" -> [Thu nhập chịu thuế]-[TỔng BHXH]-[Truy thu BHXH]+[Hoàn trả BHXH]-[NPT]*[Giảm trừ NPT]-[Giảm trừ cá nhân] | BL19: ="IF(["&E17&"]=""TV"",["&BK17&"]*10%,IF(["&BK17&"]>0,ROUND(IF(["&BK17&"]>=80000000,["&BK17&"]*35%-9850000,IF(["&BK17&"]>=52000000,["&BK17&"]*30%-5850000,IF(["&BK17&"]>=32000000,["&BK17&"]*25%-3250000,IF(["&BK17&"]>=18000000,["&BK17&"]*20%-1650000,IF(["&BK17&"]>=10000000,["&BK17&"]*15%-750000,IF(["&BK17&"]>5000000,["&BK17&"]*10%-250000,["&BK17&"]*5%)))))),0),0))" -> IF([Loại HĐLĐ]="TV",[TNTT]*10%,IF([TNTT]>0,ROUND(IF([TNTT]>=80000000,[TNTT]*35%-9850000,IF([TNTT]>=52000000,[TNTT]*30%-5850000,IF([TNTT]>=32000000,[TNTT]*25%-3250000,IF([TNTT]>=18000000,[TNTT]*20%-1650000,IF([TNTT]>=10000000,[TNTT]*15%-750000,IF([TNTT]>5000000,[TNTT]*10%-250000,[TNTT]*5%)))))),0),0)) | BO19: 0 | BT19: ="["&'Mô tả Bảng lương tạm ứng kỳ 1'!BT17&"]" -> [Thực nhận kỳ 1] | BU19: ="["&AV17&"]-["&BB17&"]-["&BC17&"]+["&BD17&"]-["&BE17&"]-["&BL17&"]-["&BM17&"]-["&BN17&"]-["&BO17&"]-["&BP17&"]-["&BQ17&"]-["&BR17&"]+["&BS17&"]-["&BT17&"]" -> [Tổng thu nhập]-[TỔng BHXH]-[Truy thu BHXH]+[Hoàn trả BHXH]-[Phí công đoàn]-[Thuế TNCN]-[Thu tiền tạm ứng]-[Thu hộ cho Cty Đầu tư tiền KBT…, ]-[Thu tiền điện thoại vượt mức]-[Tiền phúng điếu]-[…..............]-[Truy thu theo QTT]+[Hoàn trả theo QTT]-[Thực nhận kỳ 1] | BW19: 60000000 | BX19: 0 | CA19: 0 | CB19: ="["&BW17&"]+["&BX17&"]+["&BY17&"]+["&BZ17&"]+["&CA17&"]" -> [Ngạch lương]+[PC chức danh]+[PC kiêm nhiệm]+[PC Biệt phái]+[PC thâm niên] | CC19: ĐT PCCC

Sheet Bảng lương tạm ứng kỳ 1
A1: CÔNG TY …..............
A2: ĐC:…...........
A3: ="BẢNG THANH TOÁN TIỀN LƯƠNG THÁNG …."&" NĂM "&YEAR(NOW()) -> BẢNG THANH TOÁN TIỀN LƯƠNG THÁNG …. NĂM 2026 | BW3: THỐNG KÊ LƯƠNG | CE3: Ngày công thực tế tháng | CF3: 25
A8: TT | B8: MSNV | C8: Họ và tên | D8: Khối | E8: Loại HĐLĐ | F8: LN/LT | G8: Mức lương HĐLĐ | H8: Phụ cấp (PCCC, ATVSV) | I8: Định mức Thưởng HQCV | J8: Tỷ lệ % tạm ứng thưởng HQCV | K8: Ngày công trong tháng | Y8: Các khoản được hưởng trong tháng | AP8: Truy lãnh lương | AQ8: Truy thu lương | AR8: Hỗ trợ cơm | AS8: Hỗ trợ Nhà ở | AT8: Thưởng năm | AU8: Chi trả phép năm chưa sử dụng | AV8: Tổng thu nhập | AW8: Thu nhập chịu thuế khác | AX8: Tham gia BHXH | AY8: Các khoản trừ | BQ8: Quyết toán thuế | BS8: Tỷ lệ tạm ứng lương | BT8: Thực nhận kỳ 1 | BU8: Thực nhận kỳ 2 | BW8: Ngạch lương | BX8: Các khoản được hưởng | CB8: Tổng lương và các khoản PC khác | CC8: Là ĐT, ĐP PCCC, AT-VSV | CD8: Mức Bồi dưỡng sức khỏe
K9: Công đi làm ngày thường | L9: Công tác | M9: Phép năm | N9: Nghỉ chế độ | O9: Nghỉ Lễ/Tết | P9: Tăng ca ngày thường | Q9: Tăng ca ngày chủ nhật | R9: Tăng ca Lễ tết | S9: Công phụ cấp ban đêm | T9: Giờ công nữ nghỉ HK | U9: Làm việc ngày T7 được nghỉ | V9: Ngày ngừng việc trong tháng | X9: Ngày công PHSK | Y9: Lương Ngày thường | Z9: Lương ngày nghỉ phép | AA9: Lương ngày nghỉ chế độ | AB9: Lương ngày nghỉ Lễ Tết | AC9: Lương Tăng ca ngày thường | AD9: Lương chủ nhật | AE9: Lương tăng ca ngày Lễ/Tết | AF9: Lương phụ cấp ban đêm | AG9: Lương nữ nghỉ HK | AH9: Lương làm việc ngày T7 được nghỉ | AI9: Lương ngày tạm ngừng việc | AJ9: Lương trực hỗ trợ bảo vệ | AK9: Phụ cấp công tác | AL9: Phép năm nghỉ việc | AM9: Bồi dưỡng PHSK | AN9: Phụ cấp PCCC (ĐT, ĐP), Phụ cấp AT-VSV | AO9: Tạm ứng thưởng HQCV | AY9: Các khoản trích nộp | BK9: Các khoản thu hộ/thu khác | BQ9: Truy thu theo QTT | BR9: Hoàn trả theo QTT
AY10: BHXH | AZ10: BHYT | BA10: BHTN | BB10: TỔng BHXH | BC10: Truy thu BHXH | BD10: Hoàn trả BHXH | BE10: Phí công đoàn (Lương HĐLĐ *1%) | BF10: TN miễn thuế | BG10: Thu nhập chịu thuế | BH10: NPT | BI10: TNTT | BJ10: Thuế TNCN | BK10: Thu tiền tạm ứng | BL10: Thu hộ cho Cty Đầu tư tiền KBT…, | BM10: Thu tiền điện thoại vượt mức | BN10: Tiền phúng điếu | BO10: Tiền cơm | BP10: …..............
V11: 14 ngày đầu | W11: Từ ngày 15 trở đi | AY11: 8% | AZ11: 1.5% | BA11: 1% | BX11: PC chức danh | BY11: PC kiêm nhiệm | BZ11: PC Biệt phái | CA11: PC thâm niên
A12: 1 | B12: =A12+1 -> 2 | C12: =B12+1 -> 3 | D12: =C12+1 -> 4 | F12: =D12+1 -> 5 | G12: =F12+1 -> 6 | H12: =G12+1 -> 7 | I12: =H12+1 -> 8 | J12: =I12+1 -> 9 | K12: =J12+1 -> 10 | L12: =K12+1 -> 11 | M12: =L12+1 -> 12 | N12: =M12+1 -> 13 | ... AV12: =AU12+1 -> 47 | AY12: =AV12+1 -> 48 | AZ12: =AY12+1 -> 49 | BA12: =AZ12+1 -> 50 | BB12: =BA12+1 -> 51 | BC12: =BB12+1 -> 52 | BD12: =BC12+1 -> 53 | BE12: =BD12+1 -> 54 | BJ12: =BE12+1 -> 55 | BK12: =BJ12+1 -> 56 | BL12: =BK12+1 -> 57 | BM12: =BL12+1 -> 58 | BN12: =BM12+1 -> 59 | BP12: =BN12+1 -> 60 | BQ12: =BP12+1 -> 61 | BR12: =BQ12+1 -> 62 | BT12: =BR12+1 -> 63 | BU12: =BT12+1 -> 64 | BW12: 65 | BX12: =BW12+1 -> 66 | BY12: =BX12+1 -> 67 | BZ12: =BY12+1 -> 68 | CA12: =BZ12+1 -> 69 | CB12: =CA12+1 -> 70 | CC12: =CB12+1 -> 71 | CD12: =CC12+1 -> 72
A13: IN | B13: IN | C13: IN | G13: IN | H13: IN | I13: IN
G14: =SUM(G15:G21) -> 50340000 | H14: =SUM(H15:H21) -> 4020000 | I14: =SUM(I15:I21) -> 167340000 | K14: =SUM(K15:K21) -> 75.5 | R14: =SUM(R15:R21) -> 12 | S14: =SUM(S15:S21) -> 0 | U14: =SUM(U15:U21) -> 0 | V14: =SUM(V15:V21) -> 0 | W14: =SUM(W15:W21) -> 0 | X14: =SUM(X15:X21) -> 0 | Y14: =SUM(Y15:Y21) -> 20878269 | AC14: =SUM(AC15:AC21) -> 0 | AD14: =SUM(AD15:AD21) -> 0 | AF14: =SUM(AF15:AF21) -> 0 | AG14: =SUM(AG15:AG21) -> 0 | AH14: =SUM(AH15:AH21) -> 0 | AI14: =SUM(AI15:AI21) -> 0 | AJ14: =SUM(AJ15:AJ21) -> 0 | AK14: =SUM(AK15:AK21) -> 0 | AL14: =SUM(AL15:AL21) -> 0 | AM14: =SUM(AM15:AM21) -> 0 | ... AO14: =SUM(AO15:AO21) -> 92927596 | AV14: =SUM(AV15:AV21) -> 1.2852721e+08 | AY14: =SUM(AY15:AY21) -> 4348800 | AZ14: =SUM(AZ15:AZ21) -> 815400 | BA14: =SUM(BA15:BA21) -> 543600 | BB14: =SUM(BB15:BB21) -> 5707800 | BC14: =SUM(BC15:BC21) -> 0 | BE14: =SUM(BE15:BE21) -> 503400 | BJ14: =SUM(BJ15:BJ21) -> 4630005 | BK14: =SUM(BK15:BK21) -> 0 | BL14: =SUM(BL15:BL21) -> 0 | BM14: =SUM(BM15:BM21) -> 0 | BN14: =SUM(BN15:BN21) -> 0 | BP14: =SUM(BP15:BP21) -> 0 | BT14: =SUM(BT15:BT21) -> 1.0432138e+08 | BU14: =SUM(BU15:BU21) -> 0
A15: =IF(B15=0,"",COUNTA($B$15:(B15))) -> 1 | B15: 2405236 | C15: Tô Thanh Liêm | D15: Ban kế toán | E15: TV | F15: LT | G15: 9520000 | H15: =+IF(OR(CC15="ĐT PCCC",CC15="ĐP PCCC"),780000,IF(CC15="AT-VSV",300000,0)) -> 780000 | I15: =CB15-BZ15-G15-H15 -> 49700000 | J15: 1 | K15: 11 | O15: 2 | R15: 0 | S15: 0 | U15: 0 | V15: 0 | W15: 0 | X15: 0 | Y15: =G15*(K15+L15)/26 -> 4027692.3 | Z15: =M15*G15/26 -> 0 | AA15: =G15*N15/26 -> 0 | AB15: =G15*O15/26 -> 732307.69 | AC15: =G15*P15*150%/26 -> 0 | AD15: =G15*Q15/26*200% -> 0 | AE15: =G15*R15/26*300% -> 0 | AF15: =IF(F15="LT",0,(G15+H15)/26*S15*30%) -> 0 | AG15: =T15*G15/23/8 -> 0 | AH15: =CB15/26*U15 -> 0 | AI15: =G15*V15/26 -> 0 | AK15: =BZ15*L15/26 -> 0 | AM15: =X15*CD15 -> 0 | AN15: =H15/26*(K15+L15) -> 330000 | AO15: =IF(F15="LN",I15*(K15+L15)/26+(H15+I15)*50%*M15/26+IF(F15="LT",BW15*O15/26-AB15,0)+MAX($G15*P15/26*150%,P15*$BW15/26)-AC15+MAX($G15*Q15/26*200%,Q15*$BW15/26)-AD15+MAX($G15*R15/26*300%,R15*$BW15/26)-AE15+BW15*S15/26-AF15+AH15-AG15,I15-I15*($CF$3-K15-L15)/26+(H15+I15)*50%*M15/26+IF(F15="LT",BW15*O15/26-AB15,0)+MAX($G15*P15/26*150%,P15*$BW15/26)-AC15+MAX($G15*Q15/26*200%,Q15*$BW15/26)-AD15+MAX($G15*R15/26*300%,R15*$BW15/26)-AE15+BW15*S15/26-AF15+AH15-AG15+(G15-G15*($CF$3-K15-L15)/26-Y15)+(H15-H15*($CF$3-K15-L15)/26-AN15)) -> 27217692 | AV15: =Y15+Z15+AA15+AB15+AC15+AD15+AE15+AF15+AG15+AI15+AJ15+AK15+AL15+AM15+AN15+AO15+AP15-AQ15+AR15+AS15+AT15+AU15 -> 32307692 | AX15: x | AY15: =ROUND(IF($AX15="x",($G15+$H15)*AY$11,0),0) -> 824000 | AZ15: =ROUND(IF($AX15="x",($G15+$H15)*AZ$11,0),0) -> 154500 | BA15: =ROUND(IF($AX15="x",($G15+$H15)*BA$11,0),0) -> 103000 | BB15: =SUM(AY15:BA15) -> 1081500 | BE15: =IF(G15*1%>=234000,234000,G15*1%) -> 95200 | BF15: =AM15+IF(AR15>="730000",730000,AR15)+IF(((AV15-AM15-IF(AR15>="730000",730000,AR15)-AS15)*15%-AS15)>"0",((AV15-AM15-IF(AR15>="730000",730000,AR15)-AS15)*15%-AS15),0) -> 0 | BG15: =AV15-BF15+AW15 -> 32307692 | BH15: 3 | BI15: =BG15-BB15-BC15+BD15-BH15*4400000-IF(E15="CT",11000000,0) -> 18026192 | BJ15: =IF(BI15>0,ROUND(IF(BI15>=80000000,BI15*35%-9850000,IF(BI15>=52000000,BI15*30%-5850000,IF(BI15>=32000000,BI15*25%-3250000,IF(BI15>=18000000,BI15*20%-1650000,IF(BI15>=10000000,BI15*15%-750000,IF(BI15>5000000,BI15*10%-250000,BI15*5%)))))),0),0) -> 1955238 | BM15: 0 | BS15: =IF(AV15>=11000000,"80%","100%") -> 80% | BT15: =AV15*BS15-BN15-BK15-BP15-BO15 -> 25846154 | BW15: 60000000 | BX15: 0 | CA15: 0 | CB15: =SUM(BW15:CA15) -> 60000000 | CC15: ĐT PCCC
A16: =IF(B16=0,"",COUNTA($B$15:(B16))) -> 2 | B16: 2106723 | C16: Nguyễn Thành An | D16: Ban nhân sự | E16: CT | F16: LT | G16: 8480000 | H16: =+IF(OR(CC16="ĐT PCCC",CC16="ĐP PCCC"),780000,IF(CC16="AT-VSV",300000,0)) -> 780000 | I16: =CB16-BZ16-G16-H16 -> 32740000 | J16: 1 | K16: 10.5 | M16: 0.5 | O16: 2 | R16: 0 | S16: 0 | U16: 0 | V16: 0 | W16: 0 | X16: 0 | Y16: =G16*(K16+L16)/26 -> 3424615.4 | Z16: =M16*G16/26 -> 163076.92 | AA16: =G16*N16/26 -> 0 | AB16: =G16*O16/26 -> 652307.69 | AC16: =G16*P16*150%/26 -> 0 | AD16: =G16*Q16/26*200% -> 0 | AE16: =G16*R16/26*300% -> 0 | AF16: =IF(F16="LT",0,(G16+H16)/26*S16*30%) -> 0 | AG16: =T16*G16/23/8 -> 0 | AH16: =CB16/26*U16 -> 0 | AI16: =G16*V16/26 -> 0 | AK16: =BZ16*L16/26 -> 0 | AM16: =X16*CD16 -> 0 | AN16: =H16/26*K16 -> 315000 | AO16: =IF(F16="LN",I16*(K16+L16)/26+(H16+I16)*50%*M16/26+IF(F16="LT",BW16*O16/26-AB16,0)+MAX($G16*P16/26*150%,P16*$BW16/26)-AC16+MAX($G16*Q16/26*200%,Q16*$BW16/26)-AD16+MAX($G16*R16/26*300%,R16*$BW16/26)-AE16+BW16*S16/26-AF16+AH16-AG16,I16-I16*($CF$3-K16-L16)/26+(H16+I16)*50%*M16/26+IF(F16="LT",BW16*O16/26-AB16,0)+MAX($G16*P16/26*150%,P16*$BW16/26)-AC16+MAX($G16*Q16/26*200%,Q16*$BW16/26)-AD16+MAX($G16*R16/26*300%,R16*$BW16/26)-AE16+BW16*S16/26-AF16+AH16-AG16+(G16-G16*($CF$3-K16-L16)/26-Y16)+(H16-H16*($CF$3-K16-L16)/26-AN16)) -> 17584231 | AV16: =Y16+Z16+AA16+AB16+AC16+AD16+AE16+AF16+AG16+AI16+AJ16+AK16+AL16+AM16+AN16+AO16+AP16-AQ16+AR16+AS16+AT16+AU16 -> 22139231 | AX16: x | AY16: =ROUND(IF($AX16="x",($G16+$H16)*AY$11,0),0) -> 740800 | AZ16: =ROUND(IF($AX16="x",($G16+$H16)*AZ$11,0),0) -> 138900 | BA16: =ROUND(IF($AX16="x",($G16+$H16)*BA$11,0),0) -> 92600 | BB16: =SUM(AY16:BA16) -> 972300 | BE16: =IF(G16*1%>=234000,234000,G16*1%) -> 84800 | BF16: =AM16+IF(AR16>="730000",730000,AR16)+IF(((AV16-AM16-IF(AR16>="730000",730000,AR16)-AS16)*15%-AS16)>"0",((AV16-AM16-IF(AR16>="730000",730000,AR16)-AS16)*15%-AS16),0) -> 0 | BG16: =AV16-BF16+AW16 -> 22139231 | BI16: =BG16-BB16-BC16+BD16-BH16*4400000-IF(E16="CT",11000000,0) -> 10166931 | BJ16: =IF(BI16>0,ROUND(IF(BI16>=80000000,BI16*35%-9850000,IF(BI16>=52000000,BI16*30%-5850000,IF(BI16>=32000000,BI16*25%-3250000,IF(BI16>=18000000,BI16*20%-1650000,IF(BI16>=10000000,BI16*15%-750000,IF(BI16>5000000,BI16*10%-250000,BI16*5%)))))),0),0) -> 775040 | BM16: 0 | BS16: =IF(AV16>=11000000,"80%","100%") -> 80% | BT16: =AV16*BS16-BN16-BK16-BP16-BO16 -> 17711385 | BW16: 40000000 | BX16: 0 | BY16: 0 | CA16: =+BW16*5% -> 2000000 | CB16: =SUM(BW16:CA16) -> 42000000 | CC16: ĐP PCCC
