Workbook
Name _: "SQRT"
Name _____KDX3: [1]!_____KDX3
Name ____KDX3: #N/A
Name ___a10: #N/A
Name ___atn1: #REF!
Name ___atn10: #REF!
Name ___atn2: #REF!
Name ___atn3: #REF!
Name ___atn4: #REF!
Name ___atn5: #REF!
Name ___atn6: #REF!
Name ___atn7: #REF!
Name ___atn8: #REF!
Name ___atn9: #REF!
Name ___Bia1: #N/A
Name ___Bia2: #N/A
Name ___boi1: #REF!
Name ___boi2: #REF!
Name ___BTM150: #REF!
Name ___BTM250: #REF!
Name ___BTM300: #REF!
Name ___cao1: #REF!
Name ___cao2: #REF!
Name ___cao3: #REF!
Name ___cao4: #REF!
Name ___cao5: #REF!
Name ___cao6: #REF!
Name ___coc250: #REF!
Name ___coc300: #REF!
Name ___coc350: #REF!
Name ___CON1: #REF!
Name ___CON2: #REF!
Name ___cpd1: #REF!
Name ___cpd2: #REF!
Name ___Cus1: #N/A
Name ___dai1: #REF!
Name ___dai2: #REF!
Name ___dai3: #REF!
Name ___dai4: #REF!
Name ___dai5: #REF!
Name ___dai6: #REF!
Name ___dan1: #REF!
Name ___dan2: #REF!
Name ___ddn400: #REF!
Name ___ddn600: #REF!
Name ___deo1: #REF!
Name ___deo10: #REF!
Name ___deo2: #REF!
Name ___deo3: #REF!
Name ___deo4: #REF!
Name ___deo5: #REF!
Name ___deo6: #REF!
Name ___deo7: #REF!
Name ___deo8: #REF!
Name ___deo9: #REF!
Name ___E99999: #REF!
Name ___gon4: #N/A
Name ___hom2: #N/A
Name ___KDX3: #N/A
Name ___lap1: #REF!

Sheet Template Payroll
AP1: 6200000 | AQ1: 0.08 | AR1: 0.015 | AS1: 0.01 | BA1: 0.17 | BB1: 0.03 | BC1: 0.01 | BD1: 0.005 | BF1: =2340000*20 -> 46800000 | BG1: =4960000*20 -> 99200000 | BH1: Truy thu BHYT 3% | BI1: Truy thu BHYT 1.5%
A2: No | B2: Emp. Code | C2: ID No | D2: Full name | E2: Joning Date | F2: Division | G2: Department | H2: Position | I2: Job title | J2: Income Salary | K2: Basic Salary | L2: Efficiency salary | M2: Standard working day | N2: Working day last month (21-25) | O2: Working day current month | P2: Actual Basic Salary last month (21-25) | Q2: Actual Basic Salary current month | R2: Total Actual Basic Salary | S2: Efficiency salary Advance last month (21-25) | T2: Efficiency salary Advance current month | U2: Total Efficiency salary Advance | V2: Responsibility Allows | W2: Transportation Allows | X2: Mob Allows | Y2: Meal Allows | Z2: Total Actual All Allows | AA2: Overtime | AB2: Night shift | AC2: Bonus | AD2: Acting Allowance | AE2: AL Remain | AF2: Rest of annual leave | AG2: Incentives | AH2: Other Allowance | AI2: Severance pay | AJ2: Total Gross Salary | AK2: OT untaxable | AL2: Night shift untaxable | AM2: Severance pay untaxable | AN2: Self- deduction | AO2: Qty. | AP2: AMT | AQ2: Social Ins. 8% | AR2: Health Ins. 1.5% | AS2: Jobless Ins. 1% | AT2: Total Ins. Employees paid 10.5% | AU2: Lunch Max (730,000đ) | AV2: Taxable income | AW2: Assessable income | AX2: Tax rate | AY2: Min Tax | AZ2: Monthly PIT 개인소득세 | BA2: Social Ins. 17% | BB2: Health Ins. 3% | BC2: Jobless Ins. 1% | BD2: Accident & occupational disease 0.5% | BE2: Total Ins. Employer paid 21.5% | BF2: Insurance salary (SI & HI) | BG2: Insurance salary (Jobless) | BH2: Obligation Health Insurance Employer | BI2: Obligation Health Insurance Employee | BJ2: Trade Union (Company) | BK2: Trade Union (Employee) | BL2: Support Funeral Fund | BM2: Net salary | BN2: Benefit TAX | BO2: PIT payable last year | BP2: Government funds | BQ2: Total Reduction | BR2: Total obligation of employee | BS2: Tham gia BHXH | BT2: Personal income tax subjects | BU2: Participation in Trade Union | BV2: Participation in bereavement | BW2: Number of funerals occurring in the period | BX2: Email
A3: 1 | B3: SLA2500111 | D3: Nguyen Thi Ha | E3: 27/07/2015 | F3: PVT - Store Manager | G3: Store Management | H3: Manager | I3: Store Manager - Emart Phan Van Tri | J3: 47000000 | K3: 10870000 | L3: =J3-K3 -> 36130000 | M3: 26 | N3: =IFERROR(VLOOKUP(B3,' TimeTB 1'!$C$4:$AU$5,45,0),0) -> 0 | O3: =VLOOKUP(B3,'TimeTB 2'!$C$4:$AU$11,45,0) -> 26 | P3: =ROUND(K3/M3*N3,0) -> 0 | Q3: =ROUND(K3/M3*O3,0) -> 10870000 | R3: =SUM(P3:Q3) -> 10870000 | S3: =ROUND(L3/26*N3,0) -> 0 | T3: =ROUND(L3/26*O3,0) -> 36130000 | U3: =SUM(S3:T3) -> 36130000 | V3: 0 | W3: 0 | X3: 0 | Y3: =VLOOKUP(B3,'PC cơm '!$B$3:$L$11,11,0) -> 1000000 | Z3: =SUM(V3:Y3) -> 1000000 | AA3: =VLOOKUP(B3,'OT '!$B$4:$R$11,17,0) -> 0 | AB3: =VLOOKUP(B3,NS!$B$9:$G$16,6,0) -> 135577 | AC3: 0 | AD3: 0 | AE3: 0 | AF3: =ROUND(J3/26*AE3,0) -> 0 | AG3: =IFERROR(VLOOKUP(B3,Incentive!$B$9:$H$11,7,0),0) -> 0 | AH3: =SUMIF(Others!$B$8:$B$15,$B3,Others!$F$8:$F$15) -> 0 | AI3: 0 | AJ3: =AI3+AH3+AG3+AF3+AD3+AC3+AB3+AA3+Z3+U3+R3+BN3 -> 48335577 | AK3: =VLOOKUP(B3,'OT '!$B$4:$T$11,19,0) -> 0 | AL3: =VLOOKUP(B3,NS!$B$9:$I$16,8,0) -> 135577 | AM3: =AI3 -> 0 | AN3: =IF(BT3=1,0,15500000) -> 15500000 | AO3: 4 | AP3: =AO3*$AP$1 -> 24800000 | AQ3: =BF3*$AQ$1 -> 869600 | AR3: =BF3*$AR$1 -> 163050 | AS3: =BG3*$AS$1 -> 108700 | AT3: =+AS3+AR3+AQ3 -> 1141350 | AU3: =IF(BT3=1,0,MIN(Y3,730000)) -> 730000 | AV3: =AJ3-AK3-AL3-AM3-AU3 -> 47470000 | AW3: =MAX(AV3-AN3-AP3-AT3,0) -> 6028650 | AX3: =IF(BT3=1,10%,IF(AW3>0,IF(AW3>80000000,0.35,IF(AW3>52000000,0.3,IF(AW3>32000000,0.25,IF(AW3>18000000,0.2,IF(AW3>10000000,0.15,IF(AW3>5000000,0.1,0.05)))))),0)) -> 0.1 | AY3: =IF(BT3=1,0,IF(AW3>80000000,9850000,IF(AW3>52000000,5850000,IF(AW3>32000000,3250000,IF(AW3>18000000,1650000,IF(AW3>10000000,750000,IF(AW3>5000000,250000,0))))))) -> 250000 | AZ3: =ROUND(AW3*AX3-AY3,0) -> 352865 | BA3: =BF3*$BA$1 -> 1847900 | BB3: =BF3*$BB$1 -> 326100 | BC3: =BG3*$BC$1 -> 108700 | BD3: =BG3*$BD$1 -> 54350 | BE3: =SUM(BA3:BD3) -> 2337050 | BF3: =MIN((IF(BS3=1,K3,0)),$BF$1) -> 10870000 | BG3: =MIN((IF(BS3=1,K3,0)),$BG$1) -> 10870000 | BH3: 0 | BI3: 0 | BJ3: =IF(BS3=1,BF3*2%,0) -> 217400 | BK3: =IF(BU3=1,40000,0) -> 40000 | BL3: =IF(BV3=0,0,IF(J3<11000000,5000,IF(J3<25000000,10000,IF(J3<40000000,15000,20000)))*BW3) -> 0 | BM3: =AJ3-AT3-AZ3-BK3-BL3-BN3-BO3-BP3 -> 46601362 | BN3: =IFERROR(VLOOKUP(B3,'Benefit tính thuế'!$B$2:$H$5,7,0),0) -> 200000 | BO3: 0 | BP3: 0 | BQ3: =AN3+AP3+AU3 -> 41030000 | BR3: =+AZ3+AT3 -> 1494215 | BS3: 1 | BT3: 0 | BU3: 1 | BV3: 0 | BW3: 20
A4: Cooperate Function | G4: 1 | J4: =SUM(J5:J5) -> 31000000 | K4: =SUM(K5:K5) -> 8350000 | L4: =SUM(L5:L5) -> 22650000 | M4: =SUM(M5:M5) -> 26 | N4: =SUM(N5:N5) -> 0 | O4: =SUM(O5:O5) -> 26 | P4: =SUM(P5:P5) -> 0 | Q4: =SUM(Q5:Q5) -> 8350000 | ... AM4: =SUM(AM5:AM5) -> 0 | AN4: =IF(BT4=1,0,15500000) -> 15500000 | AO4: =SUM(AO5:AO5) -> 1 | AP4: =SUM(AP5:AP5) -> 6200000 | AQ4: =SUM(AQ5:AQ5) -> 668000 | AR4: =SUM(AR5:AR5) -> 125250 | AS4: =SUM(AS5:AS5) -> 83500 | AT4: =SUM(AT5:AT5) -> 876750 | AU4: =SUM(AU5:AU5) -> 730000 | AV4: =SUM(AV5:AV5) -> 35476538 | ... BV4: =SUM(BV5:BV5) -> 1 | BX4: =SUM(BX5:BX5) -> 0
A5: 1 | B5: PHI2500112 | D5: Phung Manh Ha | E5: 19/12/2022 | F5: PVT - Cooperate Function | G5: Cooperate Function | H5: Manager | I5: Corporate Function Manager | J5: 31000000 | K5: 8350000 | L5: =J5-K5 -> 22650000 | M5: 26 | N5: =IFERROR(VLOOKUP(B5,' TimeTB 1'!$C$4:$AU$5,45,0),0) -> 0 | O5: =VLOOKUP(B5,'TimeTB 2'!$C$4:$AU$11,45,0) -> 26 | P5: =ROUND((K5/M5*N5),0) -> 0 | Q5: =ROUND(K5/M5*O5,0) -> 8350000 | R5: =SUM(P5:Q5) -> 8350000 | S5: =ROUND(L5/26*N5,0) -> 0 | T5: =ROUND(L5/26*O5,0) -> 22650000 | U5: =SUM(S5:T5) -> 22650000 | V5: 0 | W5: 0 | X5: 0 | Y5: =VLOOKUP(B5,'PC cơm '!$B$3:$L$11,11,0) -> 1120000 | Z5: =SUM(V5:Y5) -> 1120000 | AA5: =VLOOKUP(B5,'OT '!$B$4:$R$11,17,0) -> 5827403 | AB5: =VLOOKUP(B5,NS!$B$9:$G$16,6,0) -> 134135 | AC5: 0 | AD5: 0 | AE5: 0 | AF5: =ROUND(J5/26*AE5,0) -> 0 | AG5: =IFERROR(VLOOKUP(B5,Incentive!$B$9:$H$11,7,0),0) -> 0 | AH5: =SUMIF(Others!$B$8:$B$15,$B5,Others!$F$8:$F$15) -> 0 | AI5: 0 | AJ5: =AI5+AH5+AG5+AF5+AD5+AC5+AB5+AA5+Z5+U5+R5+BN5 -> 40081538 | AK5: =VLOOKUP(B5,'OT '!$B$4:$T$11,19,0) -> 3740865 | AL5: =VLOOKUP(B5,NS!$B$9:$I$16,8,0) -> 134135 | AM5: =AI5 -> 0 | AN5: =IF(BT5=1,0,15500000) -> 15500000 | AO5: 1 | AP5: =AO5*$AP$1 -> 6200000 | AQ5: =BF5*$AQ$1 -> 668000 | AR5: =BF5*$AR$1 -> 125250 | AS5: =BG5*$AS$1 -> 83500 | AT5: =+AS5+AR5+AQ5 -> 876750 | AU5: =IF(BT5=1,0,MIN(Y5,730000)) -> 730000 | AV5: =AJ5-AK5-AL5-AM5-AU5 -> 35476538 | AW5: =MAX(AV5-AN5-AP5-AT5,0) -> 12899788 | AX5: =IF(BT5=1,10%,IF(AW5>0,IF(AW5>80000000,0.35,IF(AW5>52000000,0.3,IF(AW5>32000000,0.25,IF(AW5>18000000,0.2,IF(AW5>10000000,0.15,IF(AW5>5000000,0.1,0.05)))))),0)) -> 0.15 | AY5: =IF(BT5=1,0,IF(AW5>80000000,9850000,IF(AW5>52000000,5850000,IF(AW5>32000000,3250000,IF(AW5>18000000,1650000,IF(AW5>10000000,750000,IF(AW5>5000000,250000,0))))))) -> 750000 | AZ5: =ROUND(AW5*AX5-AY5,0) -> 1184968 | BA5: =BF5*$BA$1 -> 1419500 | BB5: =BF5*$BB$1 -> 250500 | BC5: =BG5*$BC$1 -> 83500 | BD5: =BG5*$BD$1 -> 41750 | BE5: =SUM(BA5:BD5) -> 1795250 | BF5: =MIN((IF(BS5=1,K5,0)),$BF$1) -> 8350000 | BG5: =MIN((IF(BS5=1,K5,0)),$BG$1) -> 8350000 | BH5: 0 | BI5: 0 | BJ5: =IF(BS5=1,BF5*2%,0) -> 167000 | BK5: =IF(BU5=1,40000,0) -> 40000 | BL5: =IF(BV5=0,0,IF(J5<11000000,5000,IF(J5<25000000,10000,IF(J5<40000000,15000,20000)))*BW5) -> 300000 | BM5: =AJ5-AT5-AZ5-BK5-BL5-BN5-BO5-BP5 -> 35679820 | BN5: =IFERROR(VLOOKUP(B5,'Benefit tính thuế'!$B$2:$H$5,7,0),0) -> 2000000 | BO5: 0 | BP5: 0 | BQ5: =AN5+AP5+AU5 -> 22430000 | BR5: =+AZ5+AT5 -> 2061718 | BS5: 1 | BT5: 0 | BU5: 1 | BV5: 1 | BW5: 20
A6: Cashier | G6: 2 | J6: =SUM(J7:J8) -> 16500000 | K6: =SUM(K7:K8) -> 10620000 | L6: =SUM(L7:L8) -> 5880000 | M6: =SUM(M7:M8) -> 52 | N6: =SUM(N7:N8) -> 2 | O6: =SUM(O7:O8) -> 42 | P6: =SUM(P7:P8) -> 408462 | Q6: =SUM(Q7:Q8) -> 8577692 | ... AM6: =SUM(AM7:AM8) -> 0 | AN6: =IF(BT6=1,0,15500000) -> 0 | AO6: =SUM(AO7:AO8) -> 0 | AP6: =SUM(AP7:AP8) -> 0 | AQ6: =SUM(AQ7:AQ8) -> 0 | AR6: =SUM(AR7:AR8) -> 0 | AS6: =SUM(AS7:AS8) -> 0 | AT6: =SUM(AT7:AT8) -> 0 | AU6: =SUM(AU7:AU8) -> 720000 | AV6: =SUM(AV7:AV8) -> 19972284 | ... BV6: =SUM(BV7:BV8) -> 0 | BX6: =SUM(BX7:BX8) -> 0
A7: 2 | B7: PVT2500114 | D7: Nguyen Duc Khanh | E7: 44562 | F7: PVT - Cashier | G7: Cashier | H7: Staff | I7: Cashier Staff | J7: 8000000 | K7: 5310000 | L7: =J7-K7 -> 2690000 | M7: 26 | N7: =IFERROR(VLOOKUP(B7,' TimeTB 1'!$C$4:$AU$5,45,0),0) -> 0 | O7: =VLOOKUP(B7,'TimeTB 2'!$C$4:$AU$11,45,0) -> 16 | P7: =ROUND((K7/M7*N7),0) -> 0 | Q7: =ROUND(K7/M7*O7,0) -> 3267692 | R7: =SUM(P7:Q7) -> 3267692 | S7: =ROUND(L7/26*N7,0) -> 0 | T7: =ROUND(L7/26*O7,0) -> 1655385 | U7: =SUM(S7:T7) -> 1655385 | V7: 0 | W7: 0 | X7: 0 | Y7: =VLOOKUP(B7,'PC cơm '!$B$3:$L$11,11,0) -> 720000 | Z7: =SUM(V7:Y7) -> 720000 | AA7: =VLOOKUP(B7,'OT '!$B$4:$R$11,17,0) -> 965384 | AB7: =VLOOKUP(B7,NS!$B$9:$G$16,6,0) -> 17308 | AC7: 0 | AD7: 0 | AE7: 4 | AF7: =ROUND(J7/26*AE7,0) -> 1230769 | AG7: =IFERROR(VLOOKUP(B7,Incentive!$B$9:$H$11,7,0),0) -> 0 | AH7: =SUMIF(Others!$B$8:$B$15,$B7,Others!$F$8:$F$15) -> 500000 | AI7: 0 | AJ7: =AI7+AH7+AG7+AF7+AD7+AC7+AB7+AA7+Z7+U7+R7+BN7 -> 9606538 | AK7: =VLOOKUP(B7,'OT '!$B$4:$T$11,19,0) -> 657692 | AL7: =VLOOKUP(B7,NS!$B$9:$I$16,8,0) -> 17308 | AM7: =AI7 -> 0 | AN7: =IF(BT7=1,0,15500000) -> 15500000 | AO7: 0 | AP7: =AO7*$AP$1 -> 0 | AQ7: =BF7*$AQ$1 -> 0 | AR7: =BF7*$AR$1 -> 0 | AS7: =BG7*$AS$1 -> 0 | AT7: =+AS7+AR7+AQ7 -> 0 | AU7: =IF(BT7=1,0,MIN(Y7,730000)) -> 720000 | AV7: =AJ7-AK7-AL7-AM7-AU7 -> 8211538 | AW7: =MAX(AV7-AN7-AP7-AT7,0) -> 0 | AX7: =IF(BT7=1,10%,IF(AW7>0,IF(AW7>80000000,0.35,IF(AW7>52000000,0.3,IF(AW7>32000000,0.25,IF(AW7>18000000,0.2,IF(AW7>10000000,0.15,IF(AW7>5000000,0.1,0.05)))))),0)) -> 0 | AY7: =IF(BT7=1,0,IF(AW7>80000000,9850000,IF(AW7>52000000,5850000,IF(AW7>32000000,3250000,IF(AW7>18000000,1650000,IF(AW7>10000000,750000,IF(AW7>5000000,250000,0))))))) -> 0 | AZ7: =ROUND(AW7*AX7-AY7,0) -> 0 | BA7: =BF7*$BA$1 -> 0 | BB7: =BF7*$BB$1 -> 0 | BC7: =BG7*$BC$1 -> 0 | BD7: =BG7*$BD$1 -> 0 | BE7: =SUM(BA7:BD7) -> 0 | BF7: =MIN((IF(BS7=1,K7,0)),$BF$1) -> 0 | BG7: =MIN((IF(BS7=1,K7,0)),$BG$1) -> 0 | BH7: 0 | BI7: 0 | BJ7: =IF(BS7=1,BF7*2%,0) -> 0 | BK7: =IF(BU7=1,40000,0) -> 0 | BL7: =IF(BV7=0,0,IF(J7<11000000,5000,IF(J7<25000000,10000,IF(J7<40000000,15000,20000)))*BW7) -> 0 | BM7: =AJ7-AT7-AZ7-BK7-BL7-BN7-BO7-BP7 -> 8356538 | BN7: =IFERROR(VLOOKUP(B7,'Benefit tính thuế'!$B$2:$H$5,7,0),0) -> 1250000 | BO7: 0 | BP7: 0 | BQ7: =AN7+AP7+AU7 -> 16220000 | BR7: =+AZ7+AT7 -> 0 | BS7: 0 | BT7: 0 | BU7: 0 | BV7: 0 | BW7: 20
A8: 3 | B8: PVT2500115 | D8: Nguyen Son Tung | E8: 45740 | F8: PVT - Cashier | G8: Cashier | H8: Staff | I8: Cashier Staff | J8: 8500000 | K8: 5310000 | L8: =J8-K8 -> 3190000 | M8: 26 | N8: =IFERROR(VLOOKUP(B8,' TimeTB 1'!$C$4:$AU$5,45,0),0) -> 2 | O8: =VLOOKUP(B8,'TimeTB 2'!$C$4:$AU$11,45,0) -> 26 | P8: =ROUND((K8/M8*N8),0) -> 408462 | Q8: =ROUND(K8/M8*O8,0) -> 5310000 | R8: =SUM(P8:Q8) -> 5718462 | S8: =ROUND(L8/26*N8,0) -> 245385 | T8: =ROUND(L8/26*O8,0) -> 3190000 | U8: =SUM(S8:T8) -> 3435385 | V8: 0 | W8: 0 | X8: 0 | Y8: =VLOOKUP(B8,'PC cơm '!$B$3:$L$11,11,0) -> 1120000 | Z8: =SUM(V8:Y8) -> 1120000 | AA8: =VLOOKUP(B8,'OT '!$B$4:$R$11,17,0) -> 980769 | AB8: =VLOOKUP(B8,NS!$B$9:$G$16,6,0) -> 6130 | AC8: 0 | AD8: 0 | AE8: 0 | AF8: =ROUND(J8/26*AE8,0) -> 0 | AG8: =IFERROR(VLOOKUP(B8,Incentive!$B$9:$H$11,7,0),0) -> 0 | AH8: =SUMIF(Others!$B$8:$B$15,$B8,Others!$F$8:$F$15) -> 500000 | AI8: 0 | AJ8: =AI8+AH8+AG8+AF8+AD8+AC8+AB8+AA8+Z8+U8+R8+BN8 -> 11760746 | AK8: =VLOOKUP(B8,'OT '!$B$4:$T$11,19,0) -> 0 | AL8: =VLOOKUP(B8,NS!$B$9:$I$16,8,0) -> 0 | AM8: =AI8 -> 0 | AN8: =IF(BT8=1,0,15500000) -> 0 | AO8: 0 | AP8: =AO8*$AP$1 -> 0 | AQ8: =BF8*$AQ$1 -> 0 | AR8: =BF8*$AR$1 -> 0 | AS8: =BG8*$AS$1 -> 0 | AT8: =+AS8+AR8+AQ8 -> 0 | AU8: =IF(BT8=1,0,MIN(Y8,730000)) -> 0 | AV8: =AJ8-AK8-AL8-AM8-AU8 -> 11760746 | AW8: =MAX(AV8-AN8-AP8-AT8,0) -> 11760746 | AX8: =IF(BT8=1,10%,IF(AW8>0,IF(AW8>80000000,0.35,IF(AW8>52000000,0.3,IF(AW8>32000000,0.25,IF(AW8>18000000,0.2,IF(AW8>10000000,0.15,IF(AW8>5000000,0.1,0.05)))))),0)) -> 0.1 | AY8: =IF(BT8=1,0,IF(AW8>80000000,9850000,IF(AW8>52000000,5850000,IF(AW8>32000000,3250000,IF(AW8>18000000,1650000,IF(AW8>10000000,750000,IF(AW8>5000000,250000,0))))))) -> 0 | AZ8: =ROUND(AW8*AX8-AY8,0) -> 1176075 | BA8: =BF8*$BA$1 -> 0 | BB8: =BF8*$BB$1 -> 0 | BC8: =BG8*$BC$1 -> 0 | BD8: =BG8*$BD$1 -> 0 | BE8: =SUM(BA8:BD8) -> 0 | BF8: =MIN((IF(BS8=1,K8,0)),$BF$1) -> 0 | BG8: =MIN((IF(BS8=1,K8,0)),$BG$1) -> 0 | BH8: 0 | BI8: 0 | BJ8: =IF(BS8=1,BF8*2%,0) -> 0 | BK8: =IF(BU8=1,40000,0) -> 0 | BL8: =IF(BV8=0,0,IF(J8<11000000,5000,IF(J8<25000000,10000,IF(J8<40000000,15000,20000)))*BW8) -> 0 | BM8: =AJ8-AT8-AZ8-BK8-BL8-BN8-BO8-BP8 -> 10584671 | BN8: =IFERROR(VLOOKUP(B8,'Benefit tính thuế'!$B$2:$H$5,7,0),0) -> 0 | BO8: 0 | BP8: 0 | BQ8: =AN8+AP8+AU8 -> 0 | BR8: =+AZ8+AT8 -> 1176075 | BS8: 0 | BT8: 1 | BU8: 0 | BV8: 0 | BW8: 20
A9: Quality Assurance | G9: 1 | J9: =SUM(J10:J10) -> 7056000 | K9: =SUM(K10:K10) -> 5310000 | L9: =SUM(L10:L10) -> 1746000 | M9: =SUM(M10:M10) -> 26 | N9: =SUM(N10:N10) -> 0 | O9: =SUM(O10:O10) -> 26 | P9: =SUM(P10:P10) -> 0 | Q9: =SUM(Q10:Q10) -> 5310000 | ... AM9: =SUM(AM10:AM10) -> 0 | AN9: =IF(BT9=1,0,15500000) -> 15500000 | AO9: =SUM(AO10:AO10) -> 0 | AP9: =SUM(AP10:AP10) -> 0 | AQ9: =SUM(AQ10:AQ10) -> 424800 | AR9: =SUM(AR10:AR10) -> 79650 | AS9: =SUM(AS10:AS10) -> 53100 | AT9: =SUM(AT10:AT10) -> 557550 | AU9: =SUM(AU10:AU10) -> 730000 | AV9: =SUM(AV10:AV10) -> 10056615 | ... BV9: =SUM(BV10:BV10) -> 1 | BX9: =SUM(BX10:BX10) -> 0
A10: 1 | B10: PVT2500116 | D10: Nguyen Quang Cuong | E10: 12/10/2016 | F10: PVT - Quality Assurance | G10: Quality Assurance | H10: Assistant | I10: QA Assistant | J10: 7056000 | K10: 5310000 | L10: =J10-K10 -> 1746000 | M10: 26 | N10: =IFERROR(VLOOKUP(B10,' TimeTB 1'!$C$4:$AU$5,45,0),0) -> 0 | O10: =VLOOKUP(B10,'TimeTB 2'!$C$4:$AU$11,45,0) -> 26 | P10: =ROUND((K10/M10*N10),0) -> 0 | Q10: =ROUND(K10/M10*O10,0) -> 5310000 | R10: =SUM(P10:Q10) -> 5310000 | S10: =ROUND(L10/26*N10,0) -> 0 | T10: =ROUND(L10/26*O10,0) -> 1746000 | U10: =SUM(S10:T10) -> 1746000 | V10: 0 | W10: 0 | X10: 0 | Y10: =VLOOKUP(B10,'PC cơm '!$B$3:$L$11,11,0) -> 1120000 | Z10: =SUM(V10:Y10) -> 1120000 | AA10: =VLOOKUP(B10,'OT '!$B$4:$R$11,17,0) -> 1596081 | AB10: =VLOOKUP(B10,NS!$B$9:$G$16,6,0) -> 10177 | AC10: 0 | AD10: 0 | AE10: 0 | AF10: =ROUND(J10/26*AE10,0) -> 0 | AG10: =IFERROR(VLOOKUP(B10,Incentive!$B$9:$H$11,7,0),0) -> 2000000 | AH10: =SUMIF(Others!$B$8:$B$15,$B10,Others!$F$8:$F$15) -> 0 | AI10: 0 | AJ10: =AI10+AH10+AG10+AF10+AD10+AC10+AB10+AA10+Z10+U10+R10+BN10 -> 11782258 | AK10: =VLOOKUP(B10,'OT '!$B$4:$T$11,19,0) -> 985466 | AL10: =VLOOKUP(B10,NS!$B$9:$I$16,8,0) -> 10177 | AM10: =AI10 -> 0 | AN10: =IF(BT10=1,0,15500000) -> 15500000 | AO10: 0 | AP10: =AO10*$AP$1 -> 0 | AQ10: =BF10*$AQ$1 -> 424800 | AR10: =BF10*$AR$1 -> 79650 | AS10: =BG10*$AS$1 -> 53100 | AT10: =+AS10+AR10+AQ10 -> 557550 | AU10: =IF(BT10=1,0,MIN(Y10,730000)) -> 730000 | AV10: =AJ10-AK10-AL10-AM10-AU10 -> 10056615 | AW10: =MAX(AV10-AN10-AP10-AT10,0) -> 0 | AX10: =IF(BT10=1,10%,IF(AW10>0,IF(AW10>80000000,0.35,IF(AW10>52000000,0.3,IF(AW10>32000000,0.25,IF(AW10>18000000,0.2,IF(AW10>10000000,0.15,IF(AW10>5000000,0.1,0.05)))))),0)) -> 0 | AY10: =IF(BT10=1,0,IF(AW10>80000000,9850000,IF(AW10>52000000,5850000,IF(AW10>32000000,3250000,IF(AW10>18000000,1650000,IF(AW10>10000000,750000,IF(AW10>5000000,250000,0))))))) -> 0 | AZ10: =ROUND(AW10*AX10-AY10,0) -> 0 | BA10: =BF10*$BA$1 -> 902700 | BB10: =BF10*$BB$1 -> 159300 | BC10: =BG10*$BC$1 -> 53100 | BD10: =BG10*$BD$1 -> 26550 | BE10: =SUM(BA10:BD10) -> 1141650 | BF10: =MIN((IF(BS10=1,K10,0)),$BF$1) -> 5310000 | BG10: =MIN((IF(BS10=1,K10,0)),$BG$1) -> 5310000 | BH10: 0 | BI10: 0 | BJ10: =IF(BS10=1,BF10*2%,0) -> 106200 | BK10: =IF(BU10=1,40000,0) -> 40000 | BL10: =IF(BV10=0,0,IF(J10<11000000,5000,IF(J10<25000000,10000,IF(J10<40000000,15000,20000)))*BW10) -> 100000 | BM10: =AJ10-AT10-AZ10-BK10-BL10-BN10-BO10-BP10 -> 11084708 | BN10: =IFERROR(VLOOKUP(B10,'Benefit tính thuế'!$B$2:$H$5,7,0),0) -> 0 | BO10: 0 | BP10: 0 | BQ10: =AN10+AP10+AU10 -> 16230000 | BR10: =+AZ10+AT10 -> 557550 | BS10: 1 | BT10: 0 | BU10: 1 | BV10: 1 | BW10: 20
A11: Security | G11: 1 | J11: =SUM(J12:J12) -> 6841000 | K11: =SUM(K12:K12) -> 5310000 | L11: =SUM(L12:L12) -> 1531000 | M11: =SUM(M12:M12) -> 26 | N11: =SUM(N12:N12) -> 0 | O11: =SUM(O12:O12) -> 26 | P11: =SUM(P12:P12) -> 0 | Q11: =SUM(Q12:Q12) -> 5310000 | ... AM11: =SUM(AM12:AM12) -> 0 | AN11: =IF(BT11=1,0,15500000) -> 15500000 | AO11: =SUM(AO12:AO12) -> 0 | AP11: =SUM(AP12:AP12) -> 0 | AQ11: =SUM(AQ12:AQ12) -> 424800 | AR11: =SUM(AR12:AR12) -> 79650 | AS11: =SUM(AS12:AS12) -> 53100 | AT11: =SUM(AT12:AT12) -> 557550 | AU11: =SUM(AU12:AU12) -> 730000 | AV11: =SUM(AV12:AV12) -> 9671000 | ... BV11: =SUM(BV12:BV12) -> 0 | BX11: =SUM(BX12:BX12) -> 0
A12: 1 | B12: PVT2500117 | D12: Pham Duc Kien | E12: 22/06/2022 | F12: PVT - Security | G12: Security | H12: Staff | I12: Security Staff | J12: 6841000 | K12: 5310000 | L12: =J12-K12 -> 1531000 | M12: 26 | N12: =IFERROR(VLOOKUP(B12,' TimeTB 1'!$C$4:$AU$5,45,0),0) -> 0 | O12: =VLOOKUP(B12,'TimeTB 2'!$C$4:$AU$11,45,0) -> 26 | P12: =ROUND((K12/M12*N12),0) -> 0 | Q12: =ROUND(K12/M12*O12,0) -> 5310000 | R12: =SUM(P12:Q12) -> 5310000 | S12: =ROUND(L12/26*N12,0) -> 0 | T12: =ROUND(L12/26*O12,0) -> 1531000 | U12: =SUM(S12:T12) -> 1531000 | V12: 0 | W12: 0 | X12: 0 | Y12: =VLOOKUP(B12,'PC cơm '!$B$3:$L$11,11,0) -> 960000 | Z12: =SUM(V12:Y12) -> 960000 | AA12: =VLOOKUP(B12,'OT '!$B$4:$R$11,17,0) -> 0 | AB12: =VLOOKUP(B12,NS!$B$9:$G$16,6,0) -> 49334 | AC12: 0 | AD12: 0 | AE12: 0 | AF12: =ROUND(J12/26*AE12,0) -> 0 | AG12: =IFERROR(VLOOKUP(B12,Incentive!$B$9:$H$11,7,0),0) -> 2600000 | AH12: =SUMIF(Others!$B$8:$B$15,$B12,Others!$F$8:$F$15) -> 0 | AI12: 0 | AJ12: =AI12+AH12+AG12+AF12+AD12+AC12+AB12+AA12+Z12+U12+R12+BN12 -> 10450334 | AK12: =VLOOKUP(B12,'OT '!$B$4:$T$11,19,0) -> 0 | AL12: =VLOOKUP(B12,NS!$B$9:$I$16,8,0) -> 49334 | AM12: =AI12 -> 0 | AN12: =IF(BT12=1,0,15500000) -> 15500000 | AO12: 0 | AP12: =AO12*$AP$1 -> 0 | AQ12: =BF12*$AQ$1 -> 424800 | AR12: =BF12*$AR$1 -> 79650 | AS12: =BG12*$AS$1 -> 53100 | AT12: =+AS12+AR12+AQ12 -> 557550 | AU12: =IF(BT12=1,0,MIN(Y12,730000)) -> 730000 | AV12: =AJ12-AK12-AL12-AM12-AU12 -> 9671000 | AW12: =MAX(AV12-AN12-AP12-AT12,0) -> 0 | AX12: =IF(BT12=1,10%,IF(AW12>0,IF(AW12>80000000,0.35,IF(AW12>52000000,0.3,IF(AW12>32000000,0.25,IF(AW12>18000000,0.2,IF(AW12>10000000,0.15,IF(AW12>5000000,0.1,0.05)))))),0)) -> 0 | AY12: =IF(BT12=1,0,IF(AW12>80000000,9850000,IF(AW12>52000000,5850000,IF(AW12>32000000,3250000,IF(AW12>18000000,1650000,IF(AW12>10000000,750000,IF(AW12>5000000,250000,0))))))) -> 0 | AZ12: =ROUND(AW12*AX12-AY12,0) -> 0 | BA12: =BF12*$BA$1 -> 902700 | BB12: =BF12*$BB$1 -> 159300 | BC12: =BG12*$BC$1 -> 53100 | BD12: =BG12*$BD$1 -> 26550 | BE12: =SUM(BA12:BD12) -> 1141650 | BF12: =MIN((IF(BS12=1,K12,0)),$BF$1) -> 5310000 | BG12: =MIN((IF(BS12=1,K12,0)),$BG$1) -> 5310000 | BH12: 0 | BI12: 0 | BJ12: =IF(BS12=1,BF12*2%,0) -> 106200 | BK12: =IF(BU12=1,40000,0) -> 40000 | BL12: =IF(BV12=0,0,IF(J12<11000000,5000,IF(J12<25000000,10000,IF(J12<40000000,15000,20000)))*BW12) -> 0 | BM12: =AJ12-AT12-AZ12-BK12-BL12-BN12-BO12-BP12 -> 9852784 | BN12: =IFERROR(VLOOKUP(B12,'Benefit tính thuế'!$B$2:$H$5,7,0),0) -> 0 | BO12: 0 | BP12: 0 | BQ12: =AN12+AP12+AU12 -> 16230000 | BR12: =+AZ12+AT12 -> 557550 | BS12: 1 | BT12: 0 | BU12: 1 | BV12: 0 | BW12: 20
A13: PVT - PP center | G13: 2 | J13: =SUM(J14:J15) -> 21448000 | K13: =SUM(K14:K15) -> 13370000 | L13: =SUM(L14:L15) -> 8078000 | M13: =SUM(M14:M15) -> 52 | N13: =SUM(N14:N15) -> 4 | O13: =SUM(O14:O15) -> 51 | P13: =SUM(P14:P15) -> 892308 | Q13: =SUM(Q14:Q15) -> 13078846 | ... AM13: =SUM(AM14:AM15) -> 0 | AN13: =IF(BT13=1,0,15500000) -> 0 | AO13: =SUM(AO14:AO15) -> 0 | AP13: =SUM(AP14:AP15) -> 0 | AQ13: =SUM(AQ14:AQ15) -> 605600 | AR13: =SUM(AR14:AR15) -> 113550 | AS13: =SUM(AS14:AS15) -> 75700 | AT13: =SUM(AT14:AT15) -> 794850 | AU13: =SUM(AU14:AU15) -> 730000 | AV13: =SUM(AV14:AV15) -> 35355644 | ... BV13: =SUM(BV14:BV15) -> 0 | BX13: =SUM(BX14:BX15) -> 0
A14: 1 | B14: PVT2500113 | D14: Nguyen Van Quan | E14: 24/10/2022 | F14: PVT - Operation | G14: PP. Center | H14: Staff | I14: Shipper Staff | J14: 10448000 | K14: 7570000 | L14: =J14-K14 -> 2878000 | M14: 26 | N14: =IFERROR(VLOOKUP(B14,' TimeTB 1'!$C$4:$AU$5,45,0),0) -> 0 | O14: =VLOOKUP(B14,'TimeTB 2'!$C$4:$AU$11,45,0) -> 25 | P14: =ROUND((K14/M14*N14),0) -> 0 | Q14: =ROUND(K14/M14*O14,0) -> 7278846 | R14: =SUM(P14:Q14) -> 7278846 | S14: =ROUND(L14/26*N14,0) -> 0 | T14: =ROUND(L14/26*O14,0) -> 2767308 | U14: =SUM(S14:T14) -> 2767308 | V14: 0 | W14: 0 | X14: 0 | Y14: =VLOOKUP(B14,'PC cơm '!$B$3:$L$11,11,0) -> 960000 | Z14: =SUM(V14:Y14) -> 960000 | AA14: =VLOOKUP(B14,'OT '!$B$4:$R$11,17,0) -> 307663 | AB14: =VLOOKUP(B14,NS!$B$9:$G$16,6,0) -> 0 | AC14: 0 | AD14: 0 | AE14: 0 | AF14: =ROUND(J14/26*AE14,0) -> 0 | AG14: =IFERROR(VLOOKUP(B14,Incentive!$B$9:$H$11,7,0),0) -> 0 | AH14: =SUMIF(Others!$B$8:$B$15,$B14,Others!$F$8:$F$15) -> 1923076.9 | AI14: 0 | AJ14: =AI14+AH14+AG14+AF14+AD14+AC14+AB14+AA14+Z14+U14+R14+BN14 -> 14236894 | AK14: =VLOOKUP(B14,'OT '!$B$4:$T$11,19,0) -> 156971 | AL14: =VLOOKUP(B14,NS!$B$9:$I$16,8,0) -> 0 | AM14: =AI14 -> 0 | AN14: =IF(BT14=1,0,15500000) -> 15500000 | AO14: 0 | AP14: =AO14*$AP$1 -> 0 | AQ14: =BF14*$AQ$1 -> 605600 | AR14: =BF14*$AR$1 -> 113550 | AS14: =BG14*$AS$1 -> 75700 | AT14: =+AS14+AR14+AQ14 -> 794850 | AU14: =IF(BT14=1,0,MIN(Y14,730000)) -> 730000 | AV14: =AJ14-AK14-AL14-AM14-AU14 -> 13349923 | AW14: =MAX(AV14-AN14-AP14-AT14,0) -> 0 | AX14: =IF(BT14=1,10%,IF(AW14>0,IF(AW14>80000000,0.35,IF(AW14>52000000,0.3,IF(AW14>32000000,0.25,IF(AW14>18000000,0.2,IF(AW14>10000000,0.15,IF(AW14>5000000,0.1,0.05)))))),0)) -> 0 | AY14: =IF(BT14=1,0,IF(AW14>80000000,9850000,IF(AW14>52000000,5850000,IF(AW14>32000000,3250000,IF(AW14>18000000,1650000,IF(AW14>10000000,750000,IF(AW14>5000000,250000,0))))))) -> 0 | AZ14: =ROUND(AW14*AX14-AY14,0) -> 0 | BA14: =BF14*$BA$1 -> 1286900 | BB14: =BF14*$BB$1 -> 227100 | BC14: =BG14*$BC$1 -> 75700 | BD14: =BG14*$BD$1 -> 37850 | BE14: =SUM(BA14:BD14) -> 1627550 | BF14: =MIN((IF(BS14=1,K14,0)),$BF$1) -> 7570000 | BG14: =MIN((IF(BS14=1,K14,0)),$BG$1) -> 7570000 | BH14: 0 | BI14: 0 | BJ14: =IF(BS14=1,BF14*2%,0) -> 151400 | BK14: =IF(BU14=1,40000,0) -> 40000 | BL14: =IF(BV14=0,0,IF(J14<11000000,5000,IF(J14<25000000,10000,IF(J14<40000000,15000,20000)))*BW14) -> 0 | BM14: =AJ14-AT14-AZ14-BK14-BL14-BN14-BO14-BP14 -> 12402044 | BN14: =IFERROR(VLOOKUP(B14,'Benefit tính thuế'!$B$2:$H$5,7,0),0) -> 1000000 | BO14: 0 | BP14: 0 | BQ14: =AN14+AP14+AU14 -> 16230000 | BR14: =+AZ14+AT14 -> 794850 | BS14: 1 | BT14: 0 | BU14: 1 | BV14: 0 | BW14: 20
A15: 1 | B15: PVT2500118 | D15: Nggo Van Tuan | E15: 45738 | F15: PVT - Operation | G15: PP. Center | H15: Staff | I15: Shipper Staff | J15: 11000000 | K15: 5800000 | L15: =J15-K15 -> 5200000 | M15: 26 | N15: =IFERROR(VLOOKUP(B15,' TimeTB 1'!$C$4:$AU$5,45,0),0) -> 4 | O15: =VLOOKUP(B15,'TimeTB 2'!$C$4:$AU$11,45,0) -> 26 | P15: =ROUND((K15/M15*N15),0) -> 892308 | Q15: =ROUND(K15/M15*O15,0) -> 5800000 | R15: =SUM(P15:Q15) -> 6692308 | S15: =ROUND(L15/26*N15,0) -> 800000 | T15: =ROUND(L15/26*O15,0) -> 5200000 | U15: =SUM(S15:T15) -> 6000000 | V15: 0 | W15: 0 | X15: 0 | Y15: =VLOOKUP(B15,'PC cơm '!$B$3:$L$11,11,0) -> 1120000 | Z15: =SUM(V15:Y15) -> 1120000 | AA15: =VLOOKUP(B15,'OT '!$B$4:$R$11,17,0) -> 2488221 | AB15: =VLOOKUP(B15,NS!$B$9:$G$16,6,0) -> 95192 | AC15: 0 | AD15: 0 | AE15: 0 | AF15: =ROUND(J15/26*AE15,0) -> 0 | AG15: =IFERROR(VLOOKUP(B15,Incentive!$B$9:$H$11,7,0),0) -> 5610000 | AH15: =SUMIF(Others!$B$8:$B$15,$B15,Others!$F$8:$F$15) -> 0 | AI15: 0 | AJ15: =AI15+AH15+AG15+AF15+AD15+AC15+AB15+AA15+Z15+U15+R15+BN15 -> 22005721 | AK15: =VLOOKUP(B15,'OT '!$B$4:$T$11,19,0) -> 0 | AL15: =VLOOKUP(B15,NS!$B$9:$I$16,8,0) -> 0 | AM15: =AI15 -> 0 | AN15: =IF(BT15=1,0,15500000) -> 0 | AO15: 0 | AP15: =AO15*$AP$1 -> 0 | AQ15: =BF15*$AQ$1 -> 0 | AR15: =BF15*$AR$1 -> 0 | AS15: =BG15*$AS$1 -> 0 | AT15: =+AS15+AR15+AQ15 -> 0 | AU15: =IF(BT15=1,0,MIN(Y15,730000)) -> 0 | AV15: =AJ15-AK15-AL15-AM15-AU15 -> 22005721 | AW15: =MAX(AV15-AN15-AP15-AT15,0) -> 22005721 | AX15: =IF(BT15=1,10%,IF(AW15>0,IF(AW15>80000000,0.35,IF(AW15>52000000,0.3,IF(AW15>32000000,0.25,IF(AW15>18000000,0.2,IF(AW15>10000000,0.15,IF(AW15>5000000,0.1,0.05)))))),0)) -> 0.1 | AY15: =IF(BT15=1,0,IF(AW15>80000000,9850000,IF(AW15>52000000,5850000,IF(AW15>32000000,3250000,IF(AW15>18000000,1650000,IF(AW15>10000000,750000,IF(AW15>5000000,250000,0))))))) -> 0 | AZ15: =ROUND(AW15*AX15-AY15,0) -> 2200572 | BA15: =BF15*$BA$1 -> 0 | BB15: =BF15*$BB$1 -> 0 | BC15: =BG15*$BC$1 -> 0 | BD15: =BG15*$BD$1 -> 0 | BE15: =SUM(BA15:BD15) -> 0 | BF15: =MIN((IF(BS15=1,K15,0)),$BF$1) -> 0 | BG15: =MIN((IF(BS15=1,K15,0)),$BG$1) -> 0 | BH15: 0 | BI15: 0 | BJ15: =IF(BS15=1,BF15*2%,0) -> 0 | BK15: =IF(BU15=1,40000,0) -> 0 | BL15: =IF(BV15=0,0,IF(J15<11000000,5000,IF(J15<25000000,10000,IF(J15<40000000,15000,20000)))*BW15) -> 0 | BM15: =AJ15-AT15-AZ15-BK15-BL15-BN15-BO15-BP15 -> 19805149 | BN15: =IFERROR(VLOOKUP(B15,'Benefit tính thuế'!$B$2:$H$5,7,0),0) -> 0 | BO15: 0 | BP15: 0 | BQ15: =AN15+AP15+AU15 -> 0 | BR15: =+AZ15+AT15 -> 2200572 | BS15: 0 | BT15: 1 | BU15: 0 | BV15: 0 | BW15: 20
A16: TOTAL | G16: 427 | J16: =SUM(J3:J15)/2 -> 106345000 | K16: =SUM(K3:K15)/2 -> 48395000 | L16: =SUM(L3:L15)/2 -> 57950000 | M16: =SUM(M3:M15)/2 -> 195 | N16: =SUM(N3:N15)/2 -> 6 | O16: =SUM(O3:O15)/2 -> 184 | P16: =SUM(P3:P15)/2 -> 1300770 | Q16: =SUM(Q3:Q15)/2 -> 46061538 | ... BV16: =SUM(BV3:BV15)/2 -> 2
N17: TB1 | O17: TB2 | Y17: PC com | AA17: OT | AB17: NS | AG17: Incentive | AH17: Others | AK17: OT | AL17: NS | BN17: Benefit
B18: Prepared by | M18: Checked By | AE18: Checked By | AZ18: Approved By
B23: Store / Retail

Sheet PC cơm 
A1: No | B1: Emp. Code | C1: Full Name | D1: Join Date | E1: Dept/Div | F1: Actual work days (excl. Holidays) | G1: OT days ≥ 4 hours | H1: Work days on Holidays | I1: Amount for actual work days (excl. Holidays) | J1: Amount for OT days ≥ 4 hours | K1: Amount for work on Holidays | L1: Total Amount | M1: Notes
I2: 40000 | J2: 40000 | K2: 80000
A3: =ROW()-6 -> -3 | B3: SLA2500111 | C3: Nguyễn Thị Hà | D3: 43466 | E3: Store Management | F3: =VLOOKUP($B3,'TimeTB 2'!$C$4:$AX$11,46,0) -> 25 | G3: =VLOOKUP($B3,'TimeTB 2'!$C$4:$AX$11,48,0) -> 0 | H3: =VLOOKUP($B3,'TimeTB 2'!$C$4:$AX$11,47,0) -> 0 | I3: =F3*$I$2 -> 1000000 | J3: =G3*$J$2 -> 0 | K3: =H3*$K$2 -> 0 | L3: =SUM(I3:K3) -> 1000000
A4: =ROW()-6 -> -2 | B4: PHI2500112 | C4: Phùng Mạnh Hà | D4: 43831 | E4: Cooperate Function | F4: =VLOOKUP(B4,'TimeTB 2'!$C$4:$AX$11,46,0) -> 26 | G4: =VLOOKUP($B4,'TimeTB 2'!$C$4:$AX$11,48,0) -> 0 | H4: =VLOOKUP($B4,'TimeTB 2'!$C$4:$AX$11,47,0) -> 1 | I4: =F4*$I$2 -> 1040000 | J4: =G4*$J$2 -> 0 | K4: =H4*$K$2 -> 80000 | L4: =SUM(I4:K4) -> 1120000
A5: =ROW()-6 -> -1 | B5: PVT2500113 | C5: Nguyễn Đức Khánh | D5: 44197 | E5: PP. Center | F5: =VLOOKUP(B5,'TimeTB 2'!$C$4:$AX$11,46,0) -> 24 | G5: =VLOOKUP($B5,'TimeTB 2'!$C$4:$AX$11,48,0) -> 0 | H5: =VLOOKUP($B5,'TimeTB 2'!$C$4:$AX$11,47,0) -> 0 | I5: =F5*$I$2 -> 960000 | J5: =G5*$J$2 -> 0 | K5: =H5*$K$2 -> 0 | L5: =SUM(I5:K5) -> 960000
A6: =ROW()-6 -> 0 | B6: PVT2500114 | C6: Nguyễn Sơn Tùng | D6: 44562 | E6: Hr/Admin | F6: =VLOOKUP(B6,'TimeTB 2'!$C$4:$AX$11,46,0) -> 16 | G6: =VLOOKUP($B6,'TimeTB 2'!$C$4:$AX$11,48,0) -> 0 | H6: =VLOOKUP($B6,'TimeTB 2'!$C$4:$AX$11,47,0) -> 1 | I6: =F6*$I$2 -> 640000 | J6: =G6*$J$2 -> 0 | K6: =H6*$K$2 -> 80000 | L6: =SUM(I6:K6) -> 720000
A7: =ROW()-6 -> 1 | B7: PVT2500115 | C7: Nguyễn Quang Cường | D7: 45740 | E7: Hr/Admin | F7: =VLOOKUP(B7,'TimeTB 2'!$C$4:$AX$11,46,0) -> 26 | G7: =VLOOKUP($B7,'TimeTB 2'!$C$4:$AX$11,48,0) -> 0 | H7: =VLOOKUP($B7,'TimeTB 2'!$C$4:$AX$11,47,0) -> 1 | I7: =F7*$I$2 -> 1040000 | J7: =G7*$J$2 -> 0 | K7: =H7*$K$2 -> 80000 | L7: =SUM(I7:K7) -> 1120000
A8: =ROW()-6 -> 2 | B8: PVT2500116 | C8: Phạm Đức Kiên | D8: 44927 | E8: Cashier | F8: =VLOOKUP(B8,'TimeTB 2'!$C$4:$AX$11,46,0) -> 26 | G8: =VLOOKUP($B8,'TimeTB 2'!$C$4:$AX$11,48,0) -> 0 | H8: =VLOOKUP($B8,'TimeTB 2'!$C$4:$AX$11,47,0) -> 1 | I8: =F8*$I$2 -> 1040000 | J8: =G8*$J$2 -> 0 | K8: =H8*$K$2 -> 80000 | L8: =SUM(I8:K8) -> 1120000
A9: =ROW()-6 -> 3 | B9: PVT2500117 | C9: Nguyễn Văn Quân | D9: 45292 | E9: Cashier | F9: =VLOOKUP(B9,'TimeTB 2'!$C$4:$AX$11,46,0) -> 24 | G9: =VLOOKUP($B9,'TimeTB 2'!$C$4:$AX$11,48,0) -> 0 | H9: =VLOOKUP($B9,'TimeTB 2'!$C$4:$AX$11,47,0) -> 0 | I9: =F9*$I$2 -> 960000 | J9: =G9*$J$2 -> 0 | K9: =H9*$K$2 -> 0 | L9: =SUM(I9:K9) -> 960000
A10: =ROW()-6 -> 4 | B10: PVT2500118 | C10: Ngô Văn Tuấn | D10: 45738 | E10: PP. Center | F10: =VLOOKUP(B10,'TimeTB 2'!$C$4:$AX$11,46,0) -> 26 | G10: =VLOOKUP($B10,'TimeTB 2'!$C$4:$AX$11,48,0) -> 0 | H10: =VLOOKUP($B10,'TimeTB 2'!$C$4:$AX$11,47,0) -> 1 | I10: =F10*$I$2 -> 1040000 | J10: =G10*$J$2 -> 0 | K10: =H10*$K$2 -> 80000 | L10: =SUM(I10:K10) -> 1120000
A11: TỔNG | F11: =SUM(F3:F10) -> 193 | G11: =SUM(G3:G10) -> 0 | H11: =SUM(H3:H10) -> 5 | I11: =SUM(I3:I10) -> 7720000 | J11: =SUM(J3:J10) -> 0 | K11: =SUM(K3:K10) -> 400000 | L11: =SUM(L3:L10) -> 8120000
B14: Lập bảng | E14: Kiểm tra | L14: Phê duyệt
E21: Dept./Div.
B34: Prepared by | E34: Checked by | L34: Approved by

Sheet TimeTB 2
B1: TT | C1: CODE VN | D1: Full Name | E1: Joinging date | F1: Dept | G1: Sub. Dept | H1: Job Title | I1: REMARK | J1: 45742 | M1: =EOMONTH(J1,0)+1 -> 45748 | AO1: Total OFF days | AP1: Unpaid leave | AQ1: Nghỉ hưởng lương (Nghỉ Phép/ Nghỉ Bù/ Nghỉ chế độ/ Nghỉ Lễ) | AR1: Actual working days | AS1: Total | AT1: Work adjustment | AU1: Total paid workdays | AV1: Total working days paid regular meals | AW1: Total working days pay for meals during Tet holidays | AX1: Total workdays pay for overtime meals | AY1: Note
J2: =J1 -> 45742 | K2: =+J2+1 -> 45743 | L2: =+K2+1 -> 45744 | M2: =+L2+1 -> 45745 | N2: =+M2+1 -> 45746 | O2: =+N2+1 -> 45747 | P2: =+O2+1 -> 45748 | Q2: =+P2+1 -> 45749 | R2: =+Q2+1 -> 45750 | ... AN2: =+AM2+1 -> 45772
J3: =TEXT(J2,"ddd") -> Wed | K3: =TEXT(K2,"ddd") -> Thu | L3: =TEXT(L2,"ddd") -> Fri | M3: =TEXT(M2,"ddd") -> Sat | N3: =TEXT(N2,"ddd") -> Sun | O3: =TEXT(O2,"ddd") -> Mon | P3: =TEXT(P2,"ddd") -> Tue | Q3: =TEXT(Q2,"ddd") -> Wed | ... AN3: =TEXT(AN2,"ddd") -> Fri
A4: 1 | B4: =ROW()-10 -> -6 | C4: SLA2500111 | D4: Nguyen Thi Ha | E4: 43466 | H4: Store Manager - Emart Phan Van Tri | J4: X | K4: X | L4: OFF | M4: X | N4: X | O4: X | P4: X | Q4: X | R4: X | T4: OFF | U4: X | V4: HL | W4: X | X4: X | Y4: X | Z4: OFF | AA4: X | AB4: X | AC4: X | AD4: X | AE4: X | AF4: X | AG4: X | AH4: X | AI4: OFF | AJ4: X | AK4: X | AL4: X | AM4: X | AN4: X | AO4: =COUNTIFS($J4:$AN4,"OFF ")+COUNTIFS($J4:$AN4,"OFF") -> 4 | AP4: =+COUNTIF(J4:AN4,"UP")+0.5*COUNTIF(J4:AN4,"1/2UP")+COUNTIFS(J4:AN4,"SL1")+COUNTIFS(J4:AN4,"ML")+COUNTIFS(J4:AN4,"CC") -> 0 | AQ4: =COUNTIF($J4:$AN4,"AL")+0.5*(COUNTIF($J4:$AN4,"1/2AL"))+COUNTIF($J4:$AN4,"CL")+0.5*(COUNTIF($J4:$AN4,"1/2CL"))+COUNTIF($J4:$AN4,"LS")+COUNTIF($J4:$AN4,"HL") -> 1 | AR4: =COUNTIF(J4:AN4,"X")+(COUNTIF(J4:AN4,"FP"))+COUNTIF(J4:AN4,"SL2")+(COUNTIF(J4:AN4,"LL"))+0.5*COUNTIF(J4:AN4,"1/2AL")+0.5*COUNTIF(J4:AN4,"1/2CL")+0.5*COUNTIF(J4:AN4,"1/2UP") -> 25 | AS4: =+AQ4+AR4 -> 26 | AU4: =MIN((AS4+AT4),26) -> 26 | AV4: =COUNTIF(J4:AN4,"X") -> 25 | AW4: =COUNTIF(V4:V4,"X") -> 0 | AX4: 0
A5: =+A3+1 -> 1 | B5: =ROW()-10 -> -5 | C5: PHI2500112 | D5: Phung Manh Ha | E5: 43831 | H5: Corporate Function Manager | J5: X | K5: X | L5: X | M5: OFF | N5: X | O5: X | P5: X | Q5: X | R5: X | S5: X | T5: X | U5: OFF | V5: X | W5: X | X5: X | Y5: X | Z5: X | AA5: OFF | AB5: X | AC5: X | AD5: X | AE5: X | AF5: X | AG5: X | AH5: OFF | AI5: X | AJ5: X | AK5: X | AL5: X | AM5: X | AN5: OFF | AO5: =COUNTIFS($J5:$AN5,"OFF ")+COUNTIFS($J5:$AN5,"OFF") -> 5 | AP5: =+COUNTIF(J5:AN5,"UP")+0.5*COUNTIF(J5:AN5,"1/2UP")+COUNTIFS(J5:AN5,"SL1")+COUNTIFS(J5:AN5,"ML")+COUNTIFS(J5:AN5,"CC") -> 0 | AQ5: =COUNTIF($J5:$AN5,"AL")+0.5*(COUNTIF($J5:$AN5,"1/2AL"))+COUNTIF($J5:$AN5,"CL")+0.5*(COUNTIF($J5:$AN5,"1/2CL"))+COUNTIF($J5:$AN5,"LS")+COUNTIF($J5:$AN5,"HL") -> 0 | AR5: =COUNTIF(J5:AN5,"X")+(COUNTIF(J5:AN5,"FP"))+COUNTIF(J5:AN5,"SL2")+(COUNTIF(J5:AN5,"LL"))+0.5*COUNTIF(J5:AN5,"1/2AL")+0.5*COUNTIF(J5:AN5,"1/2CL")+0.5*COUNTIF(J5:AN5,"1/2UP") -> 26 | AS5: =+AQ5+AR5 -> 26 | AU5: =MIN((AS5+AT5),26) -> 26 | AV5: =COUNTIF(J5:AN5,"X") -> 26 | AW5: =COUNTIF(V5:V5,"X") -> 1 | AX5: 0
A6: =+A4+1 -> 2 | B6: =ROW()-10 -> -4 | C6: PVT2500113 | D6: Nguyen Duc Khanh | E6: 44197 | H6: Admin Supervisor - Store Division | J6: X | L6: X | M6: X | N6: OFF | O6: X | P6: X | Q6: X | R6: X | S6: X | T6: OFF | U6: X | V6: HL | W6: X | X6: OFF | Y6: X | Z6: X | AA6: X | AB6: X | AC6: X | AD6: X | AE6: UP | AF6: X | AG6: X | AH6: X | AI6: OFF | AJ6: X | AK6: X | AL6: X | AM6: X | AN6: X | AO6: =COUNTIFS($J6:$AN6,"OFF ")+COUNTIFS($J6:$AN6,"OFF") -> 4 | AP6: =+COUNTIF(J6:AN6,"UP")+0.5*COUNTIF(J6:AN6,"1/2UP")+COUNTIFS(J6:AN6,"SL1")+COUNTIFS(J6:AN6,"ML")+COUNTIFS(J6:AN6,"CC") -> 1 | AQ6: =COUNTIF($J6:$AN6,"AL")+0.5*(COUNTIF($J6:$AN6,"1/2AL"))+COUNTIF($J6:$AN6,"CL")+0.5*(COUNTIF($J6:$AN6,"1/2CL"))+COUNTIF($J6:$AN6,"LS")+COUNTIF($J6:$AN6,"HL") -> 1 | AR6: =COUNTIF(J6:AN6,"X")+(COUNTIF(J6:AN6,"FP"))+COUNTIF(J6:AN6,"SL2")+(COUNTIF(J6:AN6,"LL"))+0.5*COUNTIF(J6:AN6,"1/2AL")+0.5*COUNTIF(J6:AN6,"1/2CL")+0.5*COUNTIF(J6:AN6,"1/2UP") -> 24 | AS6: =+AQ6+AR6 -> 25 | AU6: =MIN((AS6+AT6),26) -> 25 | AV6: =COUNTIF(J6:AN6,"X") -> 24 | AW6: =COUNTIF(V6:V6,"X") -> 0 | AX6: 0
A7: =+A6+1 -> 3 | B7: =ROW()-10 -> -3 | C7: PVT2500114 | D7: Nguyen Son Tung | E7: 44562 | H7: HR Supervisor - Store Division | J7: X | K7: X | L7: X | M7: X | N7: OFF | O7: X | P7: X | Q7: X | R7: X | S7: X | T7: X | U7: OFF | V7: X | W7: X | X7: X | Y7: X | Z7: X | AA7: X | AO7: =COUNTIFS($J7:$AN7,"OFF ")+COUNTIFS($J7:$AN7,"OFF") -> 2 | AP7: =+COUNTIF(J7:AN7,"UP")+0.5*COUNTIF(J7:AN7,"1/2UP")+COUNTIFS(J7:AN7,"SL1")+COUNTIFS(J7:AN7,"ML")+COUNTIFS(J7:AN7,"CC") -> 0 | AQ7: =COUNTIF($J7:$AN7,"AL")+0.5*(COUNTIF($J7:$AN7,"1/2AL"))+COUNTIF($J7:$AN7,"CL")+0.5*(COUNTIF($J7:$AN7,"1/2CL"))+COUNTIF($J7:$AN7,"LS")+COUNTIF($J7:$AN7,"HL") -> 0 | AR7: =COUNTIF(J7:AN7,"X")+(COUNTIF(J7:AN7,"FP"))+COUNTIF(J7:AN7,"SL2")+(COUNTIF(J7:AN7,"LL"))+0.5*COUNTIF(J7:AN7,"1/2AL")+0.5*COUNTIF(J7:AN7,"1/2CL")+0.5*COUNTIF(J7:AN7,"1/2UP") -> 16 | AS7: =+AQ7+AR7 -> 16 | AU7: =MIN((AS7+AT7),26) -> 16 | AV7: =COUNTIF(J7:AN7,"X") -> 16 | AW7: =COUNTIF(V7:V7,"X") -> 1 | AX7: 0
A8: =+A7+1 -> 4 | B8: =ROW()-10 -> -2 | C8: PVT2500115 | D8: Nguyen Quang Cuong | E8: 45740 | H8: HR Staff - Store Divison | J8: X | K8: OFF | L8: X | M8: X | N8: X | O8: X | P8: X | Q8: OFF | R8: X | S8: X | T8: X | U8: X | V8: X | W8: X | X8: X | Y8: OFF | Z8: X | AA8: X | AB8: X | AC8: X | AD8: X | AE8: 1/2AL | AF8: X | AG8: X | AH8: X | AI8: OFF | AJ8: X | AK8: X | AL8: X | AM8: X | AN8: X | AO8: =COUNTIFS($J8:$AN8,"OFF ")+COUNTIFS($J8:$AN8,"OFF") -> 4 | AP8: =+COUNTIF(J8:AN8,"UP")+0.5*COUNTIF(J8:AN8,"1/2UP")+COUNTIFS(J8:AN8,"SL1")+COUNTIFS(J8:AN8,"ML")+COUNTIFS(J8:AN8,"CC") -> 0 | AQ8: =COUNTIF($J8:$AN8,"AL")+0.5*(COUNTIF($J8:$AN8,"1/2AL"))+COUNTIF($J8:$AN8,"CL")+0.5*(COUNTIF($J8:$AN8,"1/2CL"))+COUNTIF($J8:$AN8,"LS")+COUNTIF($J8:$AN8,"HL") -> 0.5 | AR8: =COUNTIF(J8:AN8,"X")+(COUNTIF(J8:AN8,"FP"))+COUNTIF(J8:AN8,"SL2")+(COUNTIF(J8:AN8,"LL"))+0.5*COUNTIF(J8:AN8,"1/2AL")+0.5*COUNTIF(J8:AN8,"1/2CL")+0.5*COUNTIF(J8:AN8,"1/2UP") -> 26.5 | AS8: =+AQ8+AR8 -> 27 | AU8: =MIN((AS8+AT8),26) -> 26 | AV8: =COUNTIF(J8:AN8,"X") -> 26 | AW8: =COUNTIF(V8:V8,"X") -> 1 | AX8: 0
A9: =+A8+1 -> 5 | B9: =ROW()-10 -> -1 | C9: PVT2500116 | D9: Pham Duc Kien | E9: 44927 | H9: QA Assistant | J9: X | K9: X | L9: X | M9: X | N9: OFF | O9: X | P9: OFF | Q9: X | R9: X | S9: X | T9: X | U9: X | V9: X | W9: X | X9: X | Y9: X | Z9: OFF | AA9: X | AB9: X | AC9: OFF | AD9: X | AE9: X | AF9: X | AG9: X | AH9: X | AI9: OFF | AJ9: X | AK9: X | AL9: X | AM9: X | AN9: X | AO9: =COUNTIFS($J9:$AN9,"OFF ")+COUNTIFS($J9:$AN9,"OFF") -> 5 | AP9: =+COUNTIF(J9:AN9,"UP")+0.5*COUNTIF(J9:AN9,"1/2UP")+COUNTIFS(J9:AN9,"SL1")+COUNTIFS(J9:AN9,"ML")+COUNTIFS(J9:AN9,"CC") -> 0 | AQ9: =COUNTIF($J9:$AN9,"AL")+0.5*(COUNTIF($J9:$AN9,"1/2AL"))+COUNTIF($J9:$AN9,"CL")+0.5*(COUNTIF($J9:$AN9,"1/2CL"))+COUNTIF($J9:$AN9,"LS")+COUNTIF($J9:$AN9,"HL") -> 0 | AR9: =COUNTIF(J9:AN9,"X")+(COUNTIF(J9:AN9,"FP"))+COUNTIF(J9:AN9,"SL2")+(COUNTIF(J9:AN9,"LL"))+0.5*COUNTIF(J9:AN9,"1/2AL")+0.5*COUNTIF(J9:AN9,"1/2CL")+0.5*COUNTIF(J9:AN9,"1/2UP") -> 26 | AS9: =+AQ9+AR9 -> 26 | AU9: =MIN((AS9+AT9),26) -> 26 | AV9: =COUNTIF(J9:AN9,"X") -> 26 | AW9: =COUNTIF(V9:V9,"X") -> 1 | AX9: 0
A10: =+A9+1 -> 6 | B10: =ROW()-10 -> 0 | C10: PVT2500117 | D10: Nguyen Van Quan | E10: 45292 | H10: Security Staff | J10: X | K10: X | L10: X | M10: X | N10: X | O10: X | P10: X | Q10: X | R10: OFF | S10: X | T10: X | U10: X | V10: HL | W10: X | X10: X | Y10: X | Z10: X | AA10: OFF | AB10: X | AC10: X | AD10: X | AE10: CL | AF10: X | AG10: OFF | AH10: X | AI10: X | AJ10: X | AK10: X | AL10: SL1 | AM10: X | AN10: OFF | AO10: =COUNTIFS($J10:$AN10,"OFF ")+COUNTIFS($J10:$AN10,"OFF") -> 4 | AP10: =+COUNTIF(J10:AN10,"UP")+0.5*COUNTIF(J10:AN10,"1/2UP")+COUNTIFS(J10:AN10,"SL1")+COUNTIFS(J10:AN10,"ML")+COUNTIFS(J10:AN10,"CC") -> 1 | AQ10: =COUNTIF($J10:$AN10,"AL")+0.5*(COUNTIF($J10:$AN10,"1/2AL"))+COUNTIF($J10:$AN10,"CL")+0.5*(COUNTIF($J10:$AN10,"1/2CL"))+COUNTIF($J10:$AN10,"LS")+COUNTIF($J10:$AN10,"HL") -> 2 | AR10: =COUNTIF(J10:AN10,"X")+(COUNTIF(J10:AN10,"FP"))+COUNTIF(J10:AN10,"SL2")+(COUNTIF(J10:AN10,"LL"))+0.5*COUNTIF(J10:AN10,"1/2AL")+0.5*COUNTIF(J10:AN10,"1/2CL")+0.5*COUNTIF(J10:AN10,"1/2UP") -> 24 | AS10: =+AQ10+AR10 -> 26 | AU10: =MIN((AS10+AT10),26) -> 26 | AV10: =COUNTIF(J10:AN10,"X") -> 24 | AW10: =COUNTIF(V10:V10,"X") -> 0 | AX10: 0
A11: =+A10+1 -> 7 | B11: =ROW()-10 -> 1 | C11: PVT2500118 | D11: Nggo Van Tuan | E11: 45738 | H11: Treasury Staff | J11: X | K11: X | L11: X | M11: X | N11: OFF | O11: X | P11: X | Q11: X | R11: X | S11: X | T11: X | U11: OFF | V11: X | W11: X | X11: X | Y11: FP | Z11: X | AA11: X | AB11: OFF | AC11: X | AD11: X | AE11: X | AF11: X | AG11: X | AH11: X | AI11: OFF | AJ11: X | AK11: X | AL11: X | AM11: X | AN11: X | AO11: =COUNTIFS($J11:$AN11,"OFF ")+COUNTIFS($J11:$AN11,"OFF") -> 4 | AP11: =+COUNTIF(J11:AN11,"UP")+0.5*COUNTIF(J11:AN11,"1/2UP")+COUNTIFS(J11:AN11,"SL1")+COUNTIFS(J11:AN11,"ML")+COUNTIFS(J11:AN11,"CC") -> 0 | AQ11: =COUNTIF($J11:$AN11,"AL")+0.5*(COUNTIF($J11:$AN11,"1/2AL"))+COUNTIF($J11:$AN11,"CL")+0.5*(COUNTIF($J11:$AN11,"1/2CL"))+COUNTIF($J11:$AN11,"LS")+COUNTIF($J11:$AN11,"HL") -> 0 | AR11: =COUNTIF(J11:AN11,"X")+(COUNTIF(J11:AN11,"FP"))+COUNTIF(J11:AN11,"SL2")+(COUNTIF(J11:AN11,"LL"))+0.5*COUNTIF(J11:AN11,"1/2AL")+0.5*COUNTIF(J11:AN11,"1/2CL")+0.5*COUNTIF(J11:AN11,"1/2UP") -> 27 | AS11: =+AQ11+AR11 -> 27 | AU11: =MIN((AS11+AT11),26) -> 26 | AV11: =COUNTIF(J11:AN11,"X") -> 26 | AW11: =COUNTIF(V11:V11,"X") -> 1 | AX11: 0
B12: Total | AO12: =SUM(AO4:AO11) -> 32 | AP12: =SUM(AP4:AP11) -> 2 | AQ12: =SUM(AQ4:AQ11) -> 4.5 | AR12: =SUM(AR4:AR11) -> 194.5 | AS12: =SUM(AS4:AS11) -> 199 | AU12: =SUM(AU4:AU11) -> 197 | AV12: =SUM(AV4:AV11) -> 193 | AW12: =SUM(AW4:AW11) -> 5 | AX12: =SUM(AX4:AX11) -> 0
C15: Regulations on timekeeping symbols
C16: X | D16: Go to work 01 day
C17: HL | D17: Holidays, Tet
C18: OFF | D18: 1 day off OFF weekly shifts
C19: AL | D19: Annual Leave/ Annual leave 01 day
C20: 1/2AL | D20: 1/2 Annual Leave/Annual leave 1/2 day + Work 1/2 day
C21: FP | D21: Full paid leave for personal affairs/Personal leave with pay for 01 day (marriage, bereavement...)
C22: UP | D22: Unpaid leave/Personal leave without pay for 01 day
C23: 1/2UP | D23: 1/2 Unpaid leave/Leave without pay for 1/2 day + Work 1/2 day
C24: SL1 | D24: Sick leave / Sick leave (entitled to social insurance)
C25: ML | D25: Maternity leave / Maternity leave
C26: CC | D26: Children care leave / Sick child leave / wife's birth leave (social insurance benefits)
C27: LL | D27: Lactation leave/ Leave early/ stay 1 hour late/ take 1 day off after 7 working days
... C30: 1/2CL | D30: 1/2 Compensation leave (in-lieu day-off)/ Compensation leave 1/2 day + Work 1/2 days

Sheet  TimeTB 1
A1: TT | B1: Division | C1: CODE VN | D1: Full Name | E1: Bộ Phận | F1: Joinging date | G1: 45444 | I1: 45689 | AK1: Tổng ngày Off | AL1: Total days/month | AM1: Nghỉ hưởng lương (Nghỉ Phép/ Nghỉ Bù/ Nghỉ chế độ/ Nghỉ Lễ) | AN1: Tổng ngày nghỉ có lương | AO1: Tổng ngày nghỉ không lương | AP1: Holiday | AQ1: Compensation | AR1: OT Sunday | AS1: OT Holiday | AT1: Ngày đi làm thực tế | AU1: NGÀY CÔNG TÍNH LƯƠNG
G2: 45411 | H2: 45412 | I2: 45566 | J2: 45567 | K2: 45568 | L2: 45569 | M2: 45570 | N2: 45571 | O2: 45572 | P2: 45573 | Q2: 45574 | R2: 45575 | S2: 45576 | T2: 45577 | U2: 45578 | V2: 45579 | W2: 45580 | X2: 45581 | Y2: 45582 | Z2: 45583 | AA2: 45584 | AB2: 45585 | AC2: 45586 | AD2: 45587 | AE2: 45588 | AF2: 45589 | AG2: 45590 | AH2: =1+AG2 -> 45591 | AI2: =1+AH2 -> 45592
G3: Sun | H3: Mon | I3: Tue | J3: Wed | K3: Thu | L3: Fri | M3: Sat | N3: Sun | O3: Mon | P3: Tue | Q3: Wed | R3: Thu | S3: Fri | T3: Sat | U3: Sun | V3: Mon | W3: Tue | X3: Wed | Y3: Thu | Z3: Fri | AA3: Sat | AB3: Sun | AC3: Mon | AD3: Tue | AE3: Wed | AF3: Thu | AG3: Fri | AH3: Mon | AI3: Mon | AJ3: Sat
A4: 1 | C4: PVT2500115 | D4: Nguyễn Văn Quân | F4: 45740 | G4: GV - PP. Center | H4: Staff | AF4: X | AG4: X | AK4: =COUNTIF(G4:AJ4,"OFF") -> 0 | AL4: =COUNTA(G4:AJ4) -> 4 | AM4: =COUNTIF(G4:AJ4,#REF!)+(COUNTIF(G4:AJ4,#REF!)/2) -> 0 | AN4: =COUNTIF(G4:AJ4,#REF!)+(COUNTIF(G4:AJ4,#REF!)/2) -> 0 | AO4: =COUNTIF(G4:AJ4,#REF!)+(COUNTIF(G4:AJ4,#REF!)/2)+COUNTIF(G4:AJ4,#REF!) -> 0 | AP4: =COUNTIF(G4:AJ4,#REF!) -> 0 | AQ4: =COUNTIF(G4:AJ4,#REF!)+(COUNTIF(G4:AJ4,#REF!)/2) -> 0 | AR4: =COUNTIF(G4:AJ4,#REF!)+(COUNTIF(G4:AJ4,#REF!)/2) -> 0 | AS4: =COUNTIF(G4:AJ4,#REF!)+(COUNTIF(G4:AJ4,#REF!)/2) -> 0 | AT4: =COUNTIF(G4:AG4,"X") -> 2 | AU4: =IF(OR(AT4=26,AT4=26),26,AT4) -> 2
A5: 2 | C5: PVT2500118 | D5: Ngô Văn Tuấn | F5: 45738 | G5: GV - PP. Center | H5: Staff | AD5: X | AE5: X | AF5: X | AG5: X | AK5: =COUNTIF(G5:AJ5,"OFF") -> 0 | AL5: =COUNTA(G5:AJ5) -> 6 | AM5: =COUNTIF(G5:AJ5,#REF!)+(COUNTIF(G5:AJ5,#REF!)/2) -> 0 | AN5: =COUNTIF(G5:AJ5,#REF!)+(COUNTIF(G5:AJ5,#REF!)/2) -> 0 | AO5: =COUNTIF(G5:AJ5,#REF!)+(COUNTIF(G5:AJ5,#REF!)/2)+COUNTIF(G5:AJ5,#REF!) -> 0 | AP5: =COUNTIF(G5:AJ5,#REF!) -> 0 | AQ5: =COUNTIF(G5:AJ5,#REF!)+(COUNTIF(G5:AJ5,#REF!)/2) -> 0 | AR5: =COUNTIF(G5:AJ5,#REF!)+(COUNTIF(G5:AJ5,#REF!)/2) -> 0 | AS5: =COUNTIF(G5:AJ5,#REF!)+(COUNTIF(G5:AJ5,#REF!)/2) -> 0 | AT5: =COUNTIF(G5:AG5,"X") -> 4 | AU5: =IF(OR(AT5=26,AT5=26),26,AT5) -> 4 | AX5: =VLOOKUP(C5,[20]Timetable_T03!$B$9:$AS$19,44,0) -> #N/A
A6: =ROW()-21 -> -15 | AK6: =COUNTIF(G6:AJ6,"OFF") -> 0 | AL6: =COUNTA(G6:AJ6) -> 0 | AM6: =COUNTIF(G6:AJ6,#REF!)+(COUNTIF(G6:AJ6,#REF!)/2) -> 0 | AN6: =COUNTIF(G6:AJ6,#REF!)+(COUNTIF(G6:AJ6,#REF!)/2) -> 0 | AO6: =COUNTIF(G6:AJ6,#REF!)+(COUNTIF(G6:AJ6,#REF!)/2)+COUNTIF(G6:AJ6,#REF!) -> 0 | AP6: =COUNTIF(G6:AJ6,#REF!) -> 0 | AQ6: =COUNTIF(G6:AJ6,#REF!)+(COUNTIF(G6:AJ6,#REF!)/2) -> 0 | AR6: =COUNTIF(G6:AJ6,#REF!)+(COUNTIF(G6:AJ6,#REF!)/2) -> 0 | AS6: =COUNTIF(G6:AJ6,#REF!)+(COUNTIF(G6:AJ6,#REF!)/2) -> 0 | AT6: =COUNTIF(G6:AG6,"X") -> 0 | AU6: =IF(OR(AT6=26,AT6=26),26,AT6) -> 0 | AX6: =VLOOKUP(C6,[20]Timetable_T03!$B$9:$AS$19,44,0) -> #N/A
A7: =ROW()-21 -> -14 | AK7: =COUNTIF(G7:AJ7,"OFF") -> 0 | AL7: =COUNTA(G7:AJ7) -> 0 | AM7: =COUNTIF(G7:AJ7,#REF!)+(COUNTIF(G7:AJ7,#REF!)/2) -> 0 | AN7: =COUNTIF(G7:AJ7,#REF!)+(COUNTIF(G7:AJ7,#REF!)/2) -> 0 | AO7: =COUNTIF(G7:AJ7,#REF!)+(COUNTIF(G7:AJ7,#REF!)/2)+COUNTIF(G7:AJ7,#REF!) -> 0 | AP7: =COUNTIF(G7:AJ7,#REF!) -> 0 | AQ7: =COUNTIF(G7:AJ7,#REF!)+(COUNTIF(G7:AJ7,#REF!)/2) -> 0 | AR7: =COUNTIF(G7:AJ7,#REF!)+(COUNTIF(G7:AJ7,#REF!)/2) -> 0 | AS7: =COUNTIF(G7:AJ7,#REF!)+(COUNTIF(G7:AJ7,#REF!)/2) -> 0 | AT7: =COUNTIF(G7:AG7,"X") -> 0 | AU7: =IF(OR(AT7=26,AT7=26),26,AT7) -> 0
A8: =ROW()-21 -> -13 | AK8: =COUNTIF(G8:AJ8,"OFF") -> 0 | AL8: =COUNTA(G8:AJ8) -> 0 | AM8: =COUNTIF(G8:AJ8,#REF!)+(COUNTIF(G8:AJ8,#REF!)/2) -> 0 | AN8: =COUNTIF(G8:AJ8,#REF!)+(COUNTIF(G8:AJ8,#REF!)/2) -> 0 | AO8: =COUNTIF(G8:AJ8,#REF!)+(COUNTIF(G8:AJ8,#REF!)/2)+COUNTIF(G8:AJ8,#REF!) -> 0 | AP8: =COUNTIF(G8:AJ8,#REF!) -> 0 | AQ8: =COUNTIF(G8:AJ8,#REF!)+(COUNTIF(G8:AJ8,#REF!)/2) -> 0 | AR8: =COUNTIF(G8:AJ8,#REF!)+(COUNTIF(G8:AJ8,#REF!)/2) -> 0 | AS8: =COUNTIF(G8:AJ8,#REF!)+(COUNTIF(G8:AJ8,#REF!)/2) -> 0 | AT8: =COUNTIF(G8:AG8,"X") -> 0 | AU8: =IF(OR(AT8=26,AT8=26),26,AT8) -> 0
A9: =ROW()-21 -> -12 | AK9: =COUNTIF(G9:AJ9,"OFF") -> 0 | AL9: =COUNTA(G9:AJ9) -> 0 | AM9: =COUNTIF(G9:AJ9,#REF!)+(COUNTIF(G9:AJ9,#REF!)/2) -> 0 | AN9: =COUNTIF(G9:AJ9,#REF!)+(COUNTIF(G9:AJ9,#REF!)/2) -> 0 | AO9: =COUNTIF(G9:AJ9,#REF!)+(COUNTIF(G9:AJ9,#REF!)/2)+COUNTIF(G9:AJ9,#REF!) -> 0 | AP9: =COUNTIF(G9:AJ9,#REF!) -> 0 | AQ9: =COUNTIF(G9:AJ9,#REF!)+(COUNTIF(G9:AJ9,#REF!)/2) -> 0 | AR9: =COUNTIF(G9:AJ9,#REF!)+(COUNTIF(G9:AJ9,#REF!)/2) -> 0 | AS9: =COUNTIF(G9:AJ9,#REF!)+(COUNTIF(G9:AJ9,#REF!)/2) -> 0 | AT9: =COUNTIF(G9:AG9,"X") -> 0 | AU9: =IF(OR(AT9=26,AT9=26),26,AT9) -> 0
A10: =ROW()-21 -> -11 | AK10: =COUNTIF(G10:AJ10,"OFF") -> 0 | AL10: =COUNTA(G10:AJ10) -> 0 | AM10: =COUNTIF(G10:AJ10,#REF!)+(COUNTIF(G10:AJ10,#REF!)/2) -> 0 | AN10: =COUNTIF(G10:AJ10,#REF!)+(COUNTIF(G10:AJ10,#REF!)/2) -> 0 | AO10: =COUNTIF(G10:AJ10,#REF!)+(COUNTIF(G10:AJ10,#REF!)/2)+COUNTIF(G10:AJ10,#REF!) -> 0 | AP10: =COUNTIF(G10:AJ10,#REF!) -> 0 | AQ10: =COUNTIF(G10:AJ10,#REF!)+(COUNTIF(G10:AJ10,#REF!)/2) -> 0 | AR10: =COUNTIF(G10:AJ10,#REF!)+(COUNTIF(G10:AJ10,#REF!)/2) -> 0 | AS10: =COUNTIF(G10:AJ10,#REF!)+(COUNTIF(G10:AJ10,#REF!)/2) -> 0 | AT10: =COUNTIF(G10:AG10,"X") -> 0 | AU10: =IF(OR(AT10=26,AT10=26),26,AT10) -> 0
A11: =ROW()-21 -> -10 | AH11: X | AK11: =COUNTIF(G11:AJ11,"OFF") -> 0 | AL11: =COUNTA(G11:AJ11) -> 1 | AM11: =COUNTIF(G11:AJ11,#REF!)+(COUNTIF(G11:AJ11,#REF!)/2) -> 0 | AN11: =COUNTIF(G11:AJ11,#REF!)+(COUNTIF(G11:AJ11,#REF!)/2) -> 0 | AO11: =COUNTIF(G11:AJ11,#REF!)+(COUNTIF(G11:AJ11,#REF!)/2)+COUNTIF(G11:AJ11,#REF!) -> 0 | AP11: =COUNTIF(G11:AJ11,#REF!) -> 0 | AQ11: =COUNTIF(G11:AJ11,#REF!)+(COUNTIF(G11:AJ11,#REF!)/2) -> 0 | AR11: =COUNTIF(G11:AJ11,#REF!)+(COUNTIF(G11:AJ11,#REF!)/2) -> 0 | AS11: =COUNTIF(G11:AJ11,#REF!)+(COUNTIF(G11:AJ11,#REF!)/2) -> 0 | AT11: =COUNTIF(G11:AG11,"X") -> 0 | AU11: =IF(OR(AT11=26,AT11=26),26,AT11) -> 0
A12: Total | AK12: =SUM(AK4:AK11) -> 0 | AL12: =SUM(AL4:AL11) -> 11 | AM12: =SUM(AM4:AM11) -> 0 | AN12: =SUM(AN4:AN11) -> 0 | AO12: =SUM(AO4:AO11) -> 0 | AP12: =SUM(AP4:AP11) -> 0 | AQ12: =SUM(AQ4:AQ11) -> 0 | AR12: =SUM(AR4:AR11) -> 0 | ... AU12: =SUM(AU4:AU11) -> 6 | AV12: =SUM(AV11:AV11) -> 0
C16: Quy định ký hiệu chấm công
C17: X | D17: Đi làm 01 ngày
C18: HL | D18: Nghĩ Lễ, Tết
C19: OFF | D19: Nghỉ 1 ngày OFFca hàng tuần
C20: AL | D20: Annual Leave/ Nghỉ phép năm 01 ngày
C21: 1/2AL | D21: 1/2 Annual Leave/ Nghỉ phép năm 1/2 ngày + Đi làm 1/2 ngày
C22: FP | D22: Full paid leave for personal affairs/Nghỉ việc riêng có hưởng lương 01 ngày (kết hôn, tang chế...)
C23: UP | D23: Unpaid leave/ Nghỉ việc riêng không hưởng lương 01 ngày
C24: 1/2UP | D24: 1/2 Unpaid leave/ Nghỉ việc không hưởng lương 1/2 ngày + Đi làm 1/2 ngày
C25: SL1 | D25: Sick leave / Nghỉ bệnh (hưởng BHXH)
C26: ML | D26: Maternity leave / Nghỉ thai sản
C27: CC | D27: Children care leave / Nghỉ con ốm/ vợ sinh (hưởng BHXH)
C28: LL | D28: Lactation leave/ Về sớm/đi trễ 1 tiếng/nghỉ 1 ngày sau 7 ngày làm việc
... C31: 1/2CL | D31: 1/2 Compensation leave ( in-lieu day-off)/ Nghỉ bù 1/2 ngày + Đi làm 1/2 ngày

Sheet OT 
E1: Income salary | F1: Hour | L1: Overtime payment per hour | R1: Total payment (VND) | S1: Overtime taxable | T1: OT.Untaxable
A2: No. | B2: Emp. Code | C2: Full name | D2: Joinging date | E2: VND | F2: 1.5 | G2: 2.15 | H2: 2 | I2: 2.8 | J2: 3 | K2: 4.1 | L2: 1.5 | M2: 2.15 | N2: 2 | O2: 2.8 | P2: 3 | Q2: 4.1
B3: 1 | C3: =B3+1 -> 2 | D3: =C3+1 -> 3 | E3: =D3+1 -> 4 | F3: =E3+1 -> 5 | G3: =F3+1 -> 6 | H3: =G3+1 -> 7 | I3: =H3+1 -> 8 | J3: =I3+1 -> 9 | ... T3: =S3+1 -> 19
A4: =ROW()-6 -> -2 | B4: SLA2500111 | C4: Nguyễn Thị Hà | D4: 43466 | E4: =VLOOKUP(B4,'Template Payroll'!$B$3:$J$15,9,0) -> 47000000 | F4: 0 | G4: 0 | H4: 0 | I4: 0 | J4: 0 | K4: 0 | L4: =ROUND(E4/26/8*$L$2*F4,0) -> 0 | M4: =ROUND(E4/26/8*$M$2*G4,0) -> 0 | N4: =ROUND(E4/26/8*$N$2*H4,0) -> 0 | O4: =ROUND(E4/26/8*$O$2*I4,0) -> 0 | P4: =ROUND(E4/26/8*$P$2*J4,0) -> 0 | Q4: =ROUND(E4/26/8*$Q$2*K4,0) -> 0 | R4: =ROUND(SUM(L4:Q4),0) -> 0 | S4: =ROUND(SUM(F4:K4)*E4/26/8,0) -> 0 | T4: =ROUND(R4-S4,0) -> 0
A5: =ROW()-6 -> -1 | B5: PHI2500112 | C5: Phùng Mạnh Hà | D5: 43831 | E5: =VLOOKUP(B5,'Template Payroll'!$B$3:$J$15,9,0) -> 31000000 | F5: 0 | G5: 6 | H5: 0 | I5: 0 | J5: 6 | K5: 2 | L5: =ROUND(E5/26/8*$L$2*F5,0) -> 0 | M5: =ROUND(E5/26/8*$M$2*G5,0) -> 1922596 | N5: =ROUND(E5/26/8*$N$2*H5,0) -> 0 | O5: =ROUND(E5/26/8*$O$2*I5,0) -> 0 | P5: =ROUND(E5/26/8*$P$2*J5,0) -> 2682692 | Q5: =ROUND(E5/26/8*$Q$2*K5,0) -> 1222115 | R5: =ROUND(SUM(L5:Q5),0) -> 5827403 | S5: =ROUND(SUM(F5:K5)*E5/26/8,0) -> 2086538 | T5: =ROUND(R5-S5,0) -> 3740865
A6: =ROW()-6 -> 0 | B6: PVT2500113 | C6: Nguyễn Đức Khánh | D6: 44197 | E6: =VLOOKUP(B6,'Template Payroll'!$B$3:$J$15,9,0) -> 10448000 | F6: 0.5 | G6: 2.5 | H6: 0 | I6: 0 | J6: 0 | K6: 0 | L6: =ROUND(E6/26/8*$L$2*F6,0) -> 37673 | M6: =ROUND(E6/26/8*$M$2*G6,0) -> 269990 | N6: =ROUND(E6/26/8*$N$2*H6,0) -> 0 | O6: =ROUND(E6/26/8*$O$2*I6,0) -> 0 | P6: =ROUND(E6/26/8*$P$2*J6,0) -> 0 | Q6: =ROUND(E6/26/8*$Q$2*K6,0) -> 0 | R6: =ROUND(SUM(L6:Q6),0) -> 307663 | S6: =ROUND(SUM(F6:K6)*E6/26/8,0) -> 150692 | T6: =ROUND(R6-S6,0) -> 156971
A7: =ROW()-6 -> 1 | B7: PVT2500114 | C7: Nguyễn Sơn Tùng | D7: 44562 | E7: =VLOOKUP(B7,'Template Payroll'!$B$3:$J$15,9,0) -> 8000000 | F7: 0 | G7: 0 | H7: 0 | I7: 0 | J7: 7 | K7: 1 | L7: =ROUND(E7/26/8*$L$2*F7,0) -> 0 | M7: =ROUND(E7/26/8*$M$2*G7,0) -> 0 | N7: =ROUND(E7/26/8*$N$2*H7,0) -> 0 | O7: =ROUND(E7/26/8*$O$2*I7,0) -> 0 | P7: =ROUND(E7/26/8*$P$2*J7,0) -> 807692 | Q7: =ROUND(E7/26/8*$Q$2*K7,0) -> 157692 | R7: =ROUND(SUM(L7:Q7),0) -> 965384 | S7: =ROUND(SUM(F7:K7)*E7/26/8,0) -> 307692 | T7: =ROUND(R7-S7,0) -> 657692
A8: =ROW()-6 -> 2 | B8: PVT2500115 | C8: Nguyễn Quang Cường | D8: 45740 | E8: =VLOOKUP(B8,'Template Payroll'!$B$3:$J$15,9,0) -> 8500000 | F8: 0 | G8: 0 | H8: 0 | I8: 0 | J8: 8 | K8: 0 | L8: =ROUND(E8/26/8*$L$2*F8,0) -> 0 | M8: =ROUND(E8/26/8*$M$2*G8,0) -> 0 | N8: =ROUND(E8/26/8*$N$2*H8,0) -> 0 | O8: =ROUND(E8/26/8*$O$2*I8,0) -> 0 | P8: =ROUND(E8/26/8*$P$2*J8,0) -> 980769 | Q8: =ROUND(E8/26/8*$Q$2*K8,0) -> 0 | R8: =ROUND(SUM(L8:Q8),0) -> 980769 | S8: =R8 -> 980769 | T8: 0 | U8: HĐTV
A9: =ROW()-6 -> 3 | B9: PVT2500116 | C9: Phạm Đức Kiên | D9: 44927 | E9: =VLOOKUP(B9,'Template Payroll'!$B$3:$J$15,9,0) -> 7056000 | F9: 1 | G9: 9 | H9: 0 | I9: 0 | J9: 6 | K9: 2 | L9: =ROUND(E9/26/8*$L$2*F9,0) -> 50885 | M9: =ROUND(E9/26/8*$M$2*G9,0) -> 656412 | N9: =ROUND(E9/26/8*$N$2*H9,0) -> 0 | O9: =ROUND(E9/26/8*$O$2*I9,0) -> 0 | P9: =ROUND(E9/26/8*$P$2*J9,0) -> 610615 | Q9: =ROUND(E9/26/8*$Q$2*K9,0) -> 278169 | R9: =ROUND(SUM(L9:Q9),0) -> 1596081 | S9: =ROUND(SUM(F9:K9)*E9/26/8,0) -> 610615 | T9: =ROUND(R9-S9,0) -> 985466
A10: =ROW()-6 -> 4 | B10: PVT2500117 | C10: Nguyễn Văn Quân | D10: 45292 | E10: =VLOOKUP(B10,'Template Payroll'!$B$3:$J$15,9,0) -> 6841000 | F10: 0 | G10: 0 | H10: 0 | I10: 0 | J10: 0 | K10: 0 | L10: =ROUND(E10/26/8*$L$2*F10,0) -> 0 | M10: =ROUND(E10/26/8*$M$2*G10,0) -> 0 | N10: =ROUND(E10/26/8*$N$2*H10,0) -> 0 | O10: =ROUND(E10/26/8*$O$2*I10,0) -> 0 | P10: =ROUND(E10/26/8*$P$2*J10,0) -> 0 | Q10: =ROUND(E10/26/8*$Q$2*K10,0) -> 0 | R10: =ROUND(SUM(L10:Q10),0) -> 0 | S10: =ROUND(SUM(F10:K10)*E10/26/8,0) -> 0 | T10: =ROUND(R10-S10,0) -> 0
A11: =ROW()-6 -> 5 | B11: PVT2500118 | C11: Ngô Văn Tuấn | D11: 45738 | E11: =VLOOKUP(B11,'Template Payroll'!$B$3:$J$15,9,0) -> 11000000 | F11: 1 | G11: 9 | H11: 0 | I11: 0 | J11: 6 | K11: 2 | L11: =ROUND(E11/26/8*$L$2*F11,0) -> 79327 | M11: =ROUND(E11/26/8*$M$2*G11,0) -> 1023317 | N11: =ROUND(E11/26/8*$N$2*H11,0) -> 0 | O11: =ROUND(E11/26/8*$O$2*I11,0) -> 0 | P11: =ROUND(E11/26/8*$P$2*J11,0) -> 951923 | Q11: =ROUND(E11/26/8*$Q$2*K11,0) -> 433654 | R11: =ROUND(SUM(L11:Q11),0) -> 2488221 | S11: =R11 -> 2488221 | T11: 0 | U11: HĐTV
F12: =SUM(F4:F11) -> 2.5 | G12: =SUM(G4:G11) -> 26.5 | H12: =SUM(H4:H11) -> 0 | I12: =SUM(I4:I11) -> 0 | J12: =SUM(J4:J11) -> 33 | K12: =SUM(K4:K11) -> 7 | L12: =SUM(L4:L11) -> 167885 | M12: =SUM(M4:M11) -> 3872315 | ... T12: =SUM(T4:T11) -> 5540994

Sheet NS
A1: NIGHT SHIFT
F5: =SUBTOTAL(9,F9:F16) -> 23 | G5: =SUBTOTAL(9,G9:G16) -> 447853
A7: No. | B7: Emp. Code | C7: Full name | D7: Joinging date | E7: Income Salary | F7: Total hour night shift | G7: Payment night shift | H7: Night shift taxable | I7: Night shift untax
B8: 1 | C8: =B8+1 -> 2 | D8: 3 | E8: =D8+1 -> 4 | F8: =E8+1 -> 5 | G8: =F8+1 -> 6 | H8: =G8+1 -> 7 | I8: =H8+1 -> 8
A9: =ROW()-8 -> 1 | B9: SLA2500111 | C9: Nguyen Van A | D9: 43466 | E9: =IFERROR(VLOOKUP(B9,'Template Payroll'!$B$3:$J$12,9,0),0) -> 47000000 | F9: 2 | G9: =ROUND((E9/26/8)*30%*F9,0) -> 135577 | H9: =G9-I9 -> 0 | I9: =G9 -> 135577
A10: =ROW()-8 -> 2 | B10: PHI2500112 | C10: Nguyen Van B | D10: 43831 | E10: =IFERROR(VLOOKUP(B10,'Template Payroll'!$B$3:$J$12,9,0),0) -> 31000000 | F10: 3 | G10: =ROUND((E10/26/8)*30%*F10,0) -> 134135 | H10: =G10-I10 -> 0 | I10: =G10 -> 134135
A11: =ROW()-8 -> 3 | B11: PVT2500113 | C11: Nguyen Duc Khanh | D11: 44197 | E11: =IFERROR(VLOOKUP(B11,'Template Payroll'!$B$3:$J$12,9,0),0) -> 0 | F11: 4 | G11: =ROUND((E11/26/8)*30%*F11,0) -> 0 | H11: =G11-I11 -> 0 | I11: =G11 -> 0
A12: =ROW()-8 -> 4 | B12: PVT2500114 | C12: Nguyen Son Tung | D12: 44562 | E12: =IFERROR(VLOOKUP(B12,'Template Payroll'!$B$3:$J$12,9,0),0) -> 8000000 | F12: 1.5 | G12: =ROUND((E12/26/8)*30%*F12,0) -> 17308 | H12: =G12-I12 -> 0 | I12: =G12 -> 17308
A13: =ROW()-8 -> 5 | B13: PVT2500115 | C13: Nguyen Quang Cuong | D13: 45740 | E13: =IFERROR(VLOOKUP(B13,'Template Payroll'!$B$3:$J$12,9,0),0) -> 8500000 | F13: 0.5 | G13: =ROUND((E13/26/8)*30%*F13,0) -> 6130 | H13: =G13-I13 -> 6130
A14: =ROW()-8 -> 6 | B14: PVT2500116 | C14: Pham Duc Kien | D14: 44927 | E14: =IFERROR(VLOOKUP(B14,'Template Payroll'!$B$3:$J$12,9,0),0) -> 7056000 | F14: 1 | G14: =ROUND((E14/26/8)*30%*F14,0) -> 10177 | H14: =G14-I14 -> 0 | I14: =G14 -> 10177
A15: =ROW()-8 -> 7 | B15: PVT2500117 | C15: Nguyen Van Quan | D15: 45292 | E15: =IFERROR(VLOOKUP(B15,'Template Payroll'!$B$3:$J$12,9,0),0) -> 6841000 | F15: 5 | G15: =ROUND((E15/26/8)*30%*F15,0) -> 49334 | H15: =G15-I15 -> 0 | I15: =G15 -> 49334
A16: =ROW()-8 -> 8 | B16: PVT2500118 | C16: Nggo Van Tuan | D16: 45738 | E16: =IFERROR(VLOOKUP(B16,'Template Payroll'!$B$3:$J$15,9,0),0) -> 11000000 | F16: 6 | G16: =ROUND((E16/26/8)*30%*F16,0) -> 95192 | H16: =G16-I16 -> 95192
C17: Total | E17: =SUM(E9:E16) -> 119397000 | F17: =SUM(F9:F16) -> 23 | G17: =SUM(G9:G16) -> 447853 | H17: =SUM(H9:H16) -> 101322 | I17: =SUM(I9:I16) -> 346531

Sheet Incentive
A2: INCENTIVE
H3: =SUBTOTAL(9,H9:H10) -> 4600000 | I3: =SUBTOTAL(9,I9:I10) -> 0 | J3: =SUBTOTAL(9,J9:J12) -> 4000000 | K3: =SUBTOTAL(9,K9:K12) -> 600000
H4: =SUBTOTAL(9,H11:H11) -> 5610000 | I4: =SUBTOTAL(9,I11:I11) -> 5610000 | J4: =SUBTOTAL(9,J11:J11) -> 0 | K4: =SUBTOTAL(9,K11:K11) -> 0 | L4: =SUBTOTAL(9,L11:L11) -> #REF! | M4: =SUBTOTAL(9,M11:M11) -> #REF!
C6: 42004 | D6: 41974 | G6: c | H6: =SUBTOTAL(9,H9:H10) -> 4600000 | I6: =SUBTOTAL(9,I9:I10) -> 0 | J6: =SUBTOTAL(9,J9:J10) -> 4000000 | K6: =SUBTOTAL(9,K9:K10) -> 600000
D7: 44561 | F7: 42339 | G7: 364 | H7: =SUBTOTAL(9,H9:H12) -> 10210000 | I7: =SUBTOTAL(9,I9:I12) -> 5610000 | J7: =SUBTOTAL(9,J9:J12) -> 4000000 | K7: =SUBTOTAL(9,K9:K12) -> 600000
A8: No. | B8: Emp.Code | C8: Full Name | D8: Joining date | E8: Quit one's job | F8: Division | G8: Dept. | H8: Incentive | I8: PP.Shipper | J8: Cashier incentive | K8: Bill
A9: =SUBTOTAL(3,$B$9:B9) -> 1 | B9: PVT2500116 | C9: Pham Duc Kien | G9: Cashier | H9: =ROUND(SUM($I9:$K9),0) -> 2000000 | I9: 0 | J9: 2000000 | K9: 0 | L9: =VLOOKUP(B9,#REF!,36,0) -> #REF! | M9: =L9=H9 -> #REF!
A10: =SUBTOTAL(3,$B$9:B10) -> 2 | B10: PVT2500117 | C10: Nguyen Van Quan | G10: Cashier | H10: =ROUND(SUM($I10:$K10),0) -> 2600000 | I10: 0 | J10: 2000000 | K10: 600000 | L10: =VLOOKUP(B10,#REF!,36,0) -> #REF! | M10: =L10=H10 -> #REF!
A11: =SUBTOTAL(3,$B$9:B11) -> 3 | B11: PVT2500118 | C11: Nggo Van Tuan | G11: PP. Center | H11: =ROUND(SUM($I11:$K11),0) -> 5610000 | I11: 5610000 | L11: =VLOOKUP(B11,#REF!,36,0) -> #REF! | M11: =L11=H11 -> #REF!
A13: Total | H13: =SUM(H9:H12) -> 10210000 | I13: =SUM(I9:I12) -> 5610000 | J13: =SUM(J9:J12) -> 4000000 | K13: =SUM(K9:K12) -> 600000 | L13: =H13-I13-J13-K13 -> 0

Sheet Others
A2: THISO RETAIL
A3: 366 Phan Van Tri, Ward 5, Go Vap District, HCMC
A5: 1. Delivery coordination allowance
A6: No. | B6: Emp.Code | C6: Full Name | D6: Coordination allowance | E6: Workdays for salary calculation | F6: Amount
A9: 1 | B9: PVT2500113 | C9: Phung Manh Ha | D9: 2000000 | E9: =VLOOKUP(B9,'TimeTB 2'!$C$4:$AU$11,45,0) -> 25 | F9: =D9/26*E9 -> 1923076.9
F10: =E10*D10 -> 0
C11: Total | D11: =SUM(D9:D10) -> 2000000 | F11: =SUM(F9:F10) -> 1923076.9
A12: 2. Seniority CASHIER
A13: No. | B13: Emp.Code | C13: Full Name | D13: Seniority CASHIER | E13: Additional CASHIER seniority | F13: Amount
A14: 1 | B14: PVT2500114 | C14: Nguyen Duc Khanh | D14: 500000 | F14: =D14+E14 -> 500000
A15: =1+A14 -> 2 | B15: PVT2500115 | C15: Nguyen Son Tung | D15: 500000 | F15: =D15+E15 -> 500000
C16: Total | F16: =SUM(F14:F15) -> 1000000
A19: 3. Additional leave/work days (AL payment)
A20: No. | B20: Code | C20: Name | D20: Gross | E20: ALs | F20: Amount
A29: =ROW()-85 -> -56 | C29: =VLOOKUP($B29,#REF!,3,0) -> #REF! | D29: =IFERROR(VLOOKUP(B29,#REF!,81,0),0) -> 0 | F29: =ROUND((D29/26*E29),0) -> 0 | G29: =VLOOKUP(B29,#REF!,74,0) -> #REF! | H29: =G29-E29 -> #REF!
A30: =ROW()-85 -> -55 | C30: =VLOOKUP($B30,#REF!,3,0) -> #REF! | D30: =IFERROR(VLOOKUP(B30,#REF!,81,0),0) -> 0 | F30: =ROUND((D30/26*E30),0) -> 0 | G30: =VLOOKUP(B30,#REF!,74,0) -> #REF! | H30: =G30-E30 -> #REF!
A31: =ROW()-85 -> -54 | C31: =VLOOKUP($B31,#REF!,3,0) -> #REF! | D31: =IFERROR(VLOOKUP(B31,#REF!,81,0),0) -> 0 | F31: =ROUND((D31/26*E31),0) -> 0 | G31: =VLOOKUP(B31,#REF!,74,0) -> #REF! | H31: =G31-E31 -> #REF!
A32: =ROW()-85 -> -53 | C32: =VLOOKUP($B32,#REF!,3,0) -> #REF! | D32: =IFERROR(VLOOKUP(B32,#REF!,81,0),0) -> 0 | F32: =ROUND((D32/26*E32),0) -> 0 | G32: =VLOOKUP(B32,#REF!,74,0) -> #REF! | H32: =G32-E32 -> #REF!
A33: =ROW()-85 -> -52
